Workbook

Sheet Revenue_Budget
A1: FY | B1: Project | C1: Vertical | D1: Region | E1: Sub Region | F1: Region Head | G1: Practice Head | H1: 45748 | I1: =EDATE(H1,1) -> 45778 | J1: =EDATE(I1,1) -> 45809 | K1: =EDATE(J1,1) -> 45839 | L1: =EDATE(K1,1) -> 45870 | M1: =EDATE(L1,1) -> 45901 | N1: =EDATE(M1,1) -> 45931 | O1: =EDATE(N1,1) -> 45962 | P1: =EDATE(O1,1) -> 45992 | ... S1: =EDATE(R1,1) -> 46082
A2: FY2025-26 | B2: Honeywell | C2: =VLOOKUP(B2,Mapping!A:B,2,0) -> Lateral | D2: =VLOOKUP(B2,Mapping!A:C,3,0) -> South | E2: =VLOOKUP(B2,Mapping!A:D,4,0) -> South 1 | F2: =VLOOKUP(B2,Mapping!A:E,5,0) -> Bapi | G2: =VLOOKUP(B2,Mapping!A:F,6,0) -> Bapi | H2: 115.01649 | I2: 161.02309 | J2: 184.02639 | K2: 119.20399 | L2: 166.88559 | M2: 190.72639 | N2: 102.45399 | O2: 143.43559 | P2: 163.92639 | Q2: 120.04149 | R2: 168.05809 | S2: 192.06639
A3: FY2025-26 | B3: Pfizer | C3: =VLOOKUP(B3,Mapping!A:B,2,0) -> Lateral | D3: =VLOOKUP(B3,Mapping!A:C,3,0) -> West | E3: =VLOOKUP(B3,Mapping!A:D,4,0) -> West 1 | F3: =VLOOKUP(B3,Mapping!A:E,5,0) -> Anjli | G3: =VLOOKUP(B3,Mapping!A:F,6,0) -> Usha | H3: 9.75 | I3: 13.65 | J3: 15.6 | K3: 8.625 | L3: 12.075 | M3: 13.8 | N3: 5.625 | O3: 7.875 | P3: 9 | Q3: 9.6428625 | R3: 13.500008 | S3: 15.42858
A4: FY2025-26 | B4: Tata Motors | C4: =VLOOKUP(B4,Mapping!A:B,2,0) -> Lateral | D4: =VLOOKUP(B4,Mapping!A:C,3,0) -> West | E4: =VLOOKUP(B4,Mapping!A:D,4,0) -> West 2 | F4: =VLOOKUP(B4,Mapping!A:E,5,0) -> Anjli | G4: =VLOOKUP(B4,Mapping!A:F,6,0) -> Shweta | H4: 0 | I4: 0 | J4: 0 | K4: 0 | L4: 0 | M4: 0 | N4: 0 | O4: 0 | P4: 0 | Q4: 0 | R4: 0 | S4: 0
A5: FY2025-26 | B5: SKF India | C5: =VLOOKUP(B5,Mapping!A:B,2,0) -> Lateral | D5: =VLOOKUP(B5,Mapping!A:C,3,0) -> North | E5: =VLOOKUP(B5,Mapping!A:D,4,0) -> North | F5: =VLOOKUP(B5,Mapping!A:E,5,0) -> Anjli | G5: =VLOOKUP(B5,Mapping!A:F,6,0) -> Archana | H5: 13.9875 | I5: 19.5825 | J5: 22.38 | K5: 13.05 | L5: 18.27 | M5: 20.88 | N5: 10.6425 | O5: 14.8995 | P5: 17.028 | Q5: 12.2175 | R5: 17.1045 | S5: 19.548
A6: FY2025-26 | B6: Siemens | C6: =VLOOKUP(B6,Mapping!A:B,2,0) -> Lateral | D6: =VLOOKUP(B6,Mapping!A:C,3,0) -> South | E6: =VLOOKUP(B6,Mapping!A:D,4,0) -> South 1 | F6: =VLOOKUP(B6,Mapping!A:E,5,0) -> Sulabh | G6: =VLOOKUP(B6,Mapping!A:F,6,0) -> Kunal | H6: 17.625 | I6: 24.675 | J6: 28.2 | K6: 18.375 | L6: 25.725 | M6: 29.4 | N6: 17.625 | O6: 24.675 | P6: 28.2 | Q6: 15.105 | R6: 21.147 | S6: 24.168
A7: FY2025-26 | B7: Pidilite | C7: =VLOOKUP(B7,Mapping!A:B,2,0) -> Lateral | D7: =VLOOKUP(B7,Mapping!A:C,3,0) -> West | E7: =VLOOKUP(B7,Mapping!A:D,4,0) -> West 1 | F7: =VLOOKUP(B7,Mapping!A:E,5,0) -> Anjli | G7: =VLOOKUP(B7,Mapping!A:F,6,0) -> Usha | H7: 10.016875 | I7: 14.023625 | J7: 16.027 | K7: 11.6875 | L7: 16.3625 | M7: 18.7 | N7: 11.1875 | O7: 15.6625 | P7: 17.9 | Q7: 12.1875 | R7: 17.0625 | S7: 19.5
A8: FY2025-26 | B8: Vertiv | C8: =VLOOKUP(B8,Mapping!A:B,2,0) -> Lateral | D8: =VLOOKUP(B8,Mapping!A:C,3,0) -> West | E8: =VLOOKUP(B8,Mapping!A:D,4,0) -> West 2 | F8: =VLOOKUP(B8,Mapping!A:E,5,0) -> Anjli | G8: =VLOOKUP(B8,Mapping!A:F,6,0) -> Shweta | H8: 4.025 | I8: 5.635 | J8: 6.44 | K8: 4.65 | L8: 6.51 | M8: 7.44 | N8: 4.65 | O8: 6.51 | P8: 7.44 | Q8: 3.375 | R8: 4.725 | S8: 5.4
A9: FY2025-26 | B9: Birla Paints | C9: =VLOOKUP(B9,Mapping!A:B,2,0) -> Lateral | D9: =VLOOKUP(B9,Mapping!A:C,3,0) -> West | E9: =VLOOKUP(B9,Mapping!A:D,4,0) -> West 1 | F9: =VLOOKUP(B9,Mapping!A:E,5,0) -> Anjli | G9: =VLOOKUP(B9,Mapping!A:F,6,0) -> Geetu | H9: 7.5 | I9: 10.5 | J9: 12 | K9: 7.5 | L9: 10.5 | M9: 12 | N9: 7.5 | O9: 10.5 | P9: 12 | Q9: 7.5 | R9: 10.5 | S9: 12
A10: FY2025-26 | B10: Ingram Micro | C10: =VLOOKUP(B10,Mapping!A:B,2,0) -> Lateral | D10: =VLOOKUP(B10,Mapping!A:C,3,0) -> West | E10: =VLOOKUP(B10,Mapping!A:D,4,0) -> West 1 | F10: =VLOOKUP(B10,Mapping!A:E,5,0) -> Anjli | G10: =VLOOKUP(B10,Mapping!A:F,6,0) -> Geetu | H10: 6.9375 | I10: 9.7125 | J10: 11.1 | K10: 6.15 | L10: 8.61 | M10: 9.84 | N10: 5.25 | O10: 7.35 | P10: 8.4 | Q10: 6.5625 | R10: 9.1875 | S10: 10.5
A11: FY2025-26 | B11: HPE | C11: =VLOOKUP(B11,Mapping!A:B,2,0) -> Lateral | D11: =VLOOKUP(B11,Mapping!A:C,3,0) -> South | E11: =VLOOKUP(B11,Mapping!A:D,4,0) -> South 1 | F11: =VLOOKUP(B11,Mapping!A:E,5,0) -> Mahak | G11: =VLOOKUP(B11,Mapping!A:F,6,0) -> Mahak | H11: 90.74246 | I11: 127.03944 | J11: 145.18794 | K11: 103.77792 | L11: 145.28909 | M11: 166.04468 | N11: 92.472596 | O11: 129.46163 | P11: 147.95615 | Q11: 91.161021 | R11: 127.62543 | S11: 145.85763
A12: FY2025-26 | B12: Isuzu | C12: =VLOOKUP(B12,Mapping!A:B,2,0) -> Lateral | D12: =VLOOKUP(B12,Mapping!A:C,3,0) -> South | E12: =VLOOKUP(B12,Mapping!A:D,4,0) -> South 1 | F12: =VLOOKUP(B12,Mapping!A:E,5,0) -> Anjli | G12: =VLOOKUP(B12,Mapping!A:F,6,0) -> Satya | H12: 4.5375 | I12: 6.3525 | J12: 7.26 | K12: 6.05 | L12: 8.47 | M12: 9.68 | N12: 6.3975 | O12: 8.9565 | P12: 10.236 | Q12: 6.48 | R12: 9.072 | S12: 10.368
A13: FY2025-26 | B13: Mahindra Holidays | C13: =VLOOKUP(B13,Mapping!A:B,2,0) -> Lateral | D13: =VLOOKUP(B13,Mapping!A:C,3,0) -> West | E13: =VLOOKUP(B13,Mapping!A:D,4,0) -> West 1 | F13: =VLOOKUP(B13,Mapping!A:E,5,0) -> Anjli | G13: =VLOOKUP(B13,Mapping!A:F,6,0) -> Geetu | H13: 6.45 | I13: 9.03 | J13: 10.32 | K13: 6.45 | L13: 9.03 | M13: 10.32 | N13: 4 | O13: 5.6 | P13: 6.4 | Q13: 8 | R13: 11.2 | S13: 12.8
... A41: FY2025-26 | B41: M2P Fintech | C41: =VLOOKUP(B41,Mapping!A:B,2,0) -> Lateral | D41: =VLOOKUP(B41,Mapping!A:C,3,0) -> South | E41: =VLOOKUP(B41,Mapping!A:D,4,0) -> South 2 | F41: =VLOOKUP(B41,Mapping!A:E,5,0) -> Sulabh | G41: =VLOOKUP(B41,Mapping!A:F,6,0) -> Krishna | H41: 9.723616 | I41: 13.613062 | J41: 15.557786 | K41: 14.585424 | L41: 20.419594 | M41: 23.336678 | N41: 10.695978 | O41: 14.974369 | P41: 17.113564 | Q41: 13.613062 | R41: 19.058287 | S41: 21.7809
A42: FY2025-26 | B42: Tata Power | C42: =VLOOKUP(B42,Mapping!A:B,2,0) -> Lateral | D42: =VLOOKUP(B42,Mapping!A:C,3,0) -> West | E42: =VLOOKUP(B42,Mapping!A:D,4,0) -> West 1 | F42: =VLOOKUP(B42,Mapping!A:E,5,0) -> Anjli | G42: =VLOOKUP(B42,Mapping!A:F,6,0) -> Elton
A43: FY2025-26 | B43: ThyssenKrupp | C43: =VLOOKUP(B43,Mapping!A:B,2,0) -> Lateral | D43: =VLOOKUP(B43,Mapping!A:C,3,0) -> West | E43: =VLOOKUP(B43,Mapping!A:D,4,0) -> West 2 | F43: =VLOOKUP(B43,Mapping!A:E,5,0) -> Anjli | G43: =VLOOKUP(B43,Mapping!A:F,6,0) -> Shweta
A44: FY2025-26 | B44: Fedex | C44: =VLOOKUP(B44,Mapping!A:B,2,0) -> Lateral | D44: =VLOOKUP(B44,Mapping!A:C,3,0) -> West | E44: =VLOOKUP(B44,Mapping!A:D,4,0) -> West 1 | F44: =VLOOKUP(B44,Mapping!A:E,5,0) -> Anjli | G44: =VLOOKUP(B44,Mapping!A:F,6,0) -> Elton
A45: FY2025-26 | B45: Titan | C45: =VLOOKUP(B45,Mapping!A:B,2,0) -> Lateral | D45: =VLOOKUP(B45,Mapping!A:C,3,0) -> South | E45: =VLOOKUP(B45,Mapping!A:D,4,0) -> South 2 | F45: =VLOOKUP(B45,Mapping!A:E,5,0) -> Sulabh | G45: =VLOOKUP(B45,Mapping!A:F,6,0) -> Subu
A46: FY2025-26 | B46: Ultratech | C46: =VLOOKUP(B46,Mapping!A:B,2,0) -> Lateral | D46: =VLOOKUP(B46,Mapping!A:C,3,0) -> West | E46: =VLOOKUP(B46,Mapping!A:D,4,0) -> West 1 | F46: =VLOOKUP(B46,Mapping!A:E,5,0) -> Anjli | G46: =VLOOKUP(B46,Mapping!A:F,6,0) -> Elton
A47: FY2025-26 | B47: L&T (New) | C47: =VLOOKUP(B47,Mapping!A:B,2,0) -> Lateral | D47: =VLOOKUP(B47,Mapping!A:C,3,0) -> South | E47: =VLOOKUP(B47,Mapping!A:D,4,0) -> South 2 | F47: =VLOOKUP(B47,Mapping!A:E,5,0) -> Sulabh | G47: =VLOOKUP(B47,Mapping!A:F,6,0) -> Sulabh
A48: FY2025-26 | B48: DRL | C48: =VLOOKUP(B48,Mapping!A:B,2,0) -> Lateral | D48: =VLOOKUP(B48,Mapping!A:C,3,0) -> South | E48: =VLOOKUP(B48,Mapping!A:D,4,0) -> South 2 | F48: =VLOOKUP(B48,Mapping!A:E,5,0) -> Sulabh | G48: =VLOOKUP(B48,Mapping!A:F,6,0) -> Sulabh
A49: FY2025-26 | B49: Robert Bosch | C49: =VLOOKUP(B49,Mapping!A:B,2,0) -> Lateral | D49: =VLOOKUP(B49,Mapping!A:C,3,0) -> South | E49: =VLOOKUP(B49,Mapping!A:D,4,0) -> South 2 | F49: =VLOOKUP(B49,Mapping!A:E,5,0) -> Sulabh | G49: =VLOOKUP(B49,Mapping!A:F,6,0) -> Abhilash
A50: FY2025-26 | B50: Tata Teleservices | C50: =VLOOKUP(B50,Mapping!A:B,2,0) -> Lateral | D50: =VLOOKUP(B50,Mapping!A:C,3,0) -> West | E50: =VLOOKUP(B50,Mapping!A:D,4,0) -> West 1 | F50: =VLOOKUP(B50,Mapping!A:E,5,0) -> Anjli | G50: =VLOOKUP(B50,Mapping!A:F,6,0) -> Elton
A51: FY2025-26 | B51: Honeywell Leadership | C51: =VLOOKUP(B51,Mapping!A:B,2,0) -> Leadership | D51: =VLOOKUP(B51,Mapping!A:C,3,0) -> South | E51: =VLOOKUP(B51,Mapping!A:D,4,0) -> South 1 | F51: =VLOOKUP(B51,Mapping!A:E,5,0) -> Bapi | G51: =VLOOKUP(B51,Mapping!A:F,6,0) -> Parul | H51: 1.5 | I51: 2.1 | J51: 2.4 | K51: 1.25 | L51: 1.75 | M51: 2 | N51: 1.25 | O51: 1.75 | P51: 2 | Q51: 1.25 | R51: 1.75 | S51: 2
A52: FY2025-26 | B52: Siemens Leadership | C52: =VLOOKUP(B52,Mapping!A:B,2,0) -> Leadership | D52: =VLOOKUP(B52,Mapping!A:C,3,0) -> South | E52: =VLOOKUP(B52,Mapping!A:D,4,0) -> South 2 | F52: =VLOOKUP(B52,Mapping!A:E,5,0) -> Sulabh | G52: =VLOOKUP(B52,Mapping!A:F,6,0) -> Parul | H52: 1.25 | I52: 1.75 | J52: 2 | K52: 1.25 | L52: 1.75 | M52: 2 | N52: 1.25 | O52: 1.75 | P52: 2 | Q52: 1.25 | R52: 1.75 | S52: 2
A53: FY2025-26 | B53: Vertiv Leadership | C53: =VLOOKUP(B53,Mapping!A:B,2,0) -> Leadership | D53: =VLOOKUP(B53,Mapping!A:C,3,0) -> West | E53: =VLOOKUP(B53,Mapping!A:D,4,0) -> West 2 | F53: =VLOOKUP(B53,Mapping!A:E,5,0) -> Anjli | G53: =VLOOKUP(B53,Mapping!A:F,6,0) -> Parul | H53: 2 | I53: 2.8 | J53: 3.2 | K53: 2 | L53: 2.8 | M53: 3.2 | N53: 2 | O53: 2.8 | P53: 3.2 | Q53: 2 | R53: 2.8 | S53: 3.2
A54: FY2025-26 | B54: M&M Leadership | C54: =VLOOKUP(B54,Mapping!A:B,2,0) -> Leadership | D54: =VLOOKUP(B54,Mapping!A:C,3,0) -> West | E54: =VLOOKUP(B54,Mapping!A:D,4,0) -> West 1 | F54: =VLOOKUP(B54,Mapping!A:E,5,0) -> Anjli | G54: =VLOOKUP(B54,Mapping!A:F,6,0) -> Parul | H54: 8.75 | I54: 12.25 | J54: 14 | K54: 8.75 | L54: 12.25 | M54: 14 | N54: 21.25 | O54: 29.75 | P54: 34 | Q54: 21.25 | R54: 29.75 | S54: 34
A55: FY2025-26 | B55: AMNS Leadership | C55: =VLOOKUP(B55,Mapping!A:B,2,0) -> Leadership | D55: =VLOOKUP(B55,Mapping!A:C,3,0) -> West | E55: =VLOOKUP(B55,Mapping!A:D,4,0) -> West 1 | F55: =VLOOKUP(B55,Mapping!A:E,5,0) -> Anjli | G55: =VLOOKUP(B55,Mapping!A:F,6,0) -> Parul | H55: 4.375 | I55: 6.125 | J55: 7 | K55: 4.375 | L55: 6.125 | M55: 7 | N55: 4.375 | O55: 6.125 | P55: 7 | Q55: 4.375 | R55: 6.125 | S55: 7
A56: FY2025-26 | B56: Nagarjuna Leadership | C56: =VLOOKUP(B56,Mapping!A:B,2,0) -> Leadership | D56: =VLOOKUP(B56,Mapping!A:C,3,0) -> South | E56: =VLOOKUP(B56,Mapping!A:D,4,0) -> South 2 | F56: =VLOOKUP(B56,Mapping!A:E,5,0) -> Sulabh | G56: =VLOOKUP(B56,Mapping!A:F,6,0) -> Parul | H56: 0.25 | I56: 0.35 | J56: 0.4 | K56: 0.25 | L56: 0.35 | M56: 0.4 | N56: 0.25 | O56: 0.35 | P56: 0.4 | Q56: 0.25 | R56: 0.35 | S56: 0.4
A57: FY2025-26 | B57: Royal Enfield Leadership | C57: =VLOOKUP(B57,Mapping!A:B,2,0) -> Leadership | D57: =VLOOKUP(B57,Mapping!A:C,3,0) -> South | E57: =VLOOKUP(B57,Mapping!A:D,4,0) -> South 2 | F57: =VLOOKUP(B57,Mapping!A:E,5,0) -> Sulabh | G57: =VLOOKUP(B57,Mapping!A:F,6,0) -> Parul | H57: 0 | I57: 0 | J57: 0 | K57: 1.25 | L57: 1.75 | M57: 2 | N57: 0 | O57: 0 | P57: 0 | Q57: 0 | R57: 0 | S57: 0
A58: FY2025-26 | B58: Sterling Tools Leadership | C58: =VLOOKUP(B58,Mapping!A:B,2,0) -> Leadership | D58: =VLOOKUP(B58,Mapping!A:C,3,0) -> North | E58: =VLOOKUP(B58,Mapping!A:D,4,0) -> North | F58: =VLOOKUP(B58,Mapping!A:E,5,0) -> Anjli | G58: =VLOOKUP(B58,Mapping!A:F,6,0) -> Parul | H58: 0 | I58: 0 | J58: 0 | K58: 1.25 | L58: 1.75 | M58: 2 | N58: 0 | O58: 0 | P58: 0 | Q58: 0 | R58: 0 | S58: 0
A59: FY2025-26 | B59: Mahindra Holidays Leadership | C59: =VLOOKUP(B59,Mapping!A:B,2,0) -> Leadership | D59: =VLOOKUP(B59,Mapping!A:C,3,0) -> West | E59: =VLOOKUP(B59,Mapping!A:D,4,0) -> West 1 | F59: =VLOOKUP(B59,Mapping!A:E,5,0) -> Anjli | G59: =VLOOKUP(B59,Mapping!A:F,6,0) -> Parul | H59: 0 | I59: 0 | J59: 0 | K59: 0 | L59: 0 | M59: 0 | N59: 0 | O59: 0 | P59: 0 | Q59: 0 | R59: 0 | S59: 0
A60: FY2025-26 | B60: Hyundai Motor Leadership | C60: =VLOOKUP(B60,Mapping!A:B,2,0) -> Leadership | D60: =VLOOKUP(B60,Mapping!A:C,3,0) -> West | E60: =VLOOKUP(B60,Mapping!A:D,4,0) -> West 2 | F60: =VLOOKUP(B60,Mapping!A:E,5,0) -> Anjli | G60: =VLOOKUP(B60,Mapping!A:F,6,0) -> Parul | H60: 0 | I60: 0 | J60: 0 | K60: 0 | L60: 0 | M60: 0 | N60: 0 | O60: 0 | P60: 0 | Q60: 0 | R60: 0 | S60: 0
A61: FY2025-26 | B61: JINDAL STAINLESS Leadership | C61: =VLOOKUP(B61,Mapping!A:B,2,0) -> Leadership | D61: =VLOOKUP(B61,Mapping!A:C,3,0) -> North | E61: =VLOOKUP(B61,Mapping!A:D,4,0) -> North | F61: =VLOOKUP(B61,Mapping!A:E,5,0) -> Anjli | G61: =VLOOKUP(B61,Mapping!A:F,6,0) -> Parul | H61: 0 | I61: 0 | J61: 0 | K61: 0 | L61: 0 | M61: 0 | N61: 0 | O61: 0 | P61: 0 | Q61: 0 | R61: 0 | S61: 0
A62: FY2025-26 | B62: SUZUKI R&D Leadership | C62: =VLOOKUP(B62,Mapping!A:B,2,0) -> Leadership | D62: =VLOOKUP(B62,Mapping!A:C,3,0) -> North | E62: =VLOOKUP(B62,Mapping!A:D,4,0) -> North | F62: =VLOOKUP(B62,Mapping!A:E,5,0) -> Anjli | G62: =VLOOKUP(B62,Mapping!A:F,6,0) -> Parul | H62: 0 | I62: 0 | J62: 0 | K62: 0 | L62: 0 | M62: 0 | N62: 0 | O62: 0 | P62: 0 | Q62: 0 | R62: 0 | S62: 0
... A73: FY2025-26 | B73: ABB | C73: =VLOOKUP(B73,Mapping!A:B,2,0) -> Lateral | D73: =VLOOKUP(B73,Mapping!A:C,3,0) -> South | E73: =VLOOKUP(B73,Mapping!A:D,4,0) -> South 2 | F73: =VLOOKUP(B73,Mapping!A:E,5,0) -> Sulabh | G73: =VLOOKUP(B73,Mapping!A:F,6,0) -> Satya | H73: 0 | I73: 0 | J73: 0 | K73: 0 | L73: 0 | M73: 0 | N73: 0 | O73: 0 | P73: 0 | Q73: 0 | R73: 0 | S73: 0
A74: FY2025-26 | B74: TCG Group | C74: =VLOOKUP(B74,Mapping!A:B,2,0) -> Lateral | D74: =VLOOKUP(B74,Mapping!A:C,3,0) -> West | E74: =VLOOKUP(B74,Mapping!A:D,4,0) -> West 1 | F74: =VLOOKUP(B74,Mapping!A:E,5,0) -> Anjli | G74: =VLOOKUP(B74,Mapping!A:F,6,0) -> Anjli
A75: FY2025-26 | B75: Proterial | C75: =VLOOKUP(B75,Mapping!A:B,2,0) -> #N/A | D75: =VLOOKUP(B75,Mapping!A:C,3,0) -> #N/A | E75: =VLOOKUP(B75,Mapping!A:D,4,0) -> #N/A | F75: =VLOOKUP(B75,Mapping!A:E,5,0) -> #N/A | G75: =VLOOKUP(B75,Mapping!A:F,6,0) -> #N/A
A76: FY2025-26 | B76: CG Power | C76: =VLOOKUP(B76,Mapping!A:B,2,0) -> Lateral | D76: =VLOOKUP(B76,Mapping!A:C,3,0) -> West | E76: =VLOOKUP(B76,Mapping!A:D,4,0) -> West 1 | F76: =VLOOKUP(B76,Mapping!A:E,5,0) -> Anjli | G76: =VLOOKUP(B76,Mapping!A:F,6,0) -> Anjli

Sheet CM_Budget
A1: =Revenue_Budget!A1 -> FY | B1: =Revenue_Budget!B1 -> Project | C1: =Revenue_Budget!C1 -> Vertical | D1: =Revenue_Budget!D1 -> Region | E1: =Revenue_Budget!E1 -> Sub Region | F1: =Revenue_Budget!F1 -> Region Head | G1: =Revenue_Budget!G1 -> Practice Head | H1: =Revenue_Budget!H1 -> 45748 | ... S1: =Revenue_Budget!S1 -> 46082
A2: FY2025-26 | B2: Honeywell | C2: =VLOOKUP(B2,Mapping!A:B,2,0) -> Lateral | D2: =VLOOKUP(B2,Mapping!A:C,3,0) -> South | E2: =VLOOKUP(B2,Mapping!A:D,4,0) -> South 1 | F2: =VLOOKUP(B2,Mapping!A:E,5,0) -> Bapi | G2: =VLOOKUP(B2,Mapping!A:F,6,0) -> Bapi | H2: 64.189553 | I2: 89.865374 | J2: 102.70328 | K2: 66.526554 | L2: 93.137176 | M2: 106.44249 | N2: 57.178547 | O2: 80.049966 | P2: 91.485676 | Q2: 66.993955 | R2: 93.791537 | S2: 107.19033
A3: FY2025-26 | B3: Pfizer | C3: =VLOOKUP(B3,Mapping!A:B,2,0) -> Lateral | D3: =VLOOKUP(B3,Mapping!A:C,3,0) -> West | E3: =VLOOKUP(B3,Mapping!A:D,4,0) -> West 1 | F3: =VLOOKUP(B3,Mapping!A:E,5,0) -> Anjli | G3: =VLOOKUP(B3,Mapping!A:F,6,0) -> Usha | H3: 4.0111674 | I3: 5.6156344 | J3: 6.4178679 | K3: 3.5483404 | L3: 4.9676766 | M3: 5.6773447 | N3: 2.3141351 | O3: 3.2397891 | P3: 3.7026161 | Q3: 3.9670909 | R3: 5.5539273 | S3: 6.3473454
A4: FY2025-26 | B4: Tata Motors | C4: =VLOOKUP(B4,Mapping!A:B,2,0) -> Lateral | D4: =VLOOKUP(B4,Mapping!A:C,3,0) -> West | E4: =VLOOKUP(B4,Mapping!A:D,4,0) -> West 2 | F4: =VLOOKUP(B4,Mapping!A:E,5,0) -> Anjli | G4: =VLOOKUP(B4,Mapping!A:F,6,0) -> Shweta | H4: 0 | I4: 0 | J4: 0 | K4: 0 | L4: 0 | M4: 0 | N4: 0 | O4: 0 | P4: 0 | Q4: 0 | R4: 0 | S4: 0
A5: FY2025-26 | B5: SKF India | C5: =VLOOKUP(B5,Mapping!A:B,2,0) -> Lateral | D5: =VLOOKUP(B5,Mapping!A:C,3,0) -> North | E5: =VLOOKUP(B5,Mapping!A:D,4,0) -> North | F5: =VLOOKUP(B5,Mapping!A:E,5,0) -> Anjli | G5: =VLOOKUP(B5,Mapping!A:F,6,0) -> Archana | H5: 5.595 | I5: 7.833 | J5: 8.952 | K5: 5.22 | L5: 7.308 | M5: 8.352 | N5: 4.257 | O5: 5.9598 | P5: 6.8112 | Q5: 4.887 | R5: 6.8418 | S5: 7.8192
A6: FY2025-26 | B6: Siemens | C6: =VLOOKUP(B6,Mapping!A:B,2,0) -> Lateral | D6: =VLOOKUP(B6,Mapping!A:C,3,0) -> South | E6: =VLOOKUP(B6,Mapping!A:D,4,0) -> South 1 | F6: =VLOOKUP(B6,Mapping!A:E,5,0) -> Sulabh | G6: =VLOOKUP(B6,Mapping!A:F,6,0) -> Kunal | H6: 7.05 | I6: 9.87 | J6: 11.28 | K6: 7.35 | L6: 10.29 | M6: 11.76 | N6: 7.05 | O6: 9.87 | P6: 11.28 | Q6: 6.042 | R6: 8.4588 | S6: 9.6672
A7: FY2025-26 | B7: Pidilite | C7: =VLOOKUP(B7,Mapping!A:B,2,0) -> Lateral | D7: =VLOOKUP(B7,Mapping!A:C,3,0) -> West | E7: =VLOOKUP(B7,Mapping!A:D,4,0) -> West 1 | F7: =VLOOKUP(B7,Mapping!A:E,5,0) -> Anjli | G7: =VLOOKUP(B7,Mapping!A:F,6,0) -> Usha | H7: 4.00675 | I7: 5.60945 | J7: 6.4108 | K7: 4.675 | L7: 6.545 | M7: 7.48 | N7: 4.475 | O7: 6.265 | P7: 7.16 | Q7: 4.875 | R7: 6.825 | S7: 7.8
A8: FY2025-26 | B8: Vertiv | C8: =VLOOKUP(B8,Mapping!A:B,2,0) -> Lateral | D8: =VLOOKUP(B8,Mapping!A:C,3,0) -> West | E8: =VLOOKUP(B8,Mapping!A:D,4,0) -> West 2 | F8: =VLOOKUP(B8,Mapping!A:E,5,0) -> Anjli | G8: =VLOOKUP(B8,Mapping!A:F,6,0) -> Shweta | H8: 1.7927307 | I8: 2.509823 | J8: 2.8683691 | K8: 2.071105 | L8: 2.899547 | M8: 3.313768 | N8: 2.071105 | O8: 2.899547 | P8: 3.313768 | Q8: 1.5032214 | R8: 2.1045099 | S8: 2.4051542
A9: FY2025-26 | B9: Birla Paints | C9: =VLOOKUP(B9,Mapping!A:B,2,0) -> Lateral | D9: =VLOOKUP(B9,Mapping!A:C,3,0) -> West | E9: =VLOOKUP(B9,Mapping!A:D,4,0) -> West 1 | F9: =VLOOKUP(B9,Mapping!A:E,5,0) -> Anjli | G9: =VLOOKUP(B9,Mapping!A:F,6,0) -> Geetu | H9: 3 | I9: 4.2 | J9: 4.8 | K9: 3 | L9: 4.2 | M9: 4.8 | N9: 3 | O9: 4.2 | P9: 4.8 | Q9: 3 | R9: 4.2 | S9: 4.8
A10: FY2025-26 | B10: Ingram Micro | C10: =VLOOKUP(B10,Mapping!A:B,2,0) -> Lateral | D10: =VLOOKUP(B10,Mapping!A:C,3,0) -> West | E10: =VLOOKUP(B10,Mapping!A:D,4,0) -> West 1 | F10: =VLOOKUP(B10,Mapping!A:E,5,0) -> Anjli | G10: =VLOOKUP(B10,Mapping!A:F,6,0) -> Geetu | H10: 3.1471675 | I10: 4.4060345 | J10: 5.0354681 | K10: 2.7899215 | L10: 3.9058901 | M10: 4.4638744 | N10: 2.3816403 | O10: 3.3342964 | P10: 3.8106245 | Q10: 2.9770504 | R10: 4.1678705 | S10: 4.7632806
A11: FY2025-26 | B11: HPE | C11: =VLOOKUP(B11,Mapping!A:B,2,0) -> Lateral | D11: =VLOOKUP(B11,Mapping!A:C,3,0) -> South | E11: =VLOOKUP(B11,Mapping!A:D,4,0) -> South 1 | F11: =VLOOKUP(B11,Mapping!A:E,5,0) -> Mahak | G11: =VLOOKUP(B11,Mapping!A:F,6,0) -> Mahak | H11: 36.296984 | I11: 50.815778 | J11: 58.075175 | K11: 41.511169 | L11: 58.115637 | M11: 66.41787 | N11: 36.989038 | O11: 51.784654 | P11: 59.182461 | Q11: 36.464409 | R11: 51.050172 | S11: 58.343054
A12: FY2025-26 | B12: Isuzu | C12: =VLOOKUP(B12,Mapping!A:B,2,0) -> Lateral | D12: =VLOOKUP(B12,Mapping!A:C,3,0) -> South | E12: =VLOOKUP(B12,Mapping!A:D,4,0) -> South 1 | F12: =VLOOKUP(B12,Mapping!A:E,5,0) -> Anjli | G12: =VLOOKUP(B12,Mapping!A:F,6,0) -> Satya | H12: 2.676132 | I12: 3.7465848 | J12: 4.2818112 | K12: 3.568176 | L12: 4.9954463 | M12: 5.7090815 | N12: 3.7731249 | O12: 5.2823749 | P12: 6.0369999 | Q12: 3.8217819 | R12: 5.3504946 | S12: 6.114851
A13: FY2025-26 | B13: Mahindra Holidays | C13: =VLOOKUP(B13,Mapping!A:B,2,0) -> Lateral | D13: =VLOOKUP(B13,Mapping!A:C,3,0) -> West | E13: =VLOOKUP(B13,Mapping!A:D,4,0) -> West 1 | F13: =VLOOKUP(B13,Mapping!A:E,5,0) -> Anjli | G13: =VLOOKUP(B13,Mapping!A:F,6,0) -> Geetu | H13: 2.58 | I13: 3.612 | J13: 4.128 | K13: 2.58 | L13: 3.612 | M13: 4.128 | N13: 1.6 | O13: 2.24 | P13: 2.56 | Q13: 3.2 | R13: 4.48 | S13: 5.12
... A41: FY2025-26 | B41: M2P Fintech | C41: =VLOOKUP(B41,Mapping!A:B,2,0) -> Lateral | D41: =VLOOKUP(B41,Mapping!A:C,3,0) -> South | E41: =VLOOKUP(B41,Mapping!A:D,4,0) -> South 2 | F41: =VLOOKUP(B41,Mapping!A:E,5,0) -> Sulabh | G41: =VLOOKUP(B41,Mapping!A:F,6,0) -> Krishna | H41: 3.8894464 | I41: 5.445225 | J41: 6.2231142 | K41: 5.8341696 | L41: 8.1678374 | M41: 9.3346714 | N41: 4.278391 | O41: 5.9897475 | P41: 6.8454257 | Q41: 5.445225 | R41: 7.6233149 | S41: 8.7123599
A42: FY2025-26 | B42: Tata Power | C42: =VLOOKUP(B42,Mapping!A:B,2,0) -> Lateral | D42: =VLOOKUP(B42,Mapping!A:C,3,0) -> West | E42: =VLOOKUP(B42,Mapping!A:D,4,0) -> West 1 | F42: =VLOOKUP(B42,Mapping!A:E,5,0) -> Anjli | G42: =VLOOKUP(B42,Mapping!A:F,6,0) -> Elton
A43: FY2025-26 | B43: ThyssenKrupp | C43: =VLOOKUP(B43,Mapping!A:B,2,0) -> Lateral | D43: =VLOOKUP(B43,Mapping!A:C,3,0) -> West | E43: =VLOOKUP(B43,Mapping!A:D,4,0) -> West 2 | F43: =VLOOKUP(B43,Mapping!A:E,5,0) -> Anjli | G43: =VLOOKUP(B43,Mapping!A:F,6,0) -> Shweta
A44: FY2025-26 | B44: Fedex | C44: =VLOOKUP(B44,Mapping!A:B,2,0) -> Lateral | D44: =VLOOKUP(B44,Mapping!A:C,3,0) -> West | E44: =VLOOKUP(B44,Mapping!A:D,4,0) -> West 1 | F44: =VLOOKUP(B44,Mapping!A:E,5,0) -> Anjli | G44: =VLOOKUP(B44,Mapping!A:F,6,0) -> Elton
A45: FY2025-26 | B45: Titan | C45: =VLOOKUP(B45,Mapping!A:B,2,0) -> Lateral | D45: =VLOOKUP(B45,Mapping!A:C,3,0) -> South | E45: =VLOOKUP(B45,Mapping!A:D,4,0) -> South 2 | F45: =VLOOKUP(B45,Mapping!A:E,5,0) -> Sulabh | G45: =VLOOKUP(B45,Mapping!A:F,6,0) -> Subu
A46: FY2025-26 | B46: Ultratech | C46: =VLOOKUP(B46,Mapping!A:B,2,0) -> Lateral | D46: =VLOOKUP(B46,Mapping!A:C,3,0) -> West | E46: =VLOOKUP(B46,Mapping!A:D,4,0) -> West 1 | F46: =VLOOKUP(B46,Mapping!A:E,5,0) -> Anjli | G46: =VLOOKUP(B46,Mapping!A:F,6,0) -> Elton
A47: FY2025-26 | B47: L&T (New) | C47: =VLOOKUP(B47,Mapping!A:B,2,0) -> Lateral | D47: =VLOOKUP(B47,Mapping!A:C,3,0) -> South | E47: =VLOOKUP(B47,Mapping!A:D,4,0) -> South 2 | F47: =VLOOKUP(B47,Mapping!A:E,5,0) -> Sulabh | G47: =VLOOKUP(B47,Mapping!A:F,6,0) -> Sulabh
A48: FY2025-26 | B48: DRL | C48: =VLOOKUP(B48,Mapping!A:B,2,0) -> Lateral | D48: =VLOOKUP(B48,Mapping!A:C,3,0) -> South | E48: =VLOOKUP(B48,Mapping!A:D,4,0) -> South 2 | F48: =VLOOKUP(B48,Mapping!A:E,5,0) -> Sulabh | G48: =VLOOKUP(B48,Mapping!A:F,6,0) -> Sulabh
A49: FY2025-26 | B49: Robert Bosch | C49: =VLOOKUP(B49,Mapping!A:B,2,0) -> Lateral | D49: =VLOOKUP(B49,Mapping!A:C,3,0) -> South | E49: =VLOOKUP(B49,Mapping!A:D,4,0) -> South 2 | F49: =VLOOKUP(B49,Mapping!A:E,5,0) -> Sulabh | G49: =VLOOKUP(B49,Mapping!A:F,6,0) -> Abhilash
A50: FY2025-26 | B50: Tata Teleservices | C50: =VLOOKUP(B50,Mapping!A:B,2,0) -> Lateral | D50: =VLOOKUP(B50,Mapping!A:C,3,0) -> West | E50: =VLOOKUP(B50,Mapping!A:D,4,0) -> West 1 | F50: =VLOOKUP(B50,Mapping!A:E,5,0) -> Anjli | G50: =VLOOKUP(B50,Mapping!A:F,6,0) -> Elton
A51: FY2025-26 | B51: Honeywell Leadership | C51: =VLOOKUP(B51,Mapping!A:B,2,0) -> Leadership | D51: =VLOOKUP(B51,Mapping!A:C,3,0) -> South | E51: =VLOOKUP(B51,Mapping!A:D,4,0) -> South 1 | F51: =VLOOKUP(B51,Mapping!A:E,5,0) -> Bapi | G51: =VLOOKUP(B51,Mapping!A:F,6,0) -> Parul | H51: 0.6 | I51: 0.84 | J51: 0.96 | K51: 0.5 | L51: 0.7 | M51: 0.8 | N51: 0.5 | O51: 0.7 | P51: 0.8 | Q51: 0.5 | R51: 0.7 | S51: 0.8
A52: FY2025-26 | B52: Siemens Leadership | C52: =VLOOKUP(B52,Mapping!A:B,2,0) -> Leadership | D52: =VLOOKUP(B52,Mapping!A:C,3,0) -> South | E52: =VLOOKUP(B52,Mapping!A:D,4,0) -> South 2 | F52: =VLOOKUP(B52,Mapping!A:E,5,0) -> Sulabh | G52: =VLOOKUP(B52,Mapping!A:F,6,0) -> Parul | H52: 0.5 | I52: 0.7 | J52: 0.8 | K52: 0.5 | L52: 0.7 | M52: 0.8 | N52: 0.5 | O52: 0.7 | P52: 0.8 | Q52: 0.5 | R52: 0.7 | S52: 0.8
A53: FY2025-26 | B53: Vertiv Leadership | C53: =VLOOKUP(B53,Mapping!A:B,2,0) -> Leadership | D53: =VLOOKUP(B53,Mapping!A:C,3,0) -> West | E53: =VLOOKUP(B53,Mapping!A:D,4,0) -> West 2 | F53: =VLOOKUP(B53,Mapping!A:E,5,0) -> Anjli | G53: =VLOOKUP(B53,Mapping!A:F,6,0) -> Parul | H53: 0.8 | I53: 1.12 | J53: 1.28 | K53: 0.8 | L53: 1.12 | M53: 1.28 | N53: 0.8 | O53: 1.12 | P53: 1.28 | Q53: 0.8 | R53: 1.12 | S53: 1.28
A54: FY2025-26 | B54: M&M Leadership | C54: =VLOOKUP(B54,Mapping!A:B,2,0) -> Leadership | D54: =VLOOKUP(B54,Mapping!A:C,3,0) -> West | E54: =VLOOKUP(B54,Mapping!A:D,4,0) -> West 1 | F54: =VLOOKUP(B54,Mapping!A:E,5,0) -> Anjli | G54: =VLOOKUP(B54,Mapping!A:F,6,0) -> Parul | H54: 3.5 | I54: 4.9 | J54: 5.6 | K54: 3.5 | L54: 4.9 | M54: 5.6 | N54: 8.5 | O54: 11.9 | P54: 13.6 | Q54: 8.5 | R54: 11.9 | S54: 13.6
A55: FY2025-26 | B55: AMNS Leadership | C55: =VLOOKUP(B55,Mapping!A:B,2,0) -> Leadership | D55: =VLOOKUP(B55,Mapping!A:C,3,0) -> West | E55: =VLOOKUP(B55,Mapping!A:D,4,0) -> West 1 | F55: =VLOOKUP(B55,Mapping!A:E,5,0) -> Anjli | G55: =VLOOKUP(B55,Mapping!A:F,6,0) -> Parul | H55: 1.75 | I55: 2.45 | J55: 2.8 | K55: 1.75 | L55: 2.45 | M55: 2.8 | N55: 1.75 | O55: 2.45 | P55: 2.8 | Q55: 1.75 | R55: 2.45 | S55: 2.8
A56: FY2025-26 | B56: Nagarjuna Leadership | C56: =VLOOKUP(B56,Mapping!A:B,2,0) -> Leadership | D56: =VLOOKUP(B56,Mapping!A:C,3,0) -> South | E56: =VLOOKUP(B56,Mapping!A:D,4,0) -> South 2 | F56: =VLOOKUP(B56,Mapping!A:E,5,0) -> Sulabh | G56: =VLOOKUP(B56,Mapping!A:F,6,0) -> Parul | H56: 0.1 | I56: 0.14 | J56: 0.16 | K56: 0.1 | L56: 0.14 | M56: 0.16 | N56: 0.1 | O56: 0.14 | P56: 0.16 | Q56: 0.1 | R56: 0.14 | S56: 0.16
A57: FY2025-26 | B57: Royal Enfield Leadership | C57: =VLOOKUP(B57,Mapping!A:B,2,0) -> Leadership | D57: =VLOOKUP(B57,Mapping!A:C,3,0) -> South | E57: =VLOOKUP(B57,Mapping!A:D,4,0) -> South 2 | F57: =VLOOKUP(B57,Mapping!A:E,5,0) -> Sulabh | G57: =VLOOKUP(B57,Mapping!A:F,6,0) -> Parul | H57: 0 | I57: 0 | J57: 0 | K57: 0.5 | L57: 0.7 | M57: 0.8 | N57: 0 | O57: 0 | P57: 0 | Q57: 0 | R57: 0 | S57: 0
A58: FY2025-26 | B58: Sterling Tools Leadership | C58: =VLOOKUP(B58,Mapping!A:B,2,0) -> Leadership | D58: =VLOOKUP(B58,Mapping!A:C,3,0) -> North | E58: =VLOOKUP(B58,Mapping!A:D,4,0) -> North | F58: =VLOOKUP(B58,Mapping!A:E,5,0) -> Anjli | G58: =VLOOKUP(B58,Mapping!A:F,6,0) -> Parul | H58: 0 | I58: 0 | J58: 0 | K58: 0.5 | L58: 0.7 | M58: 0.8 | N58: 0 | O58: 0 | P58: 0 | Q58: 0 | R58: 0 | S58: 0
A59: FY2025-26 | B59: Mahindra Holidays Leadership | C59: =VLOOKUP(B59,Mapping!A:B,2,0) -> Leadership | D59: =VLOOKUP(B59,Mapping!A:C,3,0) -> West | E59: =VLOOKUP(B59,Mapping!A:D,4,0) -> West 1 | F59: =VLOOKUP(B59,Mapping!A:E,5,0) -> Anjli | G59: =VLOOKUP(B59,Mapping!A:F,6,0) -> Parul | H59: 0 | I59: 0 | J59: 0 | K59: 0 | L59: 0 | M59: 0 | N59: 0 | O59: 0 | P59: 0 | Q59: 0 | R59: 0 | S59: 0
A60: FY2025-26 | B60: Hyundai Motor Leadership | C60: =VLOOKUP(B60,Mapping!A:B,2,0) -> Leadership | D60: =VLOOKUP(B60,Mapping!A:C,3,0) -> West | E60: =VLOOKUP(B60,Mapping!A:D,4,0) -> West 2 | F60: =VLOOKUP(B60,Mapping!A:E,5,0) -> Anjli | G60: =VLOOKUP(B60,Mapping!A:F,6,0) -> Parul | H60: 0 | I60: 0 | J60: 0 | K60: 0 | L60: 0 | M60: 0 | N60: 0 | O60: 0 | P60: 0 | Q60: 0 | R60: 0 | S60: 0
A61: FY2025-26 | B61: JINDAL STAINLESS Leadership | C61: =VLOOKUP(B61,Mapping!A:B,2,0) -> Leadership | D61: =VLOOKUP(B61,Mapping!A:C,3,0) -> North | E61: =VLOOKUP(B61,Mapping!A:D,4,0) -> North | F61: =VLOOKUP(B61,Mapping!A:E,5,0) -> Anjli | G61: =VLOOKUP(B61,Mapping!A:F,6,0) -> Parul | H61: 0 | I61: 0 | J61: 0 | K61: 0 | L61: 0 | M61: 0 | N61: 0 | O61: 0 | P61: 0 | Q61: 0 | R61: 0 | S61: 0
A62: FY2025-26 | B62: SUZUKI R&D Leadership | C62: =VLOOKUP(B62,Mapping!A:B,2,0) -> Leadership | D62: =VLOOKUP(B62,Mapping!A:C,3,0) -> North | E62: =VLOOKUP(B62,Mapping!A:D,4,0) -> North | F62: =VLOOKUP(B62,Mapping!A:E,5,0) -> Anjli | G62: =VLOOKUP(B62,Mapping!A:F,6,0) -> Parul | H62: 0 | I62: 0 | J62: 0 | K62: 0 | L62: 0 | M62: 0 | N62: 0 | O62: 0 | P62: 0 | Q62: 0 | R62: 0 | S62: 0
... A73: FY2025-26 | B73: ABB | C73: =VLOOKUP(B73,Mapping!A:B,2,0) -> Lateral | D73: =VLOOKUP(B73,Mapping!A:C,3,0) -> South | E73: =VLOOKUP(B73,Mapping!A:D,4,0) -> South 2 | F73: =VLOOKUP(B73,Mapping!A:E,5,0) -> Sulabh | G73: =VLOOKUP(B73,Mapping!A:F,6,0) -> Satya | H73: 0 | I73: 0 | J73: 0 | K73: 0 | L73: 0 | M73: 0 | N73: 0 | O73: 0 | P73: 0 | Q73: 0 | R73: 0 | S73: 0
A74: FY2025-26 | B74: TCG Group | C74: =VLOOKUP(B74,Mapping!A:B,2,0) -> Lateral | D74: =VLOOKUP(B74,Mapping!A:C,3,0) -> West | E74: =VLOOKUP(B74,Mapping!A:D,4,0) -> West 1 | F74: =VLOOKUP(B74,Mapping!A:E,5,0) -> Anjli | G74: =VLOOKUP(B74,Mapping!A:F,6,0) -> Anjli
A75: FY2025-26 | B75: Proterial | C75: =VLOOKUP(B75,Mapping!A:B,2,0) -> #N/A | D75: =VLOOKUP(B75,Mapping!A:C,3,0) -> #N/A | E75: =VLOOKUP(B75,Mapping!A:D,4,0) -> #N/A | F75: =VLOOKUP(B75,Mapping!A:E,5,0) -> #N/A | G75: =VLOOKUP(B75,Mapping!A:F,6,0) -> #N/A
A76: FY2025-26 | B76: CG Power | C76: =VLOOKUP(B76,Mapping!A:B,2,0) -> Lateral | D76: =VLOOKUP(B76,Mapping!A:C,3,0) -> West | E76: =VLOOKUP(B76,Mapping!A:D,4,0) -> West 1 | F76: =VLOOKUP(B76,Mapping!A:E,5,0) -> Anjli | G76: =VLOOKUP(B76,Mapping!A:F,6,0) -> Anjli

Sheet Target Rev Productivity
A1: =Revenue_Budget!A1 -> FY | B1: =Revenue_Budget!B1 -> Project | C1: =Revenue_Budget!C1 -> Vertical | D1: =Revenue_Budget!D1 -> Region | E1: =Revenue_Budget!E1 -> Sub Region | F1: =Revenue_Budget!F1 -> Region Head | G1: =Revenue_Budget!G1 -> Practice Head | H1: =Revenue_Budget!H1 -> 45748 | ... S1: =Revenue_Budget!S1 -> 46082
A2: FY2025-26 | B2: Honeywell | C2: =VLOOKUP(B2,Mapping!A:B,2,0) -> Lateral | D2: =VLOOKUP(B2,Mapping!A:C,3,0) -> South | E2: =VLOOKUP(B2,Mapping!A:D,4,0) -> South 1 | F2: =VLOOKUP(B2,Mapping!A:E,5,0) -> Bapi | G2: =VLOOKUP(B2,Mapping!A:F,6,0) -> Bapi | H2: 3.2921657 | I2: 3.2921657 | J2: 3.2921657 | K2: 3.5555389 | L2: 3.5555389 | M2: 3.5555389 | N2: 3.0287924 | O2: 3.0287924 | P2: 3.0287924 | Q2: 3.2921657 | R2: 3.2921657 | S2: 3.2921657
A3: FY2025-26 | B3: Pfizer | C3: =VLOOKUP(B3,Mapping!A:B,2,0) -> Lateral | D3: =VLOOKUP(B3,Mapping!A:C,3,0) -> West | E3: =VLOOKUP(B3,Mapping!A:D,4,0) -> West 1 | F3: =VLOOKUP(B3,Mapping!A:E,5,0) -> Anjli | G3: =VLOOKUP(B3,Mapping!A:F,6,0) -> Usha | H3: 2.9191617 | I3: 2.9191617 | J3: 2.9191617 | K3: 3.1526946 | L3: 3.1526946 | M3: 3.1526946 | N3: 2.6856287 | O3: 2.6856287 | P3: 2.6856287 | Q3: 2.9191617 | R3: 2.9191617 | S3: 2.9191617
A4: FY2025-26 | B4: Tata Motors | C4: =VLOOKUP(B4,Mapping!A:B,2,0) -> Lateral | D4: =VLOOKUP(B4,Mapping!A:C,3,0) -> West | E4: =VLOOKUP(B4,Mapping!A:D,4,0) -> West 2 | F4: =VLOOKUP(B4,Mapping!A:E,5,0) -> Anjli | G4: =VLOOKUP(B4,Mapping!A:F,6,0) -> Shweta | H4: 2.2 | I4: 2.2 | J4: 2.2 | K4: 2.3 | L4: 2.3 | M4: 2.3 | N4: 2 | O4: 2 | P4: 2 | Q4: 2.2 | R4: 2.2 | S4: 2.2
A5: FY2025-26 | B5: SKF India | C5: =VLOOKUP(B5,Mapping!A:B,2,0) -> Lateral | D5: =VLOOKUP(B5,Mapping!A:C,3,0) -> North | E5: =VLOOKUP(B5,Mapping!A:D,4,0) -> North | F5: =VLOOKUP(B5,Mapping!A:E,5,0) -> Anjli | G5: =VLOOKUP(B5,Mapping!A:F,6,0) -> Archana | H5: 1.7212242 | I5: 1.7212242 | J5: 1.7212242 | K5: 1.8589222 | L5: 1.8589222 | M5: 1.8589222 | N5: 1.5835263 | O5: 1.5835263 | P5: 1.5835263 | Q5: 1.7212242 | R5: 1.7212242 | S5: 1.7212242
A6: FY2025-26 | B6: Siemens | C6: =VLOOKUP(B6,Mapping!A:B,2,0) -> Lateral | D6: =VLOOKUP(B6,Mapping!A:C,3,0) -> South | E6: =VLOOKUP(B6,Mapping!A:D,4,0) -> South 1 | F6: =VLOOKUP(B6,Mapping!A:E,5,0) -> Sulabh | G6: =VLOOKUP(B6,Mapping!A:F,6,0) -> Kunal | H6: 2.5484745 | I6: 2.5484745 | J6: 2.5484745 | K6: 2.7523524 | L6: 2.7523524 | M6: 2.7523524 | N6: 2.3445965 | O6: 2.3445965 | P6: 2.3445965 | Q6: 2.5484745 | R6: 2.5484745 | S6: 2.5484745
A7: FY2025-26 | B7: Pidilite | C7: =VLOOKUP(B7,Mapping!A:B,2,0) -> Lateral | D7: =VLOOKUP(B7,Mapping!A:C,3,0) -> West | E7: =VLOOKUP(B7,Mapping!A:D,4,0) -> West 1 | F7: =VLOOKUP(B7,Mapping!A:E,5,0) -> Anjli | G7: =VLOOKUP(B7,Mapping!A:F,6,0) -> Usha | H7: 1.9461078 | I7: 1.9461078 | J7: 1.9461078 | K7: 2.1017964 | L7: 2.1017964 | M7: 2.1017964 | N7: 1.7904192 | O7: 1.7904192 | P7: 1.7904192 | Q7: 1.9461078 | R7: 1.9461078 | S7: 1.9461078
A8: FY2025-26 | B8: Vertiv | C8: =VLOOKUP(B8,Mapping!A:B,2,0) -> Lateral | D8: =VLOOKUP(B8,Mapping!A:C,3,0) -> West | E8: =VLOOKUP(B8,Mapping!A:D,4,0) -> West 2 | F8: =VLOOKUP(B8,Mapping!A:E,5,0) -> Anjli | G8: =VLOOKUP(B8,Mapping!A:F,6,0) -> Shweta | H8: 2.5948104 | I8: 2.5948104 | J8: 2.5948104 | K8: 2.8023952 | L8: 2.8023952 | M8: 2.8023952 | N8: 2.3872255 | O8: 2.3872255 | P8: 2.3872255 | Q8: 2.5948104 | R8: 2.5948104 | S8: 2.5948104
A9: FY2025-26 | B9: Birla Paints | C9: =VLOOKUP(B9,Mapping!A:B,2,0) -> Lateral | D9: =VLOOKUP(B9,Mapping!A:C,3,0) -> West | E9: =VLOOKUP(B9,Mapping!A:D,4,0) -> West 1 | F9: =VLOOKUP(B9,Mapping!A:E,5,0) -> Anjli | G9: =VLOOKUP(B9,Mapping!A:F,6,0) -> Geetu | H9: 1.9461078 | I9: 1.9461078 | J9: 1.9461078 | K9: 2.1017964 | L9: 2.1017964 | M9: 2.1017964 | N9: 1.7904192 | O9: 1.7904192 | P9: 1.7904192 | Q9: 1.9461078 | R9: 1.9461078 | S9: 1.9461078
A10: FY2025-26 | B10: Ingram Micro | C10: =VLOOKUP(B10,Mapping!A:B,2,0) -> Lateral | D10: =VLOOKUP(B10,Mapping!A:C,3,0) -> West | E10: =VLOOKUP(B10,Mapping!A:D,4,0) -> West 1 | F10: =VLOOKUP(B10,Mapping!A:E,5,0) -> Anjli | G10: =VLOOKUP(B10,Mapping!A:F,6,0) -> Geetu | H10: 3.0575142 | I10: 3.0575142 | J10: 3.0575142 | K10: 3.3763798 | L10: 3.3763798 | M10: 3.3763798 | N10: 2.9840319 | O10: 2.9840319 | P10: 2.9840319 | Q10: 3.243513 | R10: 3.243513 | S10: 3.243513
A11: FY2025-26 | B11: HPE | C11: =VLOOKUP(B11,Mapping!A:B,2,0) -> Lateral | D11: =VLOOKUP(B11,Mapping!A:C,3,0) -> South | E11: =VLOOKUP(B11,Mapping!A:D,4,0) -> South 1 | F11: =VLOOKUP(B11,Mapping!A:E,5,0) -> Mahak | G11: =VLOOKUP(B11,Mapping!A:F,6,0) -> Mahak | H11: 3.1767893 | I11: 3.1767893 | J11: 3.1767893 | K11: 3.4309324 | L11: 3.4309324 | M11: 3.4309324 | N11: 2.9226461 | O11: 2.9226461 | P11: 2.9226461 | Q11: 3.1767893 | R11: 3.1767893 | S11: 3.1767893
A12: FY2025-26 | B12: Isuzu | C12: =VLOOKUP(B12,Mapping!A:B,2,0) -> Lateral | D12: =VLOOKUP(B12,Mapping!A:C,3,0) -> South | E12: =VLOOKUP(B12,Mapping!A:D,4,0) -> South 1 | F12: =VLOOKUP(B12,Mapping!A:E,5,0) -> Anjli | G12: =VLOOKUP(B12,Mapping!A:F,6,0) -> Satya | H12: 3.4844597 | I12: 3.4844597 | J12: 3.4844597 | K12: 3.2928144 | L12: 3.2928144 | M12: 3.2928144 | N12: 2.80499 | O12: 2.80499 | P12: 2.80499 | Q12: 3.0489022 | R12: 3.0489022 | S12: 3.0489022
A13: FY2025-26 | B13: Mahindra Holidays | C13: =VLOOKUP(B13,Mapping!A:B,2,0) -> Lateral | D13: =VLOOKUP(B13,Mapping!A:C,3,0) -> West | E13: =VLOOKUP(B13,Mapping!A:D,4,0) -> West 1 | F13: =VLOOKUP(B13,Mapping!A:E,5,0) -> Anjli | G13: =VLOOKUP(B13,Mapping!A:F,6,0) -> Geetu | H13: 1.6217565 | I13: 1.6217565 | J13: 1.6217565 | K13: 1.751497 | L13: 1.751497 | M13: 1.751497 | N13: 1.492016 | O13: 1.492016 | P13: 1.492016 | Q13: 1.6217565 | R13: 1.6217565 | S13: 1.6217565
... A76: FY2025-26 | B76: CG Power | C76: =VLOOKUP(B76,Mapping!A:B,2,0) -> Lateral | D76: =VLOOKUP(B76,Mapping!A:C,3,0) -> West | E76: =VLOOKUP(B76,Mapping!A:D,4,0) -> West 1 | F76: =VLOOKUP(B76,Mapping!A:E,5,0) -> Anjli | G76: =VLOOKUP(B76,Mapping!A:F,6,0) -> Anjli | H76: 2.2 | I76: 2.2 | J76: 2.2 | K76: 2.3 | L76: 2.3 | M76: 2.3 | N76: 2 | O76: 2 | P76: 2 | Q76: 2.2 | R76: 2.2 | S76: 2.2

Sheet Rev_Forecast
A1: =Revenue_Budget!A1 -> FY | B1: =Revenue_Budget!B1 -> Project | C1: =Revenue_Budget!C1 -> Vertical | D1: =Revenue_Budget!D1 -> Region | E1: =Revenue_Budget!E1 -> Sub Region | F1: =Revenue_Budget!F1 -> Region Head | G1: =Revenue_Budget!G1 -> Practice Head | H1: =Revenue_Budget!H1 -> 45748 | ... S1: =Revenue_Budget!S1 -> 46082
A2: FY2025-26 | B2: Honeywell | C2: =VLOOKUP(B2,Mapping!A:B,2,0) -> Lateral | D2: =VLOOKUP(B2,Mapping!A:C,3,0) -> South | E2: =VLOOKUP(B2,Mapping!A:D,4,0) -> South 1 | F2: =VLOOKUP(B2,Mapping!A:E,5,0) -> Bapi | G2: =VLOOKUP(B2,Mapping!A:F,6,0) -> Bapi | H2: 110 | I2: 154 | J2: 176 | K2: 119.20399 | L2: 166.88559 | M2: 190.72639 | N2: 82.453995 | O2: 115.43559 | P2: 131.92639 | Q2: 120 | R2: 152.66749 | S2: 134.57613
A3: FY2025-26 | B3: Pfizer | C3: =VLOOKUP(B3,Mapping!A:B,2,0) -> Lateral | D3: =VLOOKUP(B3,Mapping!A:C,3,0) -> West | E3: =VLOOKUP(B3,Mapping!A:D,4,0) -> West 1 | F3: =VLOOKUP(B3,Mapping!A:E,5,0) -> Anjli | G3: =VLOOKUP(B3,Mapping!A:F,6,0) -> Usha | H3: 4.375 | I3: 6.125 | J3: 7 | K3: 6.5 | L3: 9.1 | M3: 10.4 | N3: 4 | O3: 5.6 | P3: 6.4 | Q3: 8 | R3: 6.805 | S3: 7
A4: FY2025-26 | B4: Tata Motors | C4: =VLOOKUP(B4,Mapping!A:B,2,0) -> Lateral | D4: =VLOOKUP(B4,Mapping!A:C,3,0) -> West | E4: =VLOOKUP(B4,Mapping!A:D,4,0) -> West 2 | F4: =VLOOKUP(B4,Mapping!A:E,5,0) -> Anjli | G4: =VLOOKUP(B4,Mapping!A:F,6,0) -> Shweta | H4: 1.125 | I4: 1.575 | J4: 1.8 | K4: 0 | L4: 0 | M4: 0 | N4: 0 | O4: 0 | P4: 0 | S4: 0
A5: FY2025-26 | B5: SKF India | C5: =VLOOKUP(B5,Mapping!A:B,2,0) -> Lateral | D5: =VLOOKUP(B5,Mapping!A:C,3,0) -> North | E5: =VLOOKUP(B5,Mapping!A:D,4,0) -> North | F5: =VLOOKUP(B5,Mapping!A:E,5,0) -> Anjli | G5: =VLOOKUP(B5,Mapping!A:F,6,0) -> Archana | H5: 12.75 | I5: 17.85 | J5: 20.4 | K5: 13.05 | L5: 18.27 | M5: 20.88 | N5: 8.025 | O5: 11.235 | P5: 12.84 | Q5: 13 | R5: 21.7 | S5: 17
A6: FY2025-26 | B6: Siemens | C6: =VLOOKUP(B6,Mapping!A:B,2,0) -> Lateral | D6: =VLOOKUP(B6,Mapping!A:C,3,0) -> South | E6: =VLOOKUP(B6,Mapping!A:D,4,0) -> South 1 | F6: =VLOOKUP(B6,Mapping!A:E,5,0) -> Sulabh | G6: =VLOOKUP(B6,Mapping!A:F,6,0) -> Kunal | H6: 2.5 | I6: 3.5 | J6: 4 | K6: 6.75 | L6: 9.45 | M6: 10.8 | N6: 2.5 | O6: 3.5 | P6: 4 | Q6: 5 | R6: 23.6872 | S6: 24
A7: FY2025-26 | B7: Pidilite | C7: =VLOOKUP(B7,Mapping!A:B,2,0) -> Lateral | D7: =VLOOKUP(B7,Mapping!A:C,3,0) -> West | E7: =VLOOKUP(B7,Mapping!A:D,4,0) -> West 1 | F7: =VLOOKUP(B7,Mapping!A:E,5,0) -> Anjli | G7: =VLOOKUP(B7,Mapping!A:F,6,0) -> Usha | H7: 16.375 | I7: 22.925 | J7: 26.2 | K7: 18.375 | L7: 25.725 | M7: 29.4 | N7: 15 | O7: 21 | P7: 24 | Q7: 19.75 | R7: 3.88 | S7: 7.25
A8: FY2025-26 | B8: Vertiv | C8: =VLOOKUP(B8,Mapping!A:B,2,0) -> Lateral | D8: =VLOOKUP(B8,Mapping!A:C,3,0) -> West | E8: =VLOOKUP(B8,Mapping!A:D,4,0) -> West 2 | F8: =VLOOKUP(B8,Mapping!A:E,5,0) -> Anjli | G8: =VLOOKUP(B8,Mapping!A:F,6,0) -> Shweta | H8: 4 | I8: 5.6 | J8: 6.4 | K8: 5 | L8: 7 | M8: 8 | N8: 7.5 | O8: 10.5 | P8: 12 | Q8: 6.4272 | R8: 5.2736 | S8: 4.5
A9: FY2025-26 | B9: Birla Paints | C9: =VLOOKUP(B9,Mapping!A:B,2,0) -> Lateral | D9: =VLOOKUP(B9,Mapping!A:C,3,0) -> West | E9: =VLOOKUP(B9,Mapping!A:D,4,0) -> West 1 | F9: =VLOOKUP(B9,Mapping!A:E,5,0) -> Anjli | G9: =VLOOKUP(B9,Mapping!A:F,6,0) -> Geetu | H9: 0 | I9: 0 | J9: 0 | K9: 0 | L9: 0 | M9: 0 | N9: 0 | O9: 0 | P9: 0 | R9: 11.25 | S9: 13
A10: FY2025-26 | B10: Ingram Micro | C10: =VLOOKUP(B10,Mapping!A:B,2,0) -> Lateral | D10: =VLOOKUP(B10,Mapping!A:C,3,0) -> West | E10: =VLOOKUP(B10,Mapping!A:D,4,0) -> West 1 | F10: =VLOOKUP(B10,Mapping!A:E,5,0) -> Anjli | G10: =VLOOKUP(B10,Mapping!A:F,6,0) -> Geetu | H10: 8 | I10: 11.2 | J10: 12.8 | K10: 7.6875 | L10: 10.7625 | M10: 12.3 | N10: 7.5 | O10: 10.5 | P10: 12 | Q10: 10 | S10: 0
A11: FY2025-26 | B11: HPE | C11: =VLOOKUP(B11,Mapping!A:B,2,0) -> Lateral | D11: =VLOOKUP(B11,Mapping!A:C,3,0) -> South | E11: =VLOOKUP(B11,Mapping!A:D,4,0) -> South 1 | F11: =VLOOKUP(B11,Mapping!A:E,5,0) -> Mahak | G11: =VLOOKUP(B11,Mapping!A:F,6,0) -> Mahak | H11: 3.625 | I11: 5.075 | J11: 5.8 | K11: 2.5 | L11: 3.5 | M11: 4 | N11: 2.5 | O11: 3.5 | P11: 4 | Q11: 1.5 | R11: 224 | S11: 129
A12: FY2025-26 | B12: Isuzu | C12: =VLOOKUP(B12,Mapping!A:B,2,0) -> Lateral | D12: =VLOOKUP(B12,Mapping!A:C,3,0) -> South | E12: =VLOOKUP(B12,Mapping!A:D,4,0) -> South 1 | F12: =VLOOKUP(B12,Mapping!A:E,5,0) -> Anjli | G12: =VLOOKUP(B12,Mapping!A:F,6,0) -> Satya | H12: 9 | I12: 12.6 | J12: 14.4 | K12: 8.55 | L12: 11.97 | M12: 13.68 | N12: 9.045 | O12: 12.663 | P12: 14.472 | Q12: 13.75 | R12: -6.89698 | S12: 5
A13: FY2025-26 | B13: Mahindra Holidays | C13: =VLOOKUP(B13,Mapping!A:B,2,0) -> Lateral | D13: =VLOOKUP(B13,Mapping!A:C,3,0) -> West | E13: =VLOOKUP(B13,Mapping!A:D,4,0) -> West 1 | F13: =VLOOKUP(B13,Mapping!A:E,5,0) -> Anjli | G13: =VLOOKUP(B13,Mapping!A:F,6,0) -> Geetu | H13: 1.75 | I13: 2.45 | J13: 2.8 | K13: 2.525 | L13: 3.535 | M13: 4.04 | N13: 1 | O13: 1.4 | P13: 1.6 | R13: 6.97 | S13: 7
A14: FY2025-26 | B14: BITS | C14: =VLOOKUP(B14,Mapping!A:B,2,0) -> Lateral | D14: =VLOOKUP(B14,Mapping!A:C,3,0) -> South | E14: =VLOOKUP(B14,Mapping!A:D,4,0) -> South 2 | F14: =VLOOKUP(B14,Mapping!A:E,5,0) -> Sulabh | G14: =VLOOKUP(B14,Mapping!A:F,6,0) -> Krishna | H14: 70 | I14: 98 | J14: 112 | K14: 85 | L14: 119 | M14: 136 | N14: 78.75 | O14: 110.25 | P14: 126 | Q14: 130 | R14: 12.00338 | S14: 0
A15: FY2025-26 | B15: M&M | C15: =VLOOKUP(B15,Mapping!A:B,2,0) -> Lateral | D15: =VLOOKUP(B15,Mapping!A:C,3,0) -> West | E15: =VLOOKUP(B15,Mapping!A:D,4,0) -> West 1 | F15: =VLOOKUP(B15,Mapping!A:E,5,0) -> Anjli | G15: =VLOOKUP(B15,Mapping!A:F,6,0) -> Dhriti | H15: 5.375 | I15: 7.525 | J15: 8.6 | K15: 6.05 | L15: 8.47 | M15: 9.68 | N15: 6.375 | O15: 8.925 | P15: 10.2 | Q15: 5.98 | R15: 120.94803 | S15: 132.86
A16: FY2025-26 | B16: P&G | C16: =VLOOKUP(B16,Mapping!A:B,2,0) -> Lateral | D16: =VLOOKUP(B16,Mapping!A:C,3,0) -> South | E16: =VLOOKUP(B16,Mapping!A:D,4,0) -> South 2 | F16: =VLOOKUP(B16,Mapping!A:E,5,0) -> Sulabh | G16: =VLOOKUP(B16,Mapping!A:F,6,0) -> Krishna | H16: 5.625 | I16: 7.875 | J16: 9 | K16: 5.95125 | L16: 8.33175 | M16: 9.522 | N16: 4.95 | O16: 6.93 | P16: 7.92 | Q16: 5 | S16: 0
A17: FY2025-26 | B17: Wipro | C17: =VLOOKUP(B17,Mapping!A:B,2,0) -> Lateral | D17: =VLOOKUP(B17,Mapping!A:C,3,0) -> South | E17: =VLOOKUP(B17,Mapping!A:D,4,0) -> South 1 | F17: =VLOOKUP(B17,Mapping!A:E,5,0) -> Sulabh | G17: =VLOOKUP(B17,Mapping!A:F,6,0) -> Subu | H17: 3 | I17: 4.2 | J17: 4.8 | K17: 3.14825 | L17: 4.40755 | M17: 5.0372 | N17: 3 | O17: 4.2 | P17: 4.8 | Q17: 4 | R17: -15.7025 | S17: 20
A18: FY2025-26 | B18: Tata Marcopolo | C18: =VLOOKUP(B18,Mapping!A:B,2,0) -> Lateral | D18: =VLOOKUP(B18,Mapping!A:C,3,0) -> West | E18: =VLOOKUP(B18,Mapping!A:D,4,0) -> West 2 | F18: =VLOOKUP(B18,Mapping!A:E,5,0) -> Anjli | G18: =VLOOKUP(B18,Mapping!A:F,6,0) -> Anjli | H18: 66 | I18: 92.4 | J18: 105.6 | K18: 71.175 | L18: 99.645 | M18: 113.88 | N18: 82.5 | O18: 115.5 | P18: 132 | Q18: 140 | S18: 0
A19: FY2025-26 | B19: DP World | C19: =VLOOKUP(B19,Mapping!A:B,2,0) -> Lateral | D19: =VLOOKUP(B19,Mapping!A:C,3,0) -> West | E19: =VLOOKUP(B19,Mapping!A:D,4,0) -> West 1 | F19: =VLOOKUP(B19,Mapping!A:E,5,0) -> Anjli | G19: =VLOOKUP(B19,Mapping!A:F,6,0) -> Geetu | H19: 1.32 | I19: 1.848 | J19: 2.112 | K19: 0 | L19: 0 | M19: 0 | N19: 0 | O19: 0 | P19: 0 | R19: 4.5 | S19: 8.57
A20: FY2025-26 | B20: Ametek | C20: =VLOOKUP(B20,Mapping!A:B,2,0) -> Lateral | D20: =VLOOKUP(B20,Mapping!A:C,3,0) -> South | E20: =VLOOKUP(B20,Mapping!A:D,4,0) -> South 1 | F20: =VLOOKUP(B20,Mapping!A:E,5,0) -> Sulabh | G20: =VLOOKUP(B20,Mapping!A:F,6,0) -> Satya | H20: 17.1 | I20: 23.94 | J20: 27.36 | K20: 41.85 | L20: 58.59 | M20: 66.96 | N20: 25 | O20: 35 | P20: 40 | Q20: 55 | S20: 0
A21: FY2025-26 | B21: AMNS | C21: =VLOOKUP(B21,Mapping!A:B,2,0) -> Lateral | D21: =VLOOKUP(B21,Mapping!A:C,3,0) -> West | E21: =VLOOKUP(B21,Mapping!A:D,4,0) -> West 1 | F21: =VLOOKUP(B21,Mapping!A:E,5,0) -> Anjli | G21: =VLOOKUP(B21,Mapping!A:F,6,0) -> Alifia | H21: 8.5 | I21: 11.9 | J21: 13.6 | K21: 4.05 | L21: 5.67 | M21: 6.48 | N21: 5.26 | O21: 7.364 | P21: 8.416 | Q21: 8.27 | R21: 21.7 | S21: 30
A22: FY2025-26 | B22: Tata Electronics | C22: =VLOOKUP(B22,Mapping!A:B,2,0) -> Lateral | D22: =VLOOKUP(B22,Mapping!A:C,3,0) -> South | E22: =VLOOKUP(B22,Mapping!A:D,4,0) -> South 2 | F22: =VLOOKUP(B22,Mapping!A:E,5,0) -> Sulabh | G22: =VLOOKUP(B22,Mapping!A:F,6,0) -> Subu | H22: 3.15 | I22: 4.41 | J22: 5.04 | K22: 4 | L22: 5.6 | M22: 6.4 | N22: 0 | O22: 0 | P22: 0 | R22: -0.26681 | S22: 5.8369
A23: FY2025-26 | B23: Jindal Stainless | C23: =VLOOKUP(B23,Mapping!A:B,2,0) -> Lateral | D23: =VLOOKUP(B23,Mapping!A:C,3,0) -> North | E23: =VLOOKUP(B23,Mapping!A:D,4,0) -> North | F23: =VLOOKUP(B23,Mapping!A:E,5,0) -> Anjli | G23: =VLOOKUP(B23,Mapping!A:F,6,0) -> Archana | H23: 27.5 | I23: 38.5 | J23: 44 | K23: 37.75 | L23: 52.85 | M23: 60.4 | N23: 22.5 | O23: 31.5 | P23: 36 | Q23: 30 | R23: 6.8787 | S23: 10
A24: FY2025-26 | B24: Nomiso | C24: =VLOOKUP(B24,Mapping!A:B,2,0) -> Lateral | D24: =VLOOKUP(B24,Mapping!A:C,3,0) -> South | E24: =VLOOKUP(B24,Mapping!A:D,4,0) -> South 2 | F24: =VLOOKUP(B24,Mapping!A:E,5,0) -> Sulabh | G24: =VLOOKUP(B24,Mapping!A:F,6,0) -> Krishna | H24: 11.625 | I24: 16.275 | J24: 18.6 | K24: 3 | L24: 4.2 | M24: 4.8 | N24: 5 | O24: 7 | P24: 8 | Q24: 3.58 | S24: 0
A25: FY2025-26 | B25: Schaeffler | C25: =VLOOKUP(B25,Mapping!A:B,2,0) -> Lateral | D25: =VLOOKUP(B25,Mapping!A:C,3,0) -> West | E25: =VLOOKUP(B25,Mapping!A:D,4,0) -> West 2 | F25: =VLOOKUP(B25,Mapping!A:E,5,0) -> Anjli | G25: =VLOOKUP(B25,Mapping!A:F,6,0) -> Shweta | H25: 0 | I25: 0 | J25: 0 | K25: 0 | L25: 0 | M25: 0 | N25: 0 | O25: 0 | P25: 0 | R25: 10.42 | S25: 9
A26: FY2025-26 | B26: Royal Enfield | C26: =VLOOKUP(B26,Mapping!A:B,2,0) -> Lateral | D26: =VLOOKUP(B26,Mapping!A:C,3,0) -> South | E26: =VLOOKUP(B26,Mapping!A:D,4,0) -> South 2 | F26: =VLOOKUP(B26,Mapping!A:E,5,0) -> Sulabh | G26: =VLOOKUP(B26,Mapping!A:F,6,0) -> Krishna | H26: 7 | I26: 9.8 | J26: 11.2 | K26: 11.5 | L26: 16.1 | M26: 18.4 | N26: 7.5 | O26: 10.5 | P26: 12 | Q26: 10 | R26: 11.89968 | S26: 17.10032
A27: FY2025-26 | B27: SBI Card | C27: =VLOOKUP(B27,Mapping!A:B,2,0) -> Lateral | D27: =VLOOKUP(B27,Mapping!A:C,3,0) -> North | E27: =VLOOKUP(B27,Mapping!A:D,4,0) -> North | F27: =VLOOKUP(B27,Mapping!A:E,5,0) -> Anjli | G27: =VLOOKUP(B27,Mapping!A:F,6,0) -> Archana | H27: 4.5 | I27: 6.3 | J27: 7.2 | K27: 4 | L27: 5.6 | M27: 6.4 | N27: 5 | O27: 7 | P27: 8 | Q27: 5 | R27: 18.9 | S27: 20
A28: FY2025-26 | B28: Hyundai Motor | C28: =VLOOKUP(B28,Mapping!A:B,2,0) -> Lateral | D28: =VLOOKUP(B28,Mapping!A:C,3,0) -> West | E28: =VLOOKUP(B28,Mapping!A:D,4,0) -> West 2 | F28: =VLOOKUP(B28,Mapping!A:E,5,0) -> Anjli | G28: =VLOOKUP(B28,Mapping!A:F,6,0) -> Shweta | H28: 5.4925 | I28: 7.6895 | J28: 8.788 | K28: 6.75 | L28: 9.45 | M28: 10.8 | N28: 9 | O28: 12.6 | P28: 14.4 | Q28: 10.25 | R28: 14.24 | S28: 5
A29: FY2025-26 | B29: Maruti Suzuki(MSIL) | C29: =VLOOKUP(B29,Mapping!A:B,2,0) -> Lateral | D29: =VLOOKUP(B29,Mapping!A:C,3,0) -> North | E29: =VLOOKUP(B29,Mapping!A:D,4,0) -> North | F29: =VLOOKUP(B29,Mapping!A:E,5,0) -> Anjli | G29: =VLOOKUP(B29,Mapping!A:F,6,0) -> Archana | H29: 8.9 | I29: 12.46 | J29: 14.24 | K29: 10.25 | L29: 14.35 | M29: 16.4 | N29: 8.775 | O29: 12.285 | P29: 14.04 | Q29: 5 | R29: 34.97242 | S29: 45
A30: FY2025-26 | B30: Excelacom | C30: =VLOOKUP(B30,Mapping!A:B,2,0) -> Lateral | D30: =VLOOKUP(B30,Mapping!A:C,3,0) -> South | E30: =VLOOKUP(B30,Mapping!A:D,4,0) -> South 2 | F30: =VLOOKUP(B30,Mapping!A:E,5,0) -> Sulabh | G30: =VLOOKUP(B30,Mapping!A:F,6,0) -> Krishna | H30: 8.75 | I30: 12.25 | J30: 14 | K30: 8 | L30: 11.2 | M30: 12.8 | N30: 5 | O30: 7 | P30: 8 | Q30: 5 | S30: 0
A31: FY2025-26 | B31: Tata Consumer | C31: =VLOOKUP(B31,Mapping!A:B,2,0) -> Lateral | D31: =VLOOKUP(B31,Mapping!A:C,3,0) -> West | E31: =VLOOKUP(B31,Mapping!A:D,4,0) -> West 1 | F31: =VLOOKUP(B31,Mapping!A:E,5,0) -> Anjli | G31: =VLOOKUP(B31,Mapping!A:F,6,0) -> Geetu | H31: 21.5 | I31: 30.1 | J31: 34.4 | K31: 29.25 | L31: 40.95 | M31: 46.8 | N31: 33.75 | O31: 47.25 | P31: 54 | Q31: 42 | R31: 19.03 | S31: 19.75
A32: FY2025-26 | B32: Tata Play | C32: =VLOOKUP(B32,Mapping!A:B,2,0) -> Lateral | D32: =VLOOKUP(B32,Mapping!A:C,3,0) -> West | E32: =VLOOKUP(B32,Mapping!A:D,4,0) -> West 1 | F32: =VLOOKUP(B32,Mapping!A:E,5,0) -> Anjli | G32: =VLOOKUP(B32,Mapping!A:F,6,0) -> Geetu | H32: 2.5 | I32: 3.5 | J32: 4 | K32: 3 | L32: 4.2 | M32: 4.8 | N32: 0 | O32: 0 | P32: 0 | R32: 0.248 | S32: 1.04
A33: FY2025-26 | B33: Mahindra Finance | C33: =VLOOKUP(B33,Mapping!A:B,2,0) -> Lateral | D33: =VLOOKUP(B33,Mapping!A:C,3,0) -> West | E33: =VLOOKUP(B33,Mapping!A:D,4,0) -> West 1 | F33: =VLOOKUP(B33,Mapping!A:E,5,0) -> Anjli | G33: =VLOOKUP(B33,Mapping!A:F,6,0) -> Geetu | H33: 11.5 | I33: 16.1 | J33: 18.4 | K33: 12.5625 | L33: 17.5875 | M33: 20.1 | N33: 15 | O33: 21 | P33: 24 | Q33: 20.25 | R33: 3.22 | S33: 3.2
A34: FY2025-26 | B34: Suzuki R&D | C34: =VLOOKUP(B34,Mapping!A:B,2,0) -> Lateral | D34: =VLOOKUP(B34,Mapping!A:C,3,0) -> North | E34: =VLOOKUP(B34,Mapping!A:D,4,0) -> North | F34: =VLOOKUP(B34,Mapping!A:E,5,0) -> Anjli | G34: =VLOOKUP(B34,Mapping!A:F,6,0) -> Archana | H34: 0.925 | I34: 1.295 | J34: 1.48 | K34: 0.375 | L34: 0.525 | M34: 0.6 | N34: 0.375 | O34: 0.525 | P34: 0.6 | Q34: 1.04 | R34: -1.267 | S34: 0
A35: FY2025-26 | B35: Subros Ltd | C35: =VLOOKUP(B35,Mapping!A:B,2,0) -> Lateral | D35: =VLOOKUP(B35,Mapping!A:C,3,0) -> North | E35: =VLOOKUP(B35,Mapping!A:D,4,0) -> North | F35: =VLOOKUP(B35,Mapping!A:E,5,0) -> Anjli | G35: =VLOOKUP(B35,Mapping!A:F,6,0) -> Archana | H35: 6.25 | I35: 8.75 | J35: 10 | K35: 3.168 | L35: 4.4352 | M35: 5.0688 | N35: 2.4 | O35: 3.36 | P35: 3.84 | Q35: 3.2 | R35: 2.9498 | S35: 6
A36: FY2025-26 | B36: Atomberg Technologies | C36: =VLOOKUP(B36,Mapping!A:B,2,0) -> Lateral | D36: =VLOOKUP(B36,Mapping!A:C,3,0) -> West | E36: =VLOOKUP(B36,Mapping!A:D,4,0) -> West 1 | F36: =VLOOKUP(B36,Mapping!A:E,5,0) -> Anjli | G36: =VLOOKUP(B36,Mapping!A:F,6,0) -> Geetu | H36: 0 | I36: 0 | J36: 0 | K36: 0 | L36: 0 | M36: 0 | N36: 0 | O36: 0 | P36: 0 | R36: 9.11 | S36: 7.51
A37: FY2025-26 | B37: Bridgestone | C37: =VLOOKUP(B37,Mapping!A:B,2,0) -> Lateral | D37: =VLOOKUP(B37,Mapping!A:C,3,0) -> West | E37: =VLOOKUP(B37,Mapping!A:D,4,0) -> West 2 | F37: =VLOOKUP(B37,Mapping!A:E,5,0) -> Anjli | G37: =VLOOKUP(B37,Mapping!A:F,6,0) -> Shweta | H37: 3.075 | I37: 4.305 | J37: 4.92 | K37: 6.7995 | L37: 9.5193 | M37: 10.8792 | N37: 5.025 | O37: 7.035 | P37: 8.04 | Q37: 1 | R37: 3.06 | S37: 5
A38: FY2025-26 | B38: Ambuja Cement | C38: =VLOOKUP(B38,Mapping!A:B,2,0) -> Lateral | D38: =VLOOKUP(B38,Mapping!A:C,3,0) -> West | E38: =VLOOKUP(B38,Mapping!A:D,4,0) -> West 1 | F38: =VLOOKUP(B38,Mapping!A:E,5,0) -> Anjli | G38: =VLOOKUP(B38,Mapping!A:F,6,0) -> Ankit | H38: 5.625 | I38: 7.875 | J38: 9 | K38: 4.7235 | L38: 6.6129 | M38: 7.5576 | N38: 5.27 | O38: 7.378 | P38: 8.432 | Q38: 7.51 | R38: 29.50095 | S38: 56
A39: FY2025-26 | B39: Ashok Leyland | C39: =VLOOKUP(B39,Mapping!A:B,2,0) -> Lateral | D39: =VLOOKUP(B39,Mapping!A:C,3,0) -> South | E39: =VLOOKUP(B39,Mapping!A:D,4,0) -> South 2 | F39: =VLOOKUP(B39,Mapping!A:E,5,0) -> Sulabh | G39: =VLOOKUP(B39,Mapping!A:F,6,0) -> Krishna | H39: 3 | I39: 4.2 | J39: 4.8 | K39: 4 | L39: 5.6 | M39: 6.4 | N39: 4 | O39: 5.6 | P39: 6.4 | Q39: 4 | R39: 6 | S39: 24
A40: FY2025-26 | B40: Sterling Tools | C40: =VLOOKUP(B40,Mapping!A:B,2,0) -> Lateral | D40: =VLOOKUP(B40,Mapping!A:C,3,0) -> North | E40: =VLOOKUP(B40,Mapping!A:D,4,0) -> North | F40: =VLOOKUP(B40,Mapping!A:E,5,0) -> Anjli | G40: =VLOOKUP(B40,Mapping!A:F,6,0) -> Archana | H40: 30 | I40: 42 | J40: 48 | K40: 22.5 | L40: 31.5 | M40: 36 | N40: 26.25 | O40: 36.75 | P40: 42 | Q40: 38 | R40: 6.59455 | S40: 6.8
...

Sheet CM_Forecast
A1: =Revenue_Budget!A1 -> FY | B1: =Revenue_Budget!B1 -> Project | C1: =Revenue_Budget!C1 -> Vertical | D1: =Revenue_Budget!D1 -> Region | E1: =Revenue_Budget!E1 -> Sub Region | F1: =Revenue_Budget!F1 -> Region Head | G1: =Revenue_Budget!G1 -> Practice Head | H1: =Revenue_Budget!H1 -> 45748 | ... S1: =Revenue_Budget!S1 -> 46082
A2: FY2025-26 | B2: Honeywell | C2: =VLOOKUP(B2,Mapping!A:B,2,0) -> Lateral | D2: =VLOOKUP(B2,Mapping!A:C,3,0) -> South | E2: =VLOOKUP(B2,Mapping!A:D,4,0) -> South 1 | F2: =VLOOKUP(B2,Mapping!A:E,5,0) -> Bapi | G2: =VLOOKUP(B2,Mapping!A:F,6,0) -> Bapi | H2: =IFERROR(Rev_Forecast!H2*45%,0) -> 49.5 | I2: =IFERROR(Rev_Forecast!I2*45%,0) -> 69.3 | J2: =IFERROR(Rev_Forecast!J2*45%,0) -> 79.2 | K2: =IFERROR(Rev_Forecast!K2*45%,0) -> 53.641798 | L2: =IFERROR(Rev_Forecast!L2*45%,0) -> 75.098517 | M2: =IFERROR(Rev_Forecast!M2*45%,0) -> 85.826876 | N2: =IFERROR(Rev_Forecast!N2*45%,0) -> 37.104298 | O2: =IFERROR(Rev_Forecast!O2*45%,0) -> 51.946017 | ... S2: =IFERROR(Rev_Forecast!S2*45%,0) -> 60.559258
A3: FY2025-26 | B3: Pfizer | C3: =VLOOKUP(B3,Mapping!A:B,2,0) -> Lateral | D3: =VLOOKUP(B3,Mapping!A:C,3,0) -> West | E3: =VLOOKUP(B3,Mapping!A:D,4,0) -> West 1 | F3: =VLOOKUP(B3,Mapping!A:E,5,0) -> Anjli | G3: =VLOOKUP(B3,Mapping!A:F,6,0) -> Usha | H3: =IFERROR(Rev_Forecast!H3*45%,0) -> 1.96875 | I3: =IFERROR(Rev_Forecast!I3*45%,0) -> 2.75625 | J3: =IFERROR(Rev_Forecast!J3*45%,0) -> 3.15 | K3: =IFERROR(Rev_Forecast!K3*45%,0) -> 2.925 | L3: =IFERROR(Rev_Forecast!L3*45%,0) -> 4.095 | M3: =IFERROR(Rev_Forecast!M3*45%,0) -> 4.68 | N3: =IFERROR(Rev_Forecast!N3*45%,0) -> 1.8 | O3: =IFERROR(Rev_Forecast!O3*45%,0) -> 2.52 | ... S3: =IFERROR(Rev_Forecast!S3*45%,0) -> 3.15
A4: FY2025-26 | B4: Tata Motors | C4: =VLOOKUP(B4,Mapping!A:B,2,0) -> Lateral | D4: =VLOOKUP(B4,Mapping!A:C,3,0) -> West | E4: =VLOOKUP(B4,Mapping!A:D,4,0) -> West 2 | F4: =VLOOKUP(B4,Mapping!A:E,5,0) -> Anjli | G4: =VLOOKUP(B4,Mapping!A:F,6,0) -> Shweta | H4: =IFERROR(Rev_Forecast!H4*45%,0) -> 0.50625 | I4: =IFERROR(Rev_Forecast!I4*45%,0) -> 0.70875 | J4: =IFERROR(Rev_Forecast!J4*45%,0) -> 0.81 | K4: =IFERROR(Rev_Forecast!K4*45%,0) -> 0 | L4: =IFERROR(Rev_Forecast!L4*45%,0) -> 0 | M4: =IFERROR(Rev_Forecast!M4*45%,0) -> 0 | N4: =IFERROR(Rev_Forecast!N4*45%,0) -> 0 | O4: =IFERROR(Rev_Forecast!O4*45%,0) -> 0 | ... S4: =IFERROR(Rev_Forecast!S4*45%,0) -> 0
A5: FY2025-26 | B5: SKF India | C5: =VLOOKUP(B5,Mapping!A:B,2,0) -> Lateral | D5: =VLOOKUP(B5,Mapping!A:C,3,0) -> North | E5: =VLOOKUP(B5,Mapping!A:D,4,0) -> North | F5: =VLOOKUP(B5,Mapping!A:E,5,0) -> Anjli | G5: =VLOOKUP(B5,Mapping!A:F,6,0) -> Archana | H5: =IFERROR(Rev_Forecast!H5*45%,0) -> 5.7375 | I5: =IFERROR(Rev_Forecast!I5*45%,0) -> 8.0325 | J5: =IFERROR(Rev_Forecast!J5*45%,0) -> 9.18 | K5: =IFERROR(Rev_Forecast!K5*45%,0) -> 5.8725 | L5: =IFERROR(Rev_Forecast!L5*45%,0) -> 8.2215 | M5: =IFERROR(Rev_Forecast!M5*45%,0) -> 9.396 | N5: =IFERROR(Rev_Forecast!N5*45%,0) -> 3.61125 | O5: =IFERROR(Rev_Forecast!O5*45%,0) -> 5.05575 | ... S5: =IFERROR(Rev_Forecast!S5*45%,0) -> 7.65
A6: FY2025-26 | B6: Siemens | C6: =VLOOKUP(B6,Mapping!A:B,2,0) -> Lateral | D6: =VLOOKUP(B6,Mapping!A:C,3,0) -> South | E6: =VLOOKUP(B6,Mapping!A:D,4,0) -> South 1 | F6: =VLOOKUP(B6,Mapping!A:E,5,0) -> Sulabh | G6: =VLOOKUP(B6,Mapping!A:F,6,0) -> Kunal | H6: =IFERROR(Rev_Forecast!H6*45%,0) -> 1.125 | I6: =IFERROR(Rev_Forecast!I6*45%,0) -> 1.575 | J6: =IFERROR(Rev_Forecast!J6*45%,0) -> 1.8 | K6: =IFERROR(Rev_Forecast!K6*45%,0) -> 3.0375 | L6: =IFERROR(Rev_Forecast!L6*45%,0) -> 4.2525 | M6: =IFERROR(Rev_Forecast!M6*45%,0) -> 4.86 | N6: =IFERROR(Rev_Forecast!N6*45%,0) -> 1.125 | O6: =IFERROR(Rev_Forecast!O6*45%,0) -> 1.575 | ... S6: =IFERROR(Rev_Forecast!S6*45%,0) -> 10.8
A7: FY2025-26 | B7: Pidilite | C7: =VLOOKUP(B7,Mapping!A:B,2,0) -> Lateral | D7: =VLOOKUP(B7,Mapping!A:C,3,0) -> West | E7: =VLOOKUP(B7,Mapping!A:D,4,0) -> West 1 | F7: =VLOOKUP(B7,Mapping!A:E,5,0) -> Anjli | G7: =VLOOKUP(B7,Mapping!A:F,6,0) -> Usha | H7: =IFERROR(Rev_Forecast!H7*45%,0) -> 7.36875 | I7: =IFERROR(Rev_Forecast!I7*45%,0) -> 10.31625 | J7: =IFERROR(Rev_Forecast!J7*45%,0) -> 11.79 | K7: =IFERROR(Rev_Forecast!K7*45%,0) -> 8.26875 | L7: =IFERROR(Rev_Forecast!L7*45%,0) -> 11.57625 | M7: =IFERROR(Rev_Forecast!M7*45%,0) -> 13.23 | N7: =IFERROR(Rev_Forecast!N7*45%,0) -> 6.75 | O7: =IFERROR(Rev_Forecast!O7*45%,0) -> 9.45 | ... S7: =IFERROR(Rev_Forecast!S7*45%,0) -> 3.2625
A8: FY2025-26 | B8: Vertiv | C8: =VLOOKUP(B8,Mapping!A:B,2,0) -> Lateral | D8: =VLOOKUP(B8,Mapping!A:C,3,0) -> West | E8: =VLOOKUP(B8,Mapping!A:D,4,0) -> West 2 | F8: =VLOOKUP(B8,Mapping!A:E,5,0) -> Anjli | G8: =VLOOKUP(B8,Mapping!A:F,6,0) -> Shweta | H8: =IFERROR(Rev_Forecast!H8*45%,0) -> 1.8 | I8: =IFERROR(Rev_Forecast!I8*45%,0) -> 2.52 | J8: =IFERROR(Rev_Forecast!J8*45%,0) -> 2.88 | K8: =IFERROR(Rev_Forecast!K8*45%,0) -> 2.25 | L8: =IFERROR(Rev_Forecast!L8*45%,0) -> 3.15 | M8: =IFERROR(Rev_Forecast!M8*45%,0) -> 3.6 | N8: =IFERROR(Rev_Forecast!N8*45%,0) -> 3.375 | O8: =IFERROR(Rev_Forecast!O8*45%,0) -> 4.725 | ... S8: =IFERROR(Rev_Forecast!S8*45%,0) -> 2.025
A9: FY2025-26 | B9: Birla Paints | C9: =VLOOKUP(B9,Mapping!A:B,2,0) -> Lateral | D9: =VLOOKUP(B9,Mapping!A:C,3,0) -> West | E9: =VLOOKUP(B9,Mapping!A:D,4,0) -> West 1 | F9: =VLOOKUP(B9,Mapping!A:E,5,0) -> Anjli | G9: =VLOOKUP(B9,Mapping!A:F,6,0) -> Geetu | H9: =IFERROR(Rev_Forecast!H9*45%,0) -> 0 | I9: =IFERROR(Rev_Forecast!I9*45%,0) -> 0 | J9: =IFERROR(Rev_Forecast!J9*45%,0) -> 0 | K9: =IFERROR(Rev_Forecast!K9*45%,0) -> 0 | L9: =IFERROR(Rev_Forecast!L9*45%,0) -> 0 | M9: =IFERROR(Rev_Forecast!M9*45%,0) -> 0 | N9: =IFERROR(Rev_Forecast!N9*45%,0) -> 0 | O9: =IFERROR(Rev_Forecast!O9*45%,0) -> 0 | ... S9: =IFERROR(Rev_Forecast!S9*45%,0) -> 5.85
A10: FY2025-26 | B10: Ingram Micro | C10: =VLOOKUP(B10,Mapping!A:B,2,0) -> Lateral | D10: =VLOOKUP(B10,Mapping!A:C,3,0) -> West | E10: =VLOOKUP(B10,Mapping!A:D,4,0) -> West 1 | F10: =VLOOKUP(B10,Mapping!A:E,5,0) -> Anjli | G10: =VLOOKUP(B10,Mapping!A:F,6,0) -> Geetu | H10: =IFERROR(Rev_Forecast!H10*45%,0) -> 3.6 | I10: =IFERROR(Rev_Forecast!I10*45%,0) -> 5.04 | J10: =IFERROR(Rev_Forecast!J10*45%,0) -> 5.76 | K10: =IFERROR(Rev_Forecast!K10*45%,0) -> 3.459375 | L10: =IFERROR(Rev_Forecast!L10*45%,0) -> 4.843125 | M10: =IFERROR(Rev_Forecast!M10*45%,0) -> 5.535 | N10: =IFERROR(Rev_Forecast!N10*45%,0) -> 3.375 | O10: =IFERROR(Rev_Forecast!O10*45%,0) -> 4.725 | ... S10: =IFERROR(Rev_Forecast!S10*45%,0) -> 0
A11: FY2025-26 | B11: HPE | C11: =VLOOKUP(B11,Mapping!A:B,2,0) -> Lateral | D11: =VLOOKUP(B11,Mapping!A:C,3,0) -> South | E11: =VLOOKUP(B11,Mapping!A:D,4,0) -> South 1 | F11: =VLOOKUP(B11,Mapping!A:E,5,0) -> Mahak | G11: =VLOOKUP(B11,Mapping!A:F,6,0) -> Mahak | H11: =IFERROR(Rev_Forecast!H11*45%,0) -> 1.63125 | I11: =IFERROR(Rev_Forecast!I11*45%,0) -> 2.28375 | J11: =IFERROR(Rev_Forecast!J11*45%,0) -> 2.61 | K11: =IFERROR(Rev_Forecast!K11*45%,0) -> 1.125 | L11: =IFERROR(Rev_Forecast!L11*45%,0) -> 1.575 | M11: =IFERROR(Rev_Forecast!M11*45%,0) -> 1.8 | N11: =IFERROR(Rev_Forecast!N11*45%,0) -> 1.125 | O11: =IFERROR(Rev_Forecast!O11*45%,0) -> 1.575 | ... S11: =IFERROR(Rev_Forecast!S11*45%,0) -> 58.05
A12: FY2025-26 | B12: Isuzu | C12: =VLOOKUP(B12,Mapping!A:B,2,0) -> Lateral | D12: =VLOOKUP(B12,Mapping!A:C,3,0) -> South | E12: =VLOOKUP(B12,Mapping!A:D,4,0) -> South 1 | F12: =VLOOKUP(B12,Mapping!A:E,5,0) -> Anjli | G12: =VLOOKUP(B12,Mapping!A:F,6,0) -> Satya | H12: =IFERROR(Rev_Forecast!H12*45%,0) -> 4.05 | I12: =IFERROR(Rev_Forecast!I12*45%,0) -> 5.67 | J12: =IFERROR(Rev_Forecast!J12*45%,0) -> 6.48 | K12: =IFERROR(Rev_Forecast!K12*45%,0) -> 3.8475 | L12: =IFERROR(Rev_Forecast!L12*45%,0) -> 5.3865 | M12: =IFERROR(Rev_Forecast!M12*45%,0) -> 6.156 | N12: =IFERROR(Rev_Forecast!N12*45%,0) -> 4.07025 | O12: =IFERROR(Rev_Forecast!O12*45%,0) -> 5.69835 | ... S12: =IFERROR(Rev_Forecast!S12*45%,0) -> 2.25
A13: FY2025-26 | B13: Mahindra Holidays | C13: =VLOOKUP(B13,Mapping!A:B,2,0) -> Lateral | D13: =VLOOKUP(B13,Mapping!A:C,3,0) -> West | E13: =VLOOKUP(B13,Mapping!A:D,4,0) -> West 1 | F13: =VLOOKUP(B13,Mapping!A:E,5,0) -> Anjli | G13: =VLOOKUP(B13,Mapping!A:F,6,0) -> Geetu | H13: =IFERROR(Rev_Forecast!H13*45%,0) -> 0.7875 | I13: =IFERROR(Rev_Forecast!I13*45%,0) -> 1.1025 | J13: =IFERROR(Rev_Forecast!J13*45%,0) -> 1.26 | K13: =IFERROR(Rev_Forecast!K13*45%,0) -> 1.13625 | L13: =IFERROR(Rev_Forecast!L13*45%,0) -> 1.59075 | M13: =IFERROR(Rev_Forecast!M13*45%,0) -> 1.818 | N13: =IFERROR(Rev_Forecast!N13*45%,0) -> 0.45 | O13: =IFERROR(Rev_Forecast!O13*45%,0) -> 0.63 | ... S13: =IFERROR(Rev_Forecast!S13*45%,0) -> 3.15
... A76: FY2025-26 | B76: CG Power | C76: =VLOOKUP(B76,Mapping!A:B,2,0) -> Lateral | D76: =VLOOKUP(B76,Mapping!A:C,3,0) -> West | E76: =VLOOKUP(B76,Mapping!A:D,4,0) -> West 1 | F76: =VLOOKUP(B76,Mapping!A:E,5,0) -> Anjli | G76: =VLOOKUP(B76,Mapping!A:F,6,0) -> Anjli | H76: =IFERROR(Rev_Forecast!H76*45%,0) -> 0 | I76: =IFERROR(Rev_Forecast!I76*45%,0) -> 0 | J76: =IFERROR(Rev_Forecast!J76*45%,0) -> 0 | K76: =IFERROR(Rev_Forecast!K76*45%,0) -> 0 | L76: =IFERROR(Rev_Forecast!L76*45%,0) -> 0 | M76: =IFERROR(Rev_Forecast!M76*45%,0) -> 0 | N76: =IFERROR(Rev_Forecast!N76*45%,0) -> 0 | O76: =IFERROR(Rev_Forecast!O76*45%,0) -> 0 | ... S76: =IFERROR(Rev_Forecast!S76*45%,0) -> 0.9

Sheet Mapping
A1: Project | B1: Vertical | C1: Region | D1: Sub Region | E1: Region Head | F1: Practice Head
A2: Honeywell | B2: Lateral | C2: South | D2: South 1 | E2: Bapi | F2: Bapi
A3: Pfizer | B3: Lateral | C3: West | D3: West 1 | E3: Anjli | F3: Usha
A4: Tata Motors | B4: Lateral | C4: West | D4: West 2 | E4: Anjli | F4: Shweta
A5: SKF India | B5: Lateral | C5: North | D5: North | E5: Anjli | F5: Archana
