Workbook

Sheet Revenue_Budget
A1: FY | B1: Project | C1: Vertical | D1: Region | E1: Sub Region | F1: Region Head | G1: Practice Head | H1: 45383 | I1: =EDATE(H1,1) -> 45413 | J1: =EDATE(I1,1) -> 45444 | K1: =EDATE(J1,1) -> 45474 | L1: =EDATE(K1,1) -> 45505 | M1: =EDATE(L1,1) -> 45536 | N1: =EDATE(M1,1) -> 45566 | O1: =EDATE(N1,1) -> 45597 | P1: =EDATE(O1,1) -> 45627 | ... S1: =EDATE(R1,1) -> 45717
A2: FY2024-25 | B2: Tata Motors | C2: =VLOOKUP(B2,Mapping!B:C,2,0) -> Lateral | D2: =VLOOKUP(B2,Mapping!B:D,3,0) -> West | E2: =VLOOKUP(B2,Mapping!B:E,4,0) -> West 2 | F2: =VLOOKUP(B2,Mapping!B:F,5,0) -> Anjli | G2: =VLOOKUP(B2,Mapping!B:G,6,0) -> Shweta | H2: 25 | I2: 35 | J2: 40 | K2: 43.5 | L2: 60.9 | M2: 69.6 | N2: 49.025 | O2: 68.635 | P2: 78.44 | Q2: 50.8825 | R2: 71.2355 | S2: 81.412
A3: FY2024-25 | B3: Schaeffler | C3: =VLOOKUP(B3,Mapping!B:C,2,0) -> Lateral | D3: =VLOOKUP(B3,Mapping!B:D,3,0) -> West | E3: =VLOOKUP(B3,Mapping!B:E,4,0) -> West 2 | F3: =VLOOKUP(B3,Mapping!B:F,5,0) -> Anjli | G3: =VLOOKUP(B3,Mapping!B:G,6,0) -> Shweta | H3: 6.175 | I3: 8.645 | J3: 9.88 | K3: 6.35 | L3: 8.89 | M3: 10.16 | N3: 6.65 | O3: 9.31 | P3: 10.64 | Q3: 7.0325 | R3: 9.8455 | S3: 11.252
A4: FY2024-25 | B4: Vertiv | C4: =VLOOKUP(B4,Mapping!B:C,2,0) -> Lateral | D4: =VLOOKUP(B4,Mapping!B:D,3,0) -> West | E4: =VLOOKUP(B4,Mapping!B:E,4,0) -> West 2 | F4: =VLOOKUP(B4,Mapping!B:F,5,0) -> Anjli | G4: =VLOOKUP(B4,Mapping!B:G,6,0) -> Shweta | H4: 3 | I4: 4.2 | J4: 4.8 | K4: 3.675 | L4: 5.145 | M4: 5.88 | N4: 3.825 | O4: 5.355 | P4: 6.12 | Q4: 4.0575 | R4: 5.6805 | S4: 6.492
A5: FY2024-25 | B5: Tata Marcopolo | C5: =VLOOKUP(B5,Mapping!B:C,2,0) -> Lateral | D5: =VLOOKUP(B5,Mapping!B:D,3,0) -> West | E5: =VLOOKUP(B5,Mapping!B:E,4,0) -> West 2 | F5: =VLOOKUP(B5,Mapping!B:F,5,0) -> Anjli | G5: =VLOOKUP(B5,Mapping!B:G,6,0) -> Anjli | H5: 1.125 | I5: 1.575 | J5: 1.8 | K5: 1.125 | L5: 1.575 | M5: 1.8 | N5: 1.125 | O5: 1.575 | P5: 1.8 | Q5: 1.2075 | R5: 1.6905 | S5: 1.932
A6: FY2024-25 | B6: ThyssenKrupp | C6: =VLOOKUP(B6,Mapping!B:C,2,0) -> Lateral | D6: =VLOOKUP(B6,Mapping!B:D,3,0) -> West | E6: =VLOOKUP(B6,Mapping!B:E,4,0) -> West 2 | F6: =VLOOKUP(B6,Mapping!B:F,5,0) -> Anjli | G6: =VLOOKUP(B6,Mapping!B:G,6,0) -> Shweta | H6: 15.4 | I6: 21.56 | J6: 24.64 | K6: 15.925 | L6: 22.295 | M6: 25.48 | N6: 16.575 | O6: 23.205 | P6: 26.52 | Q6: 17.3075 | R6: 24.2305 | S6: 27.692
A7: FY2024-25 | B7: Ultratech | C7: =VLOOKUP(B7,Mapping!B:C,2,0) -> Lateral | D7: =VLOOKUP(B7,Mapping!B:D,3,0) -> West | E7: =VLOOKUP(B7,Mapping!B:E,4,0) -> West 1 | F7: =VLOOKUP(B7,Mapping!B:F,5,0) -> Anjli | G7: =VLOOKUP(B7,Mapping!B:G,6,0) -> Elton | H7: 0.375 | I7: 0.525 | J7: 0.6 | K7: 1.8 | L7: 2.52 | M7: 2.88 | N7: 1.95 | O7: 2.73 | P7: 3.12 | Q7: 2.1825 | R7: 3.0555 | S7: 3.492
A8: FY2024-25 | B8: Tata Teleservices | C8: =VLOOKUP(B8,Mapping!B:C,2,0) -> Lateral | D8: =VLOOKUP(B8,Mapping!B:D,3,0) -> West | E8: =VLOOKUP(B8,Mapping!B:E,4,0) -> West 1 | F8: =VLOOKUP(B8,Mapping!B:F,5,0) -> Anjli | G8: =VLOOKUP(B8,Mapping!B:G,6,0) -> Elton | H8: 3.125 | I8: 4.375 | J8: 5 | K8: 6.25 | L8: 8.75 | M8: 10 | N8: 6.25 | O8: 8.75 | P8: 10 | Q8: 6.3325 | R8: 8.8655 | S8: 10.132
A9: FY2024-25 | B9: Hyundai Motor | C9: =VLOOKUP(B9,Mapping!B:C,2,0) -> Lateral | D9: =VLOOKUP(B9,Mapping!B:D,3,0) -> West | E9: =VLOOKUP(B9,Mapping!B:E,4,0) -> West 2 | F9: =VLOOKUP(B9,Mapping!B:F,5,0) -> Anjli | G9: =VLOOKUP(B9,Mapping!B:G,6,0) -> Shweta | H9: 3.75 | I9: 5.25 | J9: 6 | K9: 7.5 | L9: 10.5 | M9: 12 | N9: 10 | O9: 14 | P9: 16 | Q9: 8 | R9: 11.2 | S9: 12.8
A10: FY2024-25 | B10: Bridgestone | C10: =VLOOKUP(B10,Mapping!B:C,2,0) -> Lateral | D10: =VLOOKUP(B10,Mapping!B:D,3,0) -> West | E10: =VLOOKUP(B10,Mapping!B:E,4,0) -> West 2 | F10: =VLOOKUP(B10,Mapping!B:F,5,0) -> Anjli | G10: =VLOOKUP(B10,Mapping!B:G,6,0) -> Shweta | H10: 0 | I10: 0 | J10: 0 | K10: 0 | L10: 0 | M10: 0 | N10: 0 | O10: 0 | P10: 0 | Q10: 0 | R10: 0 | S10: 0
A11: FY2024-25 | B11: SKF India | C11: =VLOOKUP(B11,Mapping!B:C,2,0) -> Lateral | D11: =VLOOKUP(B11,Mapping!B:D,3,0) -> North | E11: =VLOOKUP(B11,Mapping!B:E,4,0) -> North | F11: =VLOOKUP(B11,Mapping!B:F,5,0) -> Anjli | G11: =VLOOKUP(B11,Mapping!B:G,6,0) -> Archana | H11: 11.375 | I11: 15.925 | J11: 18.2 | K11: 11.5 | L11: 16.1 | M11: 18.4 | N11: 11.5 | O11: 16.1 | P11: 18.4 | Q11: 11.5825 | R11: 16.2155 | S11: 18.532
A12: FY2024-25 | B12: Jindal Stainless | C12: =VLOOKUP(B12,Mapping!B:C,2,0) -> Lateral | D12: =VLOOKUP(B12,Mapping!B:D,3,0) -> North | E12: =VLOOKUP(B12,Mapping!B:E,4,0) -> North | F12: =VLOOKUP(B12,Mapping!B:F,5,0) -> Anjli | G12: =VLOOKUP(B12,Mapping!B:G,6,0) -> Archana | H12: 9 | I12: 12.6 | J12: 14.4 | K12: 7.9075 | L12: 11.0705 | M12: 12.652 | N12: 7.6575 | O12: 10.7205 | P12: 12.252 | Q12: 7.865 | R12: 11.011 | S12: 12.584
A13: FY2024-25 | B13: Maruti Suzuki(MSIL) | C13: =VLOOKUP(B13,Mapping!B:C,2,0) -> Lateral | D13: =VLOOKUP(B13,Mapping!B:D,3,0) -> North | E13: =VLOOKUP(B13,Mapping!B:E,4,0) -> North | F13: =VLOOKUP(B13,Mapping!B:F,5,0) -> Anjli | G13: =VLOOKUP(B13,Mapping!B:G,6,0) -> Archana | H13: 4.25 | I13: 5.95 | J13: 6.8 | K13: 7.5 | L13: 10.5 | M13: 12 | N13: 8.75 | O13: 12.25 | P13: 14 | Q13: 10 | R13: 14 | S13: 16
... A58: FY2024-25 | B58: New Sales + Mining | C58: =VLOOKUP(B58,Mapping!B:C,2,0) -> Lateral | D58: =VLOOKUP(B58,Mapping!B:D,3,0) -> New Sales | E58: =VLOOKUP(B58,Mapping!B:E,4,0) -> New Sales | F58: =VLOOKUP(B58,Mapping!B:F,5,0) -> Nizar | G58: =VLOOKUP(B58,Mapping!B:G,6,0) -> Nizar | H58: 95.92492 | I58: 134.29489 | J58: 153.47987 | K58: 191.84984 | L58: 268.58978 | M58: 306.95974 | N58: 287.77476 | O58: 402.88466 | P58: 460.43962 | Q58: 383.69968 | R58: 537.17955 | S58: 613.91949
H59: In lacs

Sheet CM_Budget
A1: =Revenue_Budget!A1 -> FY | B1: =Revenue_Budget!B1 -> Project | C1: =Revenue_Budget!C1 -> Vertical | D1: =Revenue_Budget!D1 -> Region | E1: =Revenue_Budget!E1 -> Sub Region | F1: =Revenue_Budget!F1 -> Region Head | G1: =Revenue_Budget!G1 -> Practice Head | H1: =Revenue_Budget!H1 -> 45383 | ... S1: =Revenue_Budget!S1 -> 45717
A2: FY2024-25 | B2: Tata Motors | C2: =VLOOKUP(B2,Mapping!B:C,2,0) -> Lateral | D2: =VLOOKUP(B2,Mapping!B:D,3,0) -> West | E2: =VLOOKUP(B2,Mapping!B:E,4,0) -> West 2 | F2: =VLOOKUP(B2,Mapping!B:F,5,0) -> Anjli | G2: =VLOOKUP(B2,Mapping!B:G,6,0) -> Shweta | H2: =Revenue_Budget!H2*42% -> 10.5 | I2: =Revenue_Budget!I2*42% -> 14.7 | J2: =Revenue_Budget!J2*42% -> 16.8 | K2: =Revenue_Budget!K2*42% -> 18.27 | L2: =Revenue_Budget!L2*42% -> 25.578 | M2: =Revenue_Budget!M2*42% -> 29.232 | N2: =Revenue_Budget!N2*42% -> 20.5905 | O2: =Revenue_Budget!O2*42% -> 28.8267 | ... S2: =Revenue_Budget!S2*42% -> 34.19304
A3: FY2024-25 | B3: Schaeffler | C3: =VLOOKUP(B3,Mapping!B:C,2,0) -> Lateral | D3: =VLOOKUP(B3,Mapping!B:D,3,0) -> West | E3: =VLOOKUP(B3,Mapping!B:E,4,0) -> West 2 | F3: =VLOOKUP(B3,Mapping!B:F,5,0) -> Anjli | G3: =VLOOKUP(B3,Mapping!B:G,6,0) -> Shweta | H3: =Revenue_Budget!H3*42% -> 2.5935 | I3: =Revenue_Budget!I3*42% -> 3.6309 | J3: =Revenue_Budget!J3*42% -> 4.1496 | K3: =Revenue_Budget!K3*42% -> 2.667 | L3: =Revenue_Budget!L3*42% -> 3.7338 | M3: =Revenue_Budget!M3*42% -> 4.2672 | N3: =Revenue_Budget!N3*42% -> 2.793 | O3: =Revenue_Budget!O3*42% -> 3.9102 | ... S3: =Revenue_Budget!S3*42% -> 4.72584
A4: FY2024-25 | B4: Vertiv | C4: =VLOOKUP(B4,Mapping!B:C,2,0) -> Lateral | D4: =VLOOKUP(B4,Mapping!B:D,3,0) -> West | E4: =VLOOKUP(B4,Mapping!B:E,4,0) -> West 2 | F4: =VLOOKUP(B4,Mapping!B:F,5,0) -> Anjli | G4: =VLOOKUP(B4,Mapping!B:G,6,0) -> Shweta | H4: =Revenue_Budget!H4*42% -> 1.26 | I4: =Revenue_Budget!I4*42% -> 1.764 | J4: =Revenue_Budget!J4*42% -> 2.016 | K4: =Revenue_Budget!K4*42% -> 1.5435 | L4: =Revenue_Budget!L4*42% -> 2.1609 | M4: =Revenue_Budget!M4*42% -> 2.4696 | N4: =Revenue_Budget!N4*42% -> 1.6065 | O4: =Revenue_Budget!O4*42% -> 2.2491 | ... S4: =Revenue_Budget!S4*42% -> 2.72664
A5: FY2024-25 | B5: Tata Marcopolo | C5: =VLOOKUP(B5,Mapping!B:C,2,0) -> Lateral | D5: =VLOOKUP(B5,Mapping!B:D,3,0) -> West | E5: =VLOOKUP(B5,Mapping!B:E,4,0) -> West 2 | F5: =VLOOKUP(B5,Mapping!B:F,5,0) -> Anjli | G5: =VLOOKUP(B5,Mapping!B:G,6,0) -> Anjli | H5: =Revenue_Budget!H5*42% -> 0.4725 | I5: =Revenue_Budget!I5*42% -> 0.6615 | J5: =Revenue_Budget!J5*42% -> 0.756 | K5: =Revenue_Budget!K5*42% -> 0.4725 | L5: =Revenue_Budget!L5*42% -> 0.6615 | M5: =Revenue_Budget!M5*42% -> 0.756 | N5: =Revenue_Budget!N5*42% -> 0.4725 | O5: =Revenue_Budget!O5*42% -> 0.6615 | ... S5: =Revenue_Budget!S5*42% -> 0.81144
A6: FY2024-25 | B6: ThyssenKrupp | C6: =VLOOKUP(B6,Mapping!B:C,2,0) -> Lateral | D6: =VLOOKUP(B6,Mapping!B:D,3,0) -> West | E6: =VLOOKUP(B6,Mapping!B:E,4,0) -> West 2 | F6: =VLOOKUP(B6,Mapping!B:F,5,0) -> Anjli | G6: =VLOOKUP(B6,Mapping!B:G,6,0) -> Shweta | H6: =Revenue_Budget!H6*42% -> 6.468 | I6: =Revenue_Budget!I6*42% -> 9.0552 | J6: =Revenue_Budget!J6*42% -> 10.3488 | K6: =Revenue_Budget!K6*42% -> 6.6885 | L6: =Revenue_Budget!L6*42% -> 9.3639 | M6: =Revenue_Budget!M6*42% -> 10.7016 | N6: =Revenue_Budget!N6*42% -> 6.9615 | O6: =Revenue_Budget!O6*42% -> 9.7461 | ... S6: =Revenue_Budget!S6*42% -> 11.63064
A7: FY2024-25 | B7: Ultratech | C7: =VLOOKUP(B7,Mapping!B:C,2,0) -> Lateral | D7: =VLOOKUP(B7,Mapping!B:D,3,0) -> West | E7: =VLOOKUP(B7,Mapping!B:E,4,0) -> West 1 | F7: =VLOOKUP(B7,Mapping!B:F,5,0) -> Anjli | G7: =VLOOKUP(B7,Mapping!B:G,6,0) -> Elton | H7: =Revenue_Budget!H7*42% -> 0.1575 | I7: =Revenue_Budget!I7*42% -> 0.2205 | J7: =Revenue_Budget!J7*42% -> 0.252 | K7: =Revenue_Budget!K7*42% -> 0.756 | L7: =Revenue_Budget!L7*42% -> 1.0584 | M7: =Revenue_Budget!M7*42% -> 1.2096 | N7: =Revenue_Budget!N7*42% -> 0.819 | O7: =Revenue_Budget!O7*42% -> 1.1466 | ... S7: =Revenue_Budget!S7*42% -> 1.46664
A8: FY2024-25 | B8: Tata Teleservices | C8: =VLOOKUP(B8,Mapping!B:C,2,0) -> Lateral | D8: =VLOOKUP(B8,Mapping!B:D,3,0) -> West | E8: =VLOOKUP(B8,Mapping!B:E,4,0) -> West 1 | F8: =VLOOKUP(B8,Mapping!B:F,5,0) -> Anjli | G8: =VLOOKUP(B8,Mapping!B:G,6,0) -> Elton | H8: =Revenue_Budget!H8*42% -> 1.3125 | I8: =Revenue_Budget!I8*42% -> 1.8375 | J8: =Revenue_Budget!J8*42% -> 2.1 | K8: =Revenue_Budget!K8*42% -> 2.625 | L8: =Revenue_Budget!L8*42% -> 3.675 | M8: =Revenue_Budget!M8*42% -> 4.2 | N8: =Revenue_Budget!N8*42% -> 2.625 | O8: =Revenue_Budget!O8*42% -> 3.675 | ... S8: =Revenue_Budget!S8*42% -> 4.25544
A9: FY2024-25 | B9: Hyundai Motor | C9: =VLOOKUP(B9,Mapping!B:C,2,0) -> Lateral | D9: =VLOOKUP(B9,Mapping!B:D,3,0) -> West | E9: =VLOOKUP(B9,Mapping!B:E,4,0) -> West 2 | F9: =VLOOKUP(B9,Mapping!B:F,5,0) -> Anjli | G9: =VLOOKUP(B9,Mapping!B:G,6,0) -> Shweta | H9: =Revenue_Budget!H9*42% -> 1.575 | I9: =Revenue_Budget!I9*42% -> 2.205 | J9: =Revenue_Budget!J9*42% -> 2.52 | K9: =Revenue_Budget!K9*42% -> 3.15 | L9: =Revenue_Budget!L9*42% -> 4.41 | M9: =Revenue_Budget!M9*42% -> 5.04 | N9: =Revenue_Budget!N9*42% -> 4.2 | O9: =Revenue_Budget!O9*42% -> 5.88 | ... S9: =Revenue_Budget!S9*42% -> 5.376
A10: FY2024-25 | B10: Bridgestone | C10: =VLOOKUP(B10,Mapping!B:C,2,0) -> Lateral | D10: =VLOOKUP(B10,Mapping!B:D,3,0) -> West | E10: =VLOOKUP(B10,Mapping!B:E,4,0) -> West 2 | F10: =VLOOKUP(B10,Mapping!B:F,5,0) -> Anjli | G10: =VLOOKUP(B10,Mapping!B:G,6,0) -> Shweta | H10: =Revenue_Budget!H10*42% -> 0 | I10: =Revenue_Budget!I10*42% -> 0 | J10: =Revenue_Budget!J10*42% -> 0 | K10: =Revenue_Budget!K10*42% -> 0 | L10: =Revenue_Budget!L10*42% -> 0 | M10: =Revenue_Budget!M10*42% -> 0 | N10: =Revenue_Budget!N10*42% -> 0 | O10: =Revenue_Budget!O10*42% -> 0 | ... S10: =Revenue_Budget!S10*42% -> 0
A11: FY2024-25 | B11: SKF India | C11: =VLOOKUP(B11,Mapping!B:C,2,0) -> Lateral | D11: =VLOOKUP(B11,Mapping!B:D,3,0) -> North | E11: =VLOOKUP(B11,Mapping!B:E,4,0) -> North | F11: =VLOOKUP(B11,Mapping!B:F,5,0) -> Anjli | G11: =VLOOKUP(B11,Mapping!B:G,6,0) -> Archana | H11: =Revenue_Budget!H11*42% -> 4.7775 | I11: =Revenue_Budget!I11*42% -> 6.6885 | J11: =Revenue_Budget!J11*42% -> 7.644 | K11: =Revenue_Budget!K11*42% -> 4.83 | L11: =Revenue_Budget!L11*42% -> 6.762 | M11: =Revenue_Budget!M11*42% -> 7.728 | N11: =Revenue_Budget!N11*42% -> 4.83 | O11: =Revenue_Budget!O11*42% -> 6.762 | ... S11: =Revenue_Budget!S11*42% -> 7.78344
A12: FY2024-25 | B12: Jindal Stainless | C12: =VLOOKUP(B12,Mapping!B:C,2,0) -> Lateral | D12: =VLOOKUP(B12,Mapping!B:D,3,0) -> North | E12: =VLOOKUP(B12,Mapping!B:E,4,0) -> North | F12: =VLOOKUP(B12,Mapping!B:F,5,0) -> Anjli | G12: =VLOOKUP(B12,Mapping!B:G,6,0) -> Archana | H12: =Revenue_Budget!H12*42% -> 3.78 | I12: =Revenue_Budget!I12*42% -> 5.292 | J12: =Revenue_Budget!J12*42% -> 6.048 | K12: =Revenue_Budget!K12*42% -> 3.32115 | L12: =Revenue_Budget!L12*42% -> 4.64961 | M12: =Revenue_Budget!M12*42% -> 5.31384 | N12: =Revenue_Budget!N12*42% -> 3.21615 | O12: =Revenue_Budget!O12*42% -> 4.50261 | ... S12: =Revenue_Budget!S12*42% -> 5.28528
A13: FY2024-25 | B13: Maruti Suzuki(MSIL) | C13: =VLOOKUP(B13,Mapping!B:C,2,0) -> Lateral | D13: =VLOOKUP(B13,Mapping!B:D,3,0) -> North | E13: =VLOOKUP(B13,Mapping!B:E,4,0) -> North | F13: =VLOOKUP(B13,Mapping!B:F,5,0) -> Anjli | G13: =VLOOKUP(B13,Mapping!B:G,6,0) -> Archana | H13: =Revenue_Budget!H13*42% -> 1.785 | I13: =Revenue_Budget!I13*42% -> 2.499 | J13: =Revenue_Budget!J13*42% -> 2.856 | K13: =Revenue_Budget!K13*42% -> 3.15 | L13: =Revenue_Budget!L13*42% -> 4.41 | M13: =Revenue_Budget!M13*42% -> 5.04 | N13: =Revenue_Budget!N13*42% -> 3.675 | O13: =Revenue_Budget!O13*42% -> 5.145 | ... S13: =Revenue_Budget!S13*42% -> 6.72
... A58: FY2024-25 | B58: New Sales + Mining | C58: =VLOOKUP(B58,Mapping!B:C,2,0) -> Lateral | D58: =VLOOKUP(B58,Mapping!B:D,3,0) -> New Sales | E58: =VLOOKUP(B58,Mapping!B:E,4,0) -> New Sales | F58: =VLOOKUP(B58,Mapping!B:F,5,0) -> Nizar | G58: =VLOOKUP(B58,Mapping!B:G,6,0) -> Nizar | H58: =Revenue_Budget!H58*42% -> 40.288466 | I58: =Revenue_Budget!I58*42% -> 56.403853 | J58: =Revenue_Budget!J58*42% -> 64.461546 | K58: =Revenue_Budget!K58*42% -> 80.576933 | L58: =Revenue_Budget!L58*42% -> 112.80771 | M58: =Revenue_Budget!M58*42% -> 128.92309 | N58: =Revenue_Budget!N58*42% -> 120.8654 | O58: =Revenue_Budget!O58*42% -> 169.21156 | ... S58: =Revenue_Budget!S58*42% -> 257.84618
H59: Check denomination

Sheet Target_Rev_Productivity
A1: FY | B1: Project | C1: Vertical | D1: Region | E1: Sub Region | F1: Region Head | G1: Practice Head | H1: 45383 | I1: =EDATE(H1,1) -> 45413 | J1: =EDATE(I1,1) -> 45444 | K1: =EDATE(J1,1) -> 45474 | L1: =EDATE(K1,1) -> 45505 | M1: =EDATE(L1,1) -> 45536 | N1: =EDATE(M1,1) -> 45566 | O1: =EDATE(N1,1) -> 45597 | P1: =EDATE(O1,1) -> 45627 | ... S1: =EDATE(R1,1) -> 45717
A2: FY2024-25 | B2: Tata Motors | C2: =VLOOKUP(B2,Mapping!B:C,2,0) -> Lateral | D2: =VLOOKUP(B2,Mapping!B:D,3,0) -> West | E2: =VLOOKUP(B2,Mapping!B:E,4,0) -> West 2 | F2: =VLOOKUP(B2,Mapping!B:F,5,0) -> Anjli | G2: =VLOOKUP(B2,Mapping!B:G,6,0) -> Shweta | H2: 0.97948379 | I2: 0.98666667 | J2: 1.1285266 | K2: 1.2770642 | L2: 1.6457143 | M2: 1.1889908 | N2: 1.1889908 | O2: 1.2274884 | P2: 2.644898 | Q2: 1.6858537 | R2: 1.5652174 | S2: 3.78
A3: FY2024-25 | B3: Schaeffler | C3: =VLOOKUP(B3,Mapping!B:C,2,0) -> Lateral | D3: =VLOOKUP(B3,Mapping!B:D,3,0) -> West | E3: =VLOOKUP(B3,Mapping!B:E,4,0) -> West 2 | F3: =VLOOKUP(B3,Mapping!B:F,5,0) -> Anjli | G3: =VLOOKUP(B3,Mapping!B:G,6,0) -> Shweta | H3: 1.3010204 | I3: 1.6363636 | J3: 1.4482759 | K3: 1.5867769 | L3: 1.7142857 | M3: 2.7428571 | N3: 1.3090909 | O3: 1.5 | P3: 0.22222222 | Q3: 1.904 | R3: 1.8 | S3: 2.6237333
A4: FY2024-25 | B4: Vertiv | C4: =VLOOKUP(B4,Mapping!B:C,2,0) -> Lateral | D4: =VLOOKUP(B4,Mapping!B:D,3,0) -> West | E4: =VLOOKUP(B4,Mapping!B:E,4,0) -> West 2 | F4: =VLOOKUP(B4,Mapping!B:F,5,0) -> Anjli | G4: =VLOOKUP(B4,Mapping!B:G,6,0) -> Shweta | H4: 0.8 | I4: 1.4 | J4: 0.91 | K4: 2.25 | L4: 1.14 | M4: 1.8 | N4: 0.66 | O4: 1.88 | P4: 3.04 | Q4: 1.369 | R4: 0.96 | S4: 0.248
A5: FY2024-25 | B5: Tata Marcopolo | C5: =VLOOKUP(B5,Mapping!B:C,2,0) -> Lateral | D5: =VLOOKUP(B5,Mapping!B:D,3,0) -> West | E5: =VLOOKUP(B5,Mapping!B:E,4,0) -> West 2 | F5: =VLOOKUP(B5,Mapping!B:F,5,0) -> Anjli | G5: =VLOOKUP(B5,Mapping!B:G,6,0) -> Anjli | H5: 0.84 | I5: 2.28 | J5: 1.704 | K5: 0.492 | L5: 2.4 | M5: 2.508 | N5: 0.132 | O5: 1.8 | P5: 1.8 | Q5: 1.8 | R5: 1.8 | S5: 0.912
A6: FY2024-25 | B6: ThyssenKrupp | C6: =VLOOKUP(B6,Mapping!B:C,2,0) -> Lateral | D6: =VLOOKUP(B6,Mapping!B:D,3,0) -> West | E6: =VLOOKUP(B6,Mapping!B:E,4,0) -> West 2 | F6: =VLOOKUP(B6,Mapping!B:F,5,0) -> Anjli | G6: =VLOOKUP(B6,Mapping!B:G,6,0) -> Shweta | H6: 1.7585485 | I6: 1.8 | J6: 1.8544832 | K6: 1.495082 | L6: 1.8526316 | M6: 1.7723077 | N6: 1.28 | O6: 0.90857143 | P6: 3.4285714 | Q6: 1.8 | R6: 30 | S6: 1.8
A7: FY2024-25 | B7: Ultratech | C7: =VLOOKUP(B7,Mapping!B:C,2,0) -> Lateral | D7: =VLOOKUP(B7,Mapping!B:D,3,0) -> West | E7: =VLOOKUP(B7,Mapping!B:E,4,0) -> West 1 | F7: =VLOOKUP(B7,Mapping!B:F,5,0) -> Anjli | G7: =VLOOKUP(B7,Mapping!B:G,6,0) -> Elton | H7: 1.248 | I7: -0.132 | J7: 1.2 | K7: 0.12 | L7: 1.8 | M7: 1.8 | N7: 1.8 | O7: 1.8 | P7: 1.8 | Q7: 1.8 | R7: 1.8 | S7: 1.8
A8: FY2024-25 | B8: Tata Teleservices | C8: =VLOOKUP(B8,Mapping!B:C,2,0) -> Lateral | D8: =VLOOKUP(B8,Mapping!B:D,3,0) -> West | E8: =VLOOKUP(B8,Mapping!B:E,4,0) -> West 1 | F8: =VLOOKUP(B8,Mapping!B:F,5,0) -> Anjli | G8: =VLOOKUP(B8,Mapping!B:G,6,0) -> Elton | H8: 1.8 | I8: 1.8 | J8: 1.8 | K8: 1.8 | L8: 1.8 | M8: 1.8 | N8: 1.8 | O8: 1.8 | P8: 1.8 | Q8: 1.8 | R8: 1.8 | S8: 1.8
A9: FY2024-25 | B9: Hyundai Motor | C9: =VLOOKUP(B9,Mapping!B:C,2,0) -> Lateral | D9: =VLOOKUP(B9,Mapping!B:D,3,0) -> West | E9: =VLOOKUP(B9,Mapping!B:E,4,0) -> West 2 | F9: =VLOOKUP(B9,Mapping!B:F,5,0) -> Anjli | G9: =VLOOKUP(B9,Mapping!B:G,6,0) -> Shweta | H9: 0.9984 | I9: 4.92 | J9: 2.4888 | K9: 2.8571429 | L9: 3.2 | M9: 3.2 | N9: 1.6340426 | O9: 2.5008 | P9: 1.25 | Q9: 1.6236 | R9: 1.5 | S9: 1.3935484
A10: FY2024-25 | B10: Bridgestone | C10: =VLOOKUP(B10,Mapping!B:C,2,0) -> Lateral | D10: =VLOOKUP(B10,Mapping!B:D,3,0) -> West | E10: =VLOOKUP(B10,Mapping!B:E,4,0) -> West 2 | F10: =VLOOKUP(B10,Mapping!B:F,5,0) -> Anjli | G10: =VLOOKUP(B10,Mapping!B:G,6,0) -> Shweta | H10: 1.8 | I10: 1.8 | J10: 1.8 | K10: 1.8 | L10: 1.8 | M10: 1.8 | N10: 1.8 | O10: 0.72 | P10: 1.8 | Q10: 1.32 | R10: 0.6 | S10: 2
A11: FY2024-25 | B11: SKF India | C11: =VLOOKUP(B11,Mapping!B:C,2,0) -> Lateral | D11: =VLOOKUP(B11,Mapping!B:D,3,0) -> North | E11: =VLOOKUP(B11,Mapping!B:E,4,0) -> North | F11: =VLOOKUP(B11,Mapping!B:F,5,0) -> Anjli | G11: =VLOOKUP(B11,Mapping!B:G,6,0) -> Archana | H11: 2.4252632 | I11: 2.3428571 | J11: 1.8743259 | K11: 1.2 | L11: 1.6363636 | M11: 2.0727273 | N11: 1.84 | O11: 2.7333333 | P11: 1.8666667 | Q11: 3.4666667 | R11: 2 | S11: 1.7466667
A12: FY2024-25 | B12: Jindal Stainless | C12: =VLOOKUP(B12,Mapping!B:C,2,0) -> Lateral | D12: =VLOOKUP(B12,Mapping!B:D,3,0) -> North | E12: =VLOOKUP(B12,Mapping!B:E,4,0) -> North | F12: =VLOOKUP(B12,Mapping!B:F,5,0) -> Anjli | G12: =VLOOKUP(B12,Mapping!B:G,6,0) -> Archana | H12: 1.2631579 | I12: 1.8 | J12: 2.52 | K12: 1.56 | L12: 2.0666667 | M12: 3 | N12: 1.8 | O12: 1.425 | P12: 2.4 | Q12: 1.975611 | R12: 1.236 | S12: 4.014
A13: FY2024-25 | B13: Maruti Suzuki(MSIL) | C13: =VLOOKUP(B13,Mapping!B:C,2,0) -> Lateral | D13: =VLOOKUP(B13,Mapping!B:D,3,0) -> North | E13: =VLOOKUP(B13,Mapping!B:E,4,0) -> North | F13: =VLOOKUP(B13,Mapping!B:F,5,0) -> Anjli | G13: =VLOOKUP(B13,Mapping!B:G,6,0) -> Archana | H13: 6 | I13: 0.438 | J13: 4.11 | K13: 0.74534161 | L13: 0.61538462 | M13: 0.31840796 | N13: 1.0344828 | O13: 1.0068966 | P13: 0.97333333 | Q13: 0.67848101 | R13: 0.51724138 | S13: 1.9901714
... A58: FY2024-25 | B58: New Sales + Mining | C58: =VLOOKUP(B58,Mapping!B:C,2,0) -> Lateral | D58: =VLOOKUP(B58,Mapping!B:D,3,0) -> New Sales | E58: =VLOOKUP(B58,Mapping!B:E,4,0) -> New Sales | F58: =VLOOKUP(B58,Mapping!B:F,5,0) -> Nizar | G58: =VLOOKUP(B58,Mapping!B:G,6,0) -> Nizar | H58: 1.8 | I58: 1.8 | J58: 1.8 | K58: 1.8 | L58: 1.8 | M58: 1.8 | N58: 1.8 | O58: 1.8 | P58: 1.8 | Q58: 1.8 | R58: 1.8 | S58: 1.8
H59: Value= Per recuiter per project in Lacs

Sheet Rev_Forecast
A1: FY | B1: Project | C1: Vertical | D1: Region | E1: Sub Region | F1: Region Head | G1: Practice Head | H1: 45383 | I1: =EDATE(H1,1) -> 45413 | J1: =EDATE(I1,1) -> 45444 | K1: =EDATE(J1,1) -> 45474 | L1: =EDATE(K1,1) -> 45505 | M1: =EDATE(L1,1) -> 45536 | N1: =EDATE(M1,1) -> 45566 | O1: =EDATE(N1,1) -> 45597 | P1: =EDATE(O1,1) -> 45627 | ... S1: =EDATE(R1,1) -> 45717
A2: FY2024-25 | B2: Tata Motors | C2: =VLOOKUP(B2,Mapping!B:C,2,0) -> Lateral | D2: =VLOOKUP(B2,Mapping!B:D,3,0) -> West | E2: =VLOOKUP(B2,Mapping!B:E,4,0) -> West 2 | F2: =VLOOKUP(B2,Mapping!B:F,5,0) -> Anjli | G2: =VLOOKUP(B2,Mapping!B:G,6,0) -> Shweta | H2: 25 | I2: 35 | J2: 40 | K2: 43.5 | L2: 60.9 | M2: 69.6 | N2: 49.025 | O2: 68.635 | P2: 78.44 | Q2: 50.8825 | R2: 71.2355 | S2: 81.412
A3: FY2024-25 | B3: Schaeffler | C3: =VLOOKUP(B3,Mapping!B:C,2,0) -> Lateral | D3: =VLOOKUP(B3,Mapping!B:D,3,0) -> West | E3: =VLOOKUP(B3,Mapping!B:E,4,0) -> West 2 | F3: =VLOOKUP(B3,Mapping!B:F,5,0) -> Anjli | G3: =VLOOKUP(B3,Mapping!B:G,6,0) -> Shweta | H3: 6.175 | I3: 8.645 | J3: 9.88 | K3: 6.35 | L3: 8.89 | M3: 10.16 | N3: 6.65 | O3: 9.31 | P3: 10.64 | Q3: 7.0325 | R3: 9.8455 | S3: 11.252
A4: FY2024-25 | B4: Vertiv | C4: =VLOOKUP(B4,Mapping!B:C,2,0) -> Lateral | D4: =VLOOKUP(B4,Mapping!B:D,3,0) -> West | E4: =VLOOKUP(B4,Mapping!B:E,4,0) -> West 2 | F4: =VLOOKUP(B4,Mapping!B:F,5,0) -> Anjli | G4: =VLOOKUP(B4,Mapping!B:G,6,0) -> Shweta | H4: 3 | I4: 4.2 | J4: 4.8 | K4: 3.675 | L4: 5.145 | M4: 5.88 | N4: 3.825 | O4: 5.355 | P4: 6.12 | Q4: 4.0575 | R4: 5.6805 | S4: 6.492
A5: FY2024-25 | B5: Tata Marcopolo | C5: =VLOOKUP(B5,Mapping!B:C,2,0) -> Lateral | D5: =VLOOKUP(B5,Mapping!B:D,3,0) -> West | E5: =VLOOKUP(B5,Mapping!B:E,4,0) -> West 2 | F5: =VLOOKUP(B5,Mapping!B:F,5,0) -> Anjli | G5: =VLOOKUP(B5,Mapping!B:G,6,0) -> Anjli | H5: 1.125 | I5: 1.575 | J5: 1.8 | K5: 1.125 | L5: 1.575 | M5: 1.8 | N5: 1.125 | O5: 1.575 | P5: 1.8 | Q5: 1.2075 | R5: 1.6905 | S5: 1.932
A6: FY2024-25 | B6: ThyssenKrupp | C6: =VLOOKUP(B6,Mapping!B:C,2,0) -> Lateral | D6: =VLOOKUP(B6,Mapping!B:D,3,0) -> West | E6: =VLOOKUP(B6,Mapping!B:E,4,0) -> West 2 | F6: =VLOOKUP(B6,Mapping!B:F,5,0) -> Anjli | G6: =VLOOKUP(B6,Mapping!B:G,6,0) -> Shweta | H6: 15.4 | I6: 21.56 | J6: 24.64 | K6: 15.925 | L6: 22.295 | M6: 25.48 | N6: 16.575 | O6: 23.205 | P6: 26.52 | Q6: 17.3075 | R6: 24.2305 | S6: 27.692
A7: FY2024-25 | B7: Ultratech | C7: =VLOOKUP(B7,Mapping!B:C,2,0) -> Lateral | D7: =VLOOKUP(B7,Mapping!B:D,3,0) -> West | E7: =VLOOKUP(B7,Mapping!B:E,4,0) -> West 1 | F7: =VLOOKUP(B7,Mapping!B:F,5,0) -> Anjli | G7: =VLOOKUP(B7,Mapping!B:G,6,0) -> Elton | H7: 0.375 | I7: 0.525 | J7: 0.6 | K7: 1.8 | L7: 2.52 | M7: 2.88 | N7: 1.95 | O7: 2.73 | P7: 3.12 | Q7: 2.1825 | R7: 3.0555 | S7: 3.492
A8: FY2024-25 | B8: Tata Teleservices | C8: =VLOOKUP(B8,Mapping!B:C,2,0) -> Lateral | D8: =VLOOKUP(B8,Mapping!B:D,3,0) -> West | E8: =VLOOKUP(B8,Mapping!B:E,4,0) -> West 1 | F8: =VLOOKUP(B8,Mapping!B:F,5,0) -> Anjli | G8: =VLOOKUP(B8,Mapping!B:G,6,0) -> Elton | H8: 3.125 | I8: 4.375 | J8: 5 | K8: 6.25 | L8: 8.75 | M8: 10 | N8: 6.25 | O8: 8.75 | P8: 10 | Q8: 6.3325 | R8: 8.8655 | S8: 10.132
A9: FY2024-25 | B9: Hyundai Motor | C9: =VLOOKUP(B9,Mapping!B:C,2,0) -> Lateral | D9: =VLOOKUP(B9,Mapping!B:D,3,0) -> West | E9: =VLOOKUP(B9,Mapping!B:E,4,0) -> West 2 | F9: =VLOOKUP(B9,Mapping!B:F,5,0) -> Anjli | G9: =VLOOKUP(B9,Mapping!B:G,6,0) -> Shweta | H9: 3.75 | I9: 5.25 | J9: 6 | K9: 7.5 | L9: 10.5 | M9: 12 | N9: 10 | O9: 14 | P9: 16 | Q9: 8 | R9: 11.2 | S9: 12.8
A10: FY2024-25 | B10: Bridgestone | C10: =VLOOKUP(B10,Mapping!B:C,2,0) -> Lateral | D10: =VLOOKUP(B10,Mapping!B:D,3,0) -> West | E10: =VLOOKUP(B10,Mapping!B:E,4,0) -> West 2 | F10: =VLOOKUP(B10,Mapping!B:F,5,0) -> Anjli | G10: =VLOOKUP(B10,Mapping!B:G,6,0) -> Shweta | H10: 0 | I10: 0 | J10: 0 | K10: 0 | L10: 0 | M10: 0 | N10: 0 | O10: 0 | P10: 0 | Q10: 0 | R10: 0 | S10: 0
A11: FY2024-25 | B11: SKF India | C11: =VLOOKUP(B11,Mapping!B:C,2,0) -> Lateral | D11: =VLOOKUP(B11,Mapping!B:D,3,0) -> North | E11: =VLOOKUP(B11,Mapping!B:E,4,0) -> North | F11: =VLOOKUP(B11,Mapping!B:F,5,0) -> Anjli | G11: =VLOOKUP(B11,Mapping!B:G,6,0) -> Archana | H11: 11.375 | I11: 15.925 | J11: 18.2 | K11: 11.5 | L11: 16.1 | M11: 18.4 | N11: 11.5 | O11: 16.1 | P11: 18.4 | Q11: 11.5825 | R11: 16.2155 | S11: 18.532
A12: FY2024-25 | B12: Jindal Stainless | C12: =VLOOKUP(B12,Mapping!B:C,2,0) -> Lateral | D12: =VLOOKUP(B12,Mapping!B:D,3,0) -> North | E12: =VLOOKUP(B12,Mapping!B:E,4,0) -> North | F12: =VLOOKUP(B12,Mapping!B:F,5,0) -> Anjli | G12: =VLOOKUP(B12,Mapping!B:G,6,0) -> Archana | H12: 9 | I12: 12.6 | J12: 14.4 | K12: 7.9075 | L12: 11.0705 | M12: 12.652 | N12: 7.6575 | O12: 10.7205 | P12: 12.252 | Q12: 7.865 | R12: 11.011 | S12: 12.584
A13: FY2024-25 | B13: Maruti Suzuki(MSIL) | C13: =VLOOKUP(B13,Mapping!B:C,2,0) -> Lateral | D13: =VLOOKUP(B13,Mapping!B:D,3,0) -> North | E13: =VLOOKUP(B13,Mapping!B:E,4,0) -> North | F13: =VLOOKUP(B13,Mapping!B:F,5,0) -> Anjli | G13: =VLOOKUP(B13,Mapping!B:G,6,0) -> Archana | H13: 4.25 | I13: 5.95 | J13: 6.8 | K13: 7.5 | L13: 10.5 | M13: 12 | N13: 8.75 | O13: 12.25 | P13: 14 | Q13: 10 | R13: 14 | S13: 16
... A57: FY2024-25 | B57: Common | C57: =VLOOKUP(B57,Mapping!B:C,2,0) -> Lateral | D57: =VLOOKUP(B57,Mapping!B:D,3,0) -> Common | E57: =VLOOKUP(B57,Mapping!B:E,4,0) -> North | F57: =VLOOKUP(B57,Mapping!B:F,5,0) -> Common | G57: =VLOOKUP(B57,Mapping!B:G,6,0) -> Common | H57: 12.5 | I57: 17.5 | J57: 20 | K57: 0 | L57: 0 | M57: 0 | N57: 0 | O57: 0 | P57: 0 | Q57: 0 | R57: 0 | S57: 0
I58: Rev forecast in lacs

Sheet CM_Forecast
A1: FY | B1: Project | C1: Vertical | D1: Region | E1: Sub Region | F1: Region Head | G1: Practice Head | H1: 45383 | I1: =EDATE(H1,1) -> 45413 | J1: =EDATE(I1,1) -> 45444 | K1: =EDATE(J1,1) -> 45474 | L1: =EDATE(K1,1) -> 45505 | M1: =EDATE(L1,1) -> 45536 | N1: =EDATE(M1,1) -> 45566 | O1: =EDATE(N1,1) -> 45597 | P1: =EDATE(O1,1) -> 45627 | ... S1: =EDATE(R1,1) -> 45717
A2: FY2024-25 | B2: Tata Motors | C2: =VLOOKUP(B2,Mapping!B:C,2,0) -> Lateral | D2: =VLOOKUP(B2,Mapping!B:D,3,0) -> West | E2: =VLOOKUP(B2,Mapping!B:E,4,0) -> West 2 | F2: =VLOOKUP(B2,Mapping!B:F,5,0) -> Anjli | G2: =VLOOKUP(B2,Mapping!B:G,6,0) -> Shweta | H2: =CM_Budget!H2-95% -> 9.55 | I2: =CM_Budget!I2-95% -> 13.75 | J2: =CM_Budget!J2-95% -> 15.85 | K2: =CM_Budget!K2-95% -> 17.32 | L2: =CM_Budget!L2-95% -> 24.628 | M2: =CM_Budget!M2-95% -> 28.282 | N2: =CM_Budget!N2-95% -> 19.6405 | O2: =CM_Budget!O2-95% -> 27.8767 | ... S2: =CM_Budget!S2-95% -> 33.24304
A3: FY2024-25 | B3: Schaeffler | C3: =VLOOKUP(B3,Mapping!B:C,2,0) -> Lateral | D3: =VLOOKUP(B3,Mapping!B:D,3,0) -> West | E3: =VLOOKUP(B3,Mapping!B:E,4,0) -> West 2 | F3: =VLOOKUP(B3,Mapping!B:F,5,0) -> Anjli | G3: =VLOOKUP(B3,Mapping!B:G,6,0) -> Shweta | H3: =CM_Budget!H3-95% -> 1.6435 | I3: =CM_Budget!I3-95% -> 2.6809 | J3: =CM_Budget!J3-95% -> 3.1996 | K3: =CM_Budget!K3-95% -> 1.717 | L3: =CM_Budget!L3-95% -> 2.7838 | M3: =CM_Budget!M3-95% -> 3.3172 | N3: =CM_Budget!N3-95% -> 1.843 | O3: =CM_Budget!O3-95% -> 2.9602 | ... S3: =CM_Budget!S3-95% -> 3.77584
A4: FY2024-25 | B4: Vertiv | C4: =VLOOKUP(B4,Mapping!B:C,2,0) -> Lateral | D4: =VLOOKUP(B4,Mapping!B:D,3,0) -> West | E4: =VLOOKUP(B4,Mapping!B:E,4,0) -> West 2 | F4: =VLOOKUP(B4,Mapping!B:F,5,0) -> Anjli | G4: =VLOOKUP(B4,Mapping!B:G,6,0) -> Shweta | H4: =CM_Budget!H4-95% -> 0.31 | I4: =CM_Budget!I4-95% -> 0.814 | J4: =CM_Budget!J4-95% -> 1.066 | K4: =CM_Budget!K4-95% -> 0.5935 | L4: =CM_Budget!L4-95% -> 1.2109 | M4: =CM_Budget!M4-95% -> 1.5196 | N4: =CM_Budget!N4-95% -> 0.6565 | O4: =CM_Budget!O4-95% -> 1.2991 | ... S4: =CM_Budget!S4-95% -> 1.77664
A5: FY2024-25 | B5: Tata Marcopolo | C5: =VLOOKUP(B5,Mapping!B:C,2,0) -> Lateral | D5: =VLOOKUP(B5,Mapping!B:D,3,0) -> West | E5: =VLOOKUP(B5,Mapping!B:E,4,0) -> West 2 | F5: =VLOOKUP(B5,Mapping!B:F,5,0) -> Anjli | G5: =VLOOKUP(B5,Mapping!B:G,6,0) -> Anjli | H5: =CM_Budget!H5-95% -> -0.4775 | I5: =CM_Budget!I5-95% -> -0.2885 | J5: =CM_Budget!J5-95% -> -0.194 | K5: =CM_Budget!K5-95% -> -0.4775 | L5: =CM_Budget!L5-95% -> -0.2885 | M5: =CM_Budget!M5-95% -> -0.194 | N5: =CM_Budget!N5-95% -> -0.4775 | O5: =CM_Budget!O5-95% -> -0.2885 | ... S5: =CM_Budget!S5-95% -> -0.13856
A6: FY2024-25 | B6: ThyssenKrupp | C6: =VLOOKUP(B6,Mapping!B:C,2,0) -> Lateral | D6: =VLOOKUP(B6,Mapping!B:D,3,0) -> West | E6: =VLOOKUP(B6,Mapping!B:E,4,0) -> West 2 | F6: =VLOOKUP(B6,Mapping!B:F,5,0) -> Anjli | G6: =VLOOKUP(B6,Mapping!B:G,6,0) -> Shweta | H6: =CM_Budget!H6-95% -> 5.518 | I6: =CM_Budget!I6-95% -> 8.1052 | J6: =CM_Budget!J6-95% -> 9.3988 | K6: =CM_Budget!K6-95% -> 5.7385 | L6: =CM_Budget!L6-95% -> 8.4139 | M6: =CM_Budget!M6-95% -> 9.7516 | N6: =CM_Budget!N6-95% -> 6.0115 | O6: =CM_Budget!O6-95% -> 8.7961 | ... S6: =CM_Budget!S6-95% -> 10.68064
A7: FY2024-25 | B7: Ultratech | C7: =VLOOKUP(B7,Mapping!B:C,2,0) -> Lateral | D7: =VLOOKUP(B7,Mapping!B:D,3,0) -> West | E7: =VLOOKUP(B7,Mapping!B:E,4,0) -> West 1 | F7: =VLOOKUP(B7,Mapping!B:F,5,0) -> Anjli | G7: =VLOOKUP(B7,Mapping!B:G,6,0) -> Elton | H7: =CM_Budget!H7-95% -> -0.7925 | I7: =CM_Budget!I7-95% -> -0.7295 | J7: =CM_Budget!J7-95% -> -0.698 | K7: =CM_Budget!K7-95% -> -0.194 | L7: =CM_Budget!L7-95% -> 0.1084 | M7: =CM_Budget!M7-95% -> 0.2596 | N7: =CM_Budget!N7-95% -> -0.131 | O7: =CM_Budget!O7-95% -> 0.1966 | ... S7: =CM_Budget!S7-95% -> 0.51664
A8: FY2024-25 | B8: Tata Teleservices | C8: =VLOOKUP(B8,Mapping!B:C,2,0) -> Lateral | D8: =VLOOKUP(B8,Mapping!B:D,3,0) -> West | E8: =VLOOKUP(B8,Mapping!B:E,4,0) -> West 1 | F8: =VLOOKUP(B8,Mapping!B:F,5,0) -> Anjli | G8: =VLOOKUP(B8,Mapping!B:G,6,0) -> Elton | H8: =CM_Budget!H8-95% -> 0.3625 | I8: =CM_Budget!I8-95% -> 0.8875 | J8: =CM_Budget!J8-95% -> 1.15 | K8: =CM_Budget!K8-95% -> 1.675 | L8: =CM_Budget!L8-95% -> 2.725 | M8: =CM_Budget!M8-95% -> 3.25 | N8: =CM_Budget!N8-95% -> 1.675 | O8: =CM_Budget!O8-95% -> 2.725 | ... S8: =CM_Budget!S8-95% -> 3.30544
A9: FY2024-25 | B9: Hyundai Motor | C9: =VLOOKUP(B9,Mapping!B:C,2,0) -> Lateral | D9: =VLOOKUP(B9,Mapping!B:D,3,0) -> West | E9: =VLOOKUP(B9,Mapping!B:E,4,0) -> West 2 | F9: =VLOOKUP(B9,Mapping!B:F,5,0) -> Anjli | G9: =VLOOKUP(B9,Mapping!B:G,6,0) -> Shweta | H9: =CM_Budget!H9-95% -> 0.625 | I9: =CM_Budget!I9-95% -> 1.255 | J9: =CM_Budget!J9-95% -> 1.57 | K9: =CM_Budget!K9-95% -> 2.2 | L9: =CM_Budget!L9-95% -> 3.46 | M9: =CM_Budget!M9-95% -> 4.09 | N9: =CM_Budget!N9-95% -> 3.25 | O9: =CM_Budget!O9-95% -> 4.93 | ... S9: =CM_Budget!S9-95% -> 4.426
A10: FY2024-25 | B10: Bridgestone | C10: =VLOOKUP(B10,Mapping!B:C,2,0) -> Lateral | D10: =VLOOKUP(B10,Mapping!B:D,3,0) -> West | E10: =VLOOKUP(B10,Mapping!B:E,4,0) -> West 2 | F10: =VLOOKUP(B10,Mapping!B:F,5,0) -> Anjli | G10: =VLOOKUP(B10,Mapping!B:G,6,0) -> Shweta | H10: =CM_Budget!H10-95% -> -0.95 | I10: =CM_Budget!I10-95% -> -0.95 | J10: =CM_Budget!J10-95% -> -0.95 | K10: =CM_Budget!K10-95% -> -0.95 | L10: =CM_Budget!L10-95% -> -0.95 | M10: =CM_Budget!M10-95% -> -0.95 | N10: =CM_Budget!N10-95% -> -0.95 | O10: =CM_Budget!O10-95% -> -0.95 | ... S10: =CM_Budget!S10-95% -> -0.95
A11: FY2024-25 | B11: SKF India | C11: =VLOOKUP(B11,Mapping!B:C,2,0) -> Lateral | D11: =VLOOKUP(B11,Mapping!B:D,3,0) -> North | E11: =VLOOKUP(B11,Mapping!B:E,4,0) -> North | F11: =VLOOKUP(B11,Mapping!B:F,5,0) -> Anjli | G11: =VLOOKUP(B11,Mapping!B:G,6,0) -> Archana | H11: =CM_Budget!H11-95% -> 3.8275 | I11: =CM_Budget!I11-95% -> 5.7385 | J11: =CM_Budget!J11-95% -> 6.694 | K11: =CM_Budget!K11-95% -> 3.88 | L11: =CM_Budget!L11-95% -> 5.812 | M11: =CM_Budget!M11-95% -> 6.778 | N11: =CM_Budget!N11-95% -> 3.88 | O11: =CM_Budget!O11-95% -> 5.812 | ... S11: =CM_Budget!S11-95% -> 6.83344
A12: FY2024-25 | B12: Jindal Stainless | C12: =VLOOKUP(B12,Mapping!B:C,2,0) -> Lateral | D12: =VLOOKUP(B12,Mapping!B:D,3,0) -> North | E12: =VLOOKUP(B12,Mapping!B:E,4,0) -> North | F12: =VLOOKUP(B12,Mapping!B:F,5,0) -> Anjli | G12: =VLOOKUP(B12,Mapping!B:G,6,0) -> Archana | H12: =CM_Budget!H12-95% -> 2.83 | I12: =CM_Budget!I12-95% -> 4.342 | J12: =CM_Budget!J12-95% -> 5.098 | K12: =CM_Budget!K12-95% -> 2.37115 | L12: =CM_Budget!L12-95% -> 3.69961 | M12: =CM_Budget!M12-95% -> 4.36384 | N12: =CM_Budget!N12-95% -> 2.26615 | O12: =CM_Budget!O12-95% -> 3.55261 | ... S12: =CM_Budget!S12-95% -> 4.33528
A13: FY2024-25 | B13: Maruti Suzuki(MSIL) | C13: =VLOOKUP(B13,Mapping!B:C,2,0) -> Lateral | D13: =VLOOKUP(B13,Mapping!B:D,3,0) -> North | E13: =VLOOKUP(B13,Mapping!B:E,4,0) -> North | F13: =VLOOKUP(B13,Mapping!B:F,5,0) -> Anjli | G13: =VLOOKUP(B13,Mapping!B:G,6,0) -> Archana | H13: =CM_Budget!H13-95% -> 0.835 | I13: =CM_Budget!I13-95% -> 1.549 | J13: =CM_Budget!J13-95% -> 1.906 | K13: =CM_Budget!K13-95% -> 2.2 | L13: =CM_Budget!L13-95% -> 3.46 | M13: =CM_Budget!M13-95% -> 4.09 | N13: =CM_Budget!N13-95% -> 2.725 | O13: =CM_Budget!O13-95% -> 4.195 | ... S13: =CM_Budget!S13-95% -> 5.77
... A57: FY2024-25 | B57: Common | C57: =VLOOKUP(B57,Mapping!B:C,2,0) -> Lateral | D57: =VLOOKUP(B57,Mapping!B:D,3,0) -> Common | E57: =VLOOKUP(B57,Mapping!B:E,4,0) -> North | F57: =VLOOKUP(B57,Mapping!B:F,5,0) -> Common | G57: =VLOOKUP(B57,Mapping!B:G,6,0) -> Common | H57: =CM_Budget!H57-95% -> 4.3 | I57: =CM_Budget!I57-95% -> 6.4 | J57: =CM_Budget!J57-95% -> 7.45 | K57: =CM_Budget!K57-95% -> -0.95 | L57: =CM_Budget!L57-95% -> -0.95 | M57: =CM_Budget!M57-95% -> -0.95 | N57: =CM_Budget!N57-95% -> -0.95 | O57: =CM_Budget!O57-95% -> -0.95 | ... S57: =CM_Budget!S57-95% -> -0.95
G59: CM= Contribution Margin in Lacs

Sheet Revenue_Actual
A1: FY | B1: Project | C1: Vertical | D1: Region | E1: Sub Region | F1: Region Head | G1: Practice Head | H1: 45383 | I1: =EDATE(H1,1) -> 45413 | J1: =EDATE(I1,1) -> 45444 | K1: =EDATE(J1,1) -> 45474 | L1: =EDATE(K1,1) -> 45505 | M1: =EDATE(L1,1) -> 45536 | N1: =EDATE(M1,1) -> 45566 | O1: =EDATE(N1,1) -> 45597 | P1: =EDATE(O1,1) -> 45627 | ... S1: =EDATE(R1,1) -> 45717
A2: FY2024-25 | B2: Tata Motors | C2: =VLOOKUP(B2,Mapping!B:C,2,0) -> Lateral | D2: =VLOOKUP(B2,Mapping!B:D,3,0) -> West | E2: =VLOOKUP(B2,Mapping!B:E,4,0) -> West 2 | F2: =VLOOKUP(B2,Mapping!B:F,5,0) -> Anjli | G2: =VLOOKUP(B2,Mapping!B:G,6,0) -> Shweta | H2: 37 | I2: 37 | J2: 30 | K2: 29 | L2: 36 | M2: 31 | N2: 27 | O2: 26.391 | P2: 54 | Q2: 28.8 | R2: 15 | S2: 6.3
A3: FY2024-25 | B3: Schaeffler | C3: =VLOOKUP(B3,Mapping!B:C,2,0) -> Lateral | D3: =VLOOKUP(B3,Mapping!B:D,3,0) -> West | E3: =VLOOKUP(B3,Mapping!B:E,4,0) -> West 2 | F3: =VLOOKUP(B3,Mapping!B:F,5,0) -> Anjli | G3: =VLOOKUP(B3,Mapping!B:G,6,0) -> Shweta | H3: 8.5 | I3: 7.5 | J3: 7 | K3: 8 | L3: 10 | M3: 12 | N3: 3 | O3: 4 | P3: 0.5 | Q3: 4.76 | R3: 6 | S3: 9.839
A4: FY2024-25 | B4: Vertiv | C4: =VLOOKUP(B4,Mapping!B:C,2,0) -> Lateral | D4: =VLOOKUP(B4,Mapping!B:D,3,0) -> West | E4: =VLOOKUP(B4,Mapping!B:E,4,0) -> West 2 | F4: =VLOOKUP(B4,Mapping!B:F,5,0) -> Anjli | G4: =VLOOKUP(B4,Mapping!B:G,6,0) -> Shweta | H4: 4 | I4: 7 | J4: 4.55 | K4: 7.5 | L4: 3.8 | M4: 6 | N4: 2.2 | O4: 4.7 | P4: 7.6 | Q4: 3.4225 | R4: 4 | S4: 0.93
A5: FY2024-25 | B5: Tata Marcopolo | C5: =VLOOKUP(B5,Mapping!B:C,2,0) -> Lateral | D5: =VLOOKUP(B5,Mapping!B:D,3,0) -> West | E5: =VLOOKUP(B5,Mapping!B:E,4,0) -> West 2 | F5: =VLOOKUP(B5,Mapping!B:F,5,0) -> Anjli | G5: =VLOOKUP(B5,Mapping!B:G,6,0) -> Anjli | H5: 0.7 | I5: 1.9 | J5: 1.42 | K5: 0.41 | L5: 2 | M5: 2.09 | N5: 0.11 | O5: 0 | P5: 3 | Q5: 0 | R5: 0 | S5: 0.76
A6: FY2024-25 | B6: ThyssenKrupp | C6: =VLOOKUP(B6,Mapping!B:C,2,0) -> Lateral | D6: =VLOOKUP(B6,Mapping!B:D,3,0) -> West | E6: =VLOOKUP(B6,Mapping!B:E,4,0) -> West 2 | F6: =VLOOKUP(B6,Mapping!B:F,5,0) -> Anjli | G6: =VLOOKUP(B6,Mapping!B:G,6,0) -> Shweta | H6: 21 | I6: 21 | J6: 23.18104 | K6: 19 | L6: 22 | M6: 24 | N6: 12 | O6: 2.12 | P6: 10 | Q6: 0 | R6: 5 | S6: -9.93469
A7: FY2024-25 | B7: Ultratech | C7: =VLOOKUP(B7,Mapping!B:C,2,0) -> Lateral | D7: =VLOOKUP(B7,Mapping!B:D,3,0) -> West | E7: =VLOOKUP(B7,Mapping!B:E,4,0) -> West 1 | F7: =VLOOKUP(B7,Mapping!B:F,5,0) -> Anjli | G7: =VLOOKUP(B7,Mapping!B:G,6,0) -> Elton | H7: 1.56 | I7: -0.165 | J7: 1.5 | K7: 0.15 | L7: 0 | M7: 0 | N7: 0 | O7: 0 | P7: 0 | Q7: 0 | R7: 0 | S7: 0
A8: FY2024-25 | B8: Tata Teleservices | C8: =VLOOKUP(B8,Mapping!B:C,2,0) -> Lateral | D8: =VLOOKUP(B8,Mapping!B:D,3,0) -> West | E8: =VLOOKUP(B8,Mapping!B:E,4,0) -> West 1 | F8: =VLOOKUP(B8,Mapping!B:F,5,0) -> Anjli | G8: =VLOOKUP(B8,Mapping!B:G,6,0) -> Elton | H8: 0 | I8: 0 | J8: 0 | K8: 0 | L8: 0 | M8: 0 | N8: 0 | O8: 0 | P8: 0 | Q8: 0 | R8: 0 | S8: 0
A9: FY2024-25 | B9: Hyundai Motor | C9: =VLOOKUP(B9,Mapping!B:C,2,0) -> Lateral | D9: =VLOOKUP(B9,Mapping!B:D,3,0) -> West | E9: =VLOOKUP(B9,Mapping!B:E,4,0) -> West 2 | F9: =VLOOKUP(B9,Mapping!B:F,5,0) -> Anjli | G9: =VLOOKUP(B9,Mapping!B:G,6,0) -> Shweta | H9: 4.16 | I9: 20.5 | J9: 10.37 | K9: 12.5 | L9: 18 | M9: 26 | N9: 16 | O9: 28.134 | P9: 12.5 | Q9: 16.236 | R9: 15 | S9: 18
A10: FY2024-25 | B10: Bridgestone | C10: =VLOOKUP(B10,Mapping!B:C,2,0) -> Lateral | D10: =VLOOKUP(B10,Mapping!B:D,3,0) -> West | E10: =VLOOKUP(B10,Mapping!B:E,4,0) -> West 2 | F10: =VLOOKUP(B10,Mapping!B:F,5,0) -> Anjli | G10: =VLOOKUP(B10,Mapping!B:G,6,0) -> Shweta | H10: 0 | I10: 0 | J10: 0 | K10: 0 | L10: 0 | M10: 0 | N10: 0 | O10: 0.6 | P10: 0 | Q10: 1.1 | R10: 1 | S10: 5
A11: FY2024-25 | B11: SKF India | C11: =VLOOKUP(B11,Mapping!B:C,2,0) -> Lateral | D11: =VLOOKUP(B11,Mapping!B:D,3,0) -> North | E11: =VLOOKUP(B11,Mapping!B:E,4,0) -> North | F11: =VLOOKUP(B11,Mapping!B:F,5,0) -> Anjli | G11: =VLOOKUP(B11,Mapping!B:G,6,0) -> Archana | H11: 19.2 | I11: 20.5 | J11: 17.96229 | K11: 12 | L11: 15 | M11: 19 | N11: 15.333333 | O11: 20.5 | P11: 14 | Q11: 26 | R11: 15 | S11: 13.1
A12: FY2024-25 | B12: Jindal Stainless | C12: =VLOOKUP(B12,Mapping!B:C,2,0) -> Lateral | D12: =VLOOKUP(B12,Mapping!B:D,3,0) -> North | E12: =VLOOKUP(B12,Mapping!B:E,4,0) -> North | F12: =VLOOKUP(B12,Mapping!B:F,5,0) -> Anjli | G12: =VLOOKUP(B12,Mapping!B:G,6,0) -> Archana | H12: 12 | I12: 15 | J12: 21 | K12: 13 | L12: 15.5 | M12: 25 | N12: 15 | O12: 9.5 | P12: 16 | Q12: 13.17074 | R12: 8.24 | S12: 13.38
A13: FY2024-25 | B13: Maruti Suzuki(MSIL) | C13: =VLOOKUP(B13,Mapping!B:C,2,0) -> Lateral | D13: =VLOOKUP(B13,Mapping!B:D,3,0) -> North | E13: =VLOOKUP(B13,Mapping!B:E,4,0) -> North | F13: =VLOOKUP(B13,Mapping!B:F,5,0) -> Anjli | G13: =VLOOKUP(B13,Mapping!B:G,6,0) -> Archana | H13: 2 | I13: 0.73 | J13: 22.2625 | K13: 10 | L13: 10 | M13: 8 | N13: 25 | O13: 36.5 | P13: 36.5 | Q13: 26.8 | R13: 20 | S13: 87.07
... A57: FY2024-25 | B57: Common | C57: =VLOOKUP(B57,Mapping!B:C,2,0) -> Lateral | D57: =VLOOKUP(B57,Mapping!B:D,3,0) -> Common | E57: =VLOOKUP(B57,Mapping!B:E,4,0) -> North | F57: =VLOOKUP(B57,Mapping!B:F,5,0) -> Common | G57: =VLOOKUP(B57,Mapping!B:G,6,0) -> Common | H57: 0 | I57: 0 | J57: 0 | K57: 0 | L57: 0 | M57: 0 | N57: 0 | O57: 0 | P57: 0 | Q57: 0 | R57: 0 | S57: 0
H59: Actual rev, when the month is closed; actual closed rev per month in lacs

Sheet Mapping
A1: FY | B1: Project | C1: Vertical | D1: Region | E1: Sub Region | F1: Region Head | G1: Practice Head
A2: FY2024-25 | B2: Tata Motors | C2: Lateral | D2: West | E2: West 2 | F2: Anjli | G2: Shweta
A3: FY2024-25 | B3: Schaeffler | C3: Lateral | D3: West | E3: West 2 | F3: Anjli | G3: Shweta
A4: FY2024-25 | B4: Vertiv | C4: Lateral | D4: West | E4: West 2 | F4: Anjli | G4: Shweta
A5: FY2024-25 | B5: Tata Marcopolo | C5: Lateral | D5: West | E5: West 2 | F5: Anjli | G5: Anjli
A6: FY2024-25 | B6: ThyssenKrupp | C6: Lateral | D6: West | E6: West 2 | F6: Anjli | G6: Shweta
A7: FY2024-25 | B7: Ultratech | C7: Lateral | D7: West | E7: West 1 | F7: Anjli | G7: Elton
A8: FY2024-25 | B8: Tata Teleservices | C8: Lateral | D8: West | E8: West 1 | F8: Anjli | G8: Elton
A9: FY2024-25 | B9: Hyundai Motor | C9: Lateral | D9: West | E9: West 2 | F9: Anjli | G9: Shweta
A10: FY2024-25 | B10: Bridgestone | C10: Lateral | D10: West | E10: West 2 | F10: Anjli | G10: Shweta
A11: FY2024-25 | B11: SKF India | C11: Lateral | D11: North | E11: North | F11: Anjli | G11: Archana
A12: FY2024-25 | B12: Jindal Stainless | C12: Lateral | D12: North | E12: North | F12: Anjli | G12: Archana
... A70: FY2024-25 | B70: Bench | C70: Lateral | D70: North | E70: North | F70: Anjli | G70: Anjli

Sheet CM_Actual
A1: FY | B1: Project | C1: Vertical | D1: Region | E1: Sub Region | F1: Region Head | G1: Practice Head | H1: 45383 | I1: =EDATE(H1,1) -> 45413 | J1: =EDATE(I1,1) -> 45444 | K1: =EDATE(J1,1) -> 45474 | L1: =EDATE(K1,1) -> 45505 | M1: =EDATE(L1,1) -> 45536 | N1: =EDATE(M1,1) -> 45566 | O1: =EDATE(N1,1) -> 45597 | P1: =EDATE(O1,1) -> 45627 | ... S1: =EDATE(R1,1) -> 45717
A2: FY2024-25 | B2: Tata Motors | C2: =VLOOKUP(B2,Mapping!B:C,2,0) -> Lateral | D2: =VLOOKUP(B2,Mapping!B:D,3,0) -> West | E2: =VLOOKUP(B2,Mapping!B:E,4,0) -> West 2 | F2: =VLOOKUP(B2,Mapping!B:F,5,0) -> Anjli | G2: =VLOOKUP(B2,Mapping!B:G,6,0) -> Shweta | H2: -3.4984519 | I2: -6.5972696 | J2: -1.1916842 | K2: 5.0178822 | L2: 13.220138 | M2: 4.4822498 | N2: 4.8323542 | O2: 5.7312193 | P2: 33.229707 | Q2: 11.970097 | R2: 5.1508936 | S2: 4.6148518
A3: FY2024-25 | B3: Schaeffler | C3: =VLOOKUP(B3,Mapping!B:C,2,0) -> Lateral | D3: =VLOOKUP(B3,Mapping!B:D,3,0) -> West | E3: =VLOOKUP(B3,Mapping!B:E,4,0) -> West 2 | F3: =VLOOKUP(B3,Mapping!B:F,5,0) -> Anjli | G3: =VLOOKUP(B3,Mapping!B:G,6,0) -> Shweta | H3: 3.0061758 | I3: 2.7177188 | J3: 1.7372026 | K3: 3.1769207 | L3: 4.7466494 | M3: 7.4672317 | N3: 0.41144086 | O3: 1.1419194 | P3: -2.2911981 | Q3: 1.7933945 | R3: 2.2400803 | S3: 3.56148
A4: FY2024-25 | B4: Vertiv | C4: =VLOOKUP(B4,Mapping!B:C,2,0) -> Lateral | D4: =VLOOKUP(B4,Mapping!B:D,3,0) -> West | E4: =VLOOKUP(B4,Mapping!B:E,4,0) -> West 2 | F4: =VLOOKUP(B4,Mapping!B:F,5,0) -> Anjli | G4: =VLOOKUP(B4,Mapping!B:G,6,0) -> Shweta | H4: -0.56970164 | I4: 2.9827788 | J4: 0.65480495 | K4: 5.16508 | L4: 1.4827097 | M4: 3.2502316 | N4: 0.37179758 | O4: 3.1404575 | P4: 5.9769285 | Q4: 1.8480259 | R4: 0.75939029 | S4: -2.5081089
A5: FY2024-25 | B5: Tata Marcopolo | C5: =VLOOKUP(B5,Mapping!B:C,2,0) -> Lateral | D5: =VLOOKUP(B5,Mapping!B:D,3,0) -> West | E5: =VLOOKUP(B5,Mapping!B:E,4,0) -> West 2 | F5: =VLOOKUP(B5,Mapping!B:F,5,0) -> Anjli | G5: =VLOOKUP(B5,Mapping!B:G,6,0) -> Anjli | H5: 0.15938975 | I5: 1.3526798 | J5: 0.88973212 | K5: -0.15096749 | L5: 1.4423874 | M5: 1.391727 | N5: -0.3917531 | O5: -0.62316998 | P5: 2.9845 | Q5: 0 | R5: -0.60034794 | S5: 0.063611554
A6: FY2024-25 | B6: ThyssenKrupp | C6: =VLOOKUP(B6,Mapping!B:C,2,0) -> Lateral | D6: =VLOOKUP(B6,Mapping!B:D,3,0) -> West | E6: =VLOOKUP(B6,Mapping!B:E,4,0) -> West 2 | F6: =VLOOKUP(B6,Mapping!B:F,5,0) -> Anjli | G6: =VLOOKUP(B6,Mapping!B:G,6,0) -> Shweta | H6: 8.546737 | I6: 8.540657 | J6: 10.467796 | K6: 6.2661246 | L6: 9.779377 | M6: 8.9807436 | N6: 2.1368529 | O6: -1.1204576 | P6: 6.5426247 | Q6: -1.113497 | R6: 3.9500194 | S6: -10.18564
A7: FY2024-25 | B7: Ultratech | C7: =VLOOKUP(B7,Mapping!B:C,2,0) -> Lateral | D7: =VLOOKUP(B7,Mapping!B:D,3,0) -> West | E7: =VLOOKUP(B7,Mapping!B:E,4,0) -> West 1 | F7: =VLOOKUP(B7,Mapping!B:F,5,0) -> Anjli | G7: =VLOOKUP(B7,Mapping!B:G,6,0) -> Elton | H7: 0.54808962 | I7: -1.1869603 | J7: 0.51190317 | K7: -0.85937623 | L7: -0.47666693 | M7: -0.3304896 | N7: 0 | O7: 0 | P7: 0 | Q7: 0 | R7: 0 | S7: 0
A8: FY2024-25 | B8: Tata Teleservices | C8: =VLOOKUP(B8,Mapping!B:C,2,0) -> Lateral | D8: =VLOOKUP(B8,Mapping!B:D,3,0) -> West | E8: =VLOOKUP(B8,Mapping!B:E,4,0) -> West 1 | F8: =VLOOKUP(B8,Mapping!B:F,5,0) -> Anjli | G8: =VLOOKUP(B8,Mapping!B:G,6,0) -> Elton | H8: -1.8422604 | I8: -2.5059706 | J8: -1.8014569 | K8: -2.2088625 | L8: -1.6417652 | M8: -1.6650784 | N8: -1.4955862 | O8: -1.4709 | P8: -1.5810076 | Q8: -1.5704428 | R8: -0.55099794 | S8: 0
A9: FY2024-25 | B9: Hyundai Motor | C9: =VLOOKUP(B9,Mapping!B:C,2,0) -> Lateral | D9: =VLOOKUP(B9,Mapping!B:D,3,0) -> West | E9: =VLOOKUP(B9,Mapping!B:E,4,0) -> West 2 | F9: =VLOOKUP(B9,Mapping!B:F,5,0) -> Anjli | G9: =VLOOKUP(B9,Mapping!B:G,6,0) -> Shweta | H9: -0.55189151 | I9: 15.390729 | J9: 5.220185 | K9: 6.6558432 | L9: 11.663532 | M9: 14.550595 | N9: 9.2125417 | O9: 17.331414 | P9: 3.0805555 | Q9: 6.2148158 | R9: 5.2146752 | S9: 4.0521489
A10: FY2024-25 | B10: Bridgestone | C10: =VLOOKUP(B10,Mapping!B:C,2,0) -> Lateral | D10: =VLOOKUP(B10,Mapping!B:D,3,0) -> West | E10: =VLOOKUP(B10,Mapping!B:E,4,0) -> West 2 | F10: =VLOOKUP(B10,Mapping!B:F,5,0) -> Anjli | G10: =VLOOKUP(B10,Mapping!B:G,6,0) -> Shweta | H10: 0 | I10: 0 | J10: 0 | K10: 0 | L10: 0 | M10: 0 | N10: 0 | O10: 0.042748413 | P10: 0 | Q10: 0.50353862 | R10: -0.50642589 | S10: 1.4748987
A11: FY2024-25 | B11: SKF India | C11: =VLOOKUP(B11,Mapping!B:C,2,0) -> Lateral | D11: =VLOOKUP(B11,Mapping!B:D,3,0) -> North | E11: =VLOOKUP(B11,Mapping!B:E,4,0) -> North | F11: =VLOOKUP(B11,Mapping!B:F,5,0) -> Anjli | G11: =VLOOKUP(B11,Mapping!B:G,6,0) -> Archana | H11: 4.6980365 | I11: 6.8777673 | J11: 3.8764851 | K11: -3.5287873 | L11: 0.042528792 | M11: 2.8735876 | N11: 1.9245568 | O11: 7.0447554 | P11: 0.25151648 | Q11: 12.345171 | R11: 1.3633688 | S11: -1.8978582
A12: FY2024-25 | B12: Jindal Stainless | C12: =VLOOKUP(B12,Mapping!B:C,2,0) -> Lateral | D12: =VLOOKUP(B12,Mapping!B:D,3,0) -> North | E12: =VLOOKUP(B12,Mapping!B:E,4,0) -> North | F12: =VLOOKUP(B12,Mapping!B:F,5,0) -> Anjli | G12: =VLOOKUP(B12,Mapping!B:G,6,0) -> Archana | H12: -0.073688688 | I12: 3.7797275 | J12: 8.4423232 | K12: 1.3150083 | L12: 4.4873035 | M12: 11.871054 | N12: 4.4473037 | O12: 0.46354478 | P12: 7.2081351 | Q12: 5.0415955 | R12: 0.82177898 | S12: 10.568915
A13: FY2024-25 | B13: Maruti Suzuki(MSIL) | C13: =VLOOKUP(B13,Mapping!B:C,2,0) -> Lateral | D13: =VLOOKUP(B13,Mapping!B:D,3,0) -> North | E13: =VLOOKUP(B13,Mapping!B:E,4,0) -> North | F13: =VLOOKUP(B13,Mapping!B:F,5,0) -> Anjli | G13: =VLOOKUP(B13,Mapping!B:G,6,0) -> Archana | H13: 1.7438099 | I13: -0.87595038 | J13: 18.087254 | K13: -2.4251811 | L13: -7.1897254 | M13: -15.548451 | N13: 2.7316406 | O13: 3.0527432 | P13: 2.8710284 | Q13: -8.4179521 | R13: -16.363207 | S13: 36.152401
... A58: FY2024-25 | B58: Bench | C58: =VLOOKUP(B58,Mapping!B:C,2,0) -> Lateral | D58: =VLOOKUP(B58,Mapping!B:D,3,0) -> North | E58: =VLOOKUP(B58,Mapping!B:E,4,0) -> North | F58: =VLOOKUP(B58,Mapping!B:F,5,0) -> Anjli | G58: =VLOOKUP(B58,Mapping!B:G,6,0) -> Anjli | H58: 0 | I58: 0 | J58: -0.0505 | K58: -0.0465 | L58: -0.049 | M58: -0.8 | N58: -0.0155 | O58: -0.0155 | P58: -0.031 | Q58: 0 | R58: 0 | S58: 0
H62: CM actual in Lacs

Sheet Taggd_Source_Joiner
A1: FY | B1: Project | C1: Vertical | D1: Region | E1: Sub Region | F1: Region Head | G1: Practice Head | H1: 45383 | I1: =EDATE(H1,1) -> 45413 | J1: =EDATE(I1,1) -> 45444 | K1: =EDATE(J1,1) -> 45474 | L1: =EDATE(K1,1) -> 45505 | M1: =EDATE(L1,1) -> 45536 | N1: =EDATE(M1,1) -> 45566 | O1: =EDATE(N1,1) -> 45597 | P1: =EDATE(O1,1) -> 45627 | ... S1: =EDATE(R1,1) -> 45717
A2: FY2024-25 | B2: Tata Motors | C2: =VLOOKUP(B2,Mapping!B:C,2,0) -> Lateral | D2: =VLOOKUP(B2,Mapping!B:D,3,0) -> West | E2: =VLOOKUP(B2,Mapping!B:E,4,0) -> West 2 | F2: =VLOOKUP(B2,Mapping!B:F,5,0) -> Anjli | G2: =VLOOKUP(B2,Mapping!B:G,6,0) -> Shweta | H2: 19 | I2: 0 | J2: 7 | K2: 24 | L2: 31 | M2: 28 | N2: 0 | O2: 28 | P2: 32 | Q2: 0 | R2: 25 | S2: 28
A3: FY2024-25 | B3: Schaeffler | C3: =VLOOKUP(B3,Mapping!B:C,2,0) -> Lateral | D3: =VLOOKUP(B3,Mapping!B:D,3,0) -> West | E3: =VLOOKUP(B3,Mapping!B:E,4,0) -> West 2 | F3: =VLOOKUP(B3,Mapping!B:F,5,0) -> Anjli | G3: =VLOOKUP(B3,Mapping!B:G,6,0) -> Shweta | H3: 11 | I3: 0 | J3: 9 | K3: 10 | L3: 3 | M3: 7 | N3: 9 | O3: 9 | P3: 3 | Q3: 1 | R3: 12 | S3: 9
A4: FY2024-25 | B4: Vertiv | C4: =VLOOKUP(B4,Mapping!B:C,2,0) -> Lateral | D4: =VLOOKUP(B4,Mapping!B:D,3,0) -> West | E4: =VLOOKUP(B4,Mapping!B:E,4,0) -> West 2 | F4: =VLOOKUP(B4,Mapping!B:F,5,0) -> Anjli | G4: =VLOOKUP(B4,Mapping!B:G,6,0) -> Shweta | H4: 7 | I4: 0 | J4: 8 | K4: 3 | L4: 2 | M4: 4 | N4: 3 | O4: 2 | P4: 7 | Q4: 2 | R4: 2 | S4: 1
A5: FY2024-25 | B5: Tata Marcopolo | C5: =VLOOKUP(B5,Mapping!B:C,2,0) -> Lateral | D5: =VLOOKUP(B5,Mapping!B:D,3,0) -> West | E5: =VLOOKUP(B5,Mapping!B:E,4,0) -> West 2 | F5: =VLOOKUP(B5,Mapping!B:F,5,0) -> Anjli | G5: =VLOOKUP(B5,Mapping!B:G,6,0) -> Anjli | H5: 0 | I5: 0 | J5: 2 | K5: 1 | L5: 2 | M5: 0 | N5: 0 | O5: 0 | P5: 1 | Q5: 0 | R5: 0 | S5: 0
A6: FY2024-25 | B6: ThyssenKrupp | C6: =VLOOKUP(B6,Mapping!B:C,2,0) -> Lateral | D6: =VLOOKUP(B6,Mapping!B:D,3,0) -> West | E6: =VLOOKUP(B6,Mapping!B:E,4,0) -> West 2 | F6: =VLOOKUP(B6,Mapping!B:F,5,0) -> Anjli | G6: =VLOOKUP(B6,Mapping!B:G,6,0) -> Shweta | H6: 0 | I6: 0 | J6: 18 | K6: 30 | L6: 32 | M6: 26 | N6: 14 | O6: 17 | P6: 12 | Q6: 8 | R6: 0 | S6: 0
A7: FY2024-25 | B7: Ultratech | C7: =VLOOKUP(B7,Mapping!B:C,2,0) -> Lateral | D7: =VLOOKUP(B7,Mapping!B:D,3,0) -> West | E7: =VLOOKUP(B7,Mapping!B:E,4,0) -> West 1 | F7: =VLOOKUP(B7,Mapping!B:F,5,0) -> Anjli | G7: =VLOOKUP(B7,Mapping!B:G,6,0) -> Elton | H7: 0 | I7: 0 | J7: 2 | K7: 0 | L7: 0 | M7: 0 | N7: 0 | O7: 0 | P7: 0 | Q7: 0 | R7: 0 | S7: 0
A8: FY2024-25 | B8: Tata Teleservices | C8: =VLOOKUP(B8,Mapping!B:C,2,0) -> Lateral | D8: =VLOOKUP(B8,Mapping!B:D,3,0) -> West | E8: =VLOOKUP(B8,Mapping!B:E,4,0) -> West 1 | F8: =VLOOKUP(B8,Mapping!B:F,5,0) -> Anjli | G8: =VLOOKUP(B8,Mapping!B:G,6,0) -> Elton | H8: 0 | I8: 0 | J8: 0 | K8: 0 | L8: 0 | M8: 0 | N8: 7 | O8: 0 | P8: 0 | Q8: 0 | R8: 0 | S8: 0
A9: FY2024-25 | B9: Hyundai Motor | C9: =VLOOKUP(B9,Mapping!B:C,2,0) -> Lateral | D9: =VLOOKUP(B9,Mapping!B:D,3,0) -> West | E9: =VLOOKUP(B9,Mapping!B:E,4,0) -> West 2 | F9: =VLOOKUP(B9,Mapping!B:F,5,0) -> Anjli | G9: =VLOOKUP(B9,Mapping!B:G,6,0) -> Shweta | H9: 46 | I9: 0 | J9: 2 | K9: 6 | L9: 18 | M9: 26 | N9: 14 | O9: 26 | P9: 30 | Q9: 26 | R9: 29 | S9: 25
A10: FY2024-25 | B10: Bridgestone | C10: =VLOOKUP(B10,Mapping!B:C,2,0) -> Lateral | D10: =VLOOKUP(B10,Mapping!B:D,3,0) -> West | E10: =VLOOKUP(B10,Mapping!B:E,4,0) -> West 2 | F10: =VLOOKUP(B10,Mapping!B:F,5,0) -> Anjli | G10: =VLOOKUP(B10,Mapping!B:G,6,0) -> Shweta | H10: 0 | I10: 0 | J10: 0 | K10: 0 | L10: 0 | M10: 0 | N10: 0 | O10: 0 | P10: 0 | Q10: 0 | R10: 0 | S10: 0
A11: FY2024-25 | B11: SKF India | C11: =VLOOKUP(B11,Mapping!B:C,2,0) -> Lateral | D11: =VLOOKUP(B11,Mapping!B:D,3,0) -> North | E11: =VLOOKUP(B11,Mapping!B:E,4,0) -> North | F11: =VLOOKUP(B11,Mapping!B:F,5,0) -> Anjli | G11: =VLOOKUP(B11,Mapping!B:G,6,0) -> Archana | H11: 12 | I11: 0 | J11: 16 | K11: 13 | L11: 15 | M11: 18 | N11: 7 | O11: 7 | P11: 12 | Q11: 2 | R11: 11 | S11: 13
A12: FY2024-25 | B12: Jindal Stainless | C12: =VLOOKUP(B12,Mapping!B:C,2,0) -> Lateral | D12: =VLOOKUP(B12,Mapping!B:D,3,0) -> North | E12: =VLOOKUP(B12,Mapping!B:E,4,0) -> North | F12: =VLOOKUP(B12,Mapping!B:F,5,0) -> Anjli | G12: =VLOOKUP(B12,Mapping!B:G,6,0) -> Archana | H12: 11 | I12: 0 | J12: 14 | K12: 17 | L12: 14 | M12: 23 | N12: 10 | O12: 17 | P12: 21 | Q12: 7 | R12: 6 | S12: 7
A13: FY2024-25 | B13: Maruti Suzuki(MSIL) | C13: =VLOOKUP(B13,Mapping!B:C,2,0) -> Lateral | D13: =VLOOKUP(B13,Mapping!B:D,3,0) -> North | E13: =VLOOKUP(B13,Mapping!B:E,4,0) -> North | F13: =VLOOKUP(B13,Mapping!B:F,5,0) -> Anjli | G13: =VLOOKUP(B13,Mapping!B:G,6,0) -> Archana | H13: 63 | I13: 0 | J13: 0 | K13: 0 | L13: 2 | M13: 17 | N13: 14 | O13: 23 | P13: 28 | Q13: 69 | R13: 89 | S13: 183
A14: FY2024-25 | B14: Suzuki R&D | C14: =VLOOKUP(B14,Mapping!B:C,2,0) -> Lateral | D14: =VLOOKUP(B14,Mapping!B:D,3,0) -> North | E14: =VLOOKUP(B14,Mapping!B:E,4,0) -> North | F14: =VLOOKUP(B14,Mapping!B:F,5,0) -> Anjli | G14: =VLOOKUP(B14,Mapping!B:G,6,0) -> Archana | H14: 1 | P14: 0 | Q14: 0 | R14: 0 | S14: 0
A15: FY2024-25 | B15: Subros Ltd | C15: =VLOOKUP(B15,Mapping!B:C,2,0) -> Lateral | D15: =VLOOKUP(B15,Mapping!B:D,3,0) -> North | E15: =VLOOKUP(B15,Mapping!B:E,4,0) -> North | F15: =VLOOKUP(B15,Mapping!B:F,5,0) -> Anjli | G15: =VLOOKUP(B15,Mapping!B:G,6,0) -> Archana | H15: 1 | I15: 0 | J15: 0 | K15: 0 | L15: 0 | M15: 0 | N15: 0 | O15: 0 | P15: 1 | Q15: 0 | R15: 0 | S15: 0
A16: FY2024-25 | B16: Pernod Ricard | C16: =VLOOKUP(B16,Mapping!B:C,2,0) -> Lateral | D16: =VLOOKUP(B16,Mapping!B:D,3,0) -> North | E16: =VLOOKUP(B16,Mapping!B:E,4,0) -> North | F16: =VLOOKUP(B16,Mapping!B:F,5,0) -> Anjli | G16: =VLOOKUP(B16,Mapping!B:G,6,0) -> Archana | H16: 0 | I16: 0 | J16: 0 | K16: 0 | L16: 0 | M16: 0 | N16: 0 | O16: 0 | P16: 0 | Q16: 0 | R16: 0 | S16: 0
A17: FY2024-25 | B17: Pfizer | C17: =VLOOKUP(B17,Mapping!B:C,2,0) -> Lateral | D17: =VLOOKUP(B17,Mapping!B:D,3,0) -> West | E17: =VLOOKUP(B17,Mapping!B:E,4,0) -> West 1 | F17: =VLOOKUP(B17,Mapping!B:F,5,0) -> Anjli | G17: =VLOOKUP(B17,Mapping!B:G,6,0) -> Usha | H17: 16 | I17: 0 | J17: 10 | K17: 10 | L17: 6 | M17: 6 | N17: 14 | O17: 16 | P17: 10 | Q17: 14 | R17: 15 | S17: 16
A18: FY2024-25 | B18: Tata Power | C18: =VLOOKUP(B18,Mapping!B:C,2,0) -> Lateral | D18: =VLOOKUP(B18,Mapping!B:D,3,0) -> West | E18: =VLOOKUP(B18,Mapping!B:E,4,0) -> West 1 | F18: =VLOOKUP(B18,Mapping!B:F,5,0) -> Anjli | G18: =VLOOKUP(B18,Mapping!B:G,6,0) -> Elton | H18: 0 | I18: 0 | J18: 1 | K18: 0 | L18: 0 | M18: 0 | N18: 0 | O18: 0 | P18: 0 | Q18: 0 | R18: 0 | S18: 0
A19: FY2024-25 | B19: Pidilite | C19: =VLOOKUP(B19,Mapping!B:C,2,0) -> Lateral | D19: =VLOOKUP(B19,Mapping!B:D,3,0) -> West | E19: =VLOOKUP(B19,Mapping!B:E,4,0) -> West 1 | F19: =VLOOKUP(B19,Mapping!B:F,5,0) -> Anjli | G19: =VLOOKUP(B19,Mapping!B:G,6,0) -> Usha | H19: 19 | I19: 0 | J19: 14 | K19: 15 | L19: 15 | M19: 50 | N19: 18 | O19: 21 | P19: 20 | Q19: 28 | R19: 19 | S19: 23
A20: FY2024-25 | B20: Birla Paints | C20: =VLOOKUP(B20,Mapping!B:C,2,0) -> Lateral | D20: =VLOOKUP(B20,Mapping!B:D,3,0) -> West | E20: =VLOOKUP(B20,Mapping!B:E,4,0) -> West 1 | F20: =VLOOKUP(B20,Mapping!B:F,5,0) -> Anjli | G20: =VLOOKUP(B20,Mapping!B:G,6,0) -> Geetu | H20: 5 | I20: 0 | J20: 21 | K20: 11 | L20: 34 | M20: 20 | N20: 23 | O20: 6 | P20: 1 | Q20: 4 | R20: 16 | S20: 8
A21: FY2024-25 | B21: M&M | C21: =VLOOKUP(B21,Mapping!B:C,2,0) -> Lateral & Leadership | D21: =VLOOKUP(B21,Mapping!B:D,3,0) -> West | E21: =VLOOKUP(B21,Mapping!B:E,4,0) -> West 1 | F21: =VLOOKUP(B21,Mapping!B:F,5,0) -> Anjli | G21: =VLOOKUP(B21,Mapping!B:G,6,0) -> Dhriti | H21: 94 | I21: 0 | J21: 114 | K21: 114 | L21: 84 | M21: 92 | N21: 75 | O21: 89 | P21: 94 | Q21: 105 | R21: 89 | S21: 87
A22: FY2024-25 | B22: DP World | C22: =VLOOKUP(B22,Mapping!B:C,2,0) -> Lateral | D22: =VLOOKUP(B22,Mapping!B:D,3,0) -> West | E22: =VLOOKUP(B22,Mapping!B:E,4,0) -> West 1 | F22: =VLOOKUP(B22,Mapping!B:F,5,0) -> Anjli | G22: =VLOOKUP(B22,Mapping!B:G,6,0) -> Geetu | H22: 16 | I22: 0 | J22: 19 | K22: 18 | L22: 9 | M22: 17 | N22: 6 | O22: 11 | P22: 9 | Q22: 10 | R22: 6 | S22: 14
A23: FY2024-25 | B23: AMNS | C23: =VLOOKUP(B23,Mapping!B:C,2,0) -> Lateral | D23: =VLOOKUP(B23,Mapping!B:D,3,0) -> West | E23: =VLOOKUP(B23,Mapping!B:E,4,0) -> West 1 | F23: =VLOOKUP(B23,Mapping!B:F,5,0) -> Anjli | G23: =VLOOKUP(B23,Mapping!B:G,6,0) -> Alifia | H23: 35 | I23: 0 | J23: 86 | K23: 75 | L23: 41 | M23: 79 | N23: 23 | O23: 32 | P23: 37 | Q23: 47 | R23: 65 | S23: 60
A24: FY2024-25 | B24: Mahindra Holidays | C24: =VLOOKUP(B24,Mapping!B:C,2,0) -> Lateral | D24: =VLOOKUP(B24,Mapping!B:D,3,0) -> West | E24: =VLOOKUP(B24,Mapping!B:E,4,0) -> West 1 | F24: =VLOOKUP(B24,Mapping!B:F,5,0) -> Anjli | G24: =VLOOKUP(B24,Mapping!B:G,6,0) -> Geetu | H24: 22 | I24: 0 | J24: 26 | K24: 10 | L24: 21 | M24: 17 | N24: 1 | O24: 2 | P24: 0 | Q24: 8 | R24: 13 | S24: 13
A25: FY2024-25 | B25: WTW | C25: =VLOOKUP(B25,Mapping!B:C,2,0) -> Lateral | D25: =VLOOKUP(B25,Mapping!B:D,3,0) -> West | E25: =VLOOKUP(B25,Mapping!B:E,4,0) -> West 1 | F25: =VLOOKUP(B25,Mapping!B:F,5,0) -> Anjli | G25: =VLOOKUP(B25,Mapping!B:G,6,0) -> Geetu | H25: 0 | I25: 0 | J25: 0 | K25: 0 | L25: 0 | M25: 0 | N25: 0 | O25: 0 | P25: 0 | Q25: 0 | R25: 0 | S25: 0
A26: FY2024-25 | B26: Fedex | C26: =VLOOKUP(B26,Mapping!B:C,2,0) -> Lateral | D26: =VLOOKUP(B26,Mapping!B:D,3,0) -> West | E26: =VLOOKUP(B26,Mapping!B:E,4,0) -> West 1 | F26: =VLOOKUP(B26,Mapping!B:F,5,0) -> Anjli | G26: =VLOOKUP(B26,Mapping!B:G,6,0) -> Elton | H26: 0 | I26: 0 | J26: 1 | K26: 1 | L26: 0 | M26: 0 | N26: 0 | O26: 0 | P26: 0 | Q26: 0 | R26: 1 | S26: 0
... A40: FY2024-25 | B40: P&G | C40: =VLOOKUP(B40,Mapping!B:C,2,0) -> Lateral | D40: =VLOOKUP(B40,Mapping!B:D,3,0) -> South | E40: =VLOOKUP(B40,Mapping!B:E,4,0) -> South 2 | F40: =VLOOKUP(B40,Mapping!B:F,5,0) -> Sulabh | G40: =VLOOKUP(B40,Mapping!B:G,6,0) -> Krishna | H40: 0 | I40: 0 | J40: 0 | K40: 0 | L40: 0 | M40: 0 | N40: 0 | O40: 0 | P40: 0 | Q40: 0 | R40: 0 | S40: 0
A41: FY2024-25 | B41: L&T Energy | C41: =VLOOKUP(B41,Mapping!B:C,2,0) -> Lateral | D41: =VLOOKUP(B41,Mapping!B:D,3,0) -> South | E41: =VLOOKUP(B41,Mapping!B:E,4,0) -> South 2 | F41: =VLOOKUP(B41,Mapping!B:F,5,0) -> Sulabh | G41: =VLOOKUP(B41,Mapping!B:G,6,0) -> Krishna | H41: 0 | P41: 0 | Q41: 0 | R41: 0 | S41: 0
A42: FY2024-25 | B42: Tata Electronics | C42: =VLOOKUP(B42,Mapping!B:C,2,0) -> Lateral | D42: =VLOOKUP(B42,Mapping!B:D,3,0) -> South | E42: =VLOOKUP(B42,Mapping!B:E,4,0) -> South 2 | F42: =VLOOKUP(B42,Mapping!B:F,5,0) -> Sulabh | G42: =VLOOKUP(B42,Mapping!B:G,6,0) -> Subu | H42: 7 | I42: 0 | J42: 24 | K42: 26 | L42: 48 | M42: 23 | N42: 4 | O42: 11 | P42: 9 | Q42: 7 | R42: 11 | S42: 16
A43: FY2024-25 | B43: Royal Enfield | C43: =VLOOKUP(B43,Mapping!B:C,2,0) -> Lateral | D43: =VLOOKUP(B43,Mapping!B:D,3,0) -> South | E43: =VLOOKUP(B43,Mapping!B:E,4,0) -> South 2 | F43: =VLOOKUP(B43,Mapping!B:F,5,0) -> Sulabh | G43: =VLOOKUP(B43,Mapping!B:G,6,0) -> Krishna | H43: 1 | I43: 0 | J43: 2 | K43: 6 | L43: 4 | M43: 1 | N43: 0 | O43: 2 | P43: 0 | Q43: 3 | R43: 1 | S43: 2
A44: FY2024-25 | B44: Excelacom | C44: =VLOOKUP(B44,Mapping!B:C,2,0) -> Lateral | D44: =VLOOKUP(B44,Mapping!B:D,3,0) -> South | E44: =VLOOKUP(B44,Mapping!B:E,4,0) -> South 2 | F44: =VLOOKUP(B44,Mapping!B:F,5,0) -> Sulabh | G44: =VLOOKUP(B44,Mapping!B:G,6,0) -> Krishna | H44: 1 | I44: 0 | J44: 9 | K44: 1 | L44: 3 | M44: 3 | N44: 23 | O44: 3 | P44: 23 | Q44: 0 | R44: 1 | S44: 2
A45: FY2024-25 | B45: Viteos | C45: =VLOOKUP(B45,Mapping!B:C,2,0) -> Lateral | D45: =VLOOKUP(B45,Mapping!B:D,3,0) -> South | E45: =VLOOKUP(B45,Mapping!B:E,4,0) -> South 2 | F45: =VLOOKUP(B45,Mapping!B:F,5,0) -> Sulabh | G45: =VLOOKUP(B45,Mapping!B:G,6,0) -> Krishna | H45: 0 | I45: 0 | J45: 0 | K45: 0 | L45: 0 | M45: 0 | N45: 0 | O45: 0 | P45: 0 | Q45: 0 | R45: 0 | S45: 0
A46: FY2024-25 | B46: Ashok Leyland | C46: =VLOOKUP(B46,Mapping!B:C,2,0) -> Lateral | D46: =VLOOKUP(B46,Mapping!B:D,3,0) -> South | E46: =VLOOKUP(B46,Mapping!B:E,4,0) -> South 2 | F46: =VLOOKUP(B46,Mapping!B:F,5,0) -> Sulabh | G46: =VLOOKUP(B46,Mapping!B:G,6,0) -> Krishna | H46: 0 | I46: 0 | J46: 0 | K46: 0 | L46: 0 | M46: 0 | N46: 0 | O46: 0 | P46: 0 | Q46: 0 | R46: 1 | S46: 2
A47: FY2024-25 | B47: M2P Fintech | C47: =VLOOKUP(B47,Mapping!B:C,2,0) -> Lateral | D47: =VLOOKUP(B47,Mapping!B:D,3,0) -> South | E47: =VLOOKUP(B47,Mapping!B:E,4,0) -> South 2 | F47: =VLOOKUP(B47,Mapping!B:F,5,0) -> Sulabh | G47: =VLOOKUP(B47,Mapping!B:G,6,0) -> Krishna | H47: 0 | I47: 0 | J47: 0 | K47: 0 | L47: 0 | M47: 0 | N47: 0 | O47: 0 | P47: 0 | Q47: 0 | R47: 0 | S47: 0
A48: FY2024-25 | B48: ABB | C48: =VLOOKUP(B48,Mapping!B:C,2,0) -> Lateral | D48: =VLOOKUP(B48,Mapping!B:D,3,0) -> South | E48: =VLOOKUP(B48,Mapping!B:E,4,0) -> South 2 | F48: =VLOOKUP(B48,Mapping!B:F,5,0) -> Sulabh | G48: =VLOOKUP(B48,Mapping!B:G,6,0) -> Satya | H48: 0 | I48: 0 | J48: 0 | K48: 0 | L48: 0 | M48: 0 | N48: 0 | O48: 0 | P48: 0 | Q48: 0 | R48: 0 | S48: 0
A49: FY2024-25 | B49: Honeywell | C49: =VLOOKUP(B49,Mapping!B:C,2,0) -> Lateral & Leadership | D49: =VLOOKUP(B49,Mapping!B:D,3,0) -> Bapi | E49: =VLOOKUP(B49,Mapping!B:E,4,0) -> South 1 | F49: =VLOOKUP(B49,Mapping!B:F,5,0) -> Bapi | G49: =VLOOKUP(B49,Mapping!B:G,6,0) -> Bapi | H49: 126 | I49: 0 | J49: 164 | K49: 206 | L49: 288 | M49: 161 | N49: 103 | O49: 50 | P49: 114 | Q49: 68 | R49: 123 | S49: 195
