Workbook

Sheet Revenue_Budget
H1: =SUM(H3:H80) -> 951.29672 | I1: =SUM(I3:I80) -> 1057.6644 | J1: =SUM(J3:J80) -> 1086.9388 | K1: =SUM(K3:K80) -> 1162.2972 | L1: =SUM(L3:L80) -> 1228.5572 | M1: =SUM(M3:M80) -> 1272.2822 | N1: =SUM(N3:N80) -> 1241.7384 | O1: =SUM(O3:O80) -> 1269.0074 | ... T1: =SUM(T3:T80) -> 15000
A2: FY | B2: Project | C2: Vertical | D2: Region | E2: Sub Region | F2: Region Head | G2: Practice Head | H2: 46113 | I2: =EDATE(H2,1) -> 46143 | J2: =EDATE(I2,1) -> 46174 | K2: =EDATE(J2,1) -> 46204 | L2: =EDATE(K2,1) -> 46235 | M2: =EDATE(L2,1) -> 46266 | N2: =EDATE(M2,1) -> 46296 | O2: =EDATE(N2,1) -> 46327 | P2: =EDATE(O2,1) -> 46357 | ... S2: =EDATE(R2,1) -> 46447 | T2: Total
A3: FY2026-27 | B3: Honeywell | C3: =VLOOKUP(B3,Mapping!A:B,2,0) -> Lateral | D3: =VLOOKUP(B3,Mapping!A:C,3,0) -> South | E3: =VLOOKUP(B3,Mapping!A:D,4,0) -> South 1 | F3: =VLOOKUP(B3,Mapping!A:E,5,0) -> Bapi | G3: =VLOOKUP(B3,Mapping!A:F,6,0) -> Bapi | H3: 120 | I3: 167 | J3: 188 | K3: 108 | L3: 155 | M3: 177 | N3: 82 | O3: 116 | P3: 132 | Q3: 120 | R3: 168 | S3: 192 | T3: =SUM(H3:S3) -> 1725
A4: FY2026-27 | B4: Pfizer | C4: =VLOOKUP(B4,Mapping!A:B,2,0) -> Lateral | D4: =VLOOKUP(B4,Mapping!A:C,3,0) -> West | E4: =VLOOKUP(B4,Mapping!A:D,4,0) -> West 1 | F4: =VLOOKUP(B4,Mapping!A:E,5,0) -> Anjli | G4: =VLOOKUP(B4,Mapping!A:F,6,0) -> Usha | H4: 8 | I4: 8 | J4: 8 | K4: 8 | L4: 8 | M4: 8 | N4: 5 | O4: 5 | P4: 5 | Q4: 5 | R4: 6 | S4: 6 | T4: =SUM(H4:S4) -> 80
A5: FY2026-27 | B5: Tata Motors | C5: =VLOOKUP(B5,Mapping!A:B,2,0) -> Lateral | D5: =VLOOKUP(B5,Mapping!A:C,3,0) -> West | E5: =VLOOKUP(B5,Mapping!A:D,4,0) -> West 2 | F5: =VLOOKUP(B5,Mapping!A:E,5,0) -> Anjli | G5: =VLOOKUP(B5,Mapping!A:F,6,0) -> Shweta | H5: 0 | I5: 0 | J5: 0 | K5: 0 | L5: 0 | M5: 0 | N5: 0 | O5: 0 | P5: 0 | Q5: 0 | R5: 0 | S5: 0 | T5: =SUM(H5:S5) -> 0
A6: FY2026-27 | B6: SKF India | C6: =VLOOKUP(B6,Mapping!A:B,2,0) -> Lateral | D6: =VLOOKUP(B6,Mapping!A:C,3,0) -> North | E6: =VLOOKUP(B6,Mapping!A:D,4,0) -> North | F6: =VLOOKUP(B6,Mapping!A:E,5,0) -> Anjli | G6: =VLOOKUP(B6,Mapping!A:F,6,0) -> Archana | H6: 20 | I6: 17 | J6: 19 | K6: 18 | L6: 23 | M6: 22 | N6: 19 | O6: 20 | P6: 18 | Q6: 17 | R6: 15 | S6: 14 | T6: =SUM(H6:S6) -> 222
A7: FY2026-27 | B7: Siemens (Advatnta & GBS) | C7: Lateral | D7: South | E7: South 1 | F7: Manish Malhotra | G7: Kunal | H7: 8.7 | I7: 9.6 | J7: 10.2 | K7: 9 | L7: 9.4 | M7: 9 | N7: 9.2 | O7: 10.7 | P7: 11.6 | Q7: 11.9 | R7: 11.9 | S7: 11.9 | T7: =SUM(H7:S7) -> 123.1
A8: FY2026-27 | B8: Siemens Energy | C8: Lateral | D8: North | E8: North | F8: Anjli | G8: Archana | H8: 11 | I8: 11 | J8: 11 | K8: 11.5 | L8: 12 | M8: 11 | N8: 10 | O8: 10 | P8: 10.6 | Q8: 11.6 | R8: 12.5 | S8: 12.5 | T8: =SUM(H8:S8) -> 134.7
A9: FY2026-27 | B9: Pidilite | C9: =VLOOKUP(B9,Mapping!A:B,2,0) -> Lateral | D9: =VLOOKUP(B9,Mapping!A:C,3,0) -> West | E9: =VLOOKUP(B9,Mapping!A:D,4,0) -> West 1 | F9: =VLOOKUP(B9,Mapping!A:E,5,0) -> Anjli | G9: =VLOOKUP(B9,Mapping!A:F,6,0) -> Usha | H9: 17.25 | I9: 17.25 | J9: 17.25 | K9: 15.166667 | L9: 15.166667 | M9: 15.166667 | N9: 16 | O9: 16 | P9: 16 | Q9: 16.833333 | R9: 16.833333 | S9: 16.833333 | T9: =SUM(H9:S9) -> 195.75
A10: FY2026-27 | B10: Vertiv | C10: =VLOOKUP(B10,Mapping!A:B,2,0) -> Lateral | D10: =VLOOKUP(B10,Mapping!A:C,3,0) -> West | E10: =VLOOKUP(B10,Mapping!A:D,4,0) -> West 2 | F10: =VLOOKUP(B10,Mapping!A:E,5,0) -> Anjli | G10: =VLOOKUP(B10,Mapping!A:F,6,0) -> Shweta | H10: 3 | I10: 3 | J10: 4 | K10: 4 | L10: 4 | M10: 4 | N10: 4.5 | O10: 4 | P10: 4.5 | Q10: 4.5 | R10: 4.5 | S10: 4 | T10: =SUM(H10:S10) -> 48
A11: FY2026-27 | B11: Birla Paints | C11: =VLOOKUP(B11,Mapping!A:B,2,0) -> Lateral | D11: =VLOOKUP(B11,Mapping!A:C,3,0) -> West | E11: =VLOOKUP(B11,Mapping!A:D,4,0) -> West 1 | F11: =VLOOKUP(B11,Mapping!A:E,5,0) -> Anjli | G11: =VLOOKUP(B11,Mapping!A:F,6,0) -> Geetu | H11: 17.166667 | I11: 17.166667 | J11: 17.166667 | K11: 15.733333 | L11: 15.733333 | M11: 15.733333 | N11: 16.6 | O11: 16.6 | P11: 16.6 | Q11: 15.533333 | R11: 15.533333 | S11: 15.533333 | T11: =SUM(H11:S11) -> 195.1
A12: FY2026-27 | B12: Ingram Micro | C12: =VLOOKUP(B12,Mapping!A:B,2,0) -> Lateral | D12: =VLOOKUP(B12,Mapping!A:C,3,0) -> West | E12: =VLOOKUP(B12,Mapping!A:D,4,0) -> West 1 | F12: =VLOOKUP(B12,Mapping!A:E,5,0) -> Anjli | G12: =VLOOKUP(B12,Mapping!A:F,6,0) -> Geetu | H12: 0 | I12: 0 | J12: 0 | K12: 0 | L12: 0 | M12: 0 | N12: 0 | O12: 0 | P12: 0 | Q12: 0 | R12: 0 | S12: 0 | T12: =SUM(H12:S12) -> 0
A13: FY2026-27 | B13: HPE | C13: =VLOOKUP(B13,Mapping!A:B,2,0) -> Lateral | D13: =VLOOKUP(B13,Mapping!A:C,3,0) -> South | E13: =VLOOKUP(B13,Mapping!A:D,4,0) -> South 1 | F13: =VLOOKUP(B13,Mapping!A:E,5,0) -> Mahak | G13: =VLOOKUP(B13,Mapping!A:F,6,0) -> Mahak | H13: 113.10139 | I13: 113.10139 | J13: 103.10139 | K13: 134.09063 | L13: 134.09063 | M13: 124.09063 | N13: 113.19042 | O13: 113.19042 | P13: 103.19042 | Q13: 134.00159 | R13: 134.00159 | S13: 124.00159 | T13: =SUM(H13:S13) -> 1443.1521
A14: FY2026-27 | B14: Isuzu | C14: =VLOOKUP(B14,Mapping!A:B,2,0) -> Lateral | D14: =VLOOKUP(B14,Mapping!A:C,3,0) -> South | E14: =VLOOKUP(B14,Mapping!A:D,4,0) -> South 1 | F14: =VLOOKUP(B14,Mapping!A:E,5,0) -> Anjli | G14: =VLOOKUP(B14,Mapping!A:F,6,0) -> Satya | H14: 9 | I14: 9 | J14: 9 | K14: 9 | L14: 9 | M14: 9 | N14: 6 | O14: 7 | P14: 7 | Q14: 8 | R14: 7 | S14: 8 | T14: =SUM(H14:S14) -> 97
A15: FY2026-27 | B15: Mahindra Holidays | C15: =VLOOKUP(B15,Mapping!A:B,2,0) -> Lateral | D15: =VLOOKUP(B15,Mapping!A:C,3,0) -> West | E15: =VLOOKUP(B15,Mapping!A:D,4,0) -> West 1 | F15: =VLOOKUP(B15,Mapping!A:E,5,0) -> Anjli | G15: =VLOOKUP(B15,Mapping!A:F,6,0) -> Geetu | H15: 0 | I15: 0 | J15: 0 | K15: 0 | L15: 0 | M15: 0 | N15: 0 | O15: 0 | P15: 0 | Q15: 0 | R15: 0 | S15: 0 | T15: =SUM(H15:S15) -> 0
A16: FY2026-27 | B16: BITS | C16: =VLOOKUP(B16,Mapping!A:B,2,0) -> Lateral | D16: =VLOOKUP(B16,Mapping!A:C,3,0) -> South | E16: =VLOOKUP(B16,Mapping!A:D,4,0) -> South 2 | F16: =VLOOKUP(B16,Mapping!A:E,5,0) -> Sulabh | G16: =VLOOKUP(B16,Mapping!A:F,6,0) -> Krishna | H16: 3 | I16: 4 | J16: 5 | K16: 4 | L16: 4 | M16: 5 | N16: 4 | O16: 4 | P16: 3 | Q16: 3 | R16: 4 | S16: 5 | T16: =SUM(H16:S16) -> 48
A17: FY2026-27 | B17: M&M | C17: =VLOOKUP(B17,Mapping!A:B,2,0) -> Lateral | D17: =VLOOKUP(B17,Mapping!A:C,3,0) -> West | E17: =VLOOKUP(B17,Mapping!A:D,4,0) -> West 1 | F17: =VLOOKUP(B17,Mapping!A:E,5,0) -> Anjli | G17: =VLOOKUP(B17,Mapping!A:F,6,0) -> Dhriti | H17: 105 | I17: 100 | J17: 100 | K17: 110 | L17: 110 | M17: 110 | N17: 120 | O17: 120 | P17: 120 | Q17: 130 | R17: 130 | S17: 130 | T17: =SUM(H17:S17) -> 1385
A18: FY2026-27 | B18: P&G | C18: =VLOOKUP(B18,Mapping!A:B,2,0) -> Lateral | D18: =VLOOKUP(B18,Mapping!A:C,3,0) -> South | E18: =VLOOKUP(B18,Mapping!A:D,4,0) -> South 2 | F18: =VLOOKUP(B18,Mapping!A:E,5,0) -> Sulabh | G18: =VLOOKUP(B18,Mapping!A:F,6,0) -> Krishna | H18: 0 | I18: 0 | J18: 0 | K18: 0 | L18: 0 | M18: 0 | N18: 0 | O18: 0 | P18: 0 | Q18: 0 | R18: 0 | S18: 0 | T18: =SUM(H18:S18) -> 0
A19: FY2026-27 | B19: Wipro | C19: =VLOOKUP(B19,Mapping!A:B,2,0) -> Lateral | D19: =VLOOKUP(B19,Mapping!A:C,3,0) -> South | E19: =VLOOKUP(B19,Mapping!A:D,4,0) -> South 1 | F19: =VLOOKUP(B19,Mapping!A:E,5,0) -> Sulabh | G19: =VLOOKUP(B19,Mapping!A:F,6,0) -> Subu | H19: 40 | I19: 60 | J19: 50 | K19: 55 | L19: 55 | M19: 40 | N19: 40 | O19: 30 | P19: 30 | Q19: 60 | R19: 60 | S19: 30 | T19: =SUM(H19:S19) -> 550
A20: FY2026-27 | B20: Tata Marcopolo | C20: =VLOOKUP(B20,Mapping!A:B,2,0) -> Lateral | D20: =VLOOKUP(B20,Mapping!A:C,3,0) -> West | E20: =VLOOKUP(B20,Mapping!A:D,4,0) -> West 2 | F20: =VLOOKUP(B20,Mapping!A:E,5,0) -> Anjli | G20: =VLOOKUP(B20,Mapping!A:F,6,0) -> Anjli | H20: 0 | I20: 0 | J20: 0 | K20: 0 | L20: 0 | M20: 0 | N20: 0 | O20: 0 | P20: 0 | Q20: 0 | R20: 0 | S20: 0 | T20: =SUM(H20:S20) -> 0
... A67: FY2026-27 | B67: Optum | C67: =VLOOKUP(B67,Mapping!A:B,2,0) -> Lateral | D67: =VLOOKUP(B67,Mapping!A:C,3,0) -> South | E67: =VLOOKUP(B67,Mapping!A:D,4,0) -> South 1 | F67: =VLOOKUP(B67,Mapping!A:E,5,0) -> Ashish | G67: =VLOOKUP(B67,Mapping!A:F,6,0) -> Ashish | H67: 45.833333 | I67: 45.833333 | J67: 45.833333 | K67: 45.833333 | L67: 45.833333 | M67: 45.833333 | N67: 45.833333 | O67: 45.833333 | P67: 45.833333 | Q67: 45.833333 | R67: 45.833333 | S67: 45.833333 | T67: =SUM(H67:S67) -> 550
A68: FY2026-27 | B68: New Sales + Mining | C68: =VLOOKUP(B68,Mapping!A:B,2,0) -> Lateral | D68: =VLOOKUP(B68,Mapping!A:C,3,0) -> New Sales | E68: =VLOOKUP(B68,Mapping!A:D,4,0) -> New Sales | F68: =VLOOKUP(B68,Mapping!A:E,5,0) -> Nizar | G68: =VLOOKUP(B68,Mapping!A:F,6,0) -> Nizar | H68: 84.381112 | I68: 84.381112 | J68: 84.381112 | K68: 168.76222 | L68: 168.76222 | M68: 168.76222 | N68: 253.14334 | O68: 253.14334 | P68: 253.14334 | Q68: 337.52445 | R68: 337.52445 | S68: 337.52445 | T68: =SUM(H68:S68) -> 2531.4334 | V68: =V2/3 -> 0 | W68: =W2/3 -> 0 | X68: =X2/3 -> 0 | Y68: =Y2/3 -> 0
A69: FY2026-27 | B69: Pernod Ricard | C69: =VLOOKUP(B69,Mapping!A:B,2,0) -> Lateral | D69: =VLOOKUP(B69,Mapping!A:C,3,0) -> North | E69: =VLOOKUP(B69,Mapping!A:D,4,0) -> North | F69: =VLOOKUP(B69,Mapping!A:E,5,0) -> Anjli | G69: =VLOOKUP(B69,Mapping!A:F,6,0) -> Archana | H69: 9.5 | I69: 9.5 | J69: 9.5 | K69: 9.5 | L69: 9.5 | M69: 9.5 | N69: 11 | O69: 11 | P69: 11 | Q69: 5 | R69: 5 | S69: 5 | T69: =SUM(H69:S69) -> 105
A70: FY2026-27 | B70: UniCharm | C70: =VLOOKUP(B70,Mapping!A:B,2,0) -> Lateral | D70: =VLOOKUP(B70,Mapping!A:C,3,0) -> North | E70: =VLOOKUP(B70,Mapping!A:D,4,0) -> North | F70: =VLOOKUP(B70,Mapping!A:E,5,0) -> Anjli | G70: =VLOOKUP(B70,Mapping!A:F,6,0) -> Archana | H70: 4 | I70: 4 | J70: 4 | K70: 4 | L70: 4 | M70: 4 | N70: 4 | O70: 4 | P70: 4 | Q70: 4 | R70: 4 | S70: 4 | T70: =SUM(H70:S70) -> 48
A71: FY2026-27 | B71: Saint Gobain | C71: =VLOOKUP(B71,Mapping!A:B,2,0) -> #N/A | D71: =VLOOKUP(B71,Mapping!A:C,3,0) -> #N/A | E71: =VLOOKUP(B71,Mapping!A:D,4,0) -> #N/A | F71: =VLOOKUP(B71,Mapping!A:E,5,0) -> #N/A | G71: =VLOOKUP(B71,Mapping!A:F,6,0) -> #N/A | H71: 17.51 | I71: 30.29 | J71: 33.83 | K71: 37.38 | L71: 37.38 | M71: 40.93 | N71: 40.93 | O71: 40.93 | P71: 40.93 | Q71: 40.93 | R71: 40.93 | S71: 40.93 | T71: =SUM(H71:S71) -> 442.9
A72: FY2026-27 | B72: Leap India | C72: =VLOOKUP(B72,Mapping!A:B,2,0) -> Lateral | D72: =VLOOKUP(B72,Mapping!A:C,3,0) -> West | E72: =VLOOKUP(B72,Mapping!A:D,4,0) -> West 1 | F72: =VLOOKUP(B72,Mapping!A:E,5,0) -> Anjli | G72: =VLOOKUP(B72,Mapping!A:F,6,0) -> Geetu | H72: 6.3666667 | I72: 6.3666667 | J72: 6.3666667 | K72: 6.8 | L72: 6.8 | M72: 6.8 | N72: 7.2166667 | O72: 7.2166667 | P72: 7.2166667 | Q72: 6.7 | R72: 6.7 | S72: 6.7 | T72: =SUM(H72:S72) -> 81.25
A73: FY2026-27 | B73: NeoSoft | C73: =VLOOKUP(B73,Mapping!A:B,2,0) -> Lateral | D73: =VLOOKUP(B73,Mapping!A:C,3,0) -> West | E73: =VLOOKUP(B73,Mapping!A:D,4,0) -> West 1 | F73: =VLOOKUP(B73,Mapping!A:E,5,0) -> Anjli | G73: =VLOOKUP(B73,Mapping!A:F,6,0) -> Archana | H73: 19 | I73: 19 | J73: 19 | K73: 36.5 | L73: 36.5 | M73: 36.5 | N73: 46.5 | O73: 46.5 | P73: 46.5 | Q73: 46.5 | R73: 46.5 | S73: 46.5 | T73: =SUM(H73:S73) -> 445.5
A74: FY2026-27 | B74: Siemens Healthnier | C74: =VLOOKUP(B74,Mapping!A:B,2,0) -> Lateral | D74: =VLOOKUP(B74,Mapping!A:C,3,0) -> South | E74: =VLOOKUP(B74,Mapping!A:D,4,0) -> South 2 | F74: =VLOOKUP(B74,Mapping!A:E,5,0) -> Sulabh | G74: =VLOOKUP(B74,Mapping!A:F,6,0) -> Lekhana | H74: 11.1936 | I74: 11.1936 | J74: 11.1936 | K74: 14.432 | L74: 14.432 | M74: 14.432 | N74: 14.432 | O74: 14.432 | P74: 14.432 | Q74: 14.432 | R74: 14.432 | S74: 14.432 | T74: =SUM(H74:S74) -> 163.4688
A75: FY2026-27 | B75: ABB | C75: =VLOOKUP(B75,Mapping!A:B,2,0) -> Lateral | D75: =VLOOKUP(B75,Mapping!A:C,3,0) -> South | E75: =VLOOKUP(B75,Mapping!A:D,4,0) -> South 2 | F75: =VLOOKUP(B75,Mapping!A:E,5,0) -> Sulabh | G75: =VLOOKUP(B75,Mapping!A:F,6,0) -> Satya | H75: 7 | I75: 7 | J75: 6 | K75: 7 | L75: 7 | M75: 6 | N75: 4 | O75: 4 | P75: 4 | Q75: 5 | R75: 5 | S75: 5 | T75: =SUM(H75:S75) -> 67
A76: FY2026-27 | B76: TCG Group | C76: =VLOOKUP(B76,Mapping!A:B,2,0) -> Lateral | D76: =VLOOKUP(B76,Mapping!A:C,3,0) -> West | E76: =VLOOKUP(B76,Mapping!A:D,4,0) -> West 1 | F76: =VLOOKUP(B76,Mapping!A:E,5,0) -> Anjli | G76: =VLOOKUP(B76,Mapping!A:F,6,0) -> Anjli | H76: 0 | I76: 0 | J76: 0 | K76: 0 | L76: 0 | M76: 0 | N76: 0 | O76: 0 | P76: 0 | Q76: 0 | R76: 0 | S76: 0 | T76: =SUM(H76:S76) -> 0
A77: FY2026-27 | B77: Proterial | C77: =VLOOKUP(B77,Mapping!A:B,2,0) -> #N/A | D77: =VLOOKUP(B77,Mapping!A:C,3,0) -> #N/A | E77: =VLOOKUP(B77,Mapping!A:D,4,0) -> #N/A | F77: =VLOOKUP(B77,Mapping!A:E,5,0) -> #N/A | G77: =VLOOKUP(B77,Mapping!A:F,6,0) -> #N/A | H77: 7.25 | I77: 7.25 | J77: 7.25 | K77: 8.3 | L77: 8.3 | M77: 8.3 | N77: 7.9 | O77: 7.9 | P77: 7.9 | Q77: 7.25 | R77: 7.25 | S77: 7.25 | T77: =SUM(H77:S77) -> 92.1
A78: FY2026-27 | B78: CG Power | C78: =VLOOKUP(B78,Mapping!A:B,2,0) -> Lateral | D78: =VLOOKUP(B78,Mapping!A:C,3,0) -> West | E78: =VLOOKUP(B78,Mapping!A:D,4,0) -> West 1 | F78: =VLOOKUP(B78,Mapping!A:E,5,0) -> Anjli | G78: =VLOOKUP(B78,Mapping!A:F,6,0) -> Anjli | H78: 9.67318 | I78: 11.29168 | J78: 39.54932 | K78: 40.30932 | L78: 41.06932 | M78: 49.24432 | N78: 54.95434 | O78: 40.72332 | P78: 53.83837 | Q78: 53.59937 | R78: 70.00341 | S78: 70.00341 | T78: =SUM(H78:S78) -> 534.25936
A79: FY2026-27 | B79: Exclusive | C79: Exclusive | D79: Exclusive | E79: Exclusive | F79: Amit Jain | G79: Naved | H79: 6.3891 | I79: 23.2754 | J79: 7 | K79: 7 | L79: 7 | M79: 10 | N79: 10 | O79: 15 | P79: 15 | Q79: 15 | R79: 15 | S79: 20 | T79: =SUM(H79:S79) -> 150.6645
A80: FY2026-27 | B80: Middle East | C80: Middle East | D80: Middle East | E80: Middle East | F80: Amit Jain | G80: Naved | H80: 4.165 | I80: 5.2479 | J80: 8 | K80: 16 | L80: 16 | M80: 32 | N80: 38 | O80: 38 | P80: 42 | Q80: 52 | R80: 44 | S80: 54 | T80: =SUM(H80:S80) -> 349.4129

Sheet Rev_Forecast
H1: =SUM(H3:H85) -> 907.53006 | I1: =SUM(I3:I85) -> 917.30935 | J1: =SUM(J3:J85) -> 1013.9392 | K1: =SUM(K3:K85) -> 905.79565 | L1: =SUM(L3:L85) -> 965.65565 | M1: =SUM(M3:M85) -> 1011.7807 | N1: =SUM(N3:N85) -> 988.59509 | O1: =SUM(O3:O85) -> 1015.8641 | ... T1: =SUM(T3:T85) -> 12190.971
A2: =Revenue_Budget!A2 -> FY | B2: =Revenue_Budget!B2 -> Project | C2: =Revenue_Budget!C2 -> Vertical | D2: =Revenue_Budget!D2 -> Region | E2: =Revenue_Budget!E2 -> Sub Region | F2: =Revenue_Budget!F2 -> Region Head | G2: =Revenue_Budget!G2 -> Practice Head | H2: =Revenue_Budget!H2 -> 46113 | ... S2: =Revenue_Budget!S2 -> 46447 | T2: Total
A3: FY2026-27 | B3: Honeywell | C3: =VLOOKUP(B3,Mapping!A:B,2,0) -> Lateral | D3: =VLOOKUP(B3,Mapping!A:C,3,0) -> South | E3: =VLOOKUP(B3,Mapping!A:D,4,0) -> South 1 | F3: =VLOOKUP(B3,Mapping!A:E,5,0) -> Bapi | G3: =VLOOKUP(B3,Mapping!A:F,6,0) -> Bapi | H3: 120 | I3: 167 | J3: 188 | K3: 108 | L3: 155 | M3: 177 | N3: 82 | O3: 116 | P3: 132 | Q3: 120 | R3: 168 | S3: 192 | T3: =SUM(H3:S3) -> 1725
A4: FY2026-27 | B4: Pfizer | C4: =VLOOKUP(B4,Mapping!A:B,2,0) -> Lateral | D4: =VLOOKUP(B4,Mapping!A:C,3,0) -> West | E4: =VLOOKUP(B4,Mapping!A:D,4,0) -> West 1 | F4: =VLOOKUP(B4,Mapping!A:E,5,0) -> Anjli | G4: =VLOOKUP(B4,Mapping!A:F,6,0) -> Usha | H4: 9.3010766 | I4: 8.4986 | J4: 5.5 | K4: 8 | L4: 8 | M4: 8 | N4: 5 | O4: 5 | P4: 5 | Q4: 5 | R4: 6 | S4: 6 | T4: =SUM(H4:S4) -> 79.299677
A5: FY2026-27 | B5: Tata Motors | C5: =VLOOKUP(B5,Mapping!A:B,2,0) -> Lateral | D5: =VLOOKUP(B5,Mapping!A:C,3,0) -> West | E5: =VLOOKUP(B5,Mapping!A:D,4,0) -> West 2 | F5: =VLOOKUP(B5,Mapping!A:E,5,0) -> Anjli | G5: =VLOOKUP(B5,Mapping!A:F,6,0) -> Shweta | H5: 0 | I5: 0 | J5: 0 | K5: 0 | L5: 0 | M5: 0 | N5: 0 | O5: 0 | P5: 0 | Q5: 0 | R5: 0 | S5: 0 | T5: =SUM(H5:S5) -> 0
A6: FY2026-27 | B6: SKF India | C6: =VLOOKUP(B6,Mapping!A:B,2,0) -> Lateral | D6: =VLOOKUP(B6,Mapping!A:C,3,0) -> North | E6: =VLOOKUP(B6,Mapping!A:D,4,0) -> North | F6: =VLOOKUP(B6,Mapping!A:E,5,0) -> Anjli | G6: =VLOOKUP(B6,Mapping!A:F,6,0) -> Archana | H6: 26.5 | I6: 17 | J6: 35.9 | K6: 18 | L6: 23 | M6: 22 | N6: 19 | O6: 20 | P6: 18 | Q6: 17 | R6: 15 | S6: 14 | T6: =SUM(H6:S6) -> 245.4
A7: FY2026-27 | B7: Siemens (Advatnta & GBS) | C7: Lateral | D7: South | E7: South 1 | F7: Manish Malhotra | G7: Kunal | H7: 6.1185 | I7: 6 | J7: 7 | K7: 6.3633333 | L7: 6.3633333 | M7: 6.3633333 | N7: 9.2 | O7: 10.7 | P7: 11.6 | Q7: 11.9 | R7: 11.9 | S7: 11.9 | T7: =SUM(H7:S7) -> 105.4085
A8: FY2026-27 | B8: Siemens Energy | C8: Lateral | D8: North | E8: North | F8: Anjli | G8: Archana | H8: 13.0525 | I8: 11.28 | J8: 11 | K8: 11.5 | L8: 12 | M8: 11 | N8: 10 | O8: 10 | P8: 10.6 | Q8: 11.6 | R8: 12.5 | S8: 12.5 | T8: =SUM(H8:S8) -> 137.0325
A9: FY2026-27 | B9: Pidilite | C9: =VLOOKUP(B9,Mapping!A:B,2,0) -> Lateral | D9: =VLOOKUP(B9,Mapping!A:C,3,0) -> West | E9: =VLOOKUP(B9,Mapping!A:D,4,0) -> West 1 | F9: =VLOOKUP(B9,Mapping!A:E,5,0) -> Anjli | G9: =VLOOKUP(B9,Mapping!A:F,6,0) -> Usha | H9: 6.83 | I9: 9.05 | J9: 8.75 | K9: 15.166667 | L9: 15.166667 | M9: 15.166667 | N9: 16 | O9: 16 | P9: 16 | Q9: 16.833333 | R9: 16.833333 | S9: 16.833333 | T9: =SUM(H9:S9) -> 168.63
A10: FY2026-27 | B10: Vertiv | C10: =VLOOKUP(B10,Mapping!A:B,2,0) -> Lateral | D10: =VLOOKUP(B10,Mapping!A:C,3,0) -> West | E10: =VLOOKUP(B10,Mapping!A:D,4,0) -> West 2 | F10: =VLOOKUP(B10,Mapping!A:E,5,0) -> Anjli | G10: =VLOOKUP(B10,Mapping!A:F,6,0) -> Shweta | H10: 2.72792 | I10: 3.2114332 | J10: 4.3313846 | K10: 4 | L10: 4 | M10: 4 | N10: 4.5 | O10: 4 | P10: 4.5 | Q10: 4.5 | R10: 4.5 | S10: 4 | T10: =SUM(H10:S10) -> 48.270738
A11: FY2026-27 | B11: Birla Paints | C11: =VLOOKUP(B11,Mapping!A:B,2,0) -> Lateral | D11: =VLOOKUP(B11,Mapping!A:C,3,0) -> West | E11: =VLOOKUP(B11,Mapping!A:D,4,0) -> West 1 | F11: =VLOOKUP(B11,Mapping!A:E,5,0) -> Anjli | G11: =VLOOKUP(B11,Mapping!A:F,6,0) -> Geetu | H11: 12.79 | I11: 13.3 | J11: 13.3 | K11: 15.733333 | L11: 15.733333 | M11: 15.733333 | N11: 16.6 | O11: 16.6 | P11: 16.6 | Q11: 15.533333 | R11: 15.533333 | S11: 15.533333 | T11: =SUM(H11:S11) -> 182.99
A12: FY2026-27 | B12: Ingram Micro | C12: =VLOOKUP(B12,Mapping!A:B,2,0) -> Lateral | D12: =VLOOKUP(B12,Mapping!A:C,3,0) -> West | E12: =VLOOKUP(B12,Mapping!A:D,4,0) -> West 1 | F12: =VLOOKUP(B12,Mapping!A:E,5,0) -> Anjli | G12: =VLOOKUP(B12,Mapping!A:F,6,0) -> Geetu | H12: 0 | I12: 0 | J12: 0 | K12: 0 | L12: 0 | M12: 0 | N12: 0 | O12: 0 | P12: 0 | Q12: 0 | R12: 0 | S12: 0 | T12: =SUM(H12:S12) -> 0
A13: FY2026-27 | B13: HPE | C13: =VLOOKUP(B13,Mapping!A:B,2,0) -> Lateral | D13: =VLOOKUP(B13,Mapping!A:C,3,0) -> South | E13: =VLOOKUP(B13,Mapping!A:D,4,0) -> South 1 | F13: =VLOOKUP(B13,Mapping!A:E,5,0) -> Mahak | G13: =VLOOKUP(B13,Mapping!A:F,6,0) -> Mahak | H13: 181.56918 | I13: 115.71541 | J13: 115.71541 | K13: 112.66667 | L13: 112.66667 | M13: 112.66667 | N13: 113.19042 | O13: 113.19042 | P13: 103.19042 | Q13: 134.00159 | R13: 134.00159 | S13: 124.00159 | T13: =SUM(H13:S13) -> 1472.576
A14: FY2026-27 | B14: Isuzu | C14: =VLOOKUP(B14,Mapping!A:B,2,0) -> Lateral | D14: =VLOOKUP(B14,Mapping!A:C,3,0) -> South | E14: =VLOOKUP(B14,Mapping!A:D,4,0) -> South 1 | F14: =VLOOKUP(B14,Mapping!A:E,5,0) -> Anjli | G14: =VLOOKUP(B14,Mapping!A:F,6,0) -> Satya | H14: 3.785 | I14: 5 | J14: 6 | K14: 5 | L14: 5 | M14: 5 | N14: 6 | O14: 7 | P14: 7 | Q14: 8 | R14: 7 | S14: 8 | T14: =SUM(H14:S14) -> 72.785
A15: FY2026-27 | B15: Mahindra Holidays | C15: =VLOOKUP(B15,Mapping!A:B,2,0) -> Lateral | D15: =VLOOKUP(B15,Mapping!A:C,3,0) -> West | E15: =VLOOKUP(B15,Mapping!A:D,4,0) -> West 1 | F15: =VLOOKUP(B15,Mapping!A:E,5,0) -> Anjli | G15: =VLOOKUP(B15,Mapping!A:F,6,0) -> Geetu | H15: 0.9 | I15: 0 | J15: 0 | K15: 0 | L15: 0 | M15: 0 | N15: 0 | O15: 0 | P15: 0 | Q15: 0 | R15: 0 | S15: 0 | T15: =SUM(H15:S15) -> 0.9
A16: FY2026-27 | B16: BITS | C16: =VLOOKUP(B16,Mapping!A:B,2,0) -> Lateral | D16: =VLOOKUP(B16,Mapping!A:C,3,0) -> South | E16: =VLOOKUP(B16,Mapping!A:D,4,0) -> South 2 | F16: =VLOOKUP(B16,Mapping!A:E,5,0) -> Sulabh | G16: =VLOOKUP(B16,Mapping!A:F,6,0) -> Krishna | H16: 4.59169 | I16: 4 | J16: 5 | K16: 1.3333333 | L16: 1.3333333 | M16: 1.3333333 | N16: 4 | O16: 4 | P16: 3 | Q16: 3 | R16: 4 | S16: 5 | T16: =SUM(H16:S16) -> 40.59169
A17: FY2026-27 | B17: M&M | C17: =VLOOKUP(B17,Mapping!A:B,2,0) -> Lateral | D17: =VLOOKUP(B17,Mapping!A:C,3,0) -> West | E17: =VLOOKUP(B17,Mapping!A:D,4,0) -> West 1 | F17: =VLOOKUP(B17,Mapping!A:E,5,0) -> Anjli | G17: =VLOOKUP(B17,Mapping!A:F,6,0) -> Dhriti | H17: 119.60778 | I17: 121 | J17: 140 | K17: 110 | L17: 110 | M17: 110 | N17: 120 | O17: 120 | P17: 120 | Q17: 130 | R17: 130 | S17: 130 | T17: =SUM(H17:S17) -> 1460.6078
A18: FY2026-27 | B18: P&G | C18: =VLOOKUP(B18,Mapping!A:B,2,0) -> Lateral | D18: =VLOOKUP(B18,Mapping!A:C,3,0) -> South | E18: =VLOOKUP(B18,Mapping!A:D,4,0) -> South 2 | F18: =VLOOKUP(B18,Mapping!A:E,5,0) -> Sulabh | G18: =VLOOKUP(B18,Mapping!A:F,6,0) -> Krishna | H18: 0 | I18: 0 | J18: 0 | K18: 0 | L18: 0 | M18: 0 | N18: 0 | O18: 0 | P18: 0 | Q18: 0 | R18: 0 | S18: 0 | T18: =SUM(H18:S18) -> 0
A19: FY2026-27 | B19: Wipro | C19: =VLOOKUP(B19,Mapping!A:B,2,0) -> Lateral | D19: =VLOOKUP(B19,Mapping!A:C,3,0) -> South | E19: =VLOOKUP(B19,Mapping!A:D,4,0) -> South 1 | F19: =VLOOKUP(B19,Mapping!A:E,5,0) -> Sulabh | G19: =VLOOKUP(B19,Mapping!A:F,6,0) -> Subu | H19: 39.9875 | I19: 23 | J19: 23 | K19: 23 | L19: 23 | M19: 23 | N19: 40 | O19: 30 | P19: 30 | Q19: 60 | R19: 60 | S19: 30 | T19: =SUM(H19:S19) -> 404.9875
A20: FY2026-27 | B20: Tata Marcopolo | C20: =VLOOKUP(B20,Mapping!A:B,2,0) -> Lateral | D20: =VLOOKUP(B20,Mapping!A:C,3,0) -> West | E20: =VLOOKUP(B20,Mapping!A:D,4,0) -> West 2 | F20: =VLOOKUP(B20,Mapping!A:E,5,0) -> Anjli | G20: =VLOOKUP(B20,Mapping!A:F,6,0) -> Anjli | H20: 0 | I20: 0 | J20: 0 | K20: 0 | L20: 0 | M20: 0 | N20: 0 | O20: 0 | P20: 0 | Q20: 0 | R20: 0 | S20: 0 | T20: =SUM(H20:S20) -> 0
... A43: FY2026-27 | B43: M2P Fintech | C43: =VLOOKUP(B43,Mapping!A:B,2,0) -> Lateral | D43: =VLOOKUP(B43,Mapping!A:C,3,0) -> South | E43: =VLOOKUP(B43,Mapping!A:D,4,0) -> South 2 | F43: =VLOOKUP(B43,Mapping!A:E,5,0) -> Sulabh | G43: =VLOOKUP(B43,Mapping!A:F,6,0) -> Krishna | H43: 0 | I43: 0 | J43: 0 | K43: 0 | L43: 0 | M43: 0 | N43: 0 | O43: 0 | P43: 0 | Q43: 0 | R43: 0 | S43: 0 | T43: =SUM(H43:S43) -> 0
A44: FY2026-27 | B44: Tata Power | C44: =VLOOKUP(B44,Mapping!A:B,2,0) -> Lateral | D44: =VLOOKUP(B44,Mapping!A:C,3,0) -> West | E44: =VLOOKUP(B44,Mapping!A:D,4,0) -> West 1 | F44: =VLOOKUP(B44,Mapping!A:E,5,0) -> Anjli | G44: =VLOOKUP(B44,Mapping!A:F,6,0) -> Elton | H44: 1.75 | I44: 1.75 | J44: 1.75 | K44: =5.1/3 -> 1.7 | L44: =5.1/3 -> 1.7 | M44: =5.1/3 -> 1.7 | N44: 0 | O44: 0 | P44: 0 | Q44: 0 | R44: 0 | S44: 0 | T44: =SUM(H44:S44) -> 10.35
A45: FY2026-27 | B45: ThyssenKrupp | C45: =VLOOKUP(B45,Mapping!A:B,2,0) -> Lateral | D45: =VLOOKUP(B45,Mapping!A:C,3,0) -> West | E45: =VLOOKUP(B45,Mapping!A:D,4,0) -> West 2 | F45: =VLOOKUP(B45,Mapping!A:E,5,0) -> Anjli | G45: =VLOOKUP(B45,Mapping!A:F,6,0) -> Shweta | H45: 0 | I45: 0 | J45: 0 | K45: 0 | L45: 0 | M45: 0 | N45: 0 | O45: 0 | P45: 0 | Q45: 0 | R45: 0 | S45: 0 | T45: =SUM(H45:S45) -> 0
A46: FY2026-27 | B46: Fedex | C46: =VLOOKUP(B46,Mapping!A:B,2,0) -> Lateral | D46: =VLOOKUP(B46,Mapping!A:C,3,0) -> West | E46: =VLOOKUP(B46,Mapping!A:D,4,0) -> West 1 | F46: =VLOOKUP(B46,Mapping!A:E,5,0) -> Anjli | G46: =VLOOKUP(B46,Mapping!A:F,6,0) -> Elton | H46: 0 | I46: 0 | J46: 0 | K46: 0 | L46: 0 | M46: 0 | N46: 0 | O46: 0 | P46: 0 | Q46: 0 | R46: 0 | S46: 0 | T46: =SUM(H46:S46) -> 0
A47: FY2026-27 | B47: Titan | C47: =VLOOKUP(B47,Mapping!A:B,2,0) -> Lateral | D47: =VLOOKUP(B47,Mapping!A:C,3,0) -> South | E47: =VLOOKUP(B47,Mapping!A:D,4,0) -> South 2 | F47: =VLOOKUP(B47,Mapping!A:E,5,0) -> Sulabh | G47: =VLOOKUP(B47,Mapping!A:F,6,0) -> Subu | H47: 0 | I47: 0 | J47: 0 | K47: 0 | L47: 0 | M47: 0 | N47: 0 | O47: 0 | P47: 0 | Q47: 0 | R47: 0 | S47: 0 | T47: =SUM(H47:S47) -> 0
A48: FY2026-27 | B48: Ultratech | C48: =VLOOKUP(B48,Mapping!A:B,2,0) -> Lateral | D48: =VLOOKUP(B48,Mapping!A:C,3,0) -> West | E48: =VLOOKUP(B48,Mapping!A:D,4,0) -> West 1 | F48: =VLOOKUP(B48,Mapping!A:E,5,0) -> Anjli | G48: =VLOOKUP(B48,Mapping!A:F,6,0) -> Elton | H48: 0 | I48: 0 | J48: 0 | K48: 0 | L48: 0 | M48: 0 | N48: 0 | O48: 0 | P48: 0 | Q48: 0 | R48: 0 | S48: 0 | T48: =SUM(H48:S48) -> 0
A49: FY2026-27 | B49: L&T (New) | C49: =VLOOKUP(B49,Mapping!A:B,2,0) -> Lateral | D49: =VLOOKUP(B49,Mapping!A:C,3,0) -> South | E49: =VLOOKUP(B49,Mapping!A:D,4,0) -> South 2 | F49: =VLOOKUP(B49,Mapping!A:E,5,0) -> Sulabh | G49: =VLOOKUP(B49,Mapping!A:F,6,0) -> Sulabh | H49: 0 | I49: 0 | J49: 0 | K49: 0 | L49: 0 | M49: 0 | N49: 0 | O49: 0 | P49: 0 | Q49: 0 | R49: 0 | S49: 0 | T49: =SUM(H49:S49) -> 0
A50: FY2026-27 | B50: DRL | C50: =VLOOKUP(B50,Mapping!A:B,2,0) -> Lateral | D50: =VLOOKUP(B50,Mapping!A:C,3,0) -> South | E50: =VLOOKUP(B50,Mapping!A:D,4,0) -> South 2 | F50: =VLOOKUP(B50,Mapping!A:E,5,0) -> Sulabh | G50: =VLOOKUP(B50,Mapping!A:F,6,0) -> Sulabh | H50: 0 | I50: 0 | J50: 0 | K50: 0 | L50: 0 | M50: 0 | N50: 0 | O50: 0 | P50: 0 | Q50: 0 | R50: 0 | S50: 0 | T50: =SUM(H50:S50) -> 0
A51: FY2026-27 | B51: Robert Bosch | C51: =VLOOKUP(B51,Mapping!A:B,2,0) -> Lateral | D51: =VLOOKUP(B51,Mapping!A:C,3,0) -> South | E51: =VLOOKUP(B51,Mapping!A:D,4,0) -> South 2 | F51: =VLOOKUP(B51,Mapping!A:E,5,0) -> Sulabh | G51: =VLOOKUP(B51,Mapping!A:F,6,0) -> Abhilash | H51: 0 | I51: 0 | J51: 0 | K51: 0 | L51: 0 | M51: 0 | N51: 0 | O51: 0 | P51: 0 | Q51: 0 | R51: 0 | S51: 0 | T51: =SUM(H51:S51) -> 0
A52: FY2026-27 | B52: Tata Teleservices | C52: =VLOOKUP(B52,Mapping!A:B,2,0) -> Lateral | D52: =VLOOKUP(B52,Mapping!A:C,3,0) -> West | E52: =VLOOKUP(B52,Mapping!A:D,4,0) -> West 1 | F52: =VLOOKUP(B52,Mapping!A:E,5,0) -> Anjli | G52: =VLOOKUP(B52,Mapping!A:F,6,0) -> Elton | H52: 0 | I52: 0 | J52: 0 | K52: 0 | L52: 0 | M52: 0 | N52: 0 | O52: 0 | P52: 0 | Q52: 0 | R52: 0 | S52: 0 | T52: =SUM(H52:S52) -> 0
A53: FY2026-27 | B53: Honeywell Leadership | C53: =VLOOKUP(B53,Mapping!A:B,2,0) -> Leadership | D53: =VLOOKUP(B53,Mapping!A:C,3,0) -> South | E53: =VLOOKUP(B53,Mapping!A:D,4,0) -> South 1 | F53: =VLOOKUP(B53,Mapping!A:E,5,0) -> Bapi | G53: =VLOOKUP(B53,Mapping!A:F,6,0) -> Parul | H53: 2.2562 | I53: 6.6 | J53: 1.02 | K53: 1 | L53: 2 | M53: 2 | N53: 1 | O53: 2 | P53: 2 | Q53: 1 | R53: 2 | S53: 2 | T53: =SUM(H53:S53) -> 24.8762
A54: FY2026-27 | B54: Siemens Leadership | C54: =VLOOKUP(B54,Mapping!A:B,2,0) -> Leadership | D54: =VLOOKUP(B54,Mapping!A:C,3,0) -> South | E54: =VLOOKUP(B54,Mapping!A:D,4,0) -> South 2 | F54: =VLOOKUP(B54,Mapping!A:E,5,0) -> Sulabh | G54: =VLOOKUP(B54,Mapping!A:F,6,0) -> Parul | H54: 0 | I54: 0 | J54: 0 | K54: 0 | L54: 0 | M54: 0 | N54: 0 | O54: 0 | P54: 0 | Q54: 0 | R54: 0 | S54: 0 | T54: =SUM(H54:S54) -> 0
A55: FY2026-27 | B55: Vertiv Leadership | C55: =VLOOKUP(B55,Mapping!A:B,2,0) -> Leadership | D55: =VLOOKUP(B55,Mapping!A:C,3,0) -> West | E55: =VLOOKUP(B55,Mapping!A:D,4,0) -> West 2 | F55: =VLOOKUP(B55,Mapping!A:E,5,0) -> Anjli | G55: =VLOOKUP(B55,Mapping!A:F,6,0) -> Parul | H55: 1 | I55: 0 | J55: 5 | K55: 1 | L55: 2 | M55: 3 | N55: 1 | O55: 5 | P55: 3 | Q55: 1 | R55: 3 | S55: 3 | T55: =SUM(H55:S55) -> 28
A56: FY2026-27 | B56: M&M Leadership | C56: =VLOOKUP(B56,Mapping!A:B,2,0) -> Leadership | D56: =VLOOKUP(B56,Mapping!A:C,3,0) -> West | E56: =VLOOKUP(B56,Mapping!A:D,4,0) -> West 1 | F56: =VLOOKUP(B56,Mapping!A:E,5,0) -> Anjli | G56: =VLOOKUP(B56,Mapping!A:F,6,0) -> Parul | H56: 6.1910835 | I56: 24.3 | J56: 45 | K56: 20 | L56: 20 | M56: 30 | N56: 20 | O56: 10 | P56: 10 | Q56: 20 | R56: 20 | S56: 30 | T56: =SUM(H56:S56) -> 255.49108
... A67: FY2026-27 | B67: Optum | C67: =VLOOKUP(B67,Mapping!A:B,2,0) -> Lateral | D67: =VLOOKUP(B67,Mapping!A:C,3,0) -> South | E67: =VLOOKUP(B67,Mapping!A:D,4,0) -> South 1 | F67: =VLOOKUP(B67,Mapping!A:E,5,0) -> Ashish | G67: =VLOOKUP(B67,Mapping!A:F,6,0) -> Ashish | H67: 65.4 | I67: 45.8 | J67: 45.8 | K67: 45.833333 | L67: 45.833333 | M67: 45.833333 | N67: 45.833333 | O67: 45.833333 | P67: 45.833333 | Q67: 45.833333 | R67: 45.833333 | S67: 45.833333 | T67: =SUM(H67:S67) -> 569.5
A68: FY2026-27 | B68: New Sales + Mining | C68: =VLOOKUP(B68,Mapping!A:B,2,0) -> Lateral | D68: =VLOOKUP(B68,Mapping!A:C,3,0) -> New Sales | E68: =VLOOKUP(B68,Mapping!A:D,4,0) -> New Sales | F68: =VLOOKUP(B68,Mapping!A:E,5,0) -> Nizar | G68: =VLOOKUP(B68,Mapping!A:F,6,0) -> Nizar | I68: 0 | J68: 0 | K68: 0 | L68: 0 | M68: 0 | N68: 0 | O68: 0 | P68: 0 | Q68: 0 | R68: 0 | S68: 0 | T68: =SUM(H68:S68) -> 0
A69: FY2026-27 | B69: Pernod Ricard | C69: =VLOOKUP(B69,Mapping!A:B,2,0) -> Lateral | D69: =VLOOKUP(B69,Mapping!A:C,3,0) -> North | E69: =VLOOKUP(B69,Mapping!A:D,4,0) -> North | F69: =VLOOKUP(B69,Mapping!A:E,5,0) -> Anjli | G69: =VLOOKUP(B69,Mapping!A:F,6,0) -> Archana | H69: 10.17 | I69: 10.19 | J69: 9.75 | K69: 9.5 | L69: 9.5 | M69: 9.5 | N69: 11 | O69: 11 | P69: 11 | Q69: 5 | R69: 5 | S69: 5 | T69: =SUM(H69:S69) -> 106.61
A70: FY2026-27 | B70: UniCharm | C70: =VLOOKUP(B70,Mapping!A:B,2,0) -> Lateral | D70: =VLOOKUP(B70,Mapping!A:C,3,0) -> North | E70: =VLOOKUP(B70,Mapping!A:D,4,0) -> North | F70: =VLOOKUP(B70,Mapping!A:E,5,0) -> Anjli | G70: =VLOOKUP(B70,Mapping!A:F,6,0) -> Archana | H70: 6.5951 | I70: 4.1 | J70: 4 | K70: 4 | L70: 4 | M70: 4 | N70: 4 | O70: 4 | P70: 4 | Q70: 4 | R70: 4 | S70: 4 | T70: =SUM(H70:S70) -> 50.6951
A71: FY2026-27 | B71: Saint Gobain | C71: =VLOOKUP(B71,Mapping!A:B,2,0) -> #N/A | D71: =VLOOKUP(B71,Mapping!A:C,3,0) -> #N/A | E71: =VLOOKUP(B71,Mapping!A:D,4,0) -> #N/A | F71: =VLOOKUP(B71,Mapping!A:E,5,0) -> #N/A | G71: =VLOOKUP(B71,Mapping!A:F,6,0) -> #N/A | H71: 17 | I71: 25 | J71: 30 | K71: 37.38 | L71: 37.38 | M71: 40.93 | N71: 40.93 | O71: 40.93 | P71: 40.93 | Q71: 40.93 | R71: 40.93 | S71: 40.93 | T71: =SUM(H71:S71) -> 433.27
A72: FY2026-27 | B72: Leap India | C72: =VLOOKUP(B72,Mapping!A:B,2,0) -> Lateral | D72: =VLOOKUP(B72,Mapping!A:C,3,0) -> West | E72: =VLOOKUP(B72,Mapping!A:D,4,0) -> West 1 | F72: =VLOOKUP(B72,Mapping!A:E,5,0) -> Anjli | G72: =VLOOKUP(B72,Mapping!A:F,6,0) -> Geetu | H72: 10.65 | I72: 8.56 | J72: 5.1 | K72: 7.1333333 | L72: 7.1333333 | M72: 7.1333333 | N72: 7.2166667 | O72: 7.2166667 | P72: 7.2166667 | Q72: 6.7 | R72: 6.7 | S72: 6.7 | T72: =SUM(H72:S72) -> 87.46
...

Sheet Revenue_Actual
A1: =Revenue_Budget!A2 -> FY | B1: =Revenue_Budget!B2 -> Project | C1: =Revenue_Budget!C2 -> Vertical | D1: =Revenue_Budget!D2 -> Region | E1: =Revenue_Budget!E2 -> Sub Region | F1: =Revenue_Budget!F2 -> Region Head | G1: =Revenue_Budget!G2 -> Practice Head | H1: =Revenue_Budget!H2 -> 46113 | ... S1: =Revenue_Budget!S2 -> 46447 | T1: FY'26 Total
A2: FY2026-27 | B2: Honeywell | C2: =VLOOKUP(B2,Mapping!A:B,2,0) -> Lateral | D2: =VLOOKUP(B2,Mapping!A:C,3,0) -> South | E2: =VLOOKUP(B2,Mapping!A:D,4,0) -> South 1 | F2: =VLOOKUP(B2,Mapping!A:E,5,0) -> Bapi | G2: =VLOOKUP(B2,Mapping!A:F,6,0) -> Bapi | H2: 120 | I2: 167 | J2: 188 | K2: 108 | L2: 155 | M2: 177 | N2: 82 | O2: 116 | P2: 132 | Q2: 120 | R2: 168 | S2: 192 | T2: =SUM(H2:S2) -> 1725
A3: FY2026-27 | B3: Pfizer | C3: =VLOOKUP(B3,Mapping!A:B,2,0) -> Lateral | D3: =VLOOKUP(B3,Mapping!A:C,3,0) -> West | E3: =VLOOKUP(B3,Mapping!A:D,4,0) -> West 1 | F3: =VLOOKUP(B3,Mapping!A:E,5,0) -> Anjli | G3: =VLOOKUP(B3,Mapping!A:F,6,0) -> Usha | H3: 9.3010766 | I3: 8.4986 | J3: 5.5 | K3: 8 | L3: 8 | M3: 8 | N3: 5 | O3: 5 | P3: 5 | Q3: 5 | R3: 6 | S3: 6 | T3: =SUM(H3:S3) -> 79.299677
A4: FY2026-27 | B4: Tata Motors | C4: =VLOOKUP(B4,Mapping!A:B,2,0) -> Lateral | D4: =VLOOKUP(B4,Mapping!A:C,3,0) -> West | E4: =VLOOKUP(B4,Mapping!A:D,4,0) -> West 2 | F4: =VLOOKUP(B4,Mapping!A:E,5,0) -> Anjli | G4: =VLOOKUP(B4,Mapping!A:F,6,0) -> Shweta | H4: 0 | I4: 0 | J4: 0 | K4: 0 | L4: 0 | M4: 0 | N4: 0 | O4: 0 | P4: 0 | Q4: 0 | R4: 0 | S4: 0 | T4: =SUM(H4:S4) -> 0
A5: FY2026-27 | B5: SKF India | C5: =VLOOKUP(B5,Mapping!A:B,2,0) -> Lateral | D5: =VLOOKUP(B5,Mapping!A:C,3,0) -> North | E5: =VLOOKUP(B5,Mapping!A:D,4,0) -> North | F5: =VLOOKUP(B5,Mapping!A:E,5,0) -> Anjli | G5: =VLOOKUP(B5,Mapping!A:F,6,0) -> Archana | H5: 26.5 | I5: 17 | J5: 35.9 | K5: 18 | L5: 23 | M5: 22 | N5: 19 | O5: 20 | P5: 18 | Q5: 17 | R5: 15 | S5: 14 | T5: =SUM(H5:S5) -> 245.4
A6: FY2026-27 | B6: Siemens (Advatnta & GBS) | C6: Lateral | D6: South | E6: South 1 | F6: Manish Malhotra | G6: Kunal | H6: 6.1185 | I6: 6 | J6: 7 | K6: 6.3633333 | L6: 6.3633333 | M6: 6.3633333 | N6: 9.2 | O6: 10.7 | P6: 11.6 | Q6: 11.9 | R6: 11.9 | S6: 11.9 | T6: =SUM(H6:S6) -> 105.4085
A7: FY2026-27 | B7: Siemens Energy | C7: Lateral | D7: North | E7: North | F7: Anjli | G7: Archana | H7: 13.0525 | I7: 11.28 | J7: 11 | K7: 11.5 | L7: 12 | M7: 11 | N7: 10 | O7: 10 | P7: 10.6 | Q7: 11.6 | R7: 12.5 | S7: 12.5 | T7: =SUM(H7:S7) -> 137.0325
A8: FY2026-27 | B8: Pidilite | C8: =VLOOKUP(B8,Mapping!A:B,2,0) -> Lateral | D8: =VLOOKUP(B8,Mapping!A:C,3,0) -> West | E8: =VLOOKUP(B8,Mapping!A:D,4,0) -> West 1 | F8: =VLOOKUP(B8,Mapping!A:E,5,0) -> Anjli | G8: =VLOOKUP(B8,Mapping!A:F,6,0) -> Usha | H8: 6.83 | I8: 9.05 | J8: 8.75 | K8: 15.166667 | L8: 15.166667 | M8: 15.166667 | N8: 16 | O8: 16 | P8: 16 | Q8: 16.833333 | R8: 16.833333 | S8: 16.833333 | T8: =SUM(H8:S8) -> 168.63
A9: FY2026-27 | B9: Vertiv | C9: =VLOOKUP(B9,Mapping!A:B,2,0) -> Lateral | D9: =VLOOKUP(B9,Mapping!A:C,3,0) -> West | E9: =VLOOKUP(B9,Mapping!A:D,4,0) -> West 2 | F9: =VLOOKUP(B9,Mapping!A:E,5,0) -> Anjli | G9: =VLOOKUP(B9,Mapping!A:F,6,0) -> Shweta | H9: 2.72792 | I9: 3.2114332 | J9: 4.3313846 | K9: 4 | L9: 4 | M9: 4 | N9: 4.5 | O9: 4 | P9: 4.5 | Q9: 4.5 | R9: 4.5 | S9: 4 | T9: =SUM(H9:S9) -> 48.270738
A10: FY2026-27 | B10: Birla Paints | C10: =VLOOKUP(B10,Mapping!A:B,2,0) -> Lateral | D10: =VLOOKUP(B10,Mapping!A:C,3,0) -> West | E10: =VLOOKUP(B10,Mapping!A:D,4,0) -> West 1 | F10: =VLOOKUP(B10,Mapping!A:E,5,0) -> Anjli | G10: =VLOOKUP(B10,Mapping!A:F,6,0) -> Geetu | H10: 12.79 | I10: 13.3 | J10: 13.3 | K10: 15.733333 | L10: 15.733333 | M10: 15.733333 | N10: 16.6 | O10: 16.6 | P10: 16.6 | Q10: 15.533333 | R10: 15.533333 | S10: 15.533333 | T10: =SUM(H10:S10) -> 182.99
A11: FY2026-27 | B11: Ingram Micro | C11: =VLOOKUP(B11,Mapping!A:B,2,0) -> Lateral | D11: =VLOOKUP(B11,Mapping!A:C,3,0) -> West | E11: =VLOOKUP(B11,Mapping!A:D,4,0) -> West 1 | F11: =VLOOKUP(B11,Mapping!A:E,5,0) -> Anjli | G11: =VLOOKUP(B11,Mapping!A:F,6,0) -> Geetu | H11: 0 | I11: 0 | J11: 0 | K11: 0 | L11: 0 | M11: 0 | N11: 0 | O11: 0 | P11: 0 | Q11: 0 | R11: 0 | S11: 0 | T11: =SUM(H11:S11) -> 0
A12: FY2026-27 | B12: HPE | C12: =VLOOKUP(B12,Mapping!A:B,2,0) -> Lateral | D12: =VLOOKUP(B12,Mapping!A:C,3,0) -> South | E12: =VLOOKUP(B12,Mapping!A:D,4,0) -> South 1 | F12: =VLOOKUP(B12,Mapping!A:E,5,0) -> Mahak | G12: =VLOOKUP(B12,Mapping!A:F,6,0) -> Mahak | H12: 181.56918 | I12: 115.71541 | J12: 115.71541 | K12: 112.66667 | L12: 112.66667 | M12: 112.66667 | N12: 113.19042 | O12: 113.19042 | P12: 103.19042 | Q12: 134.00159 | R12: 134.00159 | S12: 124.00159 | T12: =SUM(H12:S12) -> 1472.576
A13: FY2026-27 | B13: Isuzu | C13: =VLOOKUP(B13,Mapping!A:B,2,0) -> Lateral | D13: =VLOOKUP(B13,Mapping!A:C,3,0) -> South | E13: =VLOOKUP(B13,Mapping!A:D,4,0) -> South 1 | F13: =VLOOKUP(B13,Mapping!A:E,5,0) -> Anjli | G13: =VLOOKUP(B13,Mapping!A:F,6,0) -> Satya | H13: 3.785 | I13: 5 | J13: 6 | K13: 5 | L13: 5 | M13: 5 | N13: 6 | O13: 7 | P13: 7 | Q13: 8 | R13: 7 | S13: 8 | T13: =SUM(H13:S13) -> 72.785
A14: FY2026-27 | B14: Mahindra Holidays | C14: =VLOOKUP(B14,Mapping!A:B,2,0) -> Lateral | D14: =VLOOKUP(B14,Mapping!A:C,3,0) -> West | E14: =VLOOKUP(B14,Mapping!A:D,4,0) -> West 1 | F14: =VLOOKUP(B14,Mapping!A:E,5,0) -> Anjli | G14: =VLOOKUP(B14,Mapping!A:F,6,0) -> Geetu | H14: 0.9 | I14: 0 | J14: 0 | K14: 0 | L14: 0 | M14: 0 | N14: 0 | O14: 0 | P14: 0 | Q14: 0 | R14: 0 | S14: 0 | T14: =SUM(H14:S14) -> 0.9
A15: FY2026-27 | B15: BITS | C15: =VLOOKUP(B15,Mapping!A:B,2,0) -> Lateral | D15: =VLOOKUP(B15,Mapping!A:C,3,0) -> South | E15: =VLOOKUP(B15,Mapping!A:D,4,0) -> South 2 | F15: =VLOOKUP(B15,Mapping!A:E,5,0) -> Sulabh | G15: =VLOOKUP(B15,Mapping!A:F,6,0) -> Krishna | H15: 4.59169 | I15: 4 | J15: 5 | K15: 1.3333333 | L15: 1.3333333 | M15: 1.3333333 | N15: 4 | O15: 4 | P15: 3 | Q15: 3 | R15: 4 | S15: 5 | T15: =SUM(H15:S15) -> 40.59169
A16: FY2026-27 | B16: M&M | C16: =VLOOKUP(B16,Mapping!A:B,2,0) -> Lateral | D16: =VLOOKUP(B16,Mapping!A:C,3,0) -> West | E16: =VLOOKUP(B16,Mapping!A:D,4,0) -> West 1 | F16: =VLOOKUP(B16,Mapping!A:E,5,0) -> Anjli | G16: =VLOOKUP(B16,Mapping!A:F,6,0) -> Dhriti | H16: 119.60778 | I16: 121 | J16: 140 | K16: 110 | L16: 110 | M16: 110 | N16: 120 | O16: 120 | P16: 120 | Q16: 130 | R16: 130 | S16: 130 | T16: =SUM(H16:S16) -> 1460.6078
A17: FY2026-27 | B17: P&G | C17: =VLOOKUP(B17,Mapping!A:B,2,0) -> Lateral | D17: =VLOOKUP(B17,Mapping!A:C,3,0) -> South | E17: =VLOOKUP(B17,Mapping!A:D,4,0) -> South 2 | F17: =VLOOKUP(B17,Mapping!A:E,5,0) -> Sulabh | G17: =VLOOKUP(B17,Mapping!A:F,6,0) -> Krishna | H17: 0 | I17: 0 | J17: 0 | K17: 0 | L17: 0 | M17: 0 | N17: 0 | O17: 0 | P17: 0 | Q17: 0 | R17: 0 | S17: 0 | T17: =SUM(H17:S17) -> 0
A18: FY2026-27 | B18: Wipro | C18: =VLOOKUP(B18,Mapping!A:B,2,0) -> Lateral | D18: =VLOOKUP(B18,Mapping!A:C,3,0) -> South | E18: =VLOOKUP(B18,Mapping!A:D,4,0) -> South 1 | F18: =VLOOKUP(B18,Mapping!A:E,5,0) -> Sulabh | G18: =VLOOKUP(B18,Mapping!A:F,6,0) -> Subu | H18: 39.9875 | I18: 23 | J18: 23 | K18: 23 | L18: 23 | M18: 23 | N18: 40 | O18: 30 | P18: 30 | Q18: 60 | R18: 60 | S18: 30 | T18: =SUM(H18:S18) -> 404.9875
A19: FY2026-27 | B19: Tata Marcopolo | C19: =VLOOKUP(B19,Mapping!A:B,2,0) -> Lateral | D19: =VLOOKUP(B19,Mapping!A:C,3,0) -> West | E19: =VLOOKUP(B19,Mapping!A:D,4,0) -> West 2 | F19: =VLOOKUP(B19,Mapping!A:E,5,0) -> Anjli | G19: =VLOOKUP(B19,Mapping!A:F,6,0) -> Anjli | H19: 0 | I19: 0 | J19: 0 | K19: 0 | L19: 0 | M19: 0 | N19: 0 | O19: 0 | P19: 0 | Q19: 0 | R19: 0 | S19: 0 | T19: =SUM(H19:S19) -> 0
... A77: FY2026-27 | B77: CG Power | C77: =VLOOKUP(B77,Mapping!A:B,2,0) -> Lateral | D77: =VLOOKUP(B77,Mapping!A:C,3,0) -> West | E77: =VLOOKUP(B77,Mapping!A:D,4,0) -> West 1 | F77: =VLOOKUP(B77,Mapping!A:E,5,0) -> Anjli | G77: =VLOOKUP(B77,Mapping!A:F,6,0) -> Anjli | H77: 9 | I77: 12.5 | J77: 11 | K77: 40.30932 | L77: 41.06932 | M77: 49.24432 | N77: 54.95434 | O77: 40.72332 | P77: 53.83837 | Q77: 53.59937 | R77: 70.00341 | S77: 70.00341 | T77: =SUM(H77:S77) -> 506.24518
A78: FY2026-27 | B78: Exclusive | C78: Exclusive | D78: Exclusive | E78: Exclusive | F78: Amit Jain | G78: Naved | H78: 2.94106 | I78: 0.83 | J78: 0 | K78: 2.1666667 | L78: 2.1666667 | M78: 2.1666667 | N78: 10 | O78: 15 | P78: 15 | Q78: 15 | R78: 15 | S78: 20 | T78: =SUM(H78:S78) -> 100.27106
A79: FY2026-27 | B79: Middle East | C79: Middle East | D79: Middle East | E79: Middle East | F79: Amit Jain | G79: Naved | H79: 0 | I79: 0 | J79: 0 | K79: 10 | L79: 10 | M79: 10 | N79: 38 | O79: 38 | P79: 42 | Q79: 52 | R79: 44 | S79: 54 | T79: =SUM(H79:S79) -> 298
A80: FY2026-27 | B80: Reliance | C80: RPO | D80: West | E80: West 1 | F80: Anjli | G80: Anjli | H80: 0 | I80: 2 | J80: 2 | K80: 7.6666667 | L80: 7.6666667 | M80: 7.6666667 | N80: 0 | O80: 0 | P80: 0 | Q80: 0 | R80: 0 | S80: 0 | T80: =SUM(H80:S80) -> 27
A81: FY2026-27 | B81: CG Power Leadership | C81: Leadership | D81: West | E81: West 1 | F81: Anjli | G81: Anjli | H81: 0 | I81: 0 | J81: 0 | K81: 0 | L81: 0 | M81: 0 | N81: 0 | O81: 0 | P81: 0 | Q81: 0 | R81: 0 | S81: 0 | T81: =SUM(H81:S81) -> 0
A82: FY2026-27 | B82: Hyundai Leadership | C82: Leadership | D82: West | E82: West 1 | F82: Anjli | G82: Anjli | H82: 0 | I82: 0 | J82: 0 | K82: 0 | L82: 0 | M82: 0 | N82: 0 | O82: 0 | P82: 0 | Q82: 0 | R82: 0 | S82: 0 | T82: =SUM(H82:S82) -> 0
A83: FY2026-27 | B83: Quantiphi | C83: Lateral | D83: North | E83: North | F83: Rahul | G83: Rahul | I83: 12.5 | J83: 12.5 | K83: 9.7866667 | L83: 9.7866667 | M83: 9.7866667 | T83: =SUM(H83:S83) -> 54.36
A84: FY2026-27 | B84: LAAP India | C84: Lateral | D84: South | E84: South | F84: Manish Malhotra | G84: Manish Malhotra | I84: =1.06*2 -> 2.12 | J84: 1.06 | K84: 1.0666667 | L84: 1.0666667 | M84: 1.0666667 | T84: =SUM(H84:S84) -> 6.38

Sheet CM_Budget
A1: =Revenue_Budget!A2 -> FY | B1: =Revenue_Budget!B2 -> Project | C1: =Revenue_Budget!C2 -> Vertical | D1: =Revenue_Budget!D2 -> Region | E1: =Revenue_Budget!E2 -> Sub Region | F1: =Revenue_Budget!F2 -> Region Head | G1: =Revenue_Budget!G2 -> Practice Head | H1: =Revenue_Budget!H2 -> 46113 | ... S1: =Revenue_Budget!S2 -> 46447
A2: FY2026-27 | B2: Honeywell | C2: =VLOOKUP(B2,Mapping!A:B,2,0) -> Lateral | D2: =VLOOKUP(B2,Mapping!A:C,3,0) -> South | E2: =VLOOKUP(B2,Mapping!A:D,4,0) -> South 1 | F2: =VLOOKUP(B2,Mapping!A:E,5,0) -> Bapi | G2: =VLOOKUP(B2,Mapping!A:F,6,0) -> Bapi | H2: 0.55808997 | I2: 0.55808997 | J2: 0.55808997 | K2: 0.55808997 | L2: 0.55808997 | M2: 0.55808997 | N2: 0.55808997 | O2: 0.55808997 | P2: 0.55808997 | Q2: 0.55808997 | R2: 0.55808997 | S2: 0.55808997
A3: FY2026-27 | B3: Pfizer | C3: =VLOOKUP(B3,Mapping!A:B,2,0) -> Lateral | D3: =VLOOKUP(B3,Mapping!A:C,3,0) -> West | E3: =VLOOKUP(B3,Mapping!A:D,4,0) -> West 1 | F3: =VLOOKUP(B3,Mapping!A:E,5,0) -> Anjli | G3: =VLOOKUP(B3,Mapping!A:F,6,0) -> Usha | H3: 0.41140179 | I3: 0.41140179 | J3: 0.41140179 | K3: 0.41140179 | L3: 0.41140179 | M3: 0.41140179 | N3: 0.41140179 | O3: 0.41140179 | P3: 0.41140179 | Q3: 0.41140179 | R3: 0.41140179 | S3: 0.41140179
A4: FY2026-27 | B4: Tata Motors | C4: =VLOOKUP(B4,Mapping!A:B,2,0) -> Lateral | D4: =VLOOKUP(B4,Mapping!A:C,3,0) -> West | E4: =VLOOKUP(B4,Mapping!A:D,4,0) -> West 2 | F4: =VLOOKUP(B4,Mapping!A:E,5,0) -> Anjli | G4: =VLOOKUP(B4,Mapping!A:F,6,0) -> Shweta
A5: FY2026-27 | B5: SKF India | C5: =VLOOKUP(B5,Mapping!A:B,2,0) -> Lateral | D5: =VLOOKUP(B5,Mapping!A:C,3,0) -> North | E5: =VLOOKUP(B5,Mapping!A:D,4,0) -> North | F5: =VLOOKUP(B5,Mapping!A:E,5,0) -> Anjli | G5: =VLOOKUP(B5,Mapping!A:F,6,0) -> Archana | H5: 0.4 | I5: 0.4 | J5: 0.4 | K5: 0.4 | L5: 0.4 | M5: 0.4 | N5: 0.4 | O5: 0.4 | P5: 0.4 | Q5: 0.4 | R5: 0.4 | S5: 0.4
A6: FY2026-27 | B6: Siemens (Advatnta & GBS) | C6: Lateral | D6: =VLOOKUP(B6,Mapping!A:C,3,0) -> #N/A | E6: =VLOOKUP(B6,Mapping!A:D,4,0) -> #N/A | F6: =VLOOKUP(B6,Mapping!A:E,5,0) -> #N/A | G6: =VLOOKUP(B6,Mapping!A:F,6,0) -> #N/A | H6: 0.4 | I6: 0.4 | J6: 0.4 | K6: 0.4 | L6: 0.4 | M6: 0.4 | N6: 0.4 | O6: 0.4 | P6: 0.4 | Q6: 0.4 | R6: 0.4 | S6: 0.4
A7: FY2026-27 | B7: Siemens Energy | C7: Lateral | H7: 0.4 | I7: 0.4 | J7: 0.4 | K7: 0.4 | L7: 0.4 | M7: 0.4 | N7: 0.4 | O7: 0.4 | P7: 0.4 | Q7: 0.4 | R7: 0.4 | S7: 0.4
A8: FY2026-27 | B8: Pidilite | C8: =VLOOKUP(B8,Mapping!A:B,2,0) -> Lateral | D8: =VLOOKUP(B8,Mapping!A:C,3,0) -> West | E8: =VLOOKUP(B8,Mapping!A:D,4,0) -> West 1 | F8: =VLOOKUP(B8,Mapping!A:E,5,0) -> Anjli | G8: =VLOOKUP(B8,Mapping!A:F,6,0) -> Usha | H8: 0.4 | I8: 0.4 | J8: 0.4 | K8: 0.4 | L8: 0.4 | M8: 0.4 | N8: 0.4 | O8: 0.4 | P8: 0.4 | Q8: 0.4 | R8: 0.4 | S8: 0.4
A9: FY2026-27 | B9: Vertiv | C9: =VLOOKUP(B9,Mapping!A:B,2,0) -> Lateral | D9: =VLOOKUP(B9,Mapping!A:C,3,0) -> West | E9: =VLOOKUP(B9,Mapping!A:D,4,0) -> West 2 | F9: =VLOOKUP(B9,Mapping!A:E,5,0) -> Anjli | G9: =VLOOKUP(B9,Mapping!A:F,6,0) -> Shweta | H9: 0.44539893 | I9: 0.44539893 | J9: 0.44539893 | K9: 0.44539893 | L9: 0.44539893 | M9: 0.44539893 | N9: 0.44539893 | O9: 0.44539893 | P9: 0.44539893 | Q9: 0.44539893 | R9: 0.44539893 | S9: 0.44539893
A10: FY2026-27 | B10: Birla Paints | C10: =VLOOKUP(B10,Mapping!A:B,2,0) -> Lateral | D10: =VLOOKUP(B10,Mapping!A:C,3,0) -> West | E10: =VLOOKUP(B10,Mapping!A:D,4,0) -> West 1 | F10: =VLOOKUP(B10,Mapping!A:E,5,0) -> Anjli | G10: =VLOOKUP(B10,Mapping!A:F,6,0) -> Geetu | H10: 0.4 | I10: 0.4 | J10: 0.4 | K10: 0.4 | L10: 0.4 | M10: 0.4 | N10: 0.4 | O10: 0.4 | P10: 0.4 | Q10: 0.4 | R10: 0.4 | S10: 0.4
A11: FY2026-27 | B11: Ingram Micro | C11: =VLOOKUP(B11,Mapping!A:B,2,0) -> Lateral | D11: =VLOOKUP(B11,Mapping!A:C,3,0) -> West | E11: =VLOOKUP(B11,Mapping!A:D,4,0) -> West 1 | F11: =VLOOKUP(B11,Mapping!A:E,5,0) -> Anjli | G11: =VLOOKUP(B11,Mapping!A:F,6,0) -> Geetu
A12: FY2026-27 | B12: HPE | C12: =VLOOKUP(B12,Mapping!A:B,2,0) -> Lateral | D12: =VLOOKUP(B12,Mapping!A:C,3,0) -> South | E12: =VLOOKUP(B12,Mapping!A:D,4,0) -> South 1 | F12: =VLOOKUP(B12,Mapping!A:E,5,0) -> Mahak | G12: =VLOOKUP(B12,Mapping!A:F,6,0) -> Mahak | H12: 0.48 | I12: 0.48 | J12: 0.48 | K12: 0.48 | L12: 0.48 | M12: 0.48 | N12: 0.48 | O12: 0.48 | P12: 0.48 | Q12: 0.48 | R12: 0.48 | S12: 0.48
A13: FY2026-27 | B13: Isuzu | C13: =VLOOKUP(B13,Mapping!A:B,2,0) -> Lateral | D13: =VLOOKUP(B13,Mapping!A:C,3,0) -> South | E13: =VLOOKUP(B13,Mapping!A:D,4,0) -> South 1 | F13: =VLOOKUP(B13,Mapping!A:E,5,0) -> Anjli | G13: =VLOOKUP(B13,Mapping!A:F,6,0) -> Satya | H13: 0.4 | I13: 0.4 | J13: 0.4 | K13: 0.4 | L13: 0.4 | M13: 0.4 | N13: 0.4 | O13: 0.4 | P13: 0.4 | Q13: 0.4 | R13: 0.4 | S13: 0.4
A14: FY2026-27 | B14: Mahindra Holidays | C14: =VLOOKUP(B14,Mapping!A:B,2,0) -> Lateral | D14: =VLOOKUP(B14,Mapping!A:C,3,0) -> West | E14: =VLOOKUP(B14,Mapping!A:D,4,0) -> West 1 | F14: =VLOOKUP(B14,Mapping!A:E,5,0) -> Anjli | G14: =VLOOKUP(B14,Mapping!A:F,6,0) -> Geetu
A15: FY2026-27 | B15: BITS | C15: =VLOOKUP(B15,Mapping!A:B,2,0) -> Lateral | D15: =VLOOKUP(B15,Mapping!A:C,3,0) -> South | E15: =VLOOKUP(B15,Mapping!A:D,4,0) -> South 2 | F15: =VLOOKUP(B15,Mapping!A:E,5,0) -> Sulabh | G15: =VLOOKUP(B15,Mapping!A:F,6,0) -> Krishna | H15: 0.5 | I15: 0.5 | J15: 0.5 | K15: 0.5 | L15: 0.5 | M15: 0.5 | N15: 0.5 | O15: 0.5 | P15: 0.5 | Q15: 0.5 | R15: 0.5 | S15: 0.5
A16: FY2026-27 | B16: M&M | C16: =VLOOKUP(B16,Mapping!A:B,2,0) -> Lateral | D16: =VLOOKUP(B16,Mapping!A:C,3,0) -> West | E16: =VLOOKUP(B16,Mapping!A:D,4,0) -> West 1 | F16: =VLOOKUP(B16,Mapping!A:E,5,0) -> Anjli | G16: =VLOOKUP(B16,Mapping!A:F,6,0) -> Dhriti | H16: 0.55 | I16: 0.55 | J16: 0.55 | K16: 0.55 | L16: 0.55 | M16: 0.55 | N16: 0.55 | O16: 0.55 | P16: 0.55 | Q16: 0.55 | R16: 0.55 | S16: 0.55
A17: FY2026-27 | B17: P&G | C17: =VLOOKUP(B17,Mapping!A:B,2,0) -> Lateral | D17: =VLOOKUP(B17,Mapping!A:C,3,0) -> South | E17: =VLOOKUP(B17,Mapping!A:D,4,0) -> South 2 | F17: =VLOOKUP(B17,Mapping!A:E,5,0) -> Sulabh | G17: =VLOOKUP(B17,Mapping!A:F,6,0) -> Krishna
A18: FY2026-27 | B18: Wipro | C18: =VLOOKUP(B18,Mapping!A:B,2,0) -> Lateral | D18: =VLOOKUP(B18,Mapping!A:C,3,0) -> South | E18: =VLOOKUP(B18,Mapping!A:D,4,0) -> South 1 | F18: =VLOOKUP(B18,Mapping!A:E,5,0) -> Sulabh | G18: =VLOOKUP(B18,Mapping!A:F,6,0) -> Subu | H18: 0.45 | I18: 0.45 | J18: 0.45 | K18: 0.45 | L18: 0.45 | M18: 0.45 | N18: 0.45 | O18: 0.45 | P18: 0.45 | Q18: 0.45 | R18: 0.45 | S18: 0.45
A19: FY2026-27 | B19: Tata Marcopolo | C19: =VLOOKUP(B19,Mapping!A:B,2,0) -> Lateral | D19: =VLOOKUP(B19,Mapping!A:C,3,0) -> West | E19: =VLOOKUP(B19,Mapping!A:D,4,0) -> West 2 | F19: =VLOOKUP(B19,Mapping!A:E,5,0) -> Anjli | G19: =VLOOKUP(B19,Mapping!A:F,6,0) -> Anjli
A20: FY2026-27 | B20: DP World | C20: =VLOOKUP(B20,Mapping!A:B,2,0) -> Lateral | D20: =VLOOKUP(B20,Mapping!A:C,3,0) -> West | E20: =VLOOKUP(B20,Mapping!A:D,4,0) -> West 1 | F20: =VLOOKUP(B20,Mapping!A:E,5,0) -> Anjli | G20: =VLOOKUP(B20,Mapping!A:F,6,0) -> Geetu | H20: 0.4 | I20: 0.4 | J20: 0.4 | K20: 0.4 | L20: 0.4 | M20: 0.4 | N20: 0.4 | O20: 0.4 | P20: 0.4 | Q20: 0.4 | R20: 0.4 | S20: 0.4
A21: FY2026-27 | B21: Ametek | C21: =VLOOKUP(B21,Mapping!A:B,2,0) -> Lateral | D21: =VLOOKUP(B21,Mapping!A:C,3,0) -> South | E21: =VLOOKUP(B21,Mapping!A:D,4,0) -> South 1 | F21: =VLOOKUP(B21,Mapping!A:E,5,0) -> Sulabh | G21: =VLOOKUP(B21,Mapping!A:F,6,0) -> Satya
A22: FY2026-27 | B22: AMNS | C22: =VLOOKUP(B22,Mapping!A:B,2,0) -> Lateral | D22: =VLOOKUP(B22,Mapping!A:C,3,0) -> West | E22: =VLOOKUP(B22,Mapping!A:D,4,0) -> West 1 | F22: =VLOOKUP(B22,Mapping!A:E,5,0) -> Anjli | G22: =VLOOKUP(B22,Mapping!A:F,6,0) -> Alifia | H22: 0.4 | I22: 0.4 | J22: 0.4 | K22: 0.4 | L22: 0.4 | M22: 0.4 | N22: 0.4 | O22: 0.4 | P22: 0.4 | Q22: 0.4 | R22: 0.4 | S22: 0.4
A23: FY2026-27 | B23: Tata Electronics | C23: =VLOOKUP(B23,Mapping!A:B,2,0) -> Lateral | D23: =VLOOKUP(B23,Mapping!A:C,3,0) -> South | E23: =VLOOKUP(B23,Mapping!A:D,4,0) -> South 2 | F23: =VLOOKUP(B23,Mapping!A:E,5,0) -> Sulabh | G23: =VLOOKUP(B23,Mapping!A:F,6,0) -> Subu
A24: FY2026-27 | B24: Jindal Stainless | C24: =VLOOKUP(B24,Mapping!A:B,2,0) -> Lateral | D24: =VLOOKUP(B24,Mapping!A:C,3,0) -> North | E24: =VLOOKUP(B24,Mapping!A:D,4,0) -> North | F24: =VLOOKUP(B24,Mapping!A:E,5,0) -> Anjli | G24: =VLOOKUP(B24,Mapping!A:F,6,0) -> Archana | H24: 0.5 | I24: 0.5 | J24: 0.5 | K24: 0.5 | L24: 0.5 | M24: 0.5 | N24: 0.5 | O24: 0.5 | P24: 0.5 | Q24: 0.5 | R24: 0.5 | S24: 0.5
A25: FY2026-27 | B25: Nomiso | C25: =VLOOKUP(B25,Mapping!A:B,2,0) -> Lateral | D25: =VLOOKUP(B25,Mapping!A:C,3,0) -> South | E25: =VLOOKUP(B25,Mapping!A:D,4,0) -> South 2 | F25: =VLOOKUP(B25,Mapping!A:E,5,0) -> Sulabh | G25: =VLOOKUP(B25,Mapping!A:F,6,0) -> Krishna
A26: FY2026-27 | B26: Schaeffler | C26: =VLOOKUP(B26,Mapping!A:B,2,0) -> Lateral | D26: =VLOOKUP(B26,Mapping!A:C,3,0) -> West | E26: =VLOOKUP(B26,Mapping!A:D,4,0) -> West 2 | F26: =VLOOKUP(B26,Mapping!A:E,5,0) -> Anjli | G26: =VLOOKUP(B26,Mapping!A:F,6,0) -> Shweta | H26: 0.45 | I26: 0.45 | J26: 0.45 | K26: 0.45 | L26: 0.45 | M26: 0.45 | N26: 0.45 | O26: 0.45 | P26: 0.45 | Q26: 0.45 | R26: 0.45 | S26: 0.45
A27: FY2026-27 | B27: Royal Enfield | C27: =VLOOKUP(B27,Mapping!A:B,2,0) -> Lateral | D27: =VLOOKUP(B27,Mapping!A:C,3,0) -> South | E27: =VLOOKUP(B27,Mapping!A:D,4,0) -> South 2 | F27: =VLOOKUP(B27,Mapping!A:E,5,0) -> Sulabh | G27: =VLOOKUP(B27,Mapping!A:F,6,0) -> Krishna | H27: 0.45 | I27: 0.45 | J27: 0.45 | K27: 0.45 | L27: 0.45 | M27: 0.45 | N27: 0.45 | O27: 0.45 | P27: 0.45 | Q27: 0.45 | R27: 0.45 | S27: 0.45
A28: FY2026-27 | B28: SBI Card | C28: =VLOOKUP(B28,Mapping!A:B,2,0) -> Lateral | D28: =VLOOKUP(B28,Mapping!A:C,3,0) -> North | E28: =VLOOKUP(B28,Mapping!A:D,4,0) -> North | F28: =VLOOKUP(B28,Mapping!A:E,5,0) -> Anjli | G28: =VLOOKUP(B28,Mapping!A:F,6,0) -> Archana | H28: 0.35 | I28: 0.35 | J28: 0.35 | K28: 0.35 | L28: 0.35 | M28: 0.35 | N28: 0.35 | O28: 0.35 | P28: 0.35 | Q28: 0.35 | R28: 0.35 | S28: 0.35
A29: FY2026-27 | B29: Hyundai Motor | C29: =VLOOKUP(B29,Mapping!A:B,2,0) -> Lateral | D29: =VLOOKUP(B29,Mapping!A:C,3,0) -> West | E29: =VLOOKUP(B29,Mapping!A:D,4,0) -> West 2 | F29: =VLOOKUP(B29,Mapping!A:E,5,0) -> Anjli | G29: =VLOOKUP(B29,Mapping!A:F,6,0) -> Shweta | H29: 0.54629512 | I29: 0.54629512 | J29: 0.54629512 | K29: 0.54629512 | L29: 0.54629512 | M29: 0.54629512 | N29: 0.54629512 | O29: 0.54629512 | P29: 0.54629512 | Q29: 0.54629512 | R29: 0.54629512 | S29: 0.54629512
A30: FY2026-27 | B30: Maruti Suzuki(MSIL) | C30: =VLOOKUP(B30,Mapping!A:B,2,0) -> Lateral | D30: =VLOOKUP(B30,Mapping!A:C,3,0) -> North | E30: =VLOOKUP(B30,Mapping!A:D,4,0) -> North | F30: =VLOOKUP(B30,Mapping!A:E,5,0) -> Anjli | G30: =VLOOKUP(B30,Mapping!A:F,6,0) -> Archana | H30: 0.4 | I30: 0.4 | J30: 0.4 | K30: 0.4 | L30: 0.4 | M30: 0.4 | N30: 0.4 | O30: 0.4 | P30: 0.4 | Q30: 0.4 | R30: 0.4 | S30: 0.4
A31: FY2026-27 | B31: Excelacom | C31: =VLOOKUP(B31,Mapping!A:B,2,0) -> Lateral | D31: =VLOOKUP(B31,Mapping!A:C,3,0) -> South | E31: =VLOOKUP(B31,Mapping!A:D,4,0) -> South 2 | F31: =VLOOKUP(B31,Mapping!A:E,5,0) -> Sulabh | G31: =VLOOKUP(B31,Mapping!A:F,6,0) -> Krishna
A32: FY2026-27 | B32: Tata Consumer | C32: =VLOOKUP(B32,Mapping!A:B,2,0) -> Lateral | D32: =VLOOKUP(B32,Mapping!A:C,3,0) -> West | E32: =VLOOKUP(B32,Mapping!A:D,4,0) -> West 1 | F32: =VLOOKUP(B32,Mapping!A:E,5,0) -> Anjli | G32: =VLOOKUP(B32,Mapping!A:F,6,0) -> Geetu | H32: 0.45 | I32: 0.45 | J32: 0.45 | K32: 0.45 | L32: 0.45 | M32: 0.45 | N32: 0.45 | O32: 0.45 | P32: 0.45 | Q32: 0.45 | R32: 0.45 | S32: 0.45
A33: FY2026-27 | B33: Tata Play | C33: =VLOOKUP(B33,Mapping!A:B,2,0) -> Lateral | D33: =VLOOKUP(B33,Mapping!A:C,3,0) -> West | E33: =VLOOKUP(B33,Mapping!A:D,4,0) -> West 1 | F33: =VLOOKUP(B33,Mapping!A:E,5,0) -> Anjli | G33: =VLOOKUP(B33,Mapping!A:F,6,0) -> Geetu | H33: 0.4 | I33: 0.4 | J33: 0.4 | K33: 0.4 | L33: 0.4 | M33: 0.4 | N33: 0.4 | O33: 0.4 | P33: 0.4 | Q33: 0.4 | R33: 0.4 | S33: 0.4
A34: FY2026-27 | B34: Mahindra Finance | C34: =VLOOKUP(B34,Mapping!A:B,2,0) -> Lateral | D34: =VLOOKUP(B34,Mapping!A:C,3,0) -> West | E34: =VLOOKUP(B34,Mapping!A:D,4,0) -> West 1 | F34: =VLOOKUP(B34,Mapping!A:E,5,0) -> Anjli | G34: =VLOOKUP(B34,Mapping!A:F,6,0) -> Geetu
A35: FY2026-27 | B35: Suzuki R&D | C35: =VLOOKUP(B35,Mapping!A:B,2,0) -> Lateral | D35: =VLOOKUP(B35,Mapping!A:C,3,0) -> North | E35: =VLOOKUP(B35,Mapping!A:D,4,0) -> North | F35: =VLOOKUP(B35,Mapping!A:E,5,0) -> Anjli | G35: =VLOOKUP(B35,Mapping!A:F,6,0) -> Archana
A36: FY2026-27 | B36: Subros Ltd | C36: =VLOOKUP(B36,Mapping!A:B,2,0) -> Lateral | D36: =VLOOKUP(B36,Mapping!A:C,3,0) -> North | E36: =VLOOKUP(B36,Mapping!A:D,4,0) -> North | F36: =VLOOKUP(B36,Mapping!A:E,5,0) -> Anjli | G36: =VLOOKUP(B36,Mapping!A:F,6,0) -> Archana | H36: 0.39942438 | I36: 0.39942438 | J36: 0.39942438 | K36: 0.39942438 | L36: 0.39942438 | M36: 0.39942438 | N36: 0.39942438 | O36: 0.39942438 | P36: 0.39942438 | Q36: 0.39942438 | R36: 0.39942438 | S36: 0.39942438
A37: FY2026-27 | B37: Atomberg Technologies | C37: =VLOOKUP(B37,Mapping!A:B,2,0) -> Lateral | D37: =VLOOKUP(B37,Mapping!A:C,3,0) -> West | E37: =VLOOKUP(B37,Mapping!A:D,4,0) -> West 1 | F37: =VLOOKUP(B37,Mapping!A:E,5,0) -> Anjli | G37: =VLOOKUP(B37,Mapping!A:F,6,0) -> Geetu | H37: 0.5 | I37: 0.5 | J37: 0.5 | K37: 0.5 | L37: 0.5 | M37: 0.5 | N37: 0.5 | O37: 0.5 | P37: 0.5 | Q37: 0.5 | R37: 0.5 | S37: 0.5
A38: FY2026-27 | B38: Bridgestone | C38: =VLOOKUP(B38,Mapping!A:B,2,0) -> Lateral | D38: =VLOOKUP(B38,Mapping!A:C,3,0) -> West | E38: =VLOOKUP(B38,Mapping!A:D,4,0) -> West 2 | F38: =VLOOKUP(B38,Mapping!A:E,5,0) -> Anjli | G38: =VLOOKUP(B38,Mapping!A:F,6,0) -> Shweta | H38: 0.5 | I38: 0.5 | J38: 0.5 | K38: 0.5 | L38: 0.5 | M38: 0.5 | N38: 0.5 | O38: 0.5 | P38: 0.5 | Q38: 0.5 | R38: 0.5 | S38: 0.5
A39: FY2026-27 | B39: Ambuja Cement | C39: =VLOOKUP(B39,Mapping!A:B,2,0) -> Lateral | D39: =VLOOKUP(B39,Mapping!A:C,3,0) -> West | E39: =VLOOKUP(B39,Mapping!A:D,4,0) -> West 1 | F39: =VLOOKUP(B39,Mapping!A:E,5,0) -> Anjli | G39: =VLOOKUP(B39,Mapping!A:F,6,0) -> Ankit | H39: 0.45 | I39: 0.45 | J39: 0.45 | K39: 0.45 | L39: 0.45 | M39: 0.45 | N39: 0.45 | O39: 0.45 | P39: 0.45 | Q39: 0.45 | R39: 0.45 | S39: 0.45
A40: FY2026-27 | B40: Ashok Leyland | C40: =VLOOKUP(B40,Mapping!A:B,2,0) -> Lateral | D40: =VLOOKUP(B40,Mapping!A:C,3,0) -> South | E40: =VLOOKUP(B40,Mapping!A:D,4,0) -> South 2 | F40: =VLOOKUP(B40,Mapping!A:E,5,0) -> Sulabh | G40: =VLOOKUP(B40,Mapping!A:F,6,0) -> Krishna | H40: 0.4 | I40: 0.4 | J40: 0.4 | K40: 0.4 | L40: 0.4 | M40: 0.4 | N40: 0.4 | O40: 0.4 | P40: 0.4 | Q40: 0.4 | R40: 0.4 | S40: 0.4
...

Sheet Target Rev Productivity
A1: =Revenue_Budget!A2 -> FY | B1: =Revenue_Budget!B2 -> Project | C1: =Revenue_Budget!C2 -> Vertical | D1: =Revenue_Budget!D2 -> Region | E1: =Revenue_Budget!E2 -> Sub Region | F1: =Revenue_Budget!F2 -> Region Head | G1: =Revenue_Budget!G2 -> Practice Head | H1: =Revenue_Budget!H2 -> 46113 | ... S1: =Revenue_Budget!S2 -> 46447
A2: FY2026-27 | B2: Honeywell | C2: =VLOOKUP(B2,Mapping!A:B,2,0) -> Lateral | D2: =VLOOKUP(B2,Mapping!A:C,3,0) -> South | E2: =VLOOKUP(B2,Mapping!A:D,4,0) -> South 1 | F2: =VLOOKUP(B2,Mapping!A:E,5,0) -> Bapi | G2: =VLOOKUP(B2,Mapping!A:F,6,0) -> Bapi | H2: 3.5 | I2: 3.5 | J2: 3.5 | K2: 3.5 | L2: 3.5 | M2: 3.5 | N2: 3.5 | O2: 3.5 | P2: 3.5 | Q2: 3.5 | R2: 3.5 | S2: 3.5
A3: FY2026-27 | B3: Pfizer | C3: =VLOOKUP(B3,Mapping!A:B,2,0) -> Lateral | D3: =VLOOKUP(B3,Mapping!A:C,3,0) -> West | E3: =VLOOKUP(B3,Mapping!A:D,4,0) -> West 1 | F3: =VLOOKUP(B3,Mapping!A:E,5,0) -> Anjli | G3: =VLOOKUP(B3,Mapping!A:F,6,0) -> Usha | H3: 1.5 | I3: 1.5 | J3: 1.5 | K3: 1.5 | L3: 1.5 | M3: 1.5 | N3: 1.5 | O3: 1.5 | P3: 1.5 | Q3: 1.5 | R3: 1.5 | S3: 1.5
A4: FY2026-27 | B4: Tata Motors | C4: =VLOOKUP(B4,Mapping!A:B,2,0) -> Lateral | D4: =VLOOKUP(B4,Mapping!A:C,3,0) -> West | E4: =VLOOKUP(B4,Mapping!A:D,4,0) -> West 2 | F4: =VLOOKUP(B4,Mapping!A:E,5,0) -> Anjli | G4: =VLOOKUP(B4,Mapping!A:F,6,0) -> Shweta | H4: 1.5 | I4: 1.5 | J4: 1.5 | K4: 1.5 | L4: 1.5 | M4: 1.5 | N4: 1.5 | O4: 1.5 | P4: 1.5 | Q4: 1.5 | R4: 1.5 | S4: 1.5
A5: FY2026-27 | B5: SKF India | C5: =VLOOKUP(B5,Mapping!A:B,2,0) -> Lateral | D5: =VLOOKUP(B5,Mapping!A:C,3,0) -> North | E5: =VLOOKUP(B5,Mapping!A:D,4,0) -> North | F5: =VLOOKUP(B5,Mapping!A:E,5,0) -> Anjli | G5: =VLOOKUP(B5,Mapping!A:F,6,0) -> Archana | H5: 1.5 | I5: 1.5 | J5: 1.5 | K5: 1.5 | L5: 1.5 | M5: 1.5 | N5: 1.5 | O5: 1.5 | P5: 1.5 | Q5: 1.5 | R5: 1.5 | S5: 1.5
A6: FY2026-27 | B6: Siemens (Advatnta & GBS) | C6: Lateral | D6: South | E6: South 1 | F6: Manish Malhotra | G6: Kunal | H6: 1.5 | I6: 1.5 | J6: 1.5 | K6: 1.5 | L6: 1.5 | M6: 1.5 | N6: 1.5 | O6: 1.5 | P6: 1.5 | Q6: 1.5 | R6: 1.5 | S6: 1.5
A7: FY2026-27 | B7: Siemens Energy | C7: Lateral | D7: North | E7: North | F7: Anjli | G7: Archana | H7: 1.5 | I7: 1.5 | J7: 1.5 | K7: 1.5 | L7: 1.5 | M7: 1.5 | N7: 1.5 | O7: 1.5 | P7: 1.5 | Q7: 1.5 | R7: 1.5 | S7: 1.5
A8: FY2026-27 | B8: Pidilite | C8: =VLOOKUP(B8,Mapping!A:B,2,0) -> Lateral | D8: =VLOOKUP(B8,Mapping!A:C,3,0) -> West | E8: =VLOOKUP(B8,Mapping!A:D,4,0) -> West 1 | F8: =VLOOKUP(B8,Mapping!A:E,5,0) -> Anjli | G8: =VLOOKUP(B8,Mapping!A:F,6,0) -> Usha | H8: 1.5 | I8: 1.5 | J8: 1.5 | K8: 1.5 | L8: 1.5 | M8: 1.5 | N8: 1.5 | O8: 1.5 | P8: 1.5 | Q8: 1.5 | R8: 1.5 | S8: 1.5
A9: FY2026-27 | B9: Vertiv | C9: =VLOOKUP(B9,Mapping!A:B,2,0) -> Lateral | D9: =VLOOKUP(B9,Mapping!A:C,3,0) -> West | E9: =VLOOKUP(B9,Mapping!A:D,4,0) -> West 2 | F9: =VLOOKUP(B9,Mapping!A:E,5,0) -> Anjli | G9: =VLOOKUP(B9,Mapping!A:F,6,0) -> Shweta | H9: 1.5 | I9: 1.5 | J9: 1.5 | K9: 1.5 | L9: 1.5 | M9: 1.5 | N9: 1.5 | O9: 1.5 | P9: 1.5 | Q9: 1.5 | R9: 1.5 | S9: 1.5
A10: FY2026-27 | B10: Birla Paints | C10: =VLOOKUP(B10,Mapping!A:B,2,0) -> Lateral | D10: =VLOOKUP(B10,Mapping!A:C,3,0) -> West | E10: =VLOOKUP(B10,Mapping!A:D,4,0) -> West 1 | F10: =VLOOKUP(B10,Mapping!A:E,5,0) -> Anjli | G10: =VLOOKUP(B10,Mapping!A:F,6,0) -> Geetu | H10: 1.5 | I10: 1.5 | J10: 1.5 | K10: 1.5 | L10: 1.5 | M10: 1.5 | N10: 1.5 | O10: 1.5 | P10: 1.5 | Q10: 1.5 | R10: 1.5 | S10: 1.5
A11: FY2026-27 | B11: Ingram Micro | C11: =VLOOKUP(B11,Mapping!A:B,2,0) -> Lateral | D11: =VLOOKUP(B11,Mapping!A:C,3,0) -> West | E11: =VLOOKUP(B11,Mapping!A:D,4,0) -> West 1 | F11: =VLOOKUP(B11,Mapping!A:E,5,0) -> Anjli | G11: =VLOOKUP(B11,Mapping!A:F,6,0) -> Geetu | H11: 1.5 | I11: 1.5 | J11: 1.5 | K11: 1.5 | L11: 1.5 | M11: 1.5 | N11: 1.5 | O11: 1.5 | P11: 1.5 | Q11: 1.5 | R11: 1.5 | S11: 1.5
A12: FY2026-27 | B12: HPE | C12: =VLOOKUP(B12,Mapping!A:B,2,0) -> Lateral | D12: =VLOOKUP(B12,Mapping!A:C,3,0) -> South | E12: =VLOOKUP(B12,Mapping!A:D,4,0) -> South 1 | F12: =VLOOKUP(B12,Mapping!A:E,5,0) -> Mahak | G12: =VLOOKUP(B12,Mapping!A:F,6,0) -> Mahak | H12: 1.5 | I12: 1.5 | J12: 1.5 | K12: 1.5 | L12: 1.5 | M12: 1.5 | N12: 1.5 | O12: 1.5 | P12: 1.5 | Q12: 1.5 | R12: 1.5 | S12: 1.5
A13: FY2026-27 | B13: Isuzu | C13: =VLOOKUP(B13,Mapping!A:B,2,0) -> Lateral | D13: =VLOOKUP(B13,Mapping!A:C,3,0) -> South | E13: =VLOOKUP(B13,Mapping!A:D,4,0) -> South 1 | F13: =VLOOKUP(B13,Mapping!A:E,5,0) -> Anjli | G13: =VLOOKUP(B13,Mapping!A:F,6,0) -> Satya | H13: 1.5 | I13: 1.5 | J13: 1.5 | K13: 1.5 | L13: 1.5 | M13: 1.5 | N13: 1.5 | O13: 1.5 | P13: 1.5 | Q13: 1.5 | R13: 1.5 | S13: 1.5
A14: FY2026-27 | B14: Mahindra Holidays | C14: =VLOOKUP(B14,Mapping!A:B,2,0) -> Lateral | D14: =VLOOKUP(B14,Mapping!A:C,3,0) -> West | E14: =VLOOKUP(B14,Mapping!A:D,4,0) -> West 1 | F14: =VLOOKUP(B14,Mapping!A:E,5,0) -> Anjli | G14: =VLOOKUP(B14,Mapping!A:F,6,0) -> Geetu | H14: 1.5 | I14: 1.5 | J14: 1.5 | K14: 1.5 | L14: 1.5 | M14: 1.5 | N14: 1.5 | O14: 1.5 | P14: 1.5 | Q14: 1.5 | R14: 1.5 | S14: 1.5
A15: FY2026-27 | B15: BITS | C15: =VLOOKUP(B15,Mapping!A:B,2,0) -> Lateral | D15: =VLOOKUP(B15,Mapping!A:C,3,0) -> South | E15: =VLOOKUP(B15,Mapping!A:D,4,0) -> South 2 | F15: =VLOOKUP(B15,Mapping!A:E,5,0) -> Sulabh | G15: =VLOOKUP(B15,Mapping!A:F,6,0) -> Krishna | H15: 1.5 | I15: 1.5 | J15: 1.5 | K15: 1.5 | L15: 1.5 | M15: 1.5 | N15: 1.5 | O15: 1.5 | P15: 1.5 | Q15: 1.5 | R15: 1.5 | S15: 1.5
