Workbook

Sheet Summary Dashboard
A1: CONTRACT SUMMARY DASHBOARD
A2: Real-time Portfolio Overview | Taggd RPO
A4: Total Clients | C4: Current ACV (₹L) | E4: Avg Contribution Margin % | G4: Total Headcount | I4: Active | K4: Renewed | M4: Expired
A5: =COUNTA('Contract Data'!B4:B8) -> 5 | C5: ='Contract Data'!G110 -> 580.75 | E5: ='Contract Data'!I8 -> 0.45408617 | G5: ='Contract Data'!J8 -> 21 | I5: =COUNTIF('Contract Data'!H4:H8,"Active") -> 3 | K5: =COUNTIF('Contract Data'!H4:H8,"Renewed") -> 0 | M5: =COUNTIF('Contract Data'!H4:H8,"Expired") -> 2
A9: CLIENT-LEVEL PERFORMANCE SUMMARY
A10: Customer | B10: Status | C10: Signed ACV (₹L) | D10: Current ACV (₹L) | E10: ACV Growth% | F10: CM% | G10: HC | H10: Renewal Date | I10: Remarks
A11: ='Contract Data'!B4 -> BITS | B11: ='Contract Data'!H4 -> Active | C11: ='Contract Data'!G4 -> 40 | D11: ='Contract Data'!#REF! -> #REF! | E11: ='Contract Data'!P4 -> No | F11: ='Contract Data'!I4 -> 0 | G11: ='Contract Data'!J4 -> 0 | H11: ='Contract Data'!F4 -> 46236 | I11: ='Contract Data'!U4 -> Renewal in discussion | L11: STATUS BREAKDOWN
A12: ='Contract Data'!B5 -> Pfizer | B12: ='Contract Data'!H5 -> Active | C12: ='Contract Data'!G5 -> 170 | D12: ='Contract Data'!#REF! -> #REF! | E12: ='Contract Data'!P5 -> Yes | F12: ='Contract Data'!I5 -> 0.7165 | G12: ='Contract Data'!J5 -> 1.4 | H12: ='Contract Data'!F5 -> 46539 | I12: ='Contract Data'!U5 -> 0 | L12: Active | M12: =COUNTIF('Contract Data'!H4:H8,"Active") -> 3
A13: ='Contract Data'!B6 -> Siemens | B13: ='Contract Data'!H6 -> Expired | C13: ='Contract Data'!G6 -> 208 | D13: ='Contract Data'!#REF! -> #REF! | E13: ='Contract Data'!P6 -> No | F13: ='Contract Data'!I6 -> 0 | G13: ='Contract Data'!J6 -> 0 | H13: ='Contract Data'!F6 -> 46082 | I13: ='Contract Data'!U6 -> Auto-renewed at +8% | L13: Renewed | M13: =COUNTIF('Contract Data'!H4:H8,"Renewed") -> 0
A14: ='Contract Data'!B7 -> Vertiv | B14: ='Contract Data'!H7 -> Expired | C14: ='Contract Data'!G7 -> 60 | D14: ='Contract Data'!#REF! -> #REF! | E14: ='Contract Data'!P7 -> Yes | F14: ='Contract Data'!I7 -> 0.5628277 | G14: ='Contract Data'!J7 -> 3 | H14: ='Contract Data'!F7 -> 44406 | I14: ='Contract Data'!U7 -> 0 | L14: Expired | M14: =COUNTIF('Contract Data'!H4:H8,"Expired") -> 2
A15: ='Contract Data'!B8 -> Pidilite | B15: ='Contract Data'!H8 -> Active | C15: ='Contract Data'!G8 -> 102.75 | D15: ='Contract Data'!#REF! -> #REF! | E15: ='Contract Data'!P8 -> Yes | F15: ='Contract Data'!I8 -> 0.45408617 | G15: ='Contract Data'!J8 -> 21 | H15: ='Contract Data'!F8 -> 46439 | I15: ='Contract Data'!U8 -> Follow-up required
L16: HEADCOUNT BY CLIENT
L17: ='Contract Data'!B4 -> BITS | M17: ='Contract Data'!J4 -> 0
L18: ='Contract Data'!B5 -> Pfizer | M18: ='Contract Data'!J5 -> 1.4
L19: ='Contract Data'!B6 -> Siemens | M19: ='Contract Data'!J6 -> 0
A20: Customer | B20: Signed ACV | C20: Current ACV | E20: Customer | F20: CM% | L20: ='Contract Data'!B7 -> Vertiv | M20: ='Contract Data'!J7 -> 3
A21: ='Contract Data'!B4 -> BITS | B21: ='Contract Data'!G4 -> 40 | C21: ='Contract Data'!#REF! -> #REF! | E21: ='Contract Data'!B4 -> BITS | F21: ='Contract Data'!I4 -> 0 | L21: ='Contract Data'!B8 -> Pidilite | M21: ='Contract Data'!J8 -> 21
A22: ='Contract Data'!B5 -> Pfizer | B22: ='Contract Data'!G5 -> 170 | C22: ='Contract Data'!#REF! -> #REF! | E22: ='Contract Data'!B5 -> Pfizer | F22: ='Contract Data'!I5 -> 0.7165
A23: ='Contract Data'!B6 -> Siemens | B23: ='Contract Data'!G6 -> 208 | C23: ='Contract Data'!#REF! -> #REF! | E23: ='Contract Data'!B6 -> Siemens | F23: ='Contract Data'!I6 -> 0
A24: ='Contract Data'!B7 -> Vertiv | B24: ='Contract Data'!G7 -> 60 | C24: ='Contract Data'!#REF! -> #REF! | E24: ='Contract Data'!B7 -> Vertiv | F24: ='Contract Data'!I7 -> 0.5628277
A25: ='Contract Data'!B8 -> Pidilite | B25: ='Contract Data'!G8 -> 102.75 | C25: ='Contract Data'!#REF! -> #REF! | E25: ='Contract Data'!B8 -> Pidilite | F25: ='Contract Data'!I8 -> 0.45408617

Sheet Contract Data
A1: CONTRACT INFORMATION TRACKER
A2: Taggd RPO — Client Contract Repository
A3: # | B3: Customer | C3: Account Type | D3: Practice Head | E3: Date of Signing | F3: Renewal Date | G3: Signed ACV (₹L) | H3: Current Status | I3: Signed CM% | J3: HC (Headcount) | K3: Hiring Volume | L3: Taggd Source MIX | M3: Other Source Mix | N3: Overall RPH | O3: Overall RPH Number | P3: MMF | Q3: Opening Fee | R3: Payment Terms | S3: Pricing Model | T3: Detail | U3: Remarks
A4: 1 | B4: BITS | C4: RPO | E4: 42584 | F4: 46236 | G4: 40 | H4: Active | P4: No | Q4: No | T4: Attached Contract Copy | U4: Renewal in discussion | X4: %
A5: 2 | B5: Pfizer | C5: RPO | E5: 43286 | F5: 46539 | G5: 170 | H5: Active | I5: 0.7165 | J5: 1.4 | K5: 80 | L5: 1 | M5: 0 | O5: 163681.97 | P5: Yes | Q5: Yes | T5: Attached Contract Copy | X5: Absolute
A6: 3 | B6: Siemens | C6: RPO | E6: 44287 | F6: 46082 | G6: 208 | H6: Expired | P6: No | Q6: No | T6: Attached Contract Copy | U6: Auto-renewed at +8%
A7: 4 | B7: Vertiv | C7: RPO | E7: 44405 | F7: 44406 | G7: 60 | H7: Expired | I7: 0.5628277 | J7: 3 | K7: 80 | L7: 1 | M7: 0 | O7: 69137.5 | P7: Yes | Q7: Yes | T7: Attached Contract Copy
A8: 5 | B8: Pidilite | C8: RPO | E8: 44409 | F8: 46439 | G8: 102.75 | H8: Active | I8: 0.45408617 | J8: 21 | K8: 1550 | L8: 0.8 | M8: 0.1 | O8: 22109.125 | P8: Yes | Q8: No | T8: Attached Contract Copy | U8: Follow-up required
A9: 6 | B9: Birla Paints | C9: RPO | E9: 44574 | F9: 46399 | G9: 220.8 | H9: Active | I9: 0.66954189 | J9: 8.5 | K9: 352 | L9: 0.85 | M9: 0.15 | O9: 64744.832 | P9: No | Q9: No
A10: 7 | B10: Mahindra Holidays | C10: RPO | E10: 44599 | F10: 48251 | G10: 200 | H10: Active | I10: 0.52 | J10: 14.1 | K10: 872 | L10: 0.95 | M10: 0.05 | O10: 22072.133 | P10: Yes | Q10: No
A11: 8 | B11: Ingram Micro | C11: RPO | E11: 44601 | F11: 45689 | G11: 584 | H11: Expired | I11: 0.84 | J11: 15.5 | K11: 500 | L11: 0.9 | M11: 0.1 | O11: 146025 | P11: No | Q11: No
A12: 9 | B12: Siemens Healthineers | C12: RPO | E12: 44629 | F12: 46447 | G12: 304 | H12: Active | P12: No | Q12: No
A13: 10 | B13: Isuzu | C13: RPO | E13: 44645 | F13: 46104 | G13: 128 | H13: Expired | I13: 0.74 | J13: 4.2 | K13: 112 | L13: 0.95 | M13: 0.05 | O13: 141214.29 | P13: No | Q13: No
A14: 11 | B14: HPE | C14: RPO | E14: 44655 | F14: 46327 | G14: 1600 | H14: Active | P14: Yes | Q14: Yes
A15: 12 | B15: Wipro | C15: RPO | E15: 44736 | F15: 46296 | G15: 200 | H15: Active | I15: 0.7 | J15: 6.1 | K15: 220 | L15: 1 | M15: 0 | O15: 115600 | P15: No | Q15: No
A16: 13 | B16: DP World | C16: RPO | E16: 44840 | F16: 46296 | G16: 270 | H16: Active | P16: Yes | Q16: Yes
A17: 14 | B17: SKF India | C17: RPO | E17: 44866 | F17: 46054 | G17: 184 | H17: Expired | I17: 0.451 | J17: 15.1 | K17: 410 | L17: 1 | M17: 0 | O17: 90965.713 | P17: No | Q17: No
A18: 15 | B18: Ametek | C18: RPO | E18: 44965 | F18: 46061 | G18: 96 | H18: Expired | I18: 0.62 | J18: 5.1 | K18: 120 | L18: 0.8 | M18: 0.2 | O18: 106166.83 | P18: No | Q18: No
A19: 16 | B19: Honeywell | C19: RPO | E19: 45017 | F19: 47939 | G19: 1570 | H19: Active | P19: Yes | Q19: No
A20: 17 | B20: Optum | C20: RPO | E20: 45017 | F20: 46419 | G20: 800 | H20: Active | I20: 0.6852 | J20: 23.5 | K20: 800 | L20: 0.75 | M20: 0.25 | O20: 114198.49 | P20: No | Q20: No
A21: 18 | B21: AMNS | C21: RPO | E21: 45022 | F21: 45751 | G21: 672 | H21: Active | I21: 0.79 | J21: 2 | K21: 219 | L21: 1 | M21: 0 | O21: 14691.781 | P21: Yes | Q21: No
A22: 19 | B22: Tata Electronics | C22: RPO | E22: 45063 | F22: 45793 | G22: 181 | H22: Active | I22: 0.73 | J22: 10.1 | K22: 525 | L22: 1 | M22: 0 | O22: 57074.554 | P22: No | Q22: No
A23: 20 | B23: Jindal | C23: RPO | E23: 45147 | F23: 46608 | G23: 176 | H23: Active | I23: 0.69 | J23: 8 | K23: 300 | L23: 0.8 | M23: 0.2 | O23: 75002.6 | P23: No | Q23: No
A24: 21 | B24: M&M | C24: RPO | E24: 45230 | F24: 46327 | G24: 249 | H24: Active | I24: 0.795 | J24: 7.5 | K24: 142 | L24: 0.9 | M24: 0.1 | O24: 392032.96 | P24: No | Q24: No
A25: 22 | B25: Schaeffler | C25: RPO | E25: 45232 | F25: 46175 | G25: 173.825 | H25: Active | I25: 0.74 | J25: 8.1 | K25: 250 | L25: 0.9 | M25: 0.1 | O25: 114797.2 | P25: No | Q25: No
A26: 23 | B26: Royal Enfield | C26: RPO | E26: 45260 | F26: 46356 | G26: 74.88 | H26: Active | I26: 0.63 | J26: 5 | K26: 160 | L26: 0.9 | M26: 0.1 | O26: 78627.075 | P26: No | Q26: No
A27: 24 | B27: Maruti Suzuki | C27: RPO | E27: 45299 | F27: 46395 | G27: 221 | H27: Active | I27: 0.57 | J27: 14.1 | K27: 400 | L27: 0.9 | M27: 0.1 | O27: 62167.5 | P27: No | Q27: No
A28: 25 | B28: Nagarjuna Education | C28: RPO | E28: 45299 | F28: 46416 | G28: 221 | H28: Active | P28: No | Q28: No
A29: 26 | B29: SBI Cards | C29: RPO | E29: 45338 | F29: 46432 | G29: 310 | H29: Active | I29: 0.59 | J29: 16.5 | K29: 650 | L29: 0.75 | M29: 0.25 | O29: 56847.052 | P29: No | Q29: No
A30: 27 | B30: Hyundai | C30: RPO | E30: 45343 | F30: 47170 | G30: 137 | H30: Active | I30: 0.63 | J30: 7.1 | K30: 300 | L30: 1 | M30: 0 | O30: 51038.333 | P30: No | Q30: No
A31: 28 | B31: Tata Consumer | C31: RPO | E31: 45366 | F31: 45901 | G31: 207.2 | H31: Expired | I31: 0.77 | J31: 6.1 | K31: 360 | L31: 0.6 | M31: 0.4 | O31: 59928.333 | P31: Yes | Q31: No
A32: 29 | B32: Excelacom Technologies | C32: RPO | E32: 45372 | F32: 46467 | G32: 93.5 | H32: Active | I32: 0.62 | J32: 4.1 | K32: 120 | L32: 0.9 | M32: 0.1 | O32: 85751.667 | P32: No | Q32: No
A33: 30 | B33: Tata Play | C33: RPO | E33: 45404 | F33: 46499 | G33: 79.6 | H33: Active | I33: 0.66 | J33: 3.1 | K33: 100 | L33: 0.95 | M33: 0.05 | O33: 89732.5 | P33: No | Q33: No
A34: 31 | B34: Mahindra Finance | C34: RPO | E34: 45411 | F34: 46141 | G34: 158.4 | H34: Active | I34: 0.6495 | J34: 5.1 | K34: 180 | L34: 0.95 | M34: 0.05 | O34: 102030.28 | P34: No | Q34: No
A35: 32 | B35: Suzuki R&D | C35: RPO | E35: 45490 | F35: 45855 | G35: 34.2 | H35: Expired | I35: 0.76 | J35: 2.1 | K35: 13 | L35: 1 | M35: 0 | O35: 310407.69 | P35: No | Q35: No
A36: 33 | B36: Atomberg | C36: RPO | E36: 45516 | F36: 46611 | G36: 103 | H36: Active | I36: 0.59 | J36: 4.1 | K36: 120 | L36: 0.9 | M36: 0.1 | O36: 84339.417 | P36: No | Q36: No
A37: 34 | B37: Subros | C37: RPO | E37: 45518 | F37: 46249 | G37: 103 | H37: Active | I37: 0.4957 | J37: 4.1 | K37: 120 | L37: 0.8 | M37: 0.2 | O37: 76476.533 | P37: No | Q37: No
A38: 35 | B38: Ambuja Cements | C38: RPO | E38: 45562 | F38: 46657 | G38: 111.9 | H38: Active | I38: 0.64 | J38: 37 | K38: 1500 | L38: 0.8 | M38: 0.2 | O38: 74635.346 | P38: Yes | Q38: No
A39: 36 | B39: Ashok Leyland | C39: RPO | E39: 45587 | F39: 46143 | G39: 386 | H39: Active | I39: 0.675 | J39: 10.1 | K39: 400 | L39: 0.85 | M39: 0.15 | O39: 97346.301 | P39: No | Q39: No
A40: 37 | B40: Bridgestone | C40: RPO | E40: 45600 | F40: 46330 | G40: 103 | H40: Active | I40: 0.5854 | J40: 3.1 | K40: 120 | L40: 0.9 | M40: 0.1 | O40: 83324.684 | P40: Yes | Q40: No
...

Sheet Sign-UpRenewal
A1: Project Sign-Up / Renewal Details
A3: Project ID | B3: Customer Name | C3: Project Name | D3: SBU / BU | E3: Practice Head | F3: Contract Type | G3: Contract Start Date | H3: Contract End Date | I3: Duration (Months) | J3: Renewal Reminder Date | K3: Pricing Model | L3: Agreed Rate / Fee (₹) | M3: Est. Annual Value (₹) | N3: Payment Terms | O3: SOW / MSA (Ref) | P3: SLA Terms Summary | Q3: Positions Contracted | R3: Positions Filled | S3: Renewal Status | T3: Reason for Lapse/Loss | U3: Client Sign-Off Authority | V3: Internal Sign-Off | W3: Revenue Run Rate (₹/Month)
