Workbook

Sheet Timelines
A1: Serial # | B1: Account Name | C1: PH Approval Date | D1: Reporting Date
A2: 1 | B2: Honeywell | C2: 45748 | D2: 45748
A3: 2 | B3: ISUZU (UD Trucks) | C3: Not Reported | D3: Not Reported
A4: 3 | B4: Siemens - GBS | C4: Not approved | D4: 45763
A5: 4 | B5: Siemens - Advanta | C5: Not approved | D5: 45763
A6: 5 | B6: Robert Bosch | C6: NA | D6: NA
A7: 6 | B7: Siemens - Energy | C7: Not approved | D7: 45763
A8: 7 | B8: HPE | C8: NA | D8: NA
A9: 8 | B9: Ametek | C9: NA | D9: NA
A10: 9 | B10: Titan | C10: NA | D10: NA
A11: 10 | B11: BITS | C11: NA | D11: 45745
A12: 11 | B12: P&G | C12: NA | D12: 45740
A13: 12 | B13: DP World | C13: Not Reported | D13: Not Reported
A14: 13 | B14: TATA Electronics | C14: Not approved | D14: 45749
A15: 14 | B15: Royal Enfield | C15: 45763 | D15: 45763
A16: 15 | B16: Ingram Micro | C16: 45757 | D16: 45757
A17: 16 | B17: Wipro | C17: Not approved | D17: 45755
A18: 17 | B18: NomiSo | C18: NA - Hiring on-hold | D18: NA - Hiring on-hold
A19: 18 | B19: SBI Card | C19: Not approved | D19: 45757
A20: 19 | B20: SKF | C20: Not approved | D20: 45757
A21: 20 | B21: Jindal | C21: Not approved | D21: 45756
A22: 21 | B22: Tata Motors | C22: Inactive Account | D22: Inactive Account
A23: 22 | B23: Vertiv Energy | C23: Not approved | D23: 45754
A24: 23 | B24: Thyssenkrupp | C24: Inactive Account | D24: Inactive Account
A25: 24 | B25: TATA Marco Polo | C25: Inactive Account | D25: Inactive Account
A26: 25 | B26: Schaeffler | C26: Not approved | D26: 45755
A27: 26 | B27: M&M | C27: 45763 | D27: 45757
A28: 27 | B28: Mahindra Holidays | C28: Not Reported | D28: Not Reported
A29: 28 | B29: Pidilite | C29: 45761 | D29: 45758
A30: 29 | B30: TATA Power | C30: NA - Project On-hold | D30: NA - Project On-hold
A31: 30 | B31: Birla Paints | C31: Not approved | D31: 45757
A32: 31 | B32: Fedex | C32: NA - Hiring on-hold | D32: NA - Hiring on-hold
A33: 32 | B33: AMNS | C33: Not approved | D33: 45763
A34: 33 | B34: TATA Tele | C34: NA - Project On-hold | D34: NA - Project On-hold
A35: 34 | B35: WTW | C35: NA - Project On-hold | D35: NA - Project On-hold
A36: 35 | B36: Pfizer | C36: Not approved | D36: 45758
A37: 36 | B37: Excelacom | C37: Moved to Enrichment Platform | D37: Moved to Enrichment Platform
A38: 37 | B38: Hyundai | C38: 45749 | D38: 45749
A39: 38 | B39: Maruti Suzuki | C39: Not Reported | D39: Not Reported
A40: 39 | B40: TATA Fiber | C40: NA - No Offer & Joiner | D40: NA - No Offer & Joiner
...

Sheet RAG Logics
B2: RAG | C2: Reporting Status | D2: Validation Status | E2: MET %
C3: Not Reported | D3: Not Validated | E3: < 50%
C4: Not Applicable | D4: Partially Validated | E4: > = 50% - < 75%
C5: Reported | D5: Validated | E5: > = 75 %
B8: * MET% - %(Total MET Metrics / Total Metrics Reported) (([Excludes - NA & Not Reported]))
B9: ** Accounts : < = 6months of Go-Live will have no RAG, Only MET % will be reported
B10: *** All Metrics will have equal weightages for calculations (SLA or KPI)

Sheet Region Summary
F2: April 2024 | G2: April 2024 | H2: April 2024 | I2: April 2024 | J2: May 2024 | K2: May 2024 | L2: May 2024 | M2: May 2024 | N2: June 2024 | O2: June 2024 | P2: June 2024 | Q2: June 2024 | R2: AMJ 2024 | S2: AMJ 2024 | T2: AMJ 2024 | U2: AMJ 2024 | V2: July 2024 | W2: July 2024 | X2: July 2024 | Y2: July 2024 | Z2: August 2024 | AA2: August 2024 | AB2: August 2024 | AC2: August 2024 | AD2: September 2024 | AE2: September 2024 | AF2: September 2024 | AG2: September 2024 | AH2: JAS 2024 | AI2: JAS 2024 | AJ2: JAS 2024 | AK2: JAS 2024 | AL2: Oct 2024 | AM2: Oct 2024 | AN2: Oct 2024 | AO2: Oct 2024 | AP2: Nov 2024 | AQ2: Nov 2024 | AR2: Nov 2024 | AS2: Nov 2024 | AT2: Dec 2024 | AU2: Dec 2024 | AV2: Dec 2024 | AW2: Dec 2024 | AX2: OND 2024 | AY2: OND 2024 | AZ2: OND 2024 | BA2: OND 2024 | BB2: Jan 2025 | BC2: Jan 2025 | BD2: Jan 2025 | BE2: Jan 2025 | BF2: Feb 2025 | BG2: Feb 2025 | BH2: Feb 2025 | BI2: Feb 2025 | BJ2: Mar 2025 | BK2: Mar 2025 | BL2: Mar 2025 | BM2: Mar 2025 | BN2: JFM 2025 | BO2: JFM 2025 | BP2: JFM 2025 | BQ2: JFM 2025 | BR2: YTD 2024-2025 | BS2: YTD 2024-2025 | BT2: YTD 2024-2025 | BU2: YTD 2024-2025 | BV2: 45748 | BW2: 45748 | BX2: 45748 | BY2: 45748 | BZ2: June 2025 | CA2: June 2025 | CB2: June 2025 | CC2: June 2025 | CD2: AMJ-25 | CE2: AMJ-25 | CF2: AMJ-25 | CG2: AMJ-25 | CH2: July 2025 | CI2: July 2025 | CJ2: July 2025 | CK2: July 2025 | CL2: 45894 | CM2: 45894 | CN2: 45894 | CO2: 45894 | CP2: 45925 | CQ2: 45925 | CR2: 45925 | CS2: 45925 | CT2: Oct 2025 | CU2: Oct-2025 | CV2: Oct-2025 | CW2: Oct-2025 | CX2: Nov 2025 | CY2: Nov 2025 | CZ2: Nov 2025 | DA2: Nov 2025 | DB2: JAS-2025 | DC2: JAS-2025 | DD2: JAS-2025 | DE2: JAS-2025 | DF2: Dec 2025 | DG2: Dec 2025 | DH2: Dec 2025 | DI2: Dec 2025 | DJ2: OND 2025 | DK2: OND 2025 | DL2: OND 2025 | DM2: OND 2025 | DN2: Jan 2026 | DO2: Jan 2026 | DP2: Jan 2026 | DQ2: Jan 2026 | DR2: YTD 2025-2026 | DS2: YTD 2025-2026 | DT2: YTD 2025-2026 | DU2: YTD 2025-2026
A3: Serial # | B3: Region Name | C3: PH | D3: Reporting Status | E3: Audit Status | F3: Overall MET% | G3: Contractual Non- Penalty MET% | H3: Contractual Penalty MET% | I3: Internal KPI MET% | J3: Overall MET% | K3: Contractual Non- Penalty MET% | L3: Contractual Penalty MET% | M3: Internal KPI MET% | N3: Overall MET% | O3: Contractual Non- Penalty MET% | P3: Contractual Penalty MET% | Q3: Internal KPI MET% | R3: Overall MET% | S3: Contractual Non- Penalty MET% | T3: Contractual Penalty MET% | U3: Internal KPI MET% | V3: Overall MET% | W3: Contractual Non- Penalty MET% | X3: Contractual Penalty MET% | Y3: Internal KPI MET% | Z3: Overall MET% | AA3: Contractual Non- Penalty MET% | AB3: Contractual Penalty MET% | AC3: Internal KPI MET% | AD3: Overall MET% | AE3: Contractual Non- Penalty MET% | AF3: Contractual Penalty MET% | AG3: Internal KPI MET% | AH3: Overall MET% | AI3: Contractual Non- Penalty MET% | AJ3: Contractual Penalty MET% | AK3: Internal KPI MET% | AL3: Overall MET% | AM3: Contractual Non- Penalty MET% | AN3: Contractual Penalty MET% | AO3: Internal KPI MET% | AP3: Overall MET% | AQ3: Contractual Non- Penalty MET% | AR3: Contractual Penalty MET% | AS3: Internal KPI MET% | AT3: Overall MET% | AU3: Contractual Non- Penalty MET% | AV3: Contractual Penalty MET% | AW3: Internal KPI MET% | AX3: Overall MET% | AY3: Contractual Non- Penalty MET% | AZ3: Contractual Penalty MET% | BA3: Internal KPI MET% | BB3: Overall MET% | BC3: Contractual Non- Penalty MET% | BD3: Contractual Penalty MET% | BE3: Internal KPI MET% | BF3: Overall MET% | BG3: Contractual Non- Penalty MET% | BH3: Contractual Penalty MET% | BI3: Internal KPI MET% | BJ3: Overall MET% | BK3: Contractual Non- Penalty MET% | BL3: Contractual Penalty MET% | BM3: Internal KPI MET% | BN3: Overall MET% | BO3: Contractual Non- Penalty MET% | BP3: Contractual Penalty MET% | BQ3: Internal KPI MET% | BR3: Overall MET% | BS3: Contractual Non- Penalty MET% | BT3: Contractual Penalty MET% | BU3: Internal KPI MET% | BV3: Overall MET% | BW3: Contractual Non- Penalty MET% | BX3: Contractual Penalty MET% | BY3: Internal KPI MET% | BZ3: Overall MET% | CA3: Contractual Non- Penalty MET% | CB3: Contractual Penalty MET% | CC3: Internal KPI MET% | CD3: Overall MET% | CE3: Contractual Non- Penalty MET% | CF3: Contractual Penalty MET% | CG3: Internal KPI MET% | CH3: Overall MET% | CI3: Contractual Non- Penalty MET% | CJ3: Contractual Penalty MET% | CK3: Internal KPI MET% | CL3: Overall MET% | CM3: Contractual Non- Penalty MET% | CN3: Contractual Penalty MET% | CO3: Internal KPI MET% | CP3: Overall MET% | CQ3: Contractual Non- Penalty MET% | CR3: Contractual Penalty MET% | CS3: Internal KPI MET% | CT3: Overall MET% | CU3: Contractual Non- Penalty MET% | CV3: Contractual Penalty MET% | CW3: Internal KPI MET% | CX3: Overall MET% | CY3: Contractual Non- Penalty MET% | CZ3: Contractual Penalty MET% | DA3: Internal KPI MET% | DB3: Overall MET% | DC3: Contractual Non- Penalty MET% | DD3: Contractual Penalty MET% | DE3: Internal KPI MET% | DF3: Overall MET% | DG3: Contractual Non- Penalty MET% | DH3: Contractual Penalty MET% | DI3: Internal KPI MET% | DJ3: Overall MET% | DK3: Contractual Non- Penalty MET% | DL3: Contractual Penalty MET% | DM3: Internal KPI MET% | DN3: Overall MET% | DO3: Contractual Non- Penalty MET% | DP3: Contractual Penalty MET% | DQ3: Internal KPI MET% | DR3: Overall MET% | DS3: Contractual Non- Penalty MET% | DT3: Contractual Penalty MET% | DU3: Internal KPI MET%
A4: 1 | B4: Bangalore | C4: Sulabh | D4: Partially Reported | E4: Partially Validated | F4: 0.64 | G4: 0.96 | H4: 0.69 | I4: 0.38 | J4: =50/73 -> 0.68493151 | K4: =23/25 -> 0.92 | L4: =10/13 -> 0.76923077 | M4: =17/35 -> 0.48571429 | N4: =IFERROR(COUNTIFS('Base File'!$V:$V,"Met",'Base File'!$C:$C,B4)/(COUNTIFS('Base File'!$V:$V,"Met",'Base File'!$C:$C,B4)+COUNTIFS('Base File'!$V:$V,"Not Met",'Base File'!$C:$C,B4)),"NR") -> NR | O4: =IFERROR(COUNTIFS('Base File'!$G:$G,"Contractual SLA",'Base File'!$H:$H,"No",'Base File'!$C:$C,B4,'Base File'!$V:$V,"Met")/SUM(COUNTIFS('Base File'!$G:$G,"Contractual SLA",'Base File'!$H:$H,"No",'Base File'!$C:$C,B4,'Base File'!$V:$V,"Met")+COUNTIFS('Base File'!$G:$G,"Contractual SLA",'Base File'!$H:$H,"No",'Base File'!$C:$C,B4,'Base File'!$V:$V,"Not Met")),"-") -> - | P4: =IFERROR(COUNTIFS('Base File'!$G:$G,"Contractual SLA",'Base File'!$H:$H,"Yes",'Base File'!$C:$C,B4,'Base File'!$V:$V,"Met")/SUM(COUNTIFS('Base File'!$G:$G,"Contractual SLA",'Base File'!$H:$H,"yes",'Base File'!$C:$C,B4,'Base File'!$V:$V,"Met")+COUNTIFS('Base File'!$G:$G,"Contractual SLA",'Base File'!$H:$H,"yes",'Base File'!$C:$C,B4,'Base File'!$V:$V,"Not Met")),"-") -> - | Q4: =IFERROR(COUNTIFS('Base File'!$G:$G,"Internal KPI",'Base File'!$C:$C,B4,'Base File'!$V:$V,"Met")/SUM(COUNTIFS('Base File'!$G:$G,"Internal KPI",'Base File'!$C:$C,B4,'Base File'!$V:$V,"Met")+COUNTIFS('Base File'!$G:$G,"Internal KPI",'Base File'!$C:$C,B4,'Base File'!$V:$V,"Not Met")),"-") -> - | R4: =BR4 -> 0.75 | S4: =BS4 -> 0.9375 | T4: =BT4 -> NR | U4: =BU4 -> 0.625 | V4: =IFERROR(COUNTIFS('Base File'!$X:$X,"Met",'Base File'!$C:$C,B4)/(COUNTIFS('Base File'!$X:$X,"Met",'Base File'!$C:$C,B4)+COUNTIFS('Base File'!$X:$X,"Not Met",'Base File'!$C:$C,B4)),"NR") -> NR | W4: =IFERROR(COUNTIFS('Base File'!$G:$G,"Contractual SLA",'Base File'!$H:$H,"No",'Base File'!$C:$C,B4,'Base File'!$X:$X,"Met")/SUM(COUNTIFS('Base File'!$G:$G,"Contractual SLA",'Base File'!$H:$H,"No",'Base File'!$C:$C,B4,'Base File'!$X:$X,"Met")+COUNTIFS('Base File'!$G:$G,"Contractual SLA",'Base File'!$H:$H,"No",'Base File'!$C:$C,B4,'Base File'!$X:$X,"Not Met")),"-") -> - | X4: =IFERROR(COUNTIFS('Base File'!$G:$G,"Contractual SLA",'Base File'!$H:$H,"Yes",'Base File'!$C:$C,B4,'Base File'!$X:$X,"Met")/SUM(COUNTIFS('Base File'!$G:$G,"Contractual SLA",'Base File'!$H:$H,"yes",'Base File'!$C:$C,B4,'Base File'!$X:$X,"Met")+COUNTIFS('Base File'!$G:$G,"Contractual SLA",'Base File'!$H:$H,"yes",'Base File'!$C:$C,B4,'Base File'!$X:$X,"Not Met")),"-") -> - | Y4: =IFERROR(COUNTIFS('Base File'!$G:$G,"Internal KPI",'Base File'!$C:$C,B4,'Base File'!$X:$X,"Met")/SUM(COUNTIFS('Base File'!$G:$G,"Internal KPI",'Base File'!$C:$C,B4,'Base File'!$X:$X,"Met")+COUNTIFS('Base File'!$G:$G,"Internal KPI",'Base File'!$C:$C,B4,'Base File'!$X:$X,"Not Met")),"-") -> - | Z4: =IFERROR(COUNTIFS('Base File'!$Z:$Z,"Met",'Base File'!$C:$C,B4)/(COUNTIFS('Base File'!$Z:$Z,"Met",'Base File'!$C:$C,B4)+COUNTIFS('Base File'!$Z:$Z,"Not Met",'Base File'!$C:$C,B4)),"NR") -> NR | AA4: =IFERROR(COUNTIFS('Base File'!$G:$G,"Contractual SLA",'Base File'!$H:$H,"No",'Base File'!$C:$C,B4,'Base File'!$Z:$Z,"Met")/SUM(COUNTIFS('Base File'!$G:$G,"Contractual SLA",'Base File'!$H:$H,"No",'Base File'!$C:$C,B4,'Base File'!$Z:$Z,"Met")+COUNTIFS('Base File'!$G:$G,"Contractual SLA",'Base File'!$H:$H,"No",'Base File'!$C:$C,B4,'Base File'!$Z:$Z,"Not Met")),"-") -> - | AB4: =IFERROR(COUNTIFS('Base File'!$G:$G,"Contractual SLA",'Base File'!$H:$H,"Yes",'Base File'!$C:$C,B4,'Base File'!$Z:$Z,"Met")/SUM(COUNTIFS('Base File'!$G:$G,"Contractual SLA",'Base File'!$H:$H,"yes",'Base File'!$C:$C,B4,'Base File'!$Z:$Z,"Met")+COUNTIFS('Base File'!$G:$G,"Contractual SLA",'Base File'!$H:$H,"yes",'Base File'!$C:$C,B4,'Base File'!$Z:$Z,"Not Met")),"-") -> - | AC4: =IFERROR(COUNTIFS('Base File'!$G:$G,"Internal KPI",'Base File'!$C:$C,B4,'Base File'!$Z:$Z,"Met")/SUM(COUNTIFS('Base File'!$G:$G,"Internal KPI",'Base File'!$C:$C,B4,'Base File'!$Z:$Z,"Met")+COUNTIFS('Base File'!$G:$G,"Internal KPI",'Base File'!$C:$C,B4,'Base File'!$Z:$Z,"Not Met")),"-") -> - | AD4: =IFERROR(COUNTIFS('Base File'!$AB:$AB,"Met",'Base File'!$C:$C,B4)/(COUNTIFS('Base File'!$AB:$AB,"Met",'Base File'!$C:$C,B4)+COUNTIFS('Base File'!$AB:$AB,"Not Met",'Base File'!$C:$C,B4)),"NR") -> NR | AE4: =IFERROR(COUNTIFS('Base File'!$G:$G,"Contractual SLA",'Base File'!$H:$H,"No",'Base File'!$C:$C,B4,'Base File'!$AB:$AB,"Met")/SUM(COUNTIFS('Base File'!$G:$G,"Contractual SLA",'Base File'!$H:$H,"No",'Base File'!$C:$C,B4,'Base File'!$AB:$AB,"Met")+COUNTIFS('Base File'!$G:$G,"Contractual SLA",'Base File'!$H:$H,"No",'Base File'!$C:$C,B4,'Base File'!$AB:$AB,"Not Met")),"-") -> - | AF4: =IFERROR(COUNTIFS('Base File'!$G:$G,"Contractual SLA",'Base File'!$H:$H,"Yes",'Base File'!$C:$C,B4,'Base File'!$AB:$AB,"Met")/SUM(COUNTIFS('Base File'!$G:$G,"Contractual SLA",'Base File'!$H:$H,"yes",'Base File'!$C:$C,B4,'Base File'!$AB:$AB,"Met")+COUNTIFS('Base File'!$G:$G,"Contractual SLA",'Base File'!$H:$H,"yes",'Base File'!$C:$C,B4,'Base File'!$AB:$AB,"Not Met")),"-") -> - | AG4: =IFERROR(COUNTIFS('Base File'!$G:$G,"Internal KPI",'Base File'!$C:$C,B4,'Base File'!$AB:$AB,"Met")/SUM(COUNTIFS('Base File'!$G:$G,"Internal KPI",'Base File'!$C:$C,B4,'Base File'!$AB:$AB,"Met")+COUNTIFS('Base File'!$G:$G,"Internal KPI",'Base File'!$C:$C,B4,'Base File'!$AB:$AB,"Not Met")),"-") -> - | AH4: =IFERROR(COUNTIFS('Base File'!$AD:$AD,"Met",'Base File'!$C:$C,B4)/(COUNTIFS('Base File'!$AD:$AD,"Met",'Base File'!$C:$C,B4)+COUNTIFS('Base File'!$AD:$AD,"Not Met",'Base File'!$C:$C,B4)),"NR") -> NR | AI4: =IFERROR(COUNTIFS('Base File'!$G:$G,"Contractual SLA",'Base File'!$H:$H,"No",'Base File'!$C:$C,B4,'Base File'!$AD:$AD,"Met")/SUM(COUNTIFS('Base File'!$G:$G,"Contractual SLA",'Base File'!$H:$H,"No",'Base File'!$C:$C,B4,'Base File'!$AD:$AD,"Met")+COUNTIFS('Base File'!$G:$G,"Contractual SLA",'Base File'!$H:$H,"No",'Base File'!$C:$C,B4,'Base File'!$AD:$AD,"Not Met")),"-") -> - | AJ4: =IFERROR(COUNTIFS('Base File'!$G:$G,"Contractual SLA",'Base File'!$H:$H,"Yes",'Base File'!$C:$C,B4,'Base File'!$AD:$AD,"Met")/SUM(COUNTIFS('Base File'!$G:$G,"Contractual SLA",'Base File'!$H:$H,"yes",'Base File'!$C:$C,B4,'Base File'!$AD:$AD,"Met")+COUNTIFS('Base File'!$G:$G,"Contractual SLA",'Base File'!$H:$H,"yes",'Base File'!$C:$C,B4,'Base File'!$AD:$AD,"Not Met")),"-") -> - | AK4: =IFERROR(COUNTIFS('Base File'!$G:$G,"Internal KPI",'Base File'!$C:$C,B4,'Base File'!$AD:$AD,"Met")/SUM(COUNTIFS('Base File'!$G:$G,"Internal KPI",'Base File'!$C:$C,B4,'Base File'!$AD:$AD,"Met")+COUNTIFS('Base File'!$G:$G,"Internal KPI",'Base File'!$C:$C,B4,'Base File'!$AD:$AD,"Not Met")),"-") -> - | AL4: =25/33 -> 0.75757576 | AM4: =15/15 -> 1 | AN4: NR | AO4: =10/18 -> 0.55555556 | AP4: =23/33 -> 0.6969697 | AQ4: =13/15 -> 0.86666667 | AR4: NR | AS4: =10/18 -> 0.55555556 | AT4: =24/33 -> 0.72727273 | AU4: =14/15 -> 0.93333333 | AV4: NR | AW4: =10/18 -> 0.55555556 | AX4: NR | AY4: NR | AZ4: NR | BA4: NR | BB4: =25/33 -> 0.75757576 | BC4: =14/15 -> 0.93333333 | BD4: NR | BE4: =11/18 -> 0.61111111 | BF4: =27/40 -> 0.675 | BG4: =12/16 -> 0.75 | BH4: NR | BI4: =15/24 -> 0.625 | BJ4: =27/40 -> 0.675 | BK4: =12/16 -> 0.75 | BL4: NR | BM4: =15/24 -> 0.625 | BN4: =28/40 -> 0.7 | BO4: =14/16 -> 0.875 | BP4: NR | BQ4: =14/24 -> 0.58333333 | BR4: =30/40 -> 0.75 | BS4: =15/16 -> 0.9375 | BT4: NR | BU4: =15/24 -> 0.625 | BV4: =32/40 -> 0.8 | BW4: =14/16 -> 0.875 | BX4: NR | BY4: =18/24 -> 0.75 | BZ4: =33/41 -> 0.80487805 | CA4: =14/16 -> 0.875 | CB4: NR | CC4: =19/25 -> 0.76 | CD4: =33/41 -> 0.80487805 | CE4: =15/16 -> 0.9375 | CF4: NR | CG4: =18/25 -> 0.72 | CH4: =28/40 -> 0.7 | CI4: =10/15 -> 0.66666667 | CJ4: NR | CK4: =18/25 -> 0.72 | CL4: =28/40 -> 0.7 | CM4: =13/15 -> 0.86666667 | CN4: NR | CO4: =15/25 -> 0.6 | CP4: =6/7 -> 0.85714286 | CQ4: NR | CR4: NR | CS4: =6/7 -> 0.85714286 | CT4: =31/40 -> 0.775 | CU4: =14/15 -> 0.93333333 | CV4: NR | CW4: =17/25 -> 0.68 | DF4: =6/7 -> 0.85714286 | DG4: NR | DH4: NR | DI4: =6/7 -> 0.85714286 | DJ4: =6/7 -> 0.85714286 | DK4: NR | DL4: NR | DM4: =6/7 -> 0.85714286 | DN4: =34/48 -> 0.70833333 | DO4: =15/15 -> 1 | DP4: =0/2 -> 0 | DQ4: =19/31 -> 0.61290323 | DR4: =37/48 -> 0.77083333 | DS4: =14/15 -> 0.93333333 | DT4: =1/2 -> 0.5 | DU4: =22/31 -> 0.70967742
A5: 2 | B5: Chennai | C5: Krishna | D5: Partially Reported | E5: Partially Validated | F5: =8/8 -> 1 | G5: NR | H5: NA | I5: NR | J5: =11/13 -> 0.84615385 | K5: =8/8 -> 1 | L5: NA | M5: =3/5 -> 0.6 | N5: =IFERROR(COUNTIFS('Base File'!$V:$V,"Met",'Base File'!$C:$C,B5)/(COUNTIFS('Base File'!$V:$V,"Met",'Base File'!$C:$C,B5)+COUNTIFS('Base File'!$V:$V,"Not Met",'Base File'!$C:$C,B5)),"NR") -> NR | O5: =IFERROR(COUNTIFS('Base File'!$G:$G,"Contractual SLA",'Base File'!$H:$H,"No",'Base File'!$C:$C,B5,'Base File'!$V:$V,"Met")/SUM(COUNTIFS('Base File'!$G:$G,"Contractual SLA",'Base File'!$H:$H,"No",'Base File'!$C:$C,B5,'Base File'!$V:$V,"Met")+COUNTIFS('Base File'!$G:$G,"Contractual SLA",'Base File'!$H:$H,"No",'Base File'!$C:$C,B5,'Base File'!$V:$V,"Not Met")),"-") -> - | P5: =IFERROR(COUNTIFS('Base File'!$G:$G,"Contractual SLA",'Base File'!$H:$H,"Yes",'Base File'!$C:$C,B5,'Base File'!$V:$V,"Met")/SUM(COUNTIFS('Base File'!$G:$G,"Contractual SLA",'Base File'!$H:$H,"yes",'Base File'!$C:$C,B5,'Base File'!$V:$V,"Met")+COUNTIFS('Base File'!$G:$G,"Contractual SLA",'Base File'!$H:$H,"yes",'Base File'!$C:$C,B5,'Base File'!$V:$V,"Not Met")),"-") -> - | Q5: =IFERROR(COUNTIFS('Base File'!$G:$G,"Internal KPI",'Base File'!$C:$C,B5,'Base File'!$V:$V,"Met")/SUM(COUNTIFS('Base File'!$G:$G,"Internal KPI",'Base File'!$C:$C,B5,'Base File'!$V:$V,"Met")+COUNTIFS('Base File'!$G:$G,"Internal KPI",'Base File'!$C:$C,B5,'Base File'!$V:$V,"Not Met")),"-") -> - | R5: =BR5 -> 0.57894737 | S5: =BS5 -> 1 | T5: =BT5 -> NA | U5: =BU5 -> 0 | V5: =IFERROR(COUNTIFS('Base File'!$X:$X,"Met",'Base File'!$C:$C,B5)/(COUNTIFS('Base File'!$X:$X,"Met",'Base File'!$C:$C,B5)+COUNTIFS('Base File'!$X:$X,"Not Met",'Base File'!$C:$C,B5)),"NR") -> NR | W5: =IFERROR(COUNTIFS('Base File'!$G:$G,"Contractual SLA",'Base File'!$H:$H,"No",'Base File'!$C:$C,B5,'Base File'!$X:$X,"Met")/SUM(COUNTIFS('Base File'!$G:$G,"Contractual SLA",'Base File'!$H:$H,"No",'Base File'!$C:$C,B5,'Base File'!$X:$X,"Met")+COUNTIFS('Base File'!$G:$G,"Contractual SLA",'Base File'!$H:$H,"No",'Base File'!$C:$C,B5,'Base File'!$X:$X,"Not Met")),"-") -> - | X5: =IFERROR(COUNTIFS('Base File'!$G:$G,"Contractual SLA",'Base File'!$H:$H,"Yes",'Base File'!$C:$C,B5,'Base File'!$X:$X,"Met")/SUM(COUNTIFS('Base File'!$G:$G,"Contractual SLA",'Base File'!$H:$H,"yes",'Base File'!$C:$C,B5,'Base File'!$X:$X,"Met")+COUNTIFS('Base File'!$G:$G,"Contractual SLA",'Base File'!$H:$H,"yes",'Base File'!$C:$C,B5,'Base File'!$X:$X,"Not Met")),"-") -> - | Y5: =IFERROR(COUNTIFS('Base File'!$G:$G,"Internal KPI",'Base File'!$C:$C,B5,'Base File'!$X:$X,"Met")/SUM(COUNTIFS('Base File'!$G:$G,"Internal KPI",'Base File'!$C:$C,B5,'Base File'!$X:$X,"Met")+COUNTIFS('Base File'!$G:$G,"Internal KPI",'Base File'!$C:$C,B5,'Base File'!$X:$X,"Not Met")),"-") -> - | Z5: =IFERROR(COUNTIFS('Base File'!$Z:$Z,"Met",'Base File'!$C:$C,B5)/(COUNTIFS('Base File'!$Z:$Z,"Met",'Base File'!$C:$C,B5)+COUNTIFS('Base File'!$Z:$Z,"Not Met",'Base File'!$C:$C,B5)),"NR") -> NR | AA5: =IFERROR(COUNTIFS('Base File'!$G:$G,"Contractual SLA",'Base File'!$H:$H,"No",'Base File'!$C:$C,B5,'Base File'!$Z:$Z,"Met")/SUM(COUNTIFS('Base File'!$G:$G,"Contractual SLA",'Base File'!$H:$H,"No",'Base File'!$C:$C,B5,'Base File'!$Z:$Z,"Met")+COUNTIFS('Base File'!$G:$G,"Contractual SLA",'Base File'!$H:$H,"No",'Base File'!$C:$C,B5,'Base File'!$Z:$Z,"Not Met")),"-") -> - | AB5: =IFERROR(COUNTIFS('Base File'!$G:$G,"Contractual SLA",'Base File'!$H:$H,"Yes",'Base File'!$C:$C,B5,'Base File'!$Z:$Z,"Met")/SUM(COUNTIFS('Base File'!$G:$G,"Contractual SLA",'Base File'!$H:$H,"yes",'Base File'!$C:$C,B5,'Base File'!$Z:$Z,"Met")+COUNTIFS('Base File'!$G:$G,"Contractual SLA",'Base File'!$H:$H,"yes",'Base File'!$C:$C,B5,'Base File'!$Z:$Z,"Not Met")),"-") -> - | AC5: =IFERROR(COUNTIFS('Base File'!$G:$G,"Internal KPI",'Base File'!$C:$C,B5,'Base File'!$Z:$Z,"Met")/SUM(COUNTIFS('Base File'!$G:$G,"Internal KPI",'Base File'!$C:$C,B5,'Base File'!$Z:$Z,"Met")+COUNTIFS('Base File'!$G:$G,"Internal KPI",'Base File'!$C:$C,B5,'Base File'!$Z:$Z,"Not Met")),"-") -> - | AD5: =IFERROR(COUNTIFS('Base File'!$AB:$AB,"Met",'Base File'!$C:$C,B5)/(COUNTIFS('Base File'!$AB:$AB,"Met",'Base File'!$C:$C,B5)+COUNTIFS('Base File'!$AB:$AB,"Not Met",'Base File'!$C:$C,B5)),"NR") -> NR | AE5: =IFERROR(COUNTIFS('Base File'!$G:$G,"Contractual SLA",'Base File'!$H:$H,"No",'Base File'!$C:$C,B5,'Base File'!$AB:$AB,"Met")/SUM(COUNTIFS('Base File'!$G:$G,"Contractual SLA",'Base File'!$H:$H,"No",'Base File'!$C:$C,B5,'Base File'!$AB:$AB,"Met")+COUNTIFS('Base File'!$G:$G,"Contractual SLA",'Base File'!$H:$H,"No",'Base File'!$C:$C,B5,'Base File'!$AB:$AB,"Not Met")),"-") -> - | AF5: =IFERROR(COUNTIFS('Base File'!$G:$G,"Contractual SLA",'Base File'!$H:$H,"Yes",'Base File'!$C:$C,B5,'Base File'!$AB:$AB,"Met")/SUM(COUNTIFS('Base File'!$G:$G,"Contractual SLA",'Base File'!$H:$H,"yes",'Base File'!$C:$C,B5,'Base File'!$AB:$AB,"Met")+COUNTIFS('Base File'!$G:$G,"Contractual SLA",'Base File'!$H:$H,"yes",'Base File'!$C:$C,B5,'Base File'!$AB:$AB,"Not Met")),"-") -> - | AG5: =IFERROR(COUNTIFS('Base File'!$G:$G,"Internal KPI",'Base File'!$C:$C,B5,'Base File'!$AB:$AB,"Met")/SUM(COUNTIFS('Base File'!$G:$G,"Internal KPI",'Base File'!$C:$C,B5,'Base File'!$AB:$AB,"Met")+COUNTIFS('Base File'!$G:$G,"Internal KPI",'Base File'!$C:$C,B5,'Base File'!$AB:$AB,"Not Met")),"-") -> - | AH5: =IFERROR(COUNTIFS('Base File'!$AD:$AD,"Met",'Base File'!$C:$C,B5)/(COUNTIFS('Base File'!$AD:$AD,"Met",'Base File'!$C:$C,B5)+COUNTIFS('Base File'!$AD:$AD,"Not Met",'Base File'!$C:$C,B5)),"NR") -> NR | AI5: =IFERROR(COUNTIFS('Base File'!$G:$G,"Contractual SLA",'Base File'!$H:$H,"No",'Base File'!$C:$C,B5,'Base File'!$AD:$AD,"Met")/SUM(COUNTIFS('Base File'!$G:$G,"Contractual SLA",'Base File'!$H:$H,"No",'Base File'!$C:$C,B5,'Base File'!$AD:$AD,"Met")+COUNTIFS('Base File'!$G:$G,"Contractual SLA",'Base File'!$H:$H,"No",'Base File'!$C:$C,B5,'Base File'!$AD:$AD,"Not Met")),"-") -> - | AJ5: =IFERROR(COUNTIFS('Base File'!$G:$G,"Contractual SLA",'Base File'!$H:$H,"Yes",'Base File'!$C:$C,B5,'Base File'!$AD:$AD,"Met")/SUM(COUNTIFS('Base File'!$G:$G,"Contractual SLA",'Base File'!$H:$H,"yes",'Base File'!$C:$C,B5,'Base File'!$AD:$AD,"Met")+COUNTIFS('Base File'!$G:$G,"Contractual SLA",'Base File'!$H:$H,"yes",'Base File'!$C:$C,B5,'Base File'!$AD:$AD,"Not Met")),"-") -> - | AK5: =IFERROR(COUNTIFS('Base File'!$G:$G,"Internal KPI",'Base File'!$C:$C,B5,'Base File'!$AD:$AD,"Met")/SUM(COUNTIFS('Base File'!$G:$G,"Internal KPI",'Base File'!$C:$C,B5,'Base File'!$AD:$AD,"Met")+COUNTIFS('Base File'!$G:$G,"Internal KPI",'Base File'!$C:$C,B5,'Base File'!$AD:$AD,"Not Met")),"-") -> - | AL5: =IFERROR(COUNTIFS('Base File'!$AF:$AF,"Met",'Base File'!$C:$C,B5)/(COUNTIFS('Base File'!$AF:$AF,"Met",'Base File'!$C:$C,B5)+COUNTIFS('Base File'!$AF:$AF,"Not Met",'Base File'!$C:$C,B5)),"NR") -> NR | AM5: =IFERROR(COUNTIFS('Base File'!$G:$G,"Contractual SLA",'Base File'!$H:$H,"No",'Base File'!$C:$C,B5,'Base File'!$AF:$AF,"Met")/SUM(COUNTIFS('Base File'!$G:$G,"Contractual SLA",'Base File'!$H:$H,"No",'Base File'!$C:$C,B5,'Base File'!$AF:$AF,"Met")+COUNTIFS('Base File'!$G:$G,"Contractual SLA",'Base File'!$H:$H,"No",'Base File'!$C:$C,B5,'Base File'!$AF:$AF,"Not Met")),"-") -> - | AN5: =IFERROR(COUNTIFS('Base File'!$G:$G,"Contractual SLA",'Base File'!$H:$H,"Yes",'Base File'!$C:$C,B5,'Base File'!$AF:$AF,"Met")/SUM(COUNTIFS('Base File'!$G:$G,"Contractual SLA",'Base File'!$H:$H,"yes",'Base File'!$C:$C,B5,'Base File'!$AF:$AF,"Met")+COUNTIFS('Base File'!$G:$G,"Contractual SLA",'Base File'!$H:$H,"yes",'Base File'!$C:$C,B5,'Base File'!$AF:$AF,"Not Met")),"-") -> - | AO5: =IFERROR(COUNTIFS('Base File'!$G:$G,"Internal KPI",'Base File'!$C:$C,B5,'Base File'!$AF:$AF,"Met")/SUM(COUNTIFS('Base File'!$G:$G,"Internal KPI",'Base File'!$C:$C,B5,'Base File'!$AF:$AF,"Met")+COUNTIFS('Base File'!$G:$G,"Internal KPI",'Base File'!$C:$C,B5,'Base File'!$AF:$AF,"Not Met")),"-") -> - | AP5: =IFERROR(COUNTIFS('Base File'!$AH:$AH,"Met",'Base File'!$C:$C,B5)/(COUNTIFS('Base File'!$AH:$AH,"Met",'Base File'!$C:$C,B5)+COUNTIFS('Base File'!$AH:$AH,"Not Met",'Base File'!$C:$C,B5)),"NR") -> NR | AQ5: =IFERROR(COUNTIFS('Base File'!$G:$G,"Contractual SLA",'Base File'!$H:$H,"No",'Base File'!$C:$C,B5,'Base File'!$AH:$AH,"Met")/SUM(COUNTIFS('Base File'!$G:$G,"Contractual SLA",'Base File'!$H:$H,"No",'Base File'!$C:$C,B5,'Base File'!$AH:$AH,"Met")+COUNTIFS('Base File'!$G:$G,"Contractual SLA",'Base File'!$H:$H,"No",'Base File'!$C:$C,B5,'Base File'!$AH:$AH,"Not Met")),"-") -> - | AR5: =IFERROR(COUNTIFS('Base File'!$G:$G,"Contractual SLA",'Base File'!$H:$H,"Yes",'Base File'!$C:$C,B5,'Base File'!$AH:$AH,"Met")/SUM(COUNTIFS('Base File'!$G:$G,"Contractual SLA",'Base File'!$H:$H,"yes",'Base File'!$C:$C,B5,'Base File'!$AH:$AH,"Met")+COUNTIFS('Base File'!$G:$G,"Contractual SLA",'Base File'!$H:$H,"yes",'Base File'!$C:$C,B5,'Base File'!$AH:$AH,"Not Met")),"-") -> - | AS5: =IFERROR(COUNTIFS('Base File'!$G:$G,"Internal KPI",'Base File'!$C:$C,B5,'Base File'!$AH:$AH,"Met")/SUM(COUNTIFS('Base File'!$G:$G,"Internal KPI",'Base File'!$C:$C,B5,'Base File'!$AH:$AH,"Met")+COUNTIFS('Base File'!$G:$G,"Internal KPI",'Base File'!$C:$C,B5,'Base File'!$AH:$AH,"Not Met")),"-") -> - | AT5: =22/33 -> 0.66666667 | AU5: =10/11 -> 0.90909091 | AV5: =7/7 -> 1 | AW5: =5/15 -> 0.33333333 | AX5: =17/23 -> 0.73913043 | AY5: =8/8 -> 1 | AZ5: =7/7 -> 1 | BA5: =2/8 -> 0.25 | BB5: =20/26 -> 0.76923077 | BC5: =10/11 -> 0.90909091 | BD5: =7/7 -> 1 | BE5: =3/8 -> 0.375 | BF5: =21/27 -> 0.77777778 | BG5: =11/11 -> 1 | BH5: =7/7 -> 1 | BI5: =3/9 -> 0.33333333 | BJ5: =14/19 -> 0.73684211 | BK5: 1 | BL5: NA | BM5: =3/8 -> 0.375 | BN5: =12/19 -> 0.63157895 | BO5: 1 | BP5: NA | BQ5: =1/8 -> 0.125 | BR5: =11/19 -> 0.57894737 | BS5: =11/11 -> 1 | BT5: NA | BU5: =0/8 -> 0 | BV5: =9/14 -> 0.64285714 | BW5: =8/8 -> 1 | BX5: NA | BY5: =1/6 -> 0.16666667 | BZ5: =14/20 -> 0.7 | CA5: =14/20 -> 0.7 | CB5: NA | CC5: =3/9 -> 0.33333333 | CD5: =15/21 -> 0.71428571 | CE5: =15/21 -> 0.71428571 | CF5: NA | CG5: =3/9 -> 0.33333333 | CH5: =8/16 -> 0.5 | CI5: =8/8 -> 1 | CJ5: NA | CK5: =0/8 -> 0 | CL5: =11/16 -> 0.6875 | CM5: =8/8 -> 1 | CN5: NA | CO5: =3/8 -> 0.375 | CP5: =8/8 -> 1 | CQ5: =8/8 -> 1 | CR5: NR | CS5: NR | CT5: =8/8 -> 1 | CU5: =8/8 -> 1 | CV5: NR | CW5: NR | DF5: =7/10 -> 0.7 | DG5: =7/8 -> 0.875 | DH5: NR | DI5: =0/2 -> 0 | DJ5: NR | DK5: NR | DL5: NR | DM5: NR | DN5: =5/12 -> 0.41666667 | DO5: =5/10 -> 0.5 | DP5: NR | DQ5: =0/2 -> 0 | DR5: =4/4 -> 1 | DS5: =4/4 -> 1 | DT5: NR | DU5: NR
A6: 3 | B6: North | C6: Archana | D6: Reported | E6: Validated | F6: =13/20 -> 0.65 | G6: =5/8 -> 0.625 | H6: NA | I6: =8/12 -> 0.66666667 | J6: =13/20 -> 0.65 | K6: =3/8 -> 0.375 | L6: NA | M6: =10/12 -> 0.83333333 | N6: =IFERROR(COUNTIFS('Base File'!$V:$V,"Met",'Base File'!$C:$C,B6)/(COUNTIFS('Base File'!$V:$V,"Met",'Base File'!$C:$C,B6)+COUNTIFS('Base File'!$V:$V,"Not Met",'Base File'!$C:$C,B6)),"NR") -> 0.5862069 | O6: =IFERROR(COUNTIFS('Base File'!$G:$G,"Contractual SLA",'Base File'!$H:$H,"No",'Base File'!$C:$C,B6,'Base File'!$V:$V,"Met")/SUM(COUNTIFS('Base File'!$G:$G,"Contractual SLA",'Base File'!$H:$H,"No",'Base File'!$C:$C,B6,'Base File'!$V:$V,"Met")+COUNTIFS('Base File'!$G:$G,"Contractual SLA",'Base File'!$H:$H,"No",'Base File'!$C:$C,B6,'Base File'!$V:$V,"Not Met")),"-") -> - | P6: =IFERROR(COUNTIFS('Base File'!$G:$G,"Contractual SLA",'Base File'!$H:$H,"Yes",'Base File'!$C:$C,B6,'Base File'!$V:$V,"Met")/SUM(COUNTIFS('Base File'!$G:$G,"Contractual SLA",'Base File'!$H:$H,"yes",'Base File'!$C:$C,B6,'Base File'!$V:$V,"Met")+COUNTIFS('Base File'!$G:$G,"Contractual SLA",'Base File'!$H:$H,"yes",'Base File'!$C:$C,B6,'Base File'!$V:$V,"Not Met")),"-") -> 0.7 | Q6: =IFERROR(COUNTIFS('Base File'!$G:$G,"Internal KPI",'Base File'!$C:$C,B6,'Base File'!$V:$V,"Met")/SUM(COUNTIFS('Base File'!$G:$G,"Internal KPI",'Base File'!$C:$C,B6,'Base File'!$V:$V,"Met")+COUNTIFS('Base File'!$G:$G,"Internal KPI",'Base File'!$C:$C,B6,'Base File'!$V:$V,"Not Met")),"-") -> 0.52631579 | R6: =BR6 -> 0.6 | S6: =BS6 -> - | T6: =BT6 -> 0.73333333 | U6: =BU6 -> 0.46666667 | V6: =IFERROR(COUNTIFS('Base File'!$X:$X,"Met",'Base File'!$C:$C,B6)/(COUNTIFS('Base File'!$X:$X,"Met",'Base File'!$C:$C,B6)+COUNTIFS('Base File'!$X:$X,"Not Met",'Base File'!$C:$C,B6)),"NR") -> 0.5862069 | W6: =IFERROR(COUNTIFS('Base File'!$G:$G,"Contractual SLA",'Base File'!$H:$H,"No",'Base File'!$C:$C,B6,'Base File'!$X:$X,"Met")/SUM(COUNTIFS('Base File'!$G:$G,"Contractual SLA",'Base File'!$H:$H,"No",'Base File'!$C:$C,B6,'Base File'!$X:$X,"Met")+COUNTIFS('Base File'!$G:$G,"Contractual SLA",'Base File'!$H:$H,"No",'Base File'!$C:$C,B6,'Base File'!$X:$X,"Not Met")),"-") -> - | X6: =IFERROR(COUNTIFS('Base File'!$G:$G,"Contractual SLA",'Base File'!$H:$H,"Yes",'Base File'!$C:$C,B6,'Base File'!$X:$X,"Met")/SUM(COUNTIFS('Base File'!$G:$G,"Contractual SLA",'Base File'!$H:$H,"yes",'Base File'!$C:$C,B6,'Base File'!$X:$X,"Met")+COUNTIFS('Base File'!$G:$G,"Contractual SLA",'Base File'!$H:$H,"yes",'Base File'!$C:$C,B6,'Base File'!$X:$X,"Not Met")),"-") -> 0.5 | Y6: =IFERROR(COUNTIFS('Base File'!$G:$G,"Internal KPI",'Base File'!$C:$C,B6,'Base File'!$X:$X,"Met")/SUM(COUNTIFS('Base File'!$G:$G,"Internal KPI",'Base File'!$C:$C,B6,'Base File'!$X:$X,"Met")+COUNTIFS('Base File'!$G:$G,"Internal KPI",'Base File'!$C:$C,B6,'Base File'!$X:$X,"Not Met")),"-") -> 0.63157895 | Z6: =IFERROR(COUNTIFS('Base File'!$Z:$Z,"Met",'Base File'!$C:$C,B6)/(COUNTIFS('Base File'!$Z:$Z,"Met",'Base File'!$C:$C,B6)+COUNTIFS('Base File'!$Z:$Z,"Not Met",'Base File'!$C:$C,B6)),"NR") -> 0.70967742 | AA6: =IFERROR(COUNTIFS('Base File'!$G:$G,"Contractual SLA",'Base File'!$H:$H,"No",'Base File'!$C:$C,B6,'Base File'!$Z:$Z,"Met")/SUM(COUNTIFS('Base File'!$G:$G,"Contractual SLA",'Base File'!$H:$H,"No",'Base File'!$C:$C,B6,'Base File'!$Z:$Z,"Met")+COUNTIFS('Base File'!$G:$G,"Contractual SLA",'Base File'!$H:$H,"No",'Base File'!$C:$C,B6,'Base File'!$Z:$Z,"Not Met")),"-") -> - | AB6: =IFERROR(COUNTIFS('Base File'!$G:$G,"Contractual SLA",'Base File'!$H:$H,"Yes",'Base File'!$C:$C,B6,'Base File'!$Z:$Z,"Met")/SUM(COUNTIFS('Base File'!$G:$G,"Contractual SLA",'Base File'!$H:$H,"yes",'Base File'!$C:$C,B6,'Base File'!$Z:$Z,"Met")+COUNTIFS('Base File'!$G:$G,"Contractual SLA",'Base File'!$H:$H,"yes",'Base File'!$C:$C,B6,'Base File'!$Z:$Z,"Not Met")),"-") -> 0.66666667 | AC6: =IFERROR(COUNTIFS('Base File'!$G:$G,"Internal KPI",'Base File'!$C:$C,B6,'Base File'!$Z:$Z,"Met")/SUM(COUNTIFS('Base File'!$G:$G,"Internal KPI",'Base File'!$C:$C,B6,'Base File'!$Z:$Z,"Met")+COUNTIFS('Base File'!$G:$G,"Internal KPI",'Base File'!$C:$C,B6,'Base File'!$Z:$Z,"Not Met")),"-") -> 0.75 | AD6: =IFERROR(COUNTIFS('Base File'!$AB:$AB,"Met",'Base File'!$C:$C,B6)/(COUNTIFS('Base File'!$AB:$AB,"Met",'Base File'!$C:$C,B6)+COUNTIFS('Base File'!$AB:$AB,"Not Met",'Base File'!$C:$C,B6)),"NR") -> 0.78787879 | AE6: =IFERROR(COUNTIFS('Base File'!$G:$G,"Contractual SLA",'Base File'!$H:$H,"No",'Base File'!$C:$C,B6,'Base File'!$AB:$AB,"Met")/SUM(COUNTIFS('Base File'!$G:$G,"Contractual SLA",'Base File'!$H:$H,"No",'Base File'!$C:$C,B6,'Base File'!$AB:$AB,"Met")+COUNTIFS('Base File'!$G:$G,"Contractual SLA",'Base File'!$H:$H,"No",'Base File'!$C:$C,B6,'Base File'!$AB:$AB,"Not Met")),"-") -> - | AF6: =IFERROR(COUNTIFS('Base File'!$G:$G,"Contractual SLA",'Base File'!$H:$H,"Yes",'Base File'!$C:$C,B6,'Base File'!$AB:$AB,"Met")/SUM(COUNTIFS('Base File'!$G:$G,"Contractual SLA",'Base File'!$H:$H,"yes",'Base File'!$C:$C,B6,'Base File'!$AB:$AB,"Met")+COUNTIFS('Base File'!$G:$G,"Contractual SLA",'Base File'!$H:$H,"yes",'Base File'!$C:$C,B6,'Base File'!$AB:$AB,"Not Met")),"-") -> 0.73333333 | AG6: =IFERROR(COUNTIFS('Base File'!$G:$G,"Internal KPI",'Base File'!$C:$C,B6,'Base File'!$AB:$AB,"Met")/SUM(COUNTIFS('Base File'!$G:$G,"Internal KPI",'Base File'!$C:$C,B6,'Base File'!$AB:$AB,"Met")+COUNTIFS('Base File'!$G:$G,"Internal KPI",'Base File'!$C:$C,B6,'Base File'!$AB:$AB,"Not Met")),"-") -> 0.83333333 | AH6: =IFERROR(COUNTIFS('Base File'!$AD:$AD,"Met",'Base File'!$C:$C,B6)/(COUNTIFS('Base File'!$AD:$AD,"Met",'Base File'!$C:$C,B6)+COUNTIFS('Base File'!$AD:$AD,"Not Met",'Base File'!$C:$C,B6)),"NR") -> 0.66666667 | AI6: =IFERROR(COUNTIFS('Base File'!$G:$G,"Contractual SLA",'Base File'!$H:$H,"No",'Base File'!$C:$C,B6,'Base File'!$AD:$AD,"Met")/SUM(COUNTIFS('Base File'!$G:$G,"Contractual SLA",'Base File'!$H:$H,"No",'Base File'!$C:$C,B6,'Base File'!$AD:$AD,"Met")+COUNTIFS('Base File'!$G:$G,"Contractual SLA",'Base File'!$H:$H,"No",'Base File'!$C:$C,B6,'Base File'!$AD:$AD,"Not Met")),"-") -> - | AJ6: =IFERROR(COUNTIFS('Base File'!$G:$G,"Contractual SLA",'Base File'!$H:$H,"Yes",'Base File'!$C:$C,B6,'Base File'!$AD:$AD,"Met")/SUM(COUNTIFS('Base File'!$G:$G,"Contractual SLA",'Base File'!$H:$H,"yes",'Base File'!$C:$C,B6,'Base File'!$AD:$AD,"Met")+COUNTIFS('Base File'!$G:$G,"Contractual SLA",'Base File'!$H:$H,"yes",'Base File'!$C:$C,B6,'Base File'!$AD:$AD,"Not Met")),"-") -> 0.66666667 | AK6: =IFERROR(COUNTIFS('Base File'!$G:$G,"Internal KPI",'Base File'!$C:$C,B6,'Base File'!$AD:$AD,"Met")/SUM(COUNTIFS('Base File'!$G:$G,"Internal KPI",'Base File'!$C:$C,B6,'Base File'!$AD:$AD,"Met")+COUNTIFS('Base File'!$G:$G,"Internal KPI",'Base File'!$C:$C,B6,'Base File'!$AD:$AD,"Not Met")),"-") -> 0.66666667 | AL6: =IFERROR(COUNTIFS('Base File'!$AF:$AF,"Met",'Base File'!$C:$C,B6)/(COUNTIFS('Base File'!$AF:$AF,"Met",'Base File'!$C:$C,B6)+COUNTIFS('Base File'!$AF:$AF,"Not Met",'Base File'!$C:$C,B6)),"NR") -> 0.59375 | AM6: =IFERROR(COUNTIFS('Base File'!$G:$G,"Contractual SLA",'Base File'!$H:$H,"No",'Base File'!$C:$C,B6,'Base File'!$AF:$AF,"Met")/SUM(COUNTIFS('Base File'!$G:$G,"Contractual SLA",'Base File'!$H:$H,"No",'Base File'!$C:$C,B6,'Base File'!$AF:$AF,"Met")+COUNTIFS('Base File'!$G:$G,"Contractual SLA",'Base File'!$H:$H,"No",'Base File'!$C:$C,B6,'Base File'!$AF:$AF,"Not Met")),"-") -> - | AN6: =IFERROR(COUNTIFS('Base File'!$G:$G,"Contractual SLA",'Base File'!$H:$H,"Yes",'Base File'!$C:$C,B6,'Base File'!$AF:$AF,"Met")/SUM(COUNTIFS('Base File'!$G:$G,"Contractual SLA",'Base File'!$H:$H,"yes",'Base File'!$C:$C,B6,'Base File'!$AF:$AF,"Met")+COUNTIFS('Base File'!$G:$G,"Contractual SLA",'Base File'!$H:$H,"yes",'Base File'!$C:$C,B6,'Base File'!$AF:$AF,"Not Met")),"-") -> 0.73333333 | AO6: =IFERROR(COUNTIFS('Base File'!$G:$G,"Internal KPI",'Base File'!$C:$C,B6,'Base File'!$AF:$AF,"Met")/SUM(COUNTIFS('Base File'!$G:$G,"Internal KPI",'Base File'!$C:$C,B6,'Base File'!$AF:$AF,"Met")+COUNTIFS('Base File'!$G:$G,"Internal KPI",'Base File'!$C:$C,B6,'Base File'!$AF:$AF,"Not Met")),"-") -> 0.47058824 | AP6: =IFERROR(COUNTIFS('Base File'!$AH:$AH,"Met",'Base File'!$C:$C,B6)/(COUNTIFS('Base File'!$AH:$AH,"Met",'Base File'!$C:$C,B6)+COUNTIFS('Base File'!$AH:$AH,"Not Met",'Base File'!$C:$C,B6)),"NR") -> 0.70967742 | AQ6: =IFERROR(COUNTIFS('Base File'!$G:$G,"Contractual SLA",'Base File'!$H:$H,"No",'Base File'!$C:$C,B6,'Base File'!$AH:$AH,"Met")/SUM(COUNTIFS('Base File'!$G:$G,"Contractual SLA",'Base File'!$H:$H,"No",'Base File'!$C:$C,B6,'Base File'!$AH:$AH,"Met")+COUNTIFS('Base File'!$G:$G,"Contractual SLA",'Base File'!$H:$H,"No",'Base File'!$C:$C,B6,'Base File'!$AH:$AH,"Not Met")),"-") -> - | AR6: =IFERROR(COUNTIFS('Base File'!$G:$G,"Contractual SLA",'Base File'!$H:$H,"Yes",'Base File'!$C:$C,B6,'Base File'!$AH:$AH,"Met")/SUM(COUNTIFS('Base File'!$G:$G,"Contractual SLA",'Base File'!$H:$H,"yes",'Base File'!$C:$C,B6,'Base File'!$AH:$AH,"Met")+COUNTIFS('Base File'!$G:$G,"Contractual SLA",'Base File'!$H:$H,"yes",'Base File'!$C:$C,B6,'Base File'!$AH:$AH,"Not Met")),"-") -> 0.6 | AS6: =IFERROR(COUNTIFS('Base File'!$G:$G,"Internal KPI",'Base File'!$C:$C,B6,'Base File'!$AH:$AH,"Met")/SUM(COUNTIFS('Base File'!$G:$G,"Internal KPI",'Base File'!$C:$C,B6,'Base File'!$AH:$AH,"Met")+COUNTIFS('Base File'!$G:$G,"Internal KPI",'Base File'!$C:$C,B6,'Base File'!$AH:$AH,"Not Met")),"-") -> 0.8125 | AT6: =18/25 -> 0.72 | AU6: =3/4 -> 0.75 | AV6: =7/10 -> 0.7 | AW6: =8/11 -> 0.72727273 | AX6: =8/13 -> 0.61538462 | AY6: NR | AZ6: =6/10 -> 0.6 | BA6: =2/3 -> 0.66666667 | BB6: =17/24 -> 0.70833333 | BC6: - | BD6: =8/13 -> 0.61538462 | BE6: =9/11 -> 0.81818182 | BF6: =17/25 -> 0.68 | BG6: - | BH6: =11/15 -> 0.73333333 | BI6: =6/10 -> 0.6 | BJ6: =20/29 -> 0.68965517 | BK6: - | BL6: =11/14 -> 0.78571429 | BM6: =9/15 -> 0.6 | BN6: =17/29 -> 0.5862069 | BO6: - | BP6: =9/14 -> 0.64285714 | BQ6: =8/15 -> 0.53333333 | BR6: =18/30 -> 0.6 | BS6: - | BT6: =11/15 -> 0.73333333 | BU6: =7/15 -> 0.46666667 | BV6: =14/22 -> 0.63636364 | BW6: NA | BX6: =8/10 -> 0.8 | BY6: =6/12 -> 0.5 | BZ6: =24/34 -> 0.70588235 | CA6: NA | CB6: =12/14 -> 0.85714286 | CC6: =12/20 -> 0.6 | CD6: =22/34 -> 0.64705882 | CE6: NA | CF6: =10/14 -> 0.71428571 | CG6: =12/20 -> 0.6 | CH6: =22/36 -> 0.61111111 | CI6: NA | CJ6: =12/14 -> 0.85714286 | CK6: =10/22 -> 0.45454545 | CL6: =19/37 -> 0.51351351 | CM6: NA | CN6: =7/10 -> 0.7 | CO6: =12/27 -> 0.44444444 | CP6: =16/28 -> 0.57142857 | CQ6: NA | CR6: =6/10 -> 0.6 | CS6: =10/18 -> 0.55555556 | CT6: =36/55 -> 0.65454545 | CU6: NA | CV6: =17/22 -> 0.77272727 | CW6: =19/33 -> 0.57575758 | DF6: =43/63 -> 0.68253968 | DG6: - | DH6: =19/25 -> 0.76 | DI6: =24/38 -> 0.63157895 | DJ6: =41/64 -> 0.640625 | DK6: - | DL6: =19/25 -> 0.76 | DM6: =20/32 -> 0.625 | DN6: =44/63 -> 0.6984127 | DO6: - | DP6: =18/23 -> 0.7826087 | DQ6: =26/40 -> 0.65 | DR6: =55/79 -> 0.69620253 | DS6: - | DT6: =26/35 -> 0.74285714 | DU6: =29/44 -> 0.65909091
A7: 4 | B7: Pune | C7: Shweta | D7: Partially Reported | E7: Partially Validated | F7: =17/40 -> 0.425 | G7: =1/4 -> 0.25 | H7: =4/6 -> 0.66666667 | I7: =12/30 -> 0.4 | J7: =23/40 -> 0.575 | K7: =3/4 -> 0.75 | L7: =3/6 -> 0.5 | M7: =17/30 -> 0.56666667 | N7: =IFERROR(COUNTIFS('Base File'!$V:$V,"Met",'Base File'!$C:$C,B7)/(COUNTIFS('Base File'!$V:$V,"Met",'Base File'!$C:$C,B7)+COUNTIFS('Base File'!$V:$V,"Not Met",'Base File'!$C:$C,B7)),"NR") -> NR | O7: =IFERROR(COUNTIFS('Base File'!$G:$G,"Contractual SLA",'Base File'!$H:$H,"No",'Base File'!$C:$C,B7,'Base File'!$V:$V,"Met")/SUM(COUNTIFS('Base File'!$G:$G,"Contractual SLA",'Base File'!$H:$H,"No",'Base File'!$C:$C,B7,'Base File'!$V:$V,"Met")+COUNTIFS('Base File'!$G:$G,"Contractual SLA",'Base File'!$H:$H,"No",'Base File'!$C:$C,B7,'Base File'!$V:$V,"Not Met")),"-") -> - | P7: =IFERROR(COUNTIFS('Base File'!$G:$G,"Contractual SLA",'Base File'!$H:$H,"Yes",'Base File'!$C:$C,B7,'Base File'!$V:$V,"Met")/SUM(COUNTIFS('Base File'!$G:$G,"Contractual SLA",'Base File'!$H:$H,"yes",'Base File'!$C:$C,B7,'Base File'!$V:$V,"Met")+COUNTIFS('Base File'!$G:$G,"Contractual SLA",'Base File'!$H:$H,"yes",'Base File'!$C:$C,B7,'Base File'!$V:$V,"Not Met")),"-") -> - | Q7: =IFERROR(COUNTIFS('Base File'!$G:$G,"Internal KPI",'Base File'!$C:$C,B7,'Base File'!$V:$V,"Met")/SUM(COUNTIFS('Base File'!$G:$G,"Internal KPI",'Base File'!$C:$C,B7,'Base File'!$V:$V,"Met")+COUNTIFS('Base File'!$G:$G,"Internal KPI",'Base File'!$C:$C,B7,'Base File'!$V:$V,"Not Met")),"-") -> - | R7: =BR7 -> 0.45454545 | S7: =BS7 -> NA | T7: =BT7 -> 0.5 | U7: =BU7 -> 0.4375 | V7: =IFERROR(COUNTIFS('Base File'!$X:$X,"Met",'Base File'!$C:$C,B7)/(COUNTIFS('Base File'!$X:$X,"Met",'Base File'!$C:$C,B7)+COUNTIFS('Base File'!$X:$X,"Not Met",'Base File'!$C:$C,B7)),"NR") -> NR | W7: =IFERROR(COUNTIFS('Base File'!$G:$G,"Contractual SLA",'Base File'!$H:$H,"No",'Base File'!$C:$C,B7,'Base File'!$X:$X,"Met")/SUM(COUNTIFS('Base File'!$G:$G,"Contractual SLA",'Base File'!$H:$H,"No",'Base File'!$C:$C,B7,'Base File'!$X:$X,"Met")+COUNTIFS('Base File'!$G:$G,"Contractual SLA",'Base File'!$H:$H,"No",'Base File'!$C:$C,B7,'Base File'!$X:$X,"Not Met")),"-") -> - | X7: =IFERROR(COUNTIFS('Base File'!$G:$G,"Contractual SLA",'Base File'!$H:$H,"Yes",'Base File'!$C:$C,B7,'Base File'!$X:$X,"Met")/SUM(COUNTIFS('Base File'!$G:$G,"Contractual SLA",'Base File'!$H:$H,"yes",'Base File'!$C:$C,B7,'Base File'!$X:$X,"Met")+COUNTIFS('Base File'!$G:$G,"Contractual SLA",'Base File'!$H:$H,"yes",'Base File'!$C:$C,B7,'Base File'!$X:$X,"Not Met")),"-") -> - | Y7: =IFERROR(COUNTIFS('Base File'!$G:$G,"Internal KPI",'Base File'!$C:$C,B7,'Base File'!$X:$X,"Met")/SUM(COUNTIFS('Base File'!$G:$G,"Internal KPI",'Base File'!$C:$C,B7,'Base File'!$X:$X,"Met")+COUNTIFS('Base File'!$G:$G,"Internal KPI",'Base File'!$C:$C,B7,'Base File'!$X:$X,"Not Met")),"-") -> - | Z7: =IFERROR(COUNTIFS('Base File'!$Z:$Z,"Met",'Base File'!$C:$C,B7)/(COUNTIFS('Base File'!$Z:$Z,"Met",'Base File'!$C:$C,B7)+COUNTIFS('Base File'!$Z:$Z,"Not Met",'Base File'!$C:$C,B7)),"NR") -> NR | AA7: =IFERROR(COUNTIFS('Base File'!$G:$G,"Contractual SLA",'Base File'!$H:$H,"No",'Base File'!$C:$C,B7,'Base File'!$Z:$Z,"Met")/SUM(COUNTIFS('Base File'!$G:$G,"Contractual SLA",'Base File'!$H:$H,"No",'Base File'!$C:$C,B7,'Base File'!$Z:$Z,"Met")+COUNTIFS('Base File'!$G:$G,"Contractual SLA",'Base File'!$H:$H,"No",'Base File'!$C:$C,B7,'Base File'!$Z:$Z,"Not Met")),"-") -> - | AB7: =IFERROR(COUNTIFS('Base File'!$G:$G,"Contractual SLA",'Base File'!$H:$H,"Yes",'Base File'!$C:$C,B7,'Base File'!$Z:$Z,"Met")/SUM(COUNTIFS('Base File'!$G:$G,"Contractual SLA",'Base File'!$H:$H,"yes",'Base File'!$C:$C,B7,'Base File'!$Z:$Z,"Met")+COUNTIFS('Base File'!$G:$G,"Contractual SLA",'Base File'!$H:$H,"yes",'Base File'!$C:$C,B7,'Base File'!$Z:$Z,"Not Met")),"-") -> - | AC7: =IFERROR(COUNTIFS('Base File'!$G:$G,"Internal KPI",'Base File'!$C:$C,B7,'Base File'!$Z:$Z,"Met")/SUM(COUNTIFS('Base File'!$G:$G,"Internal KPI",'Base File'!$C:$C,B7,'Base File'!$Z:$Z,"Met")+COUNTIFS('Base File'!$G:$G,"Internal KPI",'Base File'!$C:$C,B7,'Base File'!$Z:$Z,"Not Met")),"-") -> - | AD7: =IFERROR(COUNTIFS('Base File'!$AB:$AB,"Met",'Base File'!$C:$C,B7)/(COUNTIFS('Base File'!$AB:$AB,"Met",'Base File'!$C:$C,B7)+COUNTIFS('Base File'!$AB:$AB,"Not Met",'Base File'!$C:$C,B7)),"NR") -> NR | AE7: =IFERROR(COUNTIFS('Base File'!$G:$G,"Contractual SLA",'Base File'!$H:$H,"No",'Base File'!$C:$C,B7,'Base File'!$AB:$AB,"Met")/SUM(COUNTIFS('Base File'!$G:$G,"Contractual SLA",'Base File'!$H:$H,"No",'Base File'!$C:$C,B7,'Base File'!$AB:$AB,"Met")+COUNTIFS('Base File'!$G:$G,"Contractual SLA",'Base File'!$H:$H,"No",'Base File'!$C:$C,B7,'Base File'!$AB:$AB,"Not Met")),"-") -> - | AF7: =IFERROR(COUNTIFS('Base File'!$G:$G,"Contractual SLA",'Base File'!$H:$H,"Yes",'Base File'!$C:$C,B7,'Base File'!$AB:$AB,"Met")/SUM(COUNTIFS('Base File'!$G:$G,"Contractual SLA",'Base File'!$H:$H,"yes",'Base File'!$C:$C,B7,'Base File'!$AB:$AB,"Met")+COUNTIFS('Base File'!$G:$G,"Contractual SLA",'Base File'!$H:$H,"yes",'Base File'!$C:$C,B7,'Base File'!$AB:$AB,"Not Met")),"-") -> - | AG7: =IFERROR(COUNTIFS('Base File'!$G:$G,"Internal KPI",'Base File'!$C:$C,B7,'Base File'!$AB:$AB,"Met")/SUM(COUNTIFS('Base File'!$G:$G,"Internal KPI",'Base File'!$C:$C,B7,'Base File'!$AB:$AB,"Met")+COUNTIFS('Base File'!$G:$G,"Internal KPI",'Base File'!$C:$C,B7,'Base File'!$AB:$AB,"Not Met")),"-") -> - | AH7: =IFERROR(COUNTIFS('Base File'!$AD:$AD,"Met",'Base File'!$C:$C,B7)/(COUNTIFS('Base File'!$AD:$AD,"Met",'Base File'!$C:$C,B7)+COUNTIFS('Base File'!$AD:$AD,"Not Met",'Base File'!$C:$C,B7)),"NR") -> NR | AI7: =IFERROR(COUNTIFS('Base File'!$G:$G,"Contractual SLA",'Base File'!$H:$H,"No",'Base File'!$C:$C,B7,'Base File'!$AD:$AD,"Met")/SUM(COUNTIFS('Base File'!$G:$G,"Contractual SLA",'Base File'!$H:$H,"No",'Base File'!$C:$C,B7,'Base File'!$AD:$AD,"Met")+COUNTIFS('Base File'!$G:$G,"Contractual SLA",'Base File'!$H:$H,"No",'Base File'!$C:$C,B7,'Base File'!$AD:$AD,"Not Met")),"-") -> - | AJ7: =IFERROR(COUNTIFS('Base File'!$G:$G,"Contractual SLA",'Base File'!$H:$H,"Yes",'Base File'!$C:$C,B7,'Base File'!$AD:$AD,"Met")/SUM(COUNTIFS('Base File'!$G:$G,"Contractual SLA",'Base File'!$H:$H,"yes",'Base File'!$C:$C,B7,'Base File'!$AD:$AD,"Met")+COUNTIFS('Base File'!$G:$G,"Contractual SLA",'Base File'!$H:$H,"yes",'Base File'!$C:$C,B7,'Base File'!$AD:$AD,"Not Met")),"-") -> - | AK7: =IFERROR(COUNTIFS('Base File'!$G:$G,"Internal KPI",'Base File'!$C:$C,B7,'Base File'!$AD:$AD,"Met")/SUM(COUNTIFS('Base File'!$G:$G,"Internal KPI",'Base File'!$C:$C,B7,'Base File'!$AD:$AD,"Met")+COUNTIFS('Base File'!$G:$G,"Internal KPI",'Base File'!$C:$C,B7,'Base File'!$AD:$AD,"Not Met")),"-") -> - | AL7: =IFERROR(COUNTIFS('Base File'!$AF:$AF,"Met",'Base File'!$C:$C,B7)/(COUNTIFS('Base File'!$AF:$AF,"Met",'Base File'!$C:$C,B7)+COUNTIFS('Base File'!$AF:$AF,"Not Met",'Base File'!$C:$C,B7)),"NR") -> NR | AM7: =IFERROR(COUNTIFS('Base File'!$G:$G,"Contractual SLA",'Base File'!$H:$H,"No",'Base File'!$C:$C,B7,'Base File'!$AF:$AF,"Met")/SUM(COUNTIFS('Base File'!$G:$G,"Contractual SLA",'Base File'!$H:$H,"No",'Base File'!$C:$C,B7,'Base File'!$AF:$AF,"Met")+COUNTIFS('Base File'!$G:$G,"Contractual SLA",'Base File'!$H:$H,"No",'Base File'!$C:$C,B7,'Base File'!$AF:$AF,"Not Met")),"-") -> - | AN7: =IFERROR(COUNTIFS('Base File'!$G:$G,"Contractual SLA",'Base File'!$H:$H,"Yes",'Base File'!$C:$C,B7,'Base File'!$AF:$AF,"Met")/SUM(COUNTIFS('Base File'!$G:$G,"Contractual SLA",'Base File'!$H:$H,"yes",'Base File'!$C:$C,B7,'Base File'!$AF:$AF,"Met")+COUNTIFS('Base File'!$G:$G,"Contractual SLA",'Base File'!$H:$H,"yes",'Base File'!$C:$C,B7,'Base File'!$AF:$AF,"Not Met")),"-") -> - | AO7: =IFERROR(COUNTIFS('Base File'!$G:$G,"Internal KPI",'Base File'!$C:$C,B7,'Base File'!$AF:$AF,"Met")/SUM(COUNTIFS('Base File'!$G:$G,"Internal KPI",'Base File'!$C:$C,B7,'Base File'!$AF:$AF,"Met")+COUNTIFS('Base File'!$G:$G,"Internal KPI",'Base File'!$C:$C,B7,'Base File'!$AF:$AF,"Not Met")),"-") -> - | AP7: =IFERROR(COUNTIFS('Base File'!$AH:$AH,"Met",'Base File'!$C:$C,B7)/(COUNTIFS('Base File'!$AH:$AH,"Met",'Base File'!$C:$C,B7)+COUNTIFS('Base File'!$AH:$AH,"Not Met",'Base File'!$C:$C,B7)),"NR") -> NR | AQ7: =IFERROR(COUNTIFS('Base File'!$G:$G,"Contractual SLA",'Base File'!$H:$H,"No",'Base File'!$C:$C,B7,'Base File'!$AH:$AH,"Met")/SUM(COUNTIFS('Base File'!$G:$G,"Contractual SLA",'Base File'!$H:$H,"No",'Base File'!$C:$C,B7,'Base File'!$AH:$AH,"Met")+COUNTIFS('Base File'!$G:$G,"Contractual SLA",'Base File'!$H:$H,"No",'Base File'!$C:$C,B7,'Base File'!$AH:$AH,"Not Met")),"-") -> - | AR7: =IFERROR(COUNTIFS('Base File'!$G:$G,"Contractual SLA",'Base File'!$H:$H,"Yes",'Base File'!$C:$C,B7,'Base File'!$AH:$AH,"Met")/SUM(COUNTIFS('Base File'!$G:$G,"Contractual SLA",'Base File'!$H:$H,"yes",'Base File'!$C:$C,B7,'Base File'!$AH:$AH,"Met")+COUNTIFS('Base File'!$G:$G,"Contractual SLA",'Base File'!$H:$H,"yes",'Base File'!$C:$C,B7,'Base File'!$AH:$AH,"Not Met")),"-") -> - | AS7: =IFERROR(COUNTIFS('Base File'!$G:$G,"Internal KPI",'Base File'!$C:$C,B7,'Base File'!$AH:$AH,"Met")/SUM(COUNTIFS('Base File'!$G:$G,"Internal KPI",'Base File'!$C:$C,B7,'Base File'!$AH:$AH,"Met")+COUNTIFS('Base File'!$G:$G,"Internal KPI",'Base File'!$C:$C,B7,'Base File'!$AH:$AH,"Not Met")),"-") -> - | AT7: =13/28 -> 0.46428571 | AU7: =2/4 -> 0.5 | AV7: =2/2 -> 1 | AW7: =9/22 -> 0.40909091 | AX7: =15/29 -> 0.51724138 | AY7: =3/4 -> 0.75 | AZ7: =1/2 -> 0.5 | BA7: =11/23 -> 0.47826087 | BB7: =14/31 -> 0.4516129 | BC7: =2/3 -> 0.66666667 | BD7: =3/6 -> 0.5 | BE7: =9/22 -> 0.40909091 | BF7: =10/22 -> 0.45454545 | BG7: NA | BH7: =3/6 -> 0.5 | BI7: =7/16 -> 0.4375 | BJ7: =9/21 -> 0.42857143 | BK7: NA | BL7: =2/6 -> 0.33333333 | BM7: =7/15 -> 0.46666667 | BN7: =8/21 -> 0.38095238 | BO7: NA | BP7: =2/6 -> 0.33333333 | BQ7: =6/15 -> 0.4 | BR7: =10/22 -> 0.45454545 | BS7: NA | BT7: =3/6 -> 0.5 | BU7: =7/16 -> 0.4375 | BV7: =7/21 -> 0.33333333 | BW7: NA | BX7: =3/6 -> 0.5 | BY7: =4/15 -> 0.26666667 | BZ7: =13/26 -> 0.5 | CA7: =3/4 -> 0.75 | CB7: =3/5 -> 0.6 | CC7: =7/17 -> 0.41176471 | CD7: =14/26 -> 0.53846154 | CE7: =4/4 -> 1 | CF7: =3/5 -> 0.6 | CG7: =7/17 -> 0.41176471 | CH7: =14/26 -> 0.53846154 | CI7: =3/4 -> 0.75 | CJ7: =2/5 -> 0.4 | CK7: =9/17 -> 0.52941176 | CL7: =16/26 -> 0.61538462 | CM7: =3/4 -> 0.75 | CN7: =3/6 -> 0.5 | CO7: =10/16 -> 0.625 | CP7: =11/27 -> 0.40740741 | CQ7: =3/4 -> 0.75 | CR7: =1/6 -> 0.16666667 | CS7: =7/17 -> 0.41176471 | CT7: =13/25 -> 0.52 | CU7: =3/4 -> 0.75 | CV7: =2/5 -> 0.4 | CW7: =8/16 -> 0.5 | DF7: =6/12 -> 0.5 | DG7: =3/4 -> 0.75 | DH7: NR | DI7: =3/8 -> 0.375 | DJ7: NR | DK7: NR | DL7: NR | DM7: NR | DN7: NR | DO7: NR | DP7: NR | DQ7: NR | DR7: NR | DS7: NR | DT7: NR | DU7: NR
A8: 5 | B8: Mumbai & Gujrat | C8: Elton | D8: NA - Project On-hold | E8: NA - Project On-hold | F8: =61/98 -> 0.62244898 | G8: =15/23 -> 0.65217391 | H8: =2/3 -> 0.66666667 | I8: =44/72 -> 0.61111111 | J8: =68/101 -> 0.67326733 | K8: =19/27 -> 0.7037037 | L8: =5/7 -> 0.71428571 | M8: =44/67 -> 0.65671642 | N8: =IFERROR(COUNTIFS('Base File'!$V:$V,"Met",'Base File'!$C:$C,B8)/(COUNTIFS('Base File'!$V:$V,"Met",'Base File'!$C:$C,B8)+COUNTIFS('Base File'!$V:$V,"Not Met",'Base File'!$C:$C,B8)),"NR") -> NR | O8: =IFERROR(COUNTIFS('Base File'!$G:$G,"Contractual SLA",'Base File'!$H:$H,"No",'Base File'!$C:$C,B8,'Base File'!$V:$V,"Met")/SUM(COUNTIFS('Base File'!$G:$G,"Contractual SLA",'Base File'!$H:$H,"No",'Base File'!$C:$C,B8,'Base File'!$V:$V,"Met")+COUNTIFS('Base File'!$G:$G,"Contractual SLA",'Base File'!$H:$H,"No",'Base File'!$C:$C,B8,'Base File'!$V:$V,"Not Met")),"-") -> - | P8: =IFERROR(COUNTIFS('Base File'!$G:$G,"Contractual SLA",'Base File'!$H:$H,"Yes",'Base File'!$C:$C,B8,'Base File'!$V:$V,"Met")/SUM(COUNTIFS('Base File'!$G:$G,"Contractual SLA",'Base File'!$H:$H,"yes",'Base File'!$C:$C,B8,'Base File'!$V:$V,"Met")+COUNTIFS('Base File'!$G:$G,"Contractual SLA",'Base File'!$H:$H,"yes",'Base File'!$C:$C,B8,'Base File'!$V:$V,"Not Met")),"-") -> - | Q8: =IFERROR(COUNTIFS('Base File'!$G:$G,"Internal KPI",'Base File'!$C:$C,B8,'Base File'!$V:$V,"Met")/SUM(COUNTIFS('Base File'!$G:$G,"Internal KPI",'Base File'!$C:$C,B8,'Base File'!$V:$V,"Met")+COUNTIFS('Base File'!$G:$G,"Internal KPI",'Base File'!$C:$C,B8,'Base File'!$V:$V,"Not Met")),"-") -> - | R8: =BR8 -> 0.5 | S8: =BS8 -> 0 | T8: =BT8 -> NR | U8: =BU8 -> 0.51612903 | V8: =IFERROR(COUNTIFS('Base File'!$X:$X,"Met",'Base File'!$C:$C,B8)/(COUNTIFS('Base File'!$X:$X,"Met",'Base File'!$C:$C,B8)+COUNTIFS('Base File'!$X:$X,"Not Met",'Base File'!$C:$C,B8)),"NR") -> NR | W8: =IFERROR(COUNTIFS('Base File'!$G:$G,"Contractual SLA",'Base File'!$H:$H,"No",'Base File'!$C:$C,B8,'Base File'!$X:$X,"Met")/SUM(COUNTIFS('Base File'!$G:$G,"Contractual SLA",'Base File'!$H:$H,"No",'Base File'!$C:$C,B8,'Base File'!$X:$X,"Met")+COUNTIFS('Base File'!$G:$G,"Contractual SLA",'Base File'!$H:$H,"No",'Base File'!$C:$C,B8,'Base File'!$X:$X,"Not Met")),"-") -> - | X8: =IFERROR(COUNTIFS('Base File'!$G:$G,"Contractual SLA",'Base File'!$H:$H,"Yes",'Base File'!$C:$C,B8,'Base File'!$X:$X,"Met")/SUM(COUNTIFS('Base File'!$G:$G,"Contractual SLA",'Base File'!$H:$H,"yes",'Base File'!$C:$C,B8,'Base File'!$X:$X,"Met")+COUNTIFS('Base File'!$G:$G,"Contractual SLA",'Base File'!$H:$H,"yes",'Base File'!$C:$C,B8,'Base File'!$X:$X,"Not Met")),"-") -> - | Y8: =IFERROR(COUNTIFS('Base File'!$G:$G,"Internal KPI",'Base File'!$C:$C,B8,'Base File'!$X:$X,"Met")/SUM(COUNTIFS('Base File'!$G:$G,"Internal KPI",'Base File'!$C:$C,B8,'Base File'!$X:$X,"Met")+COUNTIFS('Base File'!$G:$G,"Internal KPI",'Base File'!$C:$C,B8,'Base File'!$X:$X,"Not Met")),"-") -> - | Z8: =IFERROR(COUNTIFS('Base File'!$Z:$Z,"Met",'Base File'!$C:$C,B8)/(COUNTIFS('Base File'!$Z:$Z,"Met",'Base File'!$C:$C,B8)+COUNTIFS('Base File'!$Z:$Z,"Not Met",'Base File'!$C:$C,B8)),"NR") -> NR | AA8: =IFERROR(COUNTIFS('Base File'!$G:$G,"Contractual SLA",'Base File'!$H:$H,"No",'Base File'!$C:$C,B8,'Base File'!$Z:$Z,"Met")/SUM(COUNTIFS('Base File'!$G:$G,"Contractual SLA",'Base File'!$H:$H,"No",'Base File'!$C:$C,B8,'Base File'!$Z:$Z,"Met")+COUNTIFS('Base File'!$G:$G,"Contractual SLA",'Base File'!$H:$H,"No",'Base File'!$C:$C,B8,'Base File'!$Z:$Z,"Not Met")),"-") -> - | AB8: =IFERROR(COUNTIFS('Base File'!$G:$G,"Contractual SLA",'Base File'!$H:$H,"Yes",'Base File'!$C:$C,B8,'Base File'!$Z:$Z,"Met")/SUM(COUNTIFS('Base File'!$G:$G,"Contractual SLA",'Base File'!$H:$H,"yes",'Base File'!$C:$C,B8,'Base File'!$Z:$Z,"Met")+COUNTIFS('Base File'!$G:$G,"Contractual SLA",'Base File'!$H:$H,"yes",'Base File'!$C:$C,B8,'Base File'!$Z:$Z,"Not Met")),"-") -> - | AC8: =IFERROR(COUNTIFS('Base File'!$G:$G,"Internal KPI",'Base File'!$C:$C,B8,'Base File'!$Z:$Z,"Met")/SUM(COUNTIFS('Base File'!$G:$G,"Internal KPI",'Base File'!$C:$C,B8,'Base File'!$Z:$Z,"Met")+COUNTIFS('Base File'!$G:$G,"Internal KPI",'Base File'!$C:$C,B8,'Base File'!$Z:$Z,"Not Met")),"-") -> - | AD8: =IFERROR(COUNTIFS('Base File'!$AB:$AB,"Met",'Base File'!$C:$C,B8)/(COUNTIFS('Base File'!$AB:$AB,"Met",'Base File'!$C:$C,B8)+COUNTIFS('Base File'!$AB:$AB,"Not Met",'Base File'!$C:$C,B8)),"NR") -> NR | AE8: =IFERROR(COUNTIFS('Base File'!$G:$G,"Contractual SLA",'Base File'!$H:$H,"No",'Base File'!$C:$C,B8,'Base File'!$AB:$AB,"Met")/SUM(COUNTIFS('Base File'!$G:$G,"Contractual SLA",'Base File'!$H:$H,"No",'Base File'!$C:$C,B8,'Base File'!$AB:$AB,"Met")+COUNTIFS('Base File'!$G:$G,"Contractual SLA",'Base File'!$H:$H,"No",'Base File'!$C:$C,B8,'Base File'!$AB:$AB,"Not Met")),"-") -> - | AF8: =IFERROR(COUNTIFS('Base File'!$G:$G,"Contractual SLA",'Base File'!$H:$H,"Yes",'Base File'!$C:$C,B8,'Base File'!$AB:$AB,"Met")/SUM(COUNTIFS('Base File'!$G:$G,"Contractual SLA",'Base File'!$H:$H,"yes",'Base File'!$C:$C,B8,'Base File'!$AB:$AB,"Met")+COUNTIFS('Base File'!$G:$G,"Contractual SLA",'Base File'!$H:$H,"yes",'Base File'!$C:$C,B8,'Base File'!$AB:$AB,"Not Met")),"-") -> - | AG8: =IFERROR(COUNTIFS('Base File'!$G:$G,"Internal KPI",'Base File'!$C:$C,B8,'Base File'!$AB:$AB,"Met")/SUM(COUNTIFS('Base File'!$G:$G,"Internal KPI",'Base File'!$C:$C,B8,'Base File'!$AB:$AB,"Met")+COUNTIFS('Base File'!$G:$G,"Internal KPI",'Base File'!$C:$C,B8,'Base File'!$AB:$AB,"Not Met")),"-") -> - | AH8: =IFERROR(COUNTIFS('Base File'!$AD:$AD,"Met",'Base File'!$C:$C,B8)/(COUNTIFS('Base File'!$AD:$AD,"Met",'Base File'!$C:$C,B8)+COUNTIFS('Base File'!$AD:$AD,"Not Met",'Base File'!$C:$C,B8)),"NR") -> NR | AI8: =IFERROR(COUNTIFS('Base File'!$G:$G,"Contractual SLA",'Base File'!$H:$H,"No",'Base File'!$C:$C,B8,'Base File'!$AD:$AD,"Met")/SUM(COUNTIFS('Base File'!$G:$G,"Contractual SLA",'Base File'!$H:$H,"No",'Base File'!$C:$C,B8,'Base File'!$AD:$AD,"Met")+COUNTIFS('Base File'!$G:$G,"Contractual SLA",'Base File'!$H:$H,"No",'Base File'!$C:$C,B8,'Base File'!$AD:$AD,"Not Met")),"-") -> - | AJ8: =IFERROR(COUNTIFS('Base File'!$G:$G,"Contractual SLA",'Base File'!$H:$H,"Yes",'Base File'!$C:$C,B8,'Base File'!$AD:$AD,"Met")/SUM(COUNTIFS('Base File'!$G:$G,"Contractual SLA",'Base File'!$H:$H,"yes",'Base File'!$C:$C,B8,'Base File'!$AD:$AD,"Met")+COUNTIFS('Base File'!$G:$G,"Contractual SLA",'Base File'!$H:$H,"yes",'Base File'!$C:$C,B8,'Base File'!$AD:$AD,"Not Met")),"-") -> - | AK8: =IFERROR(COUNTIFS('Base File'!$G:$G,"Internal KPI",'Base File'!$C:$C,B8,'Base File'!$AD:$AD,"Met")/SUM(COUNTIFS('Base File'!$G:$G,"Internal KPI",'Base File'!$C:$C,B8,'Base File'!$AD:$AD,"Met")+COUNTIFS('Base File'!$G:$G,"Internal KPI",'Base File'!$C:$C,B8,'Base File'!$AD:$AD,"Not Met")),"-") -> - | AL8: =IFERROR(COUNTIFS('Base File'!$AF:$AF,"Met",'Base File'!$C:$C,B8)/(COUNTIFS('Base File'!$AF:$AF,"Met",'Base File'!$C:$C,B8)+COUNTIFS('Base File'!$AF:$AF,"Not Met",'Base File'!$C:$C,B8)),"NR") -> NR | AM8: =IFERROR(COUNTIFS('Base File'!$G:$G,"Contractual SLA",'Base File'!$H:$H,"No",'Base File'!$C:$C,B8,'Base File'!$AF:$AF,"Met")/SUM(COUNTIFS('Base File'!$G:$G,"Contractual SLA",'Base File'!$H:$H,"No",'Base File'!$C:$C,B8,'Base File'!$AF:$AF,"Met")+COUNTIFS('Base File'!$G:$G,"Contractual SLA",'Base File'!$H:$H,"No",'Base File'!$C:$C,B8,'Base File'!$AF:$AF,"Not Met")),"-") -> - | AN8: =IFERROR(COUNTIFS('Base File'!$G:$G,"Contractual SLA",'Base File'!$H:$H,"Yes",'Base File'!$C:$C,B8,'Base File'!$AF:$AF,"Met")/SUM(COUNTIFS('Base File'!$G:$G,"Contractual SLA",'Base File'!$H:$H,"yes",'Base File'!$C:$C,B8,'Base File'!$AF:$AF,"Met")+COUNTIFS('Base File'!$G:$G,"Contractual SLA",'Base File'!$H:$H,"yes",'Base File'!$C:$C,B8,'Base File'!$AF:$AF,"Not Met")),"-") -> - | AO8: =IFERROR(COUNTIFS('Base File'!$G:$G,"Internal KPI",'Base File'!$C:$C,B8,'Base File'!$AF:$AF,"Met")/SUM(COUNTIFS('Base File'!$G:$G,"Internal KPI",'Base File'!$C:$C,B8,'Base File'!$AF:$AF,"Met")+COUNTIFS('Base File'!$G:$G,"Internal KPI",'Base File'!$C:$C,B8,'Base File'!$AF:$AF,"Not Met")),"-") -> - | AP8: =12/23 -> 0.52173913 | AQ8: =0/2 -> 0 | AR8: =0/2 -> 0 | AS8: =12/19 -> 0.63157895 | AT8: =29/60 -> 0.48333333 | AU8: =1/2 -> 0.5 | AV8: =0/2 -> 0 | AW8: =28/56 -> 0.5 | AX8: =28/58 -> 0.48275862 | AY8: =1/2 -> 0.5 | AZ8: =0/2 -> 0 | BA8: =27/54 -> 0.5 | BB8: =38/61 -> 0.62295082 | BC8: =0/2 -> 0 | BD8: =0/2 -> 0 | BE8: =38/57 -> 0.66666667 | BF8: =29/48 -> 0.60416667 | BG8: =1/2 -> 0.5 | BH8: NR | BI8: =28/46 -> 0.60869565 | BJ8: =25/48 -> 0.52083333 | BK8: =1/2 -> 0.5 | BL8: NR | BM8: =24/46 -> 0.52173913 | BN8: =28/48 -> 0.58333333 | BO8: =1/2 -> 0.5 | BP8: NR | BQ8: =27/46 -> 0.58695652 | BR8: =32/64 -> 0.5 | BS8: =0/2 -> 0 | BT8: NR | BU8: =32/62 -> 0.51612903 | BV8: =22/47 -> 0.46808511 | BW8: NR | BX8: NR | BY8: =22/47 -> 0.46808511 | BZ8: - | CA8: - | CB8: - | CC8: - | CD8: - | CE8: - | CF8: - | CG8: - | CH8: - | CI8: - | CJ8: - | CK8: - | CL8: NA | CM8: NA | CN8: NA | CO8: NA | CP8: NA | CQ8: NA | CR8: NA | CS8: NA | CT8: NA | CU8: NA | CV8: NA | CW8: NA | DF8: NA | DG8: NA | DH8: NA | DI8: NA | DJ8: NA | DK8: NA | DL8: NA | DM8: NA | DN8: NA | DO8: NA | DP8: NA | DQ8: NA | DR8: NA | DS8: NA | DT8: NA | DU8: NA
