Workbook

Sheet Summary Dashboard
A1: TAGGD | Revenue Forecast – Summary Dashboard
A3: Auto-updated from 'Revenue Forecast Data' sheet
A5: Total Revenue Forecast | C5: Total MMF | E5: Total Open Reqs | G5: Total Joiners | I5: Total Joiner Fee | K5: Avg Achievement %
A6: ='Revenue Forecast Data'!E62 -> 60550000 | C6: ='Revenue Forecast Data'!I62 -> 14181927 | E6: ='Revenue Forecast Data'!J62 -> 327 | G6: ='Revenue Forecast Data'!L62 -> 1284 | I6: ='Revenue Forecast Data'!M62 -> 39428000 | K6: ='Revenue Forecast Data'!Q62 -> 0.65116433
A7: ₹ Lakhs | C7: ₹ Lakhs | E7: # | G7: # | I7: ₹ Lakhs | K7: %
A10: Month | B10: Revenue Forecast (₹ Lakhs) | C10: MMF (₹ Lakhs) | D10: Open Req (#) | E10: Open Fee (₹ Lakhs) | F10: Joiner (#) | G10: Joiner Fee (₹ Lakhs) | H10: Achievement %
A11: ='Revenue Forecast Data'!D4 -> 45748 | B11: ='Revenue Forecast Data'!E4 -> 47500000 | C11: ='Revenue Forecast Data'!I4 -> 13131927 | D11: ='Revenue Forecast Data'!J4 -> 0 | E11: ='Revenue Forecast Data'!K4 -> 0 | F11: ='Revenue Forecast Data'!L4 -> 982 | G11: ='Revenue Forecast Data'!M4 -> 34370000 | H11: ='Revenue Forecast Data'!Q4 -> 1.0000406
A12: ='Revenue Forecast Data'!D5 -> 45748 | B12: ='Revenue Forecast Data'!E5 -> 2250000 | C12: ='Revenue Forecast Data'!I5 -> 1050000 | D12: ='Revenue Forecast Data'!J5 -> 10 | E12: ='Revenue Forecast Data'!K5 -> 0 | F12: ='Revenue Forecast Data'!L5 -> 35 | G12: ='Revenue Forecast Data'!M5 -> 1200000 | H12: ='Revenue Forecast Data'!Q5 -> 1
A13: ='Revenue Forecast Data'!D6 -> 45748 | B13: ='Revenue Forecast Data'!E6 -> 5600000 | C13: ='Revenue Forecast Data'!I6 -> 0 | D13: ='Revenue Forecast Data'!J6 -> 85 | E13: ='Revenue Forecast Data'!K6 -> 4200000 | F13: ='Revenue Forecast Data'!L6 -> 116 | G13: ='Revenue Forecast Data'!M6 -> 1400000 | H13: ='Revenue Forecast Data'!Q6 -> 1
A14: ='Revenue Forecast Data'!D7 -> 45748 | B14: ='Revenue Forecast Data'!E7 -> 1900000 | C14: ='Revenue Forecast Data'!I7 -> 0 | D14: ='Revenue Forecast Data'!J7 -> 102 | E14: ='Revenue Forecast Data'!K7 -> 1224000 | F14: ='Revenue Forecast Data'!L7 -> 46 | G14: ='Revenue Forecast Data'!M7 -> 718000 | H14: ='Revenue Forecast Data'!Q7 -> 1.0221053
A15: ='Revenue Forecast Data'!D8 -> 45748 | B15: ='Revenue Forecast Data'!E8 -> 3300000 | C15: ='Revenue Forecast Data'!I8 -> 0 | D15: ='Revenue Forecast Data'!J8 -> 130 | E15: ='Revenue Forecast Data'!K8 -> 1560000 | F15: ='Revenue Forecast Data'!L8 -> 105 | G15: ='Revenue Forecast Data'!M8 -> 1740000 | H15: ='Revenue Forecast Data'!Q8 -> 1
A16: TOTAL | B16: =SUM(B11:B15) -> 60550000 | C16: =SUM(C11:C15) -> 14181927 | D16: =SUM(D11:D15) -> 327 | E16: =SUM(E11:E15) -> 6984000 | F16: =SUM(F11:F15) -> 1284 | G16: =SUM(G11:G15) -> 39428000 | H16: =IF(B16=0,0,G16/B16) -> 0.65116433

Sheet Revenue Forecast Data
A1: TAGGD | Revenue Forecast Tracker
A3: Project Name | B3: Update Date | C3: Week | D3: Month | E3: Revenue Forecast (₹ Lakhs) | F3: Adjustment (If Any) | G3: Penalty (If Any) | H3: Bad Debts (If Any) | I3: MMF (₹ Lakhs) | J3: Open Req (#) | K3: Open Fee (₹ Lakhs) | L3: Joiner (#) | M3: Joiner Fee (₹ Lakhs) | N3: To Be Offer | O3: To Be Offer (₹ Lakhs) | P3: Net Revenue | Q3: Achievement % (Joiner Fee / Rev Fcst) | R3: Remarks
A4: Honeywell | B4: 45767 | C4: Week 3 | D4: 45748 | E4: 47500000 | F4: 0 | G4: 0 | H4: 0 | I4: 13131927 | L4: 982 | M4: 34370000 | P4: =E4-F4-G4-H4 -> 47500000 | Q4: =(I4+K4+M4)/E4 -> 1.0000406
A5: Pfizer | B5: 45767 | C5: Week 3 | D5: 45748 | E5: 2250000 | F5: 0 | G5: 0 | H5: 0 | I5: 1050000 | J5: 10 | K5: 0 | L5: 35 | M5: 1200000 | P5: =E5-F5-G5-H5 -> 2250000 | Q5: =(I5+K5+M5)/E5 -> 1
A6: SKF India | B6: 45767 | C6: Week 3 | D6: 45748 | E6: 5600000 | F6: 0 | G6: 0 | H6: 0 | J6: 85 | K6: 4200000 | L6: 116 | M6: 1400000 | P6: =E6-F6-G6-H6 -> 5600000 | Q6: =(I6+K6+M6)/E6 -> 1
A7: Siemens (Advatnta & GBS) | B7: 45767 | C7: Week 3 | D7: 45748 | E7: 1900000 | F7: 0 | G7: 0 | H7: 0 | J7: 102 | K7: 1224000 | L7: 46 | M7: 718000 | P7: =E7-F7-G7-H7 -> 1900000 | Q7: =(I7+K7+M7)/E7 -> 1.0221053
A8: Siemens Energy | B8: 45767 | C8: Week 3 | D8: 45748 | E8: 3300000 | F8: 0 | G8: 0 | H8: 0 | I8: 0 | J8: 130 | K8: 1560000 | L8: 105 | M8: 1740000 | P8: =E8-F8-G8-H8 -> 3300000 | Q8: =(I8+K8+M8)/E8 -> 1
A9: Pidilite | B9: 45767 | C9: Week 3 | D9: 45748 | E9: 2675000 | F9: 0 | G9: 0 | H9: 0 | I9: 675000 | J9: 0 | K9: 0 | L9: 137 | M9: 2000000 | P9: =E9-F9-G9-H9 -> 2675000 | Q9: =(I9+K9+M9)/E9 -> 1
A10: Vertiv | B10: 45767 | C10: Week 3 | D10: 45748 | E10: 1200000 | F10: 0 | G10: 0 | H10: 0 | I10: 240000 | J10: 25 | K10: 360000 | L10: 16 | M10: 600000 | P10: =E10-F10-G10-H10 -> 1200000 | Q10: =(I10+K10+M10)/E10 -> 1
A11: Birla Paints | B11: 45767 | C11: Week 3 | D11: 45748 | E11: 4185000 | F11: 0 | G11: 0 | H11: 0 | I11: 0 | J11: 215 | K11: 1935000 | L11: 165 | M11: 2250000 | P11: =E11-F11-G11-H11 -> 4185000 | Q11: =(I11+K11+M11)/E11 -> 1
A12: Mahindra Holiday | B12: 45767 | C12: Week 3 | D12: 45748 | E12: 300000 | F12: 0 | G12: 0 | H12: 0 | I12: 300000 | J12: 0 | K12: 0 | L12: 0 | M12: 0 | P12: =E12-F12-G12-H12 -> 300000 | Q12: =(I12+K12+M12)/E12 -> 1
A13: HPE | B13: 45767 | C13: Week 3 | D13: 45748 | E13: 41700000 | F13: 0 | G13: 0 | H13: 0 | I13: 21312000 | J13: 400 | L13: 390 | P13: =E13-F13-G13-H13 -> 41700000 | Q13: =(I13+K13+M13)/E13 -> 0.51107914
A14: Isuzu | B14: 45767 | C14: Week 3 | D14: 45748 | E14: 1500000 | F14: 0 | G14: 0 | H14: 0 | J14: 17 | K14: 950000 | L14: 13 | M14: 557500 | P14: =E14-F14-G14-H14 -> 1500000 | Q14: =(I14+K14+M14)/E14 -> 1.005
A15: BITS | B15: 45767 | C15: Week 3 | D15: 45748 | E15: 1200000 | F15: 0 | G15: 0 | H15: 0 | I15: 0 | J15: 0 | K15: 0 | L15: 28 | M15: 1200000 | P15: =E15-F15-G15-H15 -> 1200000 | Q15: =(I15+K15+M15)/E15 -> 1
A16: M&M | B16: 45767 | C16: Week 3 | D16: 45748 | E16: 33100000 | F16: 0 | G16: 0 | H16: 0 | I16: 0 | J16: 0 | K16: 0 | L16: 650 | M16: 33100000 | P16: =E16-F16-G16-H16 -> 33100000 | Q16: =(I16+K16+M16)/E16 -> 1
A17: Wipro | B17: 45767 | C17: Week 3 | D17: 45748 | E17: 6900000 | F17: 0 | G17: 0 | H17: 0 | P17: =E17-F17-G17-H17 -> 6900000 | Q17: =(I17+K17+M17)/E17 -> 0
A18: DP World | B18: 45767 | C18: Week 3 | D18: 45748 | E18: 2530000 | F18: 0 | G18: 0 | H18: 0 | I18: 471000 | J18: 30 | K18: 288000 | L18: 44 | M18: 300014.71 | P18: =E18-F18-G18-H18 -> 2530000 | Q18: =(I18+K18+M18)/E18 -> 0.41858289
A19: AMNS | B19: 45767 | C19: Week 3 | D19: 45748 | E19: 9000000 | F19: 0 | G19: 0 | H19: 0 | I19: 3264000 | J19: 300 | K19: 0 | L19: 144 | M19: 6500000 | P19: =E19-F19-G19-H19 -> 9000000 | Q19: =(I19+K19+M19)/E19 -> 1.0848889
A20: Tata Electronics | B20: 45767 | C20: Week 3 | D20: 45748 | E20: 320000 | F20: 0 | G20: 0 | H20: 0 | I20: 0 | J20: 0 | K20: 0 | L20: 6 | M20: 320000 | P20: =E20-F20-G20-H20 -> 320000 | Q20: =(I20+K20+M20)/E20 -> 1
A21: Jindal Stainless | B21: 45767 | C21: Week 3 | D21: 45748 | E21: 1122000 | F21: 0 | G21: 0 | H21: 0 | I21: 0 | J21: 0 | K21: 216000 | L21: 26 | M21: 906000 | P21: =E21-F21-G21-H21 -> 1122000 | Q21: =(I21+K21+M21)/E21 -> 1
A22: Schaeffler | B22: 45767 | C22: Week 3 | D22: 45748 | E22: 2100000 | F22: 0 | G22: 0 | H22: 0 | I22: 0 | J22: 54 | K22: 1000000 | L22: 42 | M22: 1100000 | P22: =E22-F22-G22-H22 -> 2100000 | Q22: =(I22+K22+M22)/E22 -> 1
A23: Royal Enfield | B23: 45767 | C23: Week 3 | D23: 45748 | E23: 4800000 | F23: 0 | G23: 0 | H23: 0 | P23: =E23-F23-G23-H23 -> 4800000 | Q23: =(I23+K23+M23)/E23 -> 0
A24: SBI Card | B24: 45767 | C24: Week 3 | D24: 45748 | E24: 3950000 | F24: 0 | G24: 0 | H24: 0 | I24: 0 | J24: 0 | K24: 0 | L24: 110 | M24: 3950000 | P24: =E24-F24-G24-H24 -> 3950000 | Q24: =(I24+K24+M24)/E24 -> 1
A25: Hyundai Motor | B25: 45767 | C25: Week 3 | D25: 45748 | E25: 1908439 | F25: 0 | G25: 0 | H25: 0 | I25: 0 | J25: 30 | K25: 550000 | L25: 30 | M25: 1350000 | P25: =E25-F25-G25-H25 -> 1908439 | Q25: =(I25+K25+M25)/E25 -> 0.99557804
A26: Maruti Suzuki(MSIL) | B26: 45767 | C26: Week 3 | D26: 45748 | E26: 7300000 | F26: 0 | G26: 0 | H26: 0 | I26: 0 | J26: 108 | K26: 1300000 | L26: 151 | M26: 6000000 | P26: =E26-F26-G26-H26 -> 7300000 | Q26: =(I26+K26+M26)/E26 -> 1
A27: Tata Consumer | B27: 45767 | C27: Week 3 | D27: 45748 | E27: 6275000 | F27: 0 | G27: 0 | H27: 0 | I27: 1125000 | J27: 165 | K27: 0 | L27: 175 | M27: 5150000 | P27: =E27-F27-G27-H27 -> 6275000 | Q27: =(I27+K27+M27)/E27 -> 1
A28: Tata Play | B28: 45767 | C28: Week 3 | D28: 45748 | E28: 0 | F28: 0 | G28: 0 | H28: 0 | P28: =E28-F28-G28-H28 -> 0 | Q28: =(I28+K28+M28)/E28 -> #DIV/0!
A29: Subros Ltd | B29: 45767 | C29: Week 3 | D29: 45748 | E29: 1050000 | F29: 0 | G29: 0 | H29: 0 | I29: 0 | J29: 21 | K29: 327000 | L29: 14 | M29: 723000 | P29: =E29-F29-G29-H29 -> 1050000 | Q29: =(I29+K29+M29)/E29 -> 1
A30: Atomberg Technologies | B30: 45767 | C30: Week 3 | D30: 45748 | E30: 2370000 | F30: 0 | G30: 0 | H30: 0 | I30: 0 | J30: 32 | K30: 727000 | L30: 30 | M30: 1643000 | P30: =E30-F30-G30-H30 -> 2370000 | Q30: =(I30+K30+M30)/E30 -> 1
A31: Ambuja Cement | B31: 45767 | C31: Week 3 | D31: 45748 | E31: 7300000 | F31: 0 | G31: 0 | H31: 0 | I31: 900000 | J31: 0 | K31: 0 | L31: 169 | M31: 6760000 | P31: =E31-F31-G31-H31 -> 7300000 | Q31: =(I31+K31+M31)/E31 -> 1.0493151
A32: Ashok Leyland | B32: 45767 | C32: Week 3 | D32: 45748 | E32: 4600000 | F32: 0 | G32: 0 | H32: 0 | J32: 45 | K32: 933750 | L32: 147 | M32: 4608750 | P32: =E32-F32-G32-H32 -> 4600000 | Q32: =(I32+K32+M32)/E32 -> 1.2048913
A33: Bridgestone | B33: 45767 | C33: Week 3 | D33: 45748 | E33: 1582000 | F33: 0 | G33: 0 | H33: 0 | I33: 330000 | J33: 30 | K33: 0 | L33: 28 | M33: 1270000 | P33: =E33-F33-G33-H33 -> 1582000 | Q33: =(I33+K33+M33)/E33 -> 1.011378
A34: Sterling Tools | B34: 45767 | C34: Week 3 | D34: 45748 | E34: 1200000 | F34: 0 | G34: 0 | H34: 0 | I34: 510000 | J34: 0 | K34: 0 | L34: 15 | M34: 690000 | P34: =E34-F34-G34-H34 -> 1200000 | Q34: =(I34+K34+M34)/E34 -> 1
A35: Pernod Ricard | B35: 45767 | C35: Week 3 | D35: 45748 | E35: 2947000 | F35: 0 | G35: 0 | H35: 0 | I35: 1356000 | J35: 0 | K35: 0 | L35: 36 | M35: 1591000 | P35: =E35-F35-G35-H35 -> 2947000 | Q35: =(I35+K35+M35)/E35 -> 1
A36: Ngarjuna Leadership | B36: 45767 | C36: Week 3 | D36: 45748 | E36: 325000 | F36: 0 | G36: 0 | H36: 0 | P36: =E36-F36-G36-H36 -> 325000 | Q36: =(I36+K36+M36)/E36 -> 0
A37: ABB | B37: 45767 | C37: Week 3 | D37: 45748 | E37: 2025000 | F37: 0 | G37: 0 | H37: 0 | I37: 510000 | J37: 0 | K37: 0 | L37: 16 | M37: 1520625 | P37: =E37-F37-G37-H37 -> 2025000 | Q37: =(I37+K37+M37)/E37 -> 1.0027778
A38: Siemens Healthnier | B38: 45767 | C38: Week 3 | D38: 45748 | E38: 2725920 | F38: 0 | G38: 0 | H38: 0 | P38: =E38-F38-G38-H38 -> 2725920 | Q38: =(I38+K38+M38)/E38 -> 0
A39: LEAP India | B39: 45767 | C39: Week 3 | D39: 45748 | E39: 1910000 | F39: 0 | G39: 0 | H39: 0 | I39: 0 | J39: 39 | K39: 624000 | L39: 56 | M39: 1280000 | P39: =E39-F39-G39-H39 -> 1910000 | Q39: =(I39+K39+M39)/E39 -> 0.99685864
A40: UniCharm | B40: 45767 | C40: Week 3 | D40: 45748 | E40: 1268000 | F40: 0 | G40: 0 | H40: 0 | I40: 0 | J40: 30 | K40: 400000 | L40: 21 | M40: 868000 | P40: =E40-F40-G40-H40 -> 1268000 | Q40: =(I40+K40+M40)/E40 -> 1
A41: Optum | B41: 45767 | C41: Week 3 | D41: 45748 | E41: 13750000 | F41: 0 | G41: 0 | H41: 0 | P41: =E41-F41-G41-H41 -> 13750000 | Q41: =(I41+K41+M41)/E41 -> 0
...

Sheet Instructions
A1: How to Use This Template
B4: SHEET | C4: Revenue Forecast Data | D4: Enter monthly forecast data here. Blue cells = inputs. Formula cells are auto-calculated.
B5: SHEET | C5: Summary Dashboard | D5: Auto-updated KPI cards, summary table and charts. No manual entry required.
B7: COLOR CODE | C7: Blue text | D7: Hard-coded input values entered by user
B8: COLOR CODE | C8: Black text | D8: Formulas / auto-calculated fields
B9: COLOR CODE | C9: Green text | D9: Values linked from other sheets
B10: COLOR CODE | C10: Gold / Yellow | D10: KPI highlight or total row
B12: COLUMN | C12: Revenue Forecast (₹ Lakhs) | D12: Total forecasted billing for the month
B13: COLUMN | C13: MMF (₹ Lakhs) | D13: Minimum Monthly Fee commitment
B14: COLUMN | C14: Open Req (#) | D14: Count of open positions / requirements
B15: COLUMN | C15: Open Fee (₹ Lakhs) | D15: Fee attached to open requirements
B16: COLUMN | C16: Joiner (#) | D16: Number of candidates who joined (DOJ)
B17: COLUMN | C17: Joiner Fee (₹ Lakhs) | D17: Fee earned from joiners
B18: COLUMN | C18: Achievement % | D18: Joiner Fee ÷ Revenue Forecast — auto-calculated
