Workbook

Sheet Summary Dashboard
A1: REVENUE VISIBILITY – SUMMARY DASHBOARD
A2: Auto-refreshes from Revenue Tracker sheet
A4: 💰 Total MMF (₹) | E4: 📥 Opening Fee (₹) | I4: ✅ Joining Fee (₹)
A5: ='Revenue Tracker'!D58 -> 46759927 | E5: ='Revenue Tracker'!F58 -> 0 | I5: ='Revenue Tracker'!H58 -> 0
A8: 📋 Open Requisitions | E8: 🤝 Total Joiners | I8: ⏳ Yet to Join
A9: ='Revenue Tracker'!E58 -> 0 | E9: ='Revenue Tracker'!G58 -> 0 | I9: ='Revenue Tracker'!I58 -> 0
A13: 🔄 Overall Conversion % | E13: 📈 Revenue Realised % | I13: ⚠️ Gap to MMF (₹)
A14: ='Revenue Tracker'!K58 -> 0 | E14: ='Revenue Tracker'!L58 -> 0 | I14: ='Revenue Tracker'!M58 -> 46759927
A18: PROJECT-WISE REVENUE SUMMARY
A19: # | B19: Project Name | C19: Open Req | D19: Opening Fee (₹) | E19: Joiners | F19: Joining Fee (₹) | G19: YTJ | H19: YTJ Fee (₹) | I19: Conv % | J19: Rev % | K19: Gap to MMF (₹) | L19: Status
A20: 1 | B20: ='Revenue Tracker'!B4 -> Honeywell | C20: ='Revenue Tracker'!E4 -> 0 | D20: ='Revenue Tracker'!F4 -> 0 | E20: ='Revenue Tracker'!G4 -> 0 | F20: ='Revenue Tracker'!H4 -> 0 | G20: ='Revenue Tracker'!I4 -> 0 | H20: ='Revenue Tracker'!J4 -> 0 | I20: ='Revenue Tracker'!K4 -> 0 | J20: ='Revenue Tracker'!L4 -> 0 | ... L20: ='Revenue Tracker'!N4 -> 🔴 At Risk
A21: 2 | B21: ='Revenue Tracker'!B5 -> Pfizer | C21: ='Revenue Tracker'!E5 -> 0 | D21: ='Revenue Tracker'!F5 -> 0 | E21: ='Revenue Tracker'!G5 -> 0 | F21: ='Revenue Tracker'!H5 -> 0 | G21: ='Revenue Tracker'!I5 -> 0 | H21: ='Revenue Tracker'!J5 -> 0 | I21: ='Revenue Tracker'!K5 -> 0 | J21: ='Revenue Tracker'!L5 -> 0 | ... L21: ='Revenue Tracker'!N5 -> 🔴 At Risk
A22: 3 | B22: ='Revenue Tracker'!B6 -> SKF India | C22: ='Revenue Tracker'!E6 -> 0 | D22: ='Revenue Tracker'!F6 -> 0 | E22: ='Revenue Tracker'!G6 -> 0 | F22: ='Revenue Tracker'!H6 -> 0 | G22: ='Revenue Tracker'!I6 -> 0 | H22: ='Revenue Tracker'!J6 -> 0 | I22: ='Revenue Tracker'!K6 -> 0 | J22: ='Revenue Tracker'!L6 -> 0 | ... L22: ='Revenue Tracker'!N6 -> 🔴 At Risk
A23: 4 | B23: ='Revenue Tracker'!B7 -> Siemens (Advatnta & GBS) | C23: ='Revenue Tracker'!E7 -> 0 | D23: ='Revenue Tracker'!F7 -> 0 | E23: ='Revenue Tracker'!G7 -> 0 | F23: ='Revenue Tracker'!H7 -> 0 | G23: ='Revenue Tracker'!I7 -> 0 | H23: ='Revenue Tracker'!J7 -> 0 | I23: ='Revenue Tracker'!K7 -> 0 | J23: ='Revenue Tracker'!L7 -> 0 | ... L23: ='Revenue Tracker'!N7 -> 🔴 At Risk
A24: 5 | B24: ='Revenue Tracker'!B8 -> Siemens Energy | C24: ='Revenue Tracker'!E8 -> 0 | D24: ='Revenue Tracker'!F8 -> 0 | E24: ='Revenue Tracker'!G8 -> 0 | F24: ='Revenue Tracker'!H8 -> 0 | G24: ='Revenue Tracker'!I8 -> 0 | H24: ='Revenue Tracker'!J8 -> 0 | I24: ='Revenue Tracker'!K8 -> 0 | J24: ='Revenue Tracker'!L8 -> 0 | ... L24: ='Revenue Tracker'!N8 -> 🔴 At Risk
B25: TOTAL | C25: =SUM(C20:C24) -> 0 | D25: =SUM(D20:D24) -> 0 | E25: =SUM(E20:E24) -> 0 | F25: =SUM(F20:F24) -> 0 | G25: =SUM(G20:G24) -> 0 | H25: =SUM(H20:H24) -> 0 | I25: =IFERROR(E25/C25,0) -> 0 | J25: ='Revenue Tracker'!L58 -> 0 | K25: =SUM(K20:K24) -> 14181927
A27: 💡 Note: All figures auto-linked from 'Revenue Tracker' sheet. Update tracker data to refresh dashboard.

Sheet Revenue Tracker
A1: REVENUE VISIBILITY TRACKER
A2: RPO Revenue Pipeline | Taggd
A3: Updated Date | B3: Project Name | C3: PH Name | D3: MMF (₹) | E3: Open Req | F3: Opening Fee (₹) | G3: Joiners as on Date | H3: Joining Fee (₹) | I3: Yet to Join | J3: YTJ Fee (₹) | K3: Conversion Rate % | L3: Revenue Realised % | M3: Gap to MMF (₹) | N3: Status
A4: 45767 | B4: Honeywell | D4: 13131927 | K4: =IF(E4>0,G4/E4,0) -> 0 | L4: =IF(D4>0,H4/D4,0) -> 0 | M4: =D4-(H4+J4) -> 13131927 | N4: =IF(L4>=1,"✅ Target Met",IF(L4>=0.6,"🟡 On Track","🔴 At Risk")) -> 🔴 At Risk
A5: 45767 | B5: Pfizer | D5: 1050000 | K5: =IF(E5>0,G5/E5,0) -> 0 | L5: =IF(D5>0,H5/D5,0) -> 0 | M5: =D5-(H5+J5) -> 1050000 | N5: =IF(L5>=1,"✅ Target Met",IF(L5>=0.6,"🟡 On Track","🔴 At Risk")) -> 🔴 At Risk
A6: 45767 | B6: SKF India | D6: 0 | K6: =IF(E6>0,G6/E6,0) -> 0 | L6: =IF(D6>0,H6/D6,0) -> 0 | M6: =D6-(H6+J6) -> 0 | N6: =IF(L6>=1,"✅ Target Met",IF(L6>=0.6,"🟡 On Track","🔴 At Risk")) -> 🔴 At Risk
A7: 45767 | B7: Siemens (Advatnta & GBS) | D7: 0 | K7: =IF(E7>0,G7/E7,0) -> 0 | L7: =IF(D7>0,H7/D7,0) -> 0 | M7: =D7-(H7+J7) -> 0 | N7: =IF(L7>=1,"✅ Target Met",IF(L7>=0.6,"🟡 On Track","🔴 At Risk")) -> 🔴 At Risk
A8: 45767 | B8: Siemens Energy | D8: 0 | K8: =IF(E8>0,G8/E8,0) -> 0 | L8: =IF(D8>0,H8/D8,0) -> 0 | M8: =D8-(H8+J8) -> 0 | N8: =IF(L8>=1,"✅ Target Met",IF(L8>=0.6,"🟡 On Track","🔴 At Risk")) -> 🔴 At Risk
A9: 45767 | B9: Pidilite | D9: 675000
A10: 45767 | B10: Vertiv | D10: 240000
A11: 45767 | B11: Birla Paints | D11: 0
A12: 45767 | B12: Mahindra Holiday | D12: 300000
A13: 45767 | B13: HPE | D13: 21312000
A14: 45767 | B14: Isuzu | D14: 0
A15: 45767 | B15: BITS | D15: 0
A16: 45767 | B16: M&M | D16: 0
A17: 45767 | B17: Wipro | D17: 0
A18: 45767 | B18: DP World | D18: 471000
A19: 45767 | B19: AMNS | D19: 3264000
A20: 45767 | B20: Tata Electronics | D20: 0
... A37: 45767 | B37: ABB | D37: 510000
A38: 45767 | B38: Siemens Healthnier | D38: 0 | K38: =IF(E38>0,G38/E38,0) -> 0 | L38: =IF(D38>0,H38/D38,0) -> 0 | M38: =D38-(H38+J38) -> 0 | N38: =IF(D38=0,"",IF(L38>=1,"✅ Target Met",IF(L38>=0.6,"🟡 On Track","🔴 At Risk")))
A39: 45767 | B39: LEAP India | D39: 0 | K39: =IF(E39>0,G39/E39,0) -> 0 | L39: =IF(D39>0,H39/D39,0) -> 0 | M39: =D39-(H39+J39) -> 0 | N39: =IF(D39=0,"",IF(L39>=1,"✅ Target Met",IF(L39>=0.6,"🟡 On Track","🔴 At Risk")))
A40: 45767 | B40: UniCharm | C40: * Drop dwon from Ph List | D40: 0 | K40: =IF(E40>0,G40/E40,0) -> 0 | L40: =IF(D40>0,H40/D40,0) -> 0 | M40: =D40-(H40+J40) -> 0 | N40: =IF(D40=0,"",IF(L40>=1,"✅ Target Met",IF(L40>=0.6,"🟡 On Track","🔴 At Risk")))
A41: 45767 | B41: Optum | D41: 0 | K41: * Auto Populated | L41: * Auto Populated | M41: =D41-(H41+J41) -> 0 | N41: =IF(D41=0,"",IF(L41>=1,"✅ Target Met",IF(L41>=0.6,"🟡 On Track","🔴 At Risk")))
A42: 45767 | B42: Saint Gobain | C42: * Manadatory | D42: 0 | E42: * Manadatory | F42: * Manadatory | G42: * Manadatory | H42: * Manadatory | I42: * Manadatory | J42: * Manadatory | M42: * Non manadatory | N42: =IF(D42=0,"",IF(L42>=1,"✅ Target Met",IF(L42>=0.6,"🟡 On Track","🔴 At Risk")))
A43: 45767 | B43: Proterial | D43: 0 | K43: =IF(E43>0,G43/E43,0) -> 0 | L43: =IF(D43>0,H43/D43,0) -> 0 | M43: =D43-(H43+J43) -> 0 | N43: =IF(D43=0,"",IF(L43>=1,"✅ Target Met",IF(L43>=0.6,"🟡 On Track","🔴 At Risk")))
A44: 45767 | B44: Neo Soft | D44: 1185000 | K44: =IF(E44>0,G44/E44,0) -> 0 | L44: =IF(D44>0,H44/D44,0) -> 0 | M44: =D44-(H44+J44) -> 1185000 | N44: =IF(D44=0,"",IF(L44>=1,"✅ Target Met",IF(L44>=0.6,"🟡 On Track","🔴 At Risk"))) -> 🔴 At Risk
A45: 45767 | B45: M&M Leadership | D45: 0 | K45: =IF(E45>0,G45/E45,0) -> 0 | L45: =IF(D45>0,H45/D45,0) -> 0 | M45: =D45-(H45+J45) -> 0 | N45: =IF(D45=0,"",IF(L45>=1,"✅ Target Met",IF(L45>=0.6,"🟡 On Track","🔴 At Risk")))
A46: 45767 | B46: Honeywell Leadership | D46: 0 | K46: =IF(E46>0,G46/E46,0) -> 0 | L46: =IF(D46>0,H46/D46,0) -> 0 | M46: =D46-(H46+J46) -> 0 | N46: =IF(D46=0,"",IF(L46>=1,"✅ Target Met",IF(L46>=0.6,"🟡 On Track","🔴 At Risk")))
A47: 45767 | B47: Vertiv Leadership | D47: 0 | K47: =IF(E47>0,G47/E47,0) -> 0 | L47: =IF(D47>0,H47/D47,0) -> 0 | M47: =D47-(H47+J47) -> 0 | N47: =IF(D47=0,"",IF(L47>=1,"✅ Target Met",IF(L47>=0.6,"🟡 On Track","🔴 At Risk")))
A48: 45767 | B48: Subros Leadership | D48: 0 | K48: =IF(E48>0,G48/E48,0) -> 0 | L48: =IF(D48>0,H48/D48,0) -> 0 | M48: =D48-(H48+J48) -> 0 | N48: =IF(D48=0,"",IF(L48>=1,"✅ Target Met",IF(L48>=0.6,"🟡 On Track","🔴 At Risk")))
A49: 45767 | B49: AMNS Leadership | D49: 0 | K49: =IF(E49>0,G49/E49,0) -> 0 | L49: =IF(D49>0,H49/D49,0) -> 0 | M49: =D49-(H49+J49) -> 0 | N49: =IF(D49=0,"",IF(L49>=1,"✅ Target Met",IF(L49>=0.6,"🟡 On Track","🔴 At Risk")))
A50: 45767 | B50: Hyundai Leadership | D50: 0 | K50: =IF(E50>0,G50/E50,0) -> 0 | L50: =IF(D50>0,H50/D50,0) -> 0 | M50: =D50-(H50+J50) -> 0 | N50: =IF(D50=0,"",IF(L50>=1,"✅ Target Met",IF(L50>=0.6,"🟡 On Track","🔴 At Risk")))
A51: 45767 | B51: Siemens Leadership | D51: 0 | K51: =IF(E51>0,G51/E51,0) -> 0 | L51: =IF(D51>0,H51/D51,0) -> 0 | M51: =D51-(H51+J51) -> 0 | N51: =IF(D51=0,"",IF(L51>=1,"✅ Target Met",IF(L51>=0.6,"🟡 On Track","🔴 At Risk")))
A52: 45767 | B52: Royal Enfield Leadership | D52: 0 | K52: =IF(E52>0,G52/E52,0) -> 0 | L52: =IF(D52>0,H52/D52,0) -> 0 | M52: =D52-(H52+J52) -> 0 | N52: =IF(D52=0,"",IF(L52>=1,"✅ Target Met",IF(L52>=0.6,"🟡 On Track","🔴 At Risk")))
A53: 45767 | B53: CG Power | D53: 0 | K53: =IF(E53>0,G53/E53,0) -> 0 | L53: =IF(D53>0,H53/D53,0) -> 0 | M53: =D53-(H53+J53) -> 0 | N53: =IF(D53=0,"",IF(L53>=1,"✅ Target Met",IF(L53>=0.6,"🟡 On Track","🔴 At Risk")))
A54: 45767 | B54: CG Power Leadership | D54: 0 | K54: =IF(E54>0,G54/E54,0) -> 0 | L54: =IF(D54>0,H54/D54,0) -> 0 | M54: =D54-(H54+J54) -> 0 | N54: =IF(D54=0,"",IF(L54>=1,"✅ Target Met",IF(L54>=0.6,"🟡 On Track","🔴 At Risk")))
... A57: 45767 | B57: Reliance | D57: 400000 | K57: =IF(E57>0,G57/E57,0) -> 0 | L57: =IF(D57>0,H57/D57,0) -> 0 | M57: =D57-(H57+J57) -> 400000 | N57: =IF(D57=0,"",IF(L57>=1,"✅ Target Met",IF(L57>=0.6,"🟡 On Track","🔴 At Risk"))) -> 🔴 At Risk
A58: GRAND TOTAL | D58: =SUM(D4:D57) -> 46759927 | E58: =SUM(E4:E57) -> 0 | F58: =SUM(F4:F57) -> 0 | G58: =SUM(G4:G57) -> 0 | H58: =SUM(H4:H57) -> 0 | I58: =SUM(I4:I57) -> 0 | J58: =SUM(J4:J57) -> 0 | K58: =IFERROR(G58/E58,0) -> 0 | L58: =IFERROR(H58/D58,0) -> 0 | M58: =D58-(H58+J58) -> 46759927
...

Sheet Legend & Guide
A1: FIELD DEFINITIONS & GUIDE
A3: Field | B3: Definition | C3: Example | D3: Notes | E3: Color Code
A4: Updated Date | B4: Date when record was last updated | C4: 01-Apr-25 | D4: DD-MMM-YY format | E4: —
A5: Project Name | B5: Client / Project identifier | C5: Optum – Tech Hiring | D5: Free text | E5: —
A6: PH Name | B6: Pursuit Head / Account Manager Name | C6: Priya Sharma | D6: Free text | E6: —
A7: MMF (₹) | B7: Monthly Monetisation Forecast in Rupees | C7: ₹5,00,000 | D7: Blue text = input | E7: Blue
A8: Open Req | B8: Number of open requisitions | C8: 12 | D8: Blue text = input | E8: Blue
A9: Opening Fee (₹) | B9: Total fee potential for open reqs | C9: ₹4,80,000 | D9: Blue text = input | E9: Blue
A10: Joiners as on Date | B10: Candidates who have joined till date | C10: 7 | D10: Blue text = input | E10: Blue
A11: Joining Fee (₹) | B11: Fee realised from joiners | C11: ₹2,80,000 | D11: Blue text = input | E11: Blue
A12: Yet to Join (YTJ) | B12: Offered/selected but not yet joined | C12: 5 | D12: Blue text = input | E12: Blue
A13: YTJ Fee (₹) | B13: Potential fee from YTJ candidates | C13: ₹2,00,000 | D13: Blue text = input | E13: Blue
A14: Conversion Rate % | B14: Joiners / Open Req | C14: 58.3% | D14: Auto-calculated | E14: Black
... A17: Status | B17: Target Met / On Track / At Risk | C17: 🟡 On Track | D17: Auto-calculated | E17: Black
A20: STATUS COLOUR GUIDE
A21: ✅ Target Met | C21: Revenue Realised ≥ 100% of MMF
A22: 🟡 On Track | C22: Revenue Realised ≥ 60% of MMF
A23: 🔴 At Risk | C23: Revenue Realised < 60% of MMF
