Workbook

Sheet Note
B2: ## | C2: Metrics | D2: Formula | E2: Value | F2: Remarks | G2: Input data
B3: 1 | C3: Revenue | E3: in lacs | G3: Finance or Ops Tracker
B4: 2 | C4: Productivity | E4: in lacs
B5: 3 | C5: Ideal Headcount | D5: Revenue/Prodcutivity | E5: Count
B6: 4 | C6: Current Headcount | E6: Count | F6: Actual emp in the system | G6: From HRMS Portal
B7: 5 | C7: Additional Headcount | E7: Count | F7: Vendor Headcount (HR Guru, Lyftr etc) | G7: Ops Team share Client wise
B8: 6 | C8: Open Position | E8: Count | G8: HR - Recruitment Tracker
B9: 7 | C9: Existing Resignation | E9: Count | F9: Currently serving notice period | G9: From HRMS Portal
B12: Final Variance | C12: Ideal Headcount -(Current Headcount + Open Position + Additional Headcount Vendor - Existing Resignation)
C16: Work Level / Band | D16: Description | H16: Ideal Headcount
C17: WL1 | D17: Recruiter/Sourcer/Onboarding Spoc | H17: Revenue/Productivity
C18: WL2 | D18: Manager ( Assistant Manager/Manager/Senior Manager) | H18: WL1 Headcount / 8
C19: WL3 | D19: Practice Head (Service Delivery Leader/ Associate Vice President) | H19: WL2 Headcount / 8
C20: WL4 | D20: Leader (Vice President/ Senior Vice President) | H20: WL3 Headcount / 8

Sheet HC_Summary Excluding Optum
A1: Summary Excluding Optum | B1: 45951 | C1: 45973 | D1: 45988 | E1: 45994 | F1: 46002 | G1: 46009 | H1: 46038 | I1: 46052 | J1: 46070
A2: Existing Headcount (including HR Guru & Lyftr resources - 35) | B2: 539 | C2: 538 | D2: 544 | E2: 539 | F2: 548 | G2: 548 | H2: 563 | I2: =545+35 -> 580 | J2: =548+35 -> 583
A3: Number of Replacement positions including resignation | B3: 20 | C3: 19 | D3: 21 | E3: 26 | F3: 31 | G3: 29 | H3: 26 | I3: 15 | J3: 8
A4: Number of New Hires | B4: 47 | C4: 31 | D4: 17 | E4: 31 | F4: 29 | G4: 35 | H4: 36 | I4: 55 | J4: 44
A5: Overall Numbers | B5: =SUM(B2:B4) -> 606 | C5: =SUM(C2:C4) -> 588 | D5: =SUM(D2:D4) -> 582 | E5: =SUM(E2:E4) -> 596 | F5: =SUM(F2:F4) -> 608 | G5: =SUM(G2:G4) -> 612 | H5: =SUM(H2:H4) -> 625 | I5: =SUM(I2:I4) -> 650 | J5: =SUM(J2:J4) -> 635
A6: Number of resignation | B6: 12 | C6: 16 | D6: 20 | E6: 22 | F6: 26 | G6: 24 | H6: 18 | I6: 17 | J6: 18
A8: Ideal HC as per productivity | B8: 436 | C8: 436 | D8: 438 | E8: 431 | F8: 440 | G8: 488 | H8: 537 | I8: 537 | J8: 505
A9: Net Variance (after excluding resignations) | B9: =B5-B8-B6 -> 158 | C9: =C5-C8-C6 -> 136 | D9: =D5-D8-D6 -> 124 | E9: =E5-E8-E6 -> 143 | F9: =F5-F8-F6 -> 142 | G9: =G5-G8-G6 -> 100 | H9: =H5-H8-H6 -> 70 | I9: =I5-I8-I6 -> 96 | J9: =J5-J8-J6 -> 112
A10: Variance from last update | C10: =C9-B9 -> -22 | D10: =D9-C9 -> -12 | E10: =E9-D9 -> 19 | F10: =F9-E9 -> -1 | G10: =G9-F9 -> -42 | H10: =H9-G9 -> -30 | I10: =I9-H9 -> 26 | J10: =J9-I9 -> 16

Sheet Mapping
A1: Project as per EDB | B1: RH | C1: PH | D1: Region
A2: Honeywell | B2: Sulabh Arora | C2: Bapi Reddy Medapati | D2: South
A3: Pfizer | B3: Anjli Zutshi | C3: Usha Babu Shetty | D3: West
A4: Tata Motors | B4: Anjli Zutshi | C4: Shweta Shalini | D4: West
A5: Tata Power | B5: Anjli Zutshi | C5: Elton Francis Isaac | D5: West
A6: SKF India | B6: Anjli Zutshi | C6: Natasha Mehta | D6: North
A7: Siemens | B7: Sulabh Arora | C7: Sulabh Arora | D7: South
A8: Bosch | B8: Sulabh Arora | C8: Sulabh Arora | D8: South
A9: Pidilite | B9: Anjli Zutshi | C9: Usha Babu Shetty | D9: West
A10: Vertiv | B10: Anjli Zutshi | C10: Shweta Shalini | D10: West
A11: Birla Paints | B11: Anjli Zutshi | C11: Geetu Lalwani | D11: West
A12: Ingram Micro | B12: Anjli Zutshi | C12: Usha Babu Shetty | D12: West
... A60: Digitization | B60: Manish Gupta | C60: Ashish Kapur | D60: Platform

Sheet HC Projection Including Optum
E3: Headcount Projection (Ops including Optum)
E4: Target | F4: 456 | G4: 456 | H4: 456
E5: Category | F5: 46054 | G5: =EOMONTH(F5,1) -> 46112 | H5: =EOMONTH(G5,1) -> 46142
E6: HC on the opening on the month | F6: 562 | G6: =F18 -> 618 | H6: =G18 -> 638
E7: HR Guru + Lyftr | F7: =33+3 -> 36 | G7: 40 | H7: 40
D8: A | E8: Total No. of Resignations (as on date) | F8: 20 | G8: 15 | H8: 15
E9: Total No. of Exits (till date) | F9: 3 | G9: 5 | H9: 12
E10: No. of People from resignations who will leave within this month | F10: 5 | G10: 13 | H10: 2
D11: B | E11: Total Open Positions as on date(Approved/Unapproved) | F11: 52
E12: YTJ as on date | F12: =7+3 -> 10 | G12: =3+25 -> 28 | H12: =1+13 -> 14
E13: Already Joined in the month | F13: 18
D14: C | E14: No. of PIP Initiated (Not Resigned) | F14: 0
E15: No. of people exited/to be exited from PIP cases (not part of resignation) in the month | F15: 0
E16: People in Talent Pool (Not Resigned) | F16: 0
E17: No. of exit from Talent Pool in the month | F17: 0
E18: Closing HC | F18: =F6-F9-F10+F12+F13-F15-F17+F7 -> 618 | G18: =G6-G9-G10+G12+G13-G15-G17+10 -> 638 | H18: =H6-H9-H10+H12+H13-H15-H17 -> 638
E19: Cost in the Quarter | F19: =F18+10 -> 628 | G19: =G18+10 -> 648 | H19: =H18+10 -> 648
E21: Variannce | F21: =F4-F19 -> -172 | G21: =G4-G19 -> -192 | H21: =H4-H19 -> -192

Sheet Projected HC - FY26 (Q4)
J1: FY26 | K1: Revenue | M1: Lateral HC | P1: Productivity | Q1: Ideal HC as per Productivity | W1: Current HC as per HRMS | AD1: Additional Headcount | AF1: Open Position | AI1: Open Positions
K2: =SUM(K4:K55) -> 2662.566 | N2: 1.5163834 | O2: 1.53 | P2: =AVERAGE(P4:P55) -> 2.0129708 | Q2: =IFERROR(K2/(P2*3),"") -> 440.90158 | R2: =IFERROR(Q2/8,"") -> 55.112697 | S2: =IFERROR(R2/8,"") -> 6.8890872 | T2: =IFERROR(S2/3,"") -> 2.2963624 | U2: =SUM(Q2:T2) -> 505.19973 | W2: =SUM(W4:W55) -> 428 | X2: =SUM(X4:X55) -> 104 | Y2: =SUM(Y4:Y55) -> 14 | Z2: =SUM(Z4:Z55) -> 2 | AA2: =SUM(AA4:AA55) -> 548 | AB2: =U2-AA2 -> -42.800274 | AD2: =SUM(AD4:AD52) -> 35 | AF2: =SUM(AF4:AF54) -> 8 | AG2: =SUM(AG4:AG54) -> 44 | AI2: =SUM(AI4:AI54) -> 39 | AJ2: =SUM(AJ4:AJ54) -> 9 | AK2: =SUM(AK4:AK54) -> 4 | AL2: =SUM(AL4:AL54) -> 0 | AM2: =SUM(AI2:AL2) -> 52 | AN2: =SUM(AN4:AN52) -> 7 | AO2: =SUM(AO4:AO52) -> 18 | AP2: =U2-(AA2+AM2+AD2-AO2) -> -111.80027
A3: Project Code | B3: Project | C3: Project | D3: Industry | E3: Signup Date | F3: Expiry Date | G3: RH | H3: PH | I3: Region | J3: RPH/CPH | K3: Q4 | N3: FY24-25 Productivity | O3: Productivity (H1) | P3: Q4 | Q3: WL1 | R3: WL2 | S3: WL3 | T3: WL4 | U3: Total HC | W3: WL1 | X3: WL2 | Y3: WL3 | Z3: WL4 | AA3: Overall HC | AB3: Variance | AD3: HC for HR Guru + Lyftr | AF3: Replacement | AG3: New | AI3: Open Positions - WL1 | AJ3: Open Positions - WL2 | AK3: Open Positions - WL3 | AL3: Open Positions - WL4 | AM3: Total Open Positions | AN3: Replacement Exited | AO3: Existing Resignation | AP3: HC Variance After Hiring
A4: CNO0000033 | B4: Honeywell | C4: Honeywell | D4: Engineering | E4: 42097 | F4: 46112 | G4: Sulabh Arora | H4: Bapi Reddy Medapati | I4: South | J4: =IFERROR(VLOOKUP(C4,CPH!$A:$E,5,0),"") -> 43500 | K4: 485.16598 | N4: 2.6 | O4: 2.5 | P4: =IFERROR(N4*1.3,1.8) -> 3.38 | Q4: =IFERROR(K4/(P4*3),"") -> 47.846744 | R4: =IFERROR(Q4/8,"") -> 5.9808429 | S4: =IFERROR(R4/8,"") -> 0.74760537 | T4: =IFERROR(S4/3,"") -> 0.24920179 | U4: =SUM(Q4:T4) -> 54.824394 | W4: =IFERROR(VLOOKUP($C4,'HC & Open Position'!$D:$J,MATCH(W$3,'HC & Open Position'!$D$3:$J$3,1),0),"") -> 37 | X4: =IFERROR(VLOOKUP($C4,'HC & Open Position'!$D:$J,MATCH(X$3,'HC & Open Position'!$D$3:$J$3,1),0),"") -> 22 | Y4: =IFERROR(VLOOKUP($C4,'HC & Open Position'!$D:$J,MATCH(Y$3,'HC & Open Position'!$D$3:$J$3,1),0),"") -> 1 | Z4: =IFERROR(VLOOKUP($C4,'HC & Open Position'!$D:$J,MATCH(Z$3,'HC & Open Position'!$D$3:$J$3,1),0),"") -> 0 | AA4: =SUM(W4:Z4) -> 60 | AB4: =U4-AA4 -> -5.1756063 | AI4: =IFERROR(VLOOKUP($C4,'HC & Open Position'!$D$3:$P$55,9,0),"") -> 0 | AJ4: =IFERROR(VLOOKUP($C4,'HC & Open Position'!$D$3:$P$55,10,0),"") -> 0 | AK4: =IFERROR(VLOOKUP($C4,'HC & Open Position'!$D$3:$P$55,11,0),"") -> 0 | AL4: =IFERROR(VLOOKUP($C4,'HC & Open Position'!$D$3:$P$55,12,0),"") -> 0 | AM4: =SUM(AI4:AL4) -> 0 | AO4: 2 | AP4: =U4-SUM(AA4+AM4+AD4-AO4) -> -3.1756063
A5: CNO0000127 | B5: Pfizer | C5: Pfizer | D5: Pharma | E5: 43286 | F5: 45504 | G5: Anjli Zutshi | H5: Usha Babu Shetty | I5: West | J5: =IFERROR(VLOOKUP(C5,CPH!$A:$E,5,0),"") -> 74000 | K5: 20.6 | N5: 1.5896958 | O5: 1.1865639 | P5: =IFERROR(N5*1.3,1.8) -> 2.0666045 | Q5: =IFERROR(K5/(P5*3),"") -> 3.3226805 | R5: =IFERROR(Q5/8,"") -> 0.41533507 | S5: =IFERROR(R5/8,"") -> 0.051916883 | T5: =IFERROR(S5/3,"") -> 0.017305628 | U5: =SUM(Q5:T5) -> 3.8072381 | W5: =IFERROR(VLOOKUP($C5,'HC & Open Position'!$D:$J,MATCH(W$3,'HC & Open Position'!$D$3:$J$3,1),0),"") -> 4 | X5: =IFERROR(VLOOKUP($C5,'HC & Open Position'!$D:$J,MATCH(X$3,'HC & Open Position'!$D$3:$J$3,1),0),"") -> 1 | Y5: =IFERROR(VLOOKUP($C5,'HC & Open Position'!$D:$J,MATCH(Y$3,'HC & Open Position'!$D$3:$J$3,1),0),"") -> 0 | Z5: =IFERROR(VLOOKUP($C5,'HC & Open Position'!$D:$J,MATCH(Z$3,'HC & Open Position'!$D$3:$J$3,1),0),"") -> 0 | AA5: =SUM(W5:Z5) -> 5 | AB5: =U5-AA5 -> -1.1927619 | AG5: 1 | AI5: =IFERROR(VLOOKUP($C5,'HC & Open Position'!$D$3:$P$55,9,0),"") -> 0 | AJ5: =IFERROR(VLOOKUP($C5,'HC & Open Position'!$D$3:$P$55,10,0),"") -> 1 | AK5: =IFERROR(VLOOKUP($C5,'HC & Open Position'!$D$3:$P$55,11,0),"") -> 0 | AL5: =IFERROR(VLOOKUP($C5,'HC & Open Position'!$D$3:$P$55,12,0),"") -> 0 | AM5: =SUM(AI5:AL5) -> 1 | AP5: =U5-SUM(AA5+AM5+AD5-AO5) -> -2.1927619 | AR5: Target HC
A6: CNO0000067 | B6: SKF | C6: SKF India | D6: Pharma | E6: 44866 | F6: 45322 | G6: Anjli Zutshi | H6: Natasha Mehta | I6: North | J6: =IFERROR(VLOOKUP(C6,CPH!$A:$E,5,0),"") -> 83000 | K6: 47 | N6: 1.8 | O6: 1.2574501 | P6: 1.8 | Q6: =IFERROR(K6/(P6*3),"") -> 8.7037037 | R6: =IFERROR(Q6/8,"") -> 1.087963 | S6: =IFERROR(R6/8,"") -> 0.13599537 | T6: =IFERROR(S6/3,"") -> 0.04533179 | U6: =SUM(Q6:T6) -> 9.9729938 | W6: =IFERROR(VLOOKUP($C6,'HC & Open Position'!$D:$J,MATCH(W$3,'HC & Open Position'!$D$3:$J$3,1),0),"") -> 11 | X6: =IFERROR(VLOOKUP($C6,'HC & Open Position'!$D:$J,MATCH(X$3,'HC & Open Position'!$D$3:$J$3,1),0),"") -> 4 | Y6: =IFERROR(VLOOKUP($C6,'HC & Open Position'!$D:$J,MATCH(Y$3,'HC & Open Position'!$D$3:$J$3,1),0),"") -> 1 | Z6: =IFERROR(VLOOKUP($C6,'HC & Open Position'!$D:$J,MATCH(Z$3,'HC & Open Position'!$D$3:$J$3,1),0),"") -> 0 | AA6: =SUM(W6:Z6) -> 16 | AB6: =U6-AA6 -> -6.0270062 | AI6: =IFERROR(VLOOKUP($C6,'HC & Open Position'!$D$3:$P$55,9,0),"") -> 0 | AJ6: =IFERROR(VLOOKUP($C6,'HC & Open Position'!$D$3:$P$55,10,0),"") -> 0 | AK6: =IFERROR(VLOOKUP($C6,'HC & Open Position'!$D$3:$P$55,11,0),"") -> 0 | AL6: =IFERROR(VLOOKUP($C6,'HC & Open Position'!$D$3:$P$55,12,0),"") -> 0 | AM6: =SUM(AI6:AL6) -> 0 | AO6: 1 | AP6: =U6-SUM(AA6+AM6+AD6-AO6) -> -5.0270062 | AQ6: + | AR6: Actual HC
A7: CNO0000065 | B7: Siemens | C7: Siemens | D7: Engineering | E7: 44287 | F7: 45350 | G7: Sulabh Arora | H7: Sulabh Arora | I7: South | J7: =IFERROR(VLOOKUP(C7,CPH!$A:$E,5,0),"") -> 32000 | K7: 77.1 | N7: 1.7 | O7: 1.75 | P7: =IFERROR(N7*1.3,1.8) -> 2.21 | Q7: =IFERROR(K7/(P7*3),"") -> 11.628959 | R7: =IFERROR(Q7/8,"") -> 1.4536199 | S7: =IFERROR(R7/8,"") -> 0.18170249 | T7: =IFERROR(S7/3,"") -> 0.060567496 | U7: =SUM(Q7:T7) -> 13.324849 | W7: =IFERROR(VLOOKUP($C7,'HC & Open Position'!$D:$J,MATCH(W$3,'HC & Open Position'!$D$3:$J$3,1),0),"") -> 12 | X7: =IFERROR(VLOOKUP($C7,'HC & Open Position'!$D:$J,MATCH(X$3,'HC & Open Position'!$D$3:$J$3,1),0),"") -> 2 | Y7: =IFERROR(VLOOKUP($C7,'HC & Open Position'!$D:$J,MATCH(Y$3,'HC & Open Position'!$D$3:$J$3,1),0),"") -> 0 | Z7: =IFERROR(VLOOKUP($C7,'HC & Open Position'!$D:$J,MATCH(Z$3,'HC & Open Position'!$D$3:$J$3,1),0),"") -> 0 | AA7: =SUM(W7:Z7) -> 14 | AB7: =U7-AA7 -> -0.67515083 | AD7: 2 | AI7: =IFERROR(VLOOKUP($C7,'HC & Open Position'!$D$3:$P$55,9,0),"") -> 0 | AJ7: =IFERROR(VLOOKUP($C7,'HC & Open Position'!$D$3:$P$55,10,0),"") -> 0 | AK7: =IFERROR(VLOOKUP($C7,'HC & Open Position'!$D$3:$P$55,11,0),"") -> 0 | AL7: =IFERROR(VLOOKUP($C7,'HC & Open Position'!$D$3:$P$55,12,0),"") -> 0 | AM7: =SUM(AI7:AL7) -> 0 | AP7: =U7-SUM(AA7+AM7+AD7-AO7) -> -2.6751508 | AQ7: + | AR7: Open Position
B8: Siemens Healthineers | C8: Siemens Healthineers | G8: Sulabh Arora | H8: Sulabh Arora | I8: South | K8: 9.45 | N8: 1.7 | O8: 0.6 | P8: =IFERROR(N8*1.3,1.8) -> 2.21 | Q8: =IFERROR(K8/(P8*3),"") -> 1.4253394 | R8: =IFERROR(Q8/8,"") -> 0.17816742 | S8: =IFERROR(R8/8,"") -> 0.022270928 | T8: =IFERROR(S8/3,"") -> 0.0074236425 | U8: =SUM(Q8:T8) -> 1.6332014 | W8: =IFERROR(VLOOKUP($C8,'HC & Open Position'!$D:$J,MATCH(W$3,'HC & Open Position'!$D$3:$J$3,1),0),"") -> 4 | X8: =IFERROR(VLOOKUP($C8,'HC & Open Position'!$D:$J,MATCH(X$3,'HC & Open Position'!$D$3:$J$3,1),0),"") -> 2 | Y8: =IFERROR(VLOOKUP($C8,'HC & Open Position'!$D:$J,MATCH(Y$3,'HC & Open Position'!$D$3:$J$3,1),0),"") -> 0 | Z8: =IFERROR(VLOOKUP($C8,'HC & Open Position'!$D:$J,MATCH(Z$3,'HC & Open Position'!$D$3:$J$3,1),0),"") -> 0 | AA8: =SUM(W8:Z8) -> 6 | AB8: =U8-AA8 -> -4.3667986 | AI8: =IFERROR(VLOOKUP($C8,'HC & Open Position'!$D$3:$P$55,9,0),"") -> 0 | AJ8: =IFERROR(VLOOKUP($C8,'HC & Open Position'!$D$3:$P$55,10,0),"") -> 0 | AK8: =IFERROR(VLOOKUP($C8,'HC & Open Position'!$D$3:$P$55,11,0),"") -> 0 | AL8: =IFERROR(VLOOKUP($C8,'HC & Open Position'!$D$3:$P$55,12,0),"") -> 0 | AM8: =SUM(AI8:AL8) -> 0 | AP8: =U8-SUM(AA8+AM8+AD8-AO8) -> -4.3667986 | AQ8: + | AR8: Additonal Vendor Support
A9: CNO0000093 | B9: Pidilite | C9: Pidilite | D9: Manufacturing | E9: 44978 | F9: 46073 | G9: Anjli Zutshi | H9: Usha Babu Shetty | I9: West | J9: =IFERROR(VLOOKUP(C9,CPH!$A:$E,5,0),"") -> 21000 | K9: 17.54 | N9: 0.9 | O9: 1.1922184 | P9: 1.5 | Q9: =IFERROR(K9/(P9*3),"") -> 3.8977778 | R9: =IFERROR(Q9/8,"") -> 0.48722222 | S9: =IFERROR(R9/8,"") -> 0.060902778 | T9: =IFERROR(S9/3,"") -> 0.020300926 | U9: =SUM(Q9:T9) -> 4.4662037 | W9: =IFERROR(VLOOKUP($C9,'HC & Open Position'!$D:$J,MATCH(W$3,'HC & Open Position'!$D$3:$J$3,1),0),"") -> 9 | X9: =IFERROR(VLOOKUP($C9,'HC & Open Position'!$D:$J,MATCH(X$3,'HC & Open Position'!$D$3:$J$3,1),0),"") -> 0 | Y9: =IFERROR(VLOOKUP($C9,'HC & Open Position'!$D:$J,MATCH(Y$3,'HC & Open Position'!$D$3:$J$3,1),0),"") -> 1 | Z9: =IFERROR(VLOOKUP($C9,'HC & Open Position'!$D:$J,MATCH(Z$3,'HC & Open Position'!$D$3:$J$3,1),0),"") -> 0 | AA9: =SUM(W9:Z9) -> 10 | AB9: =U9-AA9 -> -5.5337963 | AF9: 1 | AG9: 2 | AI9: =IFERROR(VLOOKUP($C9,'HC & Open Position'!$D$3:$P$55,9,0),"") -> 3 | AJ9: =IFERROR(VLOOKUP($C9,'HC & Open Position'!$D$3:$P$55,10,0),"") -> 0 | AK9: =IFERROR(VLOOKUP($C9,'HC & Open Position'!$D$3:$P$55,11,0),"") -> 0 | AL9: =IFERROR(VLOOKUP($C9,'HC & Open Position'!$D$3:$P$55,12,0),"") -> 0 | AM9: =SUM(AI9:AL9) -> 3 | AN9: 1 | AP9: =U9-SUM(AA9+AM9+AD9-AO9) -> -8.5337963 | AQ9: - | AR9: Existing Resignaton
A10: CNO0000106 | B10: Vertiv | C10: Vertiv | D10: Energy | E10: 44405 | F10: 45818 | G10: Anjli Zutshi | H10: Shweta Shalini | I10: West | J10: =IFERROR(VLOOKUP(C10,CPH!$A:$E,5,0),"") -> 60000 | K10: 17.8 | N10: 1.1 | O10: 2.66 | P10: 2.8 | Q10: =IFERROR(K10/(P10*3),"") -> 2.1190476 | R10: =IFERROR(Q10/8,"") -> 0.26488095 | S10: =IFERROR(R10/8,"") -> 0.033110119 | T10: =IFERROR(S10/3,"") -> 0.011036706 | U10: =SUM(Q10:T10) -> 2.4280754 | W10: =IFERROR(VLOOKUP($C10,'HC & Open Position'!$D:$J,MATCH(W$3,'HC & Open Position'!$D$3:$J$3,1),0),"") -> 2 | X10: =IFERROR(VLOOKUP($C10,'HC & Open Position'!$D:$J,MATCH(X$3,'HC & Open Position'!$D$3:$J$3,1),0),"") -> 1 | Y10: =IFERROR(VLOOKUP($C10,'HC & Open Position'!$D:$J,MATCH(Y$3,'HC & Open Position'!$D$3:$J$3,1),0),"") -> 0 | Z10: =IFERROR(VLOOKUP($C10,'HC & Open Position'!$D:$J,MATCH(Z$3,'HC & Open Position'!$D$3:$J$3,1),0),"") -> 0 | AA10: =SUM(W10:Z10) -> 3 | AB10: =U10-AA10 -> -0.5719246 | AI10: =IFERROR(VLOOKUP($C10,'HC & Open Position'!$D$3:$P$55,9,0),"") -> 0 | AJ10: =IFERROR(VLOOKUP($C10,'HC & Open Position'!$D$3:$P$55,10,0),"") -> 0 | AK10: =IFERROR(VLOOKUP($C10,'HC & Open Position'!$D$3:$P$55,11,0),"") -> 0 | AL10: =IFERROR(VLOOKUP($C10,'HC & Open Position'!$D$3:$P$55,12,0),"") -> 0 | AM10: =SUM(AI10:AL10) -> 0 | AP10: =U10-SUM(AA10+AM10+AD10-AO10) -> -0.5719246
A11: CNO0000020 | B11: Birla Paints | C11: Birla Paints | D11: Manufacturing | E11: 44574 | F11: 45303 | G11: Anjli Zutshi | H11: Geetu Lalwani | I11: West | J11: =IFERROR(VLOOKUP(C11,CPH!$A:$E,5,0),"") -> 26600 | K11: 40.64 | N11: 1.3330352 | O11: 1.2710224 | P11: =IFERROR(N11*1.3,1.8) -> 1.7329457 | Q11: =IFERROR(K11/(P11*3),"") -> 7.8171327 | R11: =IFERROR(Q11/8,"") -> 0.97714159 | S11: =IFERROR(R11/8,"") -> 0.1221427 | T11: =IFERROR(S11/3,"") -> 0.040714233 | U11: =SUM(Q11:T11) -> 8.9571312 | W11: =IFERROR(VLOOKUP($C11,'HC & Open Position'!$D:$J,MATCH(W$3,'HC & Open Position'!$D$3:$J$3,1),0),"") -> 10 | X11: =IFERROR(VLOOKUP($C11,'HC & Open Position'!$D:$J,MATCH(X$3,'HC & Open Position'!$D$3:$J$3,1),0),"") -> 1 | Y11: =IFERROR(VLOOKUP($C11,'HC & Open Position'!$D:$J,MATCH(Y$3,'HC & Open Position'!$D$3:$J$3,1),0),"") -> 0 | Z11: =IFERROR(VLOOKUP($C11,'HC & Open Position'!$D:$J,MATCH(Z$3,'HC & Open Position'!$D$3:$J$3,1),0),"") -> 0 | AA11: =SUM(W11:Z11) -> 11 | AB11: =U11-AA11 -> -2.0428688 | AD11: 1 | AG11: 2 | AI11: =IFERROR(VLOOKUP($C11,'HC & Open Position'!$D$3:$P$55,9,0),"") -> 2 | AJ11: =IFERROR(VLOOKUP($C11,'HC & Open Position'!$D$3:$P$55,10,0),"") -> 0 | AK11: =IFERROR(VLOOKUP($C11,'HC & Open Position'!$D$3:$P$55,11,0),"") -> 0 | AL11: =IFERROR(VLOOKUP($C11,'HC & Open Position'!$D$3:$P$55,12,0),"") -> 0 | AM11: =SUM(AI11:AL11) -> 2 | AO11: 2 | AP11: =U11-SUM(AA11+AM11+AD11-AO11) -> -3.0428688
A12: CNO0000041 | B12: Ingram Micro | C12: Ingram Micro | D12: IT | E12: 44593 | F12: 45688 | G12: Anjli Zutshi | H12: Usha Babu Shetty | I12: North | J12: =IFERROR(VLOOKUP(C12,CPH!$A:$E,5,0),"") -> 45000 | K12: -2.25 | N12: 1.9763086 | O12: 0.54495357 | P12: =IFERROR(N12*1.3,1.8) -> 2.5692011 | Q12: =IFERROR(K12/(P12*3),"") -> -0.29191954 | R12: =IFERROR(Q12/8,"") -> -0.036489942 | S12: =IFERROR(R12/8,"") -> -0.0045612427 | T12: =IFERROR(S12/3,"") -> -0.0015204142 | U12: =SUM(Q12:T12) -> -0.33449113 | W12: =IFERROR(VLOOKUP($C12,'HC & Open Position'!$D:$J,MATCH(W$3,'HC & Open Position'!$D$3:$J$3,1),0),"") -> 1 | X12: =IFERROR(VLOOKUP($C12,'HC & Open Position'!$D:$J,MATCH(X$3,'HC & Open Position'!$D$3:$J$3,1),0),"") -> 0 | Y12: =IFERROR(VLOOKUP($C12,'HC & Open Position'!$D:$J,MATCH(Y$3,'HC & Open Position'!$D$3:$J$3,1),0),"") -> 0 | Z12: =IFERROR(VLOOKUP($C12,'HC & Open Position'!$D:$J,MATCH(Z$3,'HC & Open Position'!$D$3:$J$3,1),0),"") -> 0 | AA12: =SUM(W12:Z12) -> 1 | AB12: =U12-AA12 -> -1.3344911 | AI12: =IFERROR(VLOOKUP($C12,'HC & Open Position'!$D$3:$P$55,9,0),"") -> 0 | AJ12: =IFERROR(VLOOKUP($C12,'HC & Open Position'!$D$3:$P$55,10,0),"") -> 0 | AK12: =IFERROR(VLOOKUP($C12,'HC & Open Position'!$D$3:$P$55,11,0),"") -> 0 | AL12: =IFERROR(VLOOKUP($C12,'HC & Open Position'!$D$3:$P$55,12,0),"") -> 0 | AM12: =SUM(AI12:AL12) -> 0 | AP12: =U12-SUM(AA12+AM12+AD12-AO12) -> -1.3344911
A13: CNO0000028 | B13: HP | C13: HPE | D13: IT | E13: 44635 | F13: - | G13: Mahak Kaura Mata | H13: Mahak Kaura Mata | I13: South | J13: =IFERROR(VLOOKUP(C13,CPH!$A:$E,5,0),"") -> 54000 | K13: 430 | N13: 2.1443547 | O13: 1.5963807 | P13: =IFERROR(N13*1.3,1.8) -> 2.7876611 | Q13: =IFERROR(K13/(P13*3),"") -> 51.417058 | R13: =IFERROR(Q13/8,"") -> 6.4271323 | S13: =IFERROR(R13/8,"") -> 0.80339153 | T13: =IFERROR(S13/3,"") -> 0.26779718 | U13: =SUM(Q13:T13) -> 58.915379 | W13: =IFERROR(VLOOKUP($C13,'HC & Open Position'!$D:$J,MATCH(W$3,'HC & Open Position'!$D$3:$J$3,1),0),"") -> 33 | X13: =IFERROR(VLOOKUP($C13,'HC & Open Position'!$D:$J,MATCH(X$3,'HC & Open Position'!$D$3:$J$3,1),0),"") -> 13 | Y13: =IFERROR(VLOOKUP($C13,'HC & Open Position'!$D:$J,MATCH(Y$3,'HC & Open Position'!$D$3:$J$3,1),0),"") -> 2 | Z13: =IFERROR(VLOOKUP($C13,'HC & Open Position'!$D:$J,MATCH(Z$3,'HC & Open Position'!$D$3:$J$3,1),0),"") -> 0 | AA13: =SUM(W13:Z13) -> 48 | AB13: =U13-AA13 -> 10.915379 | AI13: =IFERROR(VLOOKUP($C13,'HC & Open Position'!$D$3:$P$55,9,0),"") -> 0 | AJ13: =IFERROR(VLOOKUP($C13,'HC & Open Position'!$D$3:$P$55,10,0),"") -> 0 | AK13: =IFERROR(VLOOKUP($C13,'HC & Open Position'!$D$3:$P$55,11,0),"") -> 0 | AL13: =IFERROR(VLOOKUP($C13,'HC & Open Position'!$D$3:$P$55,12,0),"") -> 0 | AM13: =SUM(AI13:AL13) -> 0 | AP13: =U13-SUM(AA13+AM13+AD13-AO13) -> 10.915379
A14: CNO0000077 | B14: Isuzu | C14: Isuzu | D14: Auto | E14: 44643 | F14: 45738 | G14: Sulabh Arora | H14: Sulabh Arora | I14: South | J14: =IFERROR(VLOOKUP(C14,CPH!$A:$E,5,0),"") -> 69000 | K14: 18.84 | N14: 3.0824875 | O14: 1.7737018 | P14: =IFERROR(N14*1.3,1.8) -> 4.0072338 | Q14: =IFERROR(K14/(P14*3),"") -> 1.5671659 | R14: =IFERROR(Q14/8,"") -> 0.19589573 | S14: =IFERROR(R14/8,"") -> 0.024486967 | T14: =IFERROR(S14/3,"") -> 0.0081623223 | U14: =SUM(Q14:T14) -> 1.7957109 | W14: =IFERROR(VLOOKUP($C14,'HC & Open Position'!$D:$J,MATCH(W$3,'HC & Open Position'!$D$3:$J$3,1),0),"") -> 2 | X14: =IFERROR(VLOOKUP($C14,'HC & Open Position'!$D:$J,MATCH(X$3,'HC & Open Position'!$D$3:$J$3,1),0),"") -> 1 | Y14: =IFERROR(VLOOKUP($C14,'HC & Open Position'!$D:$J,MATCH(Y$3,'HC & Open Position'!$D$3:$J$3,1),0),"") -> 0 | Z14: =IFERROR(VLOOKUP($C14,'HC & Open Position'!$D:$J,MATCH(Z$3,'HC & Open Position'!$D$3:$J$3,1),0),"") -> 0 | AA14: =SUM(W14:Z14) -> 3 | AB14: =U14-AA14 -> -1.2042891 | AI14: =IFERROR(VLOOKUP($C14,'HC & Open Position'!$D$3:$P$55,9,0),"") -> 0 | AJ14: =IFERROR(VLOOKUP($C14,'HC & Open Position'!$D$3:$P$55,10,0),"") -> 0 | AK14: =IFERROR(VLOOKUP($C14,'HC & Open Position'!$D$3:$P$55,11,0),"") -> 0 | AL14: =IFERROR(VLOOKUP($C14,'HC & Open Position'!$D$3:$P$55,12,0),"") -> 0 | AM14: =SUM(AI14:AL14) -> 0 | AP14: =U14-SUM(AA14+AM14+AD14-AO14) -> -1.2042891
A15: CNO0000071 | B15: ThyssenKrupp | C15: Thyssenkrupp | D15: Engineering | E15: 44707 | F15: 45437 | G15: Anjli Zutshi | H15: Shweta Shalini | I15: West | J15: =IFERROR(VLOOKUP(C15,CPH!$A:$E,5,0),"") -> 54000 | K15: 0 | N15: - | O15: - | P15: =IFERROR(N15*1.3,1.8) -> 1.8 | Q15: =IFERROR(K15/(P15*3),"") -> 0 | R15: =IFERROR(Q15/8,"") -> 0 | S15: =IFERROR(R15/8,"") -> 0 | T15: =IFERROR(S15/3,"") -> 0 | U15: =SUM(Q15:T15) -> 0 | W15: =IFERROR(VLOOKUP($C15,'HC & Open Position'!$D:$J,MATCH(W$3,'HC & Open Position'!$D$3:$J$3,1),0),"") | X15: =IFERROR(VLOOKUP($C15,'HC & Open Position'!$D:$J,MATCH(X$3,'HC & Open Position'!$D$3:$J$3,1),0),"") | Y15: =IFERROR(VLOOKUP($C15,'HC & Open Position'!$D:$J,MATCH(Y$3,'HC & Open Position'!$D$3:$J$3,1),0),"") | Z15: =IFERROR(VLOOKUP($C15,'HC & Open Position'!$D:$J,MATCH(Z$3,'HC & Open Position'!$D$3:$J$3,1),0),"") | AA15: =SUM(W15:Z15) -> 0 | AB15: =U15-AA15 -> 0 | AI15: =IFERROR(VLOOKUP($C15,'HC & Open Position'!$D$3:$P$55,9,0),"") | AJ15: =IFERROR(VLOOKUP($C15,'HC & Open Position'!$D$3:$P$55,10,0),"") | AK15: =IFERROR(VLOOKUP($C15,'HC & Open Position'!$D$3:$P$55,11,0),"") | AL15: =IFERROR(VLOOKUP($C15,'HC & Open Position'!$D$3:$P$55,12,0),"") | AM15: =SUM(AI15:AL15) -> 0 | AP15: =U15-SUM(AA15+AM15+AD15-AO15) -> 0
A16: CNO0000046 | B16: Mahindra Holiday & Resort | C16: Mahindra Holidays | D16: Hospitality | E16: 44599 | F16: 48250 | G16: Anjli Zutshi | H16: Geetu Lalwani | I16: West | J16: =IFERROR(VLOOKUP(C16,CPH!$A:$E,5,0),"") -> 22000 | K16: 14.31 | N16: 0.28332427 | O16: 0.52424259 | P16: 1.2 | Q16: =IFERROR(K16/(P16*3),"") -> 3.975 | R16: =IFERROR(Q16/8,"") -> 0.496875 | S16: =IFERROR(R16/8,"") -> 0.062109375 | T16: =IFERROR(S16/3,"") -> 0.020703125 | U16: =SUM(Q16:T16) -> 4.5546875 | W16: =IFERROR(VLOOKUP($C16,'HC & Open Position'!$D:$J,MATCH(W$3,'HC & Open Position'!$D$3:$J$3,1),0),"") -> 6 | X16: =IFERROR(VLOOKUP($C16,'HC & Open Position'!$D:$J,MATCH(X$3,'HC & Open Position'!$D$3:$J$3,1),0),"") -> 1 | Y16: =IFERROR(VLOOKUP($C16,'HC & Open Position'!$D:$J,MATCH(Y$3,'HC & Open Position'!$D$3:$J$3,1),0),"") -> 0 | Z16: =IFERROR(VLOOKUP($C16,'HC & Open Position'!$D:$J,MATCH(Z$3,'HC & Open Position'!$D$3:$J$3,1),0),"") -> 0 | AA16: =SUM(W16:Z16) -> 7 | AB16: =U16-AA16 -> -2.4453125 | AI16: =IFERROR(VLOOKUP($C16,'HC & Open Position'!$D$3:$P$55,9,0),"") -> 0 | AJ16: =IFERROR(VLOOKUP($C16,'HC & Open Position'!$D$3:$P$55,10,0),"") -> 0 | AK16: =IFERROR(VLOOKUP($C16,'HC & Open Position'!$D$3:$P$55,11,0),"") -> 0 | AL16: =IFERROR(VLOOKUP($C16,'HC & Open Position'!$D$3:$P$55,12,0),"") -> 0 | AM16: =SUM(AI16:AL16) -> 0 | AO16: 1 | AP16: =U16-SUM(AA16+AM16+AD16-AO16) -> -1.4453125
A17: CNO0000011 | B17: BITS | C17: BITS | D17: Education | E17: 42584 | F17: 46235 | G17: Sulabh Arora | H17: Krishna Kumar Pillai | I17: South | J17: =IFERROR(VLOOKUP(C17,CPH!$A:$E,5,0),"") -> 27000 | K17: 11.55 | N17: 1.9794459 | O17: 1.7161432 | P17: =IFERROR(N17*1.3,1.8) -> 2.5732797 | Q17: =IFERROR(K17/(P17*3),"") -> 1.4961452 | R17: =IFERROR(Q17/8,"") -> 0.18701815 | S17: =IFERROR(R17/8,"") -> 0.023377268 | T17: =IFERROR(S17/3,"") -> 0.0077924228 | U17: =SUM(Q17:T17) -> 1.714333 | W17: =IFERROR(VLOOKUP($C17,'HC & Open Position'!$D:$J,MATCH(W$3,'HC & Open Position'!$D$3:$J$3,1),0),"") -> 2 | X17: =IFERROR(VLOOKUP($C17,'HC & Open Position'!$D:$J,MATCH(X$3,'HC & Open Position'!$D$3:$J$3,1),0),"") -> 1 | Y17: =IFERROR(VLOOKUP($C17,'HC & Open Position'!$D:$J,MATCH(Y$3,'HC & Open Position'!$D$3:$J$3,1),0),"") -> 0 | Z17: =IFERROR(VLOOKUP($C17,'HC & Open Position'!$D:$J,MATCH(Z$3,'HC & Open Position'!$D$3:$J$3,1),0),"") -> 0 | AA17: =SUM(W17:Z17) -> 3 | AB17: =U17-AA17 -> -1.285667 | AI17: =IFERROR(VLOOKUP($C17,'HC & Open Position'!$D$3:$P$55,9,0),"") -> 0 | AJ17: =IFERROR(VLOOKUP($C17,'HC & Open Position'!$D$3:$P$55,10,0),"") -> 0 | AK17: =IFERROR(VLOOKUP($C17,'HC & Open Position'!$D$3:$P$55,11,0),"") -> 0 | AL17: =IFERROR(VLOOKUP($C17,'HC & Open Position'!$D$3:$P$55,12,0),"") -> 0 | AM17: =SUM(AI17:AL17) -> 0 | AP17: =U17-SUM(AA17+AM17+AD17-AO17) -> -1.285667
A18: CNO0000089 | B18: M&M | C18: M&M | D18: Auto | E18: 42310 | F18: 46325 | G18: Anjli Zutshi | H18: Megha Joshi | I18: West | J18: =IFERROR(VLOOKUP(C18,CPH!$A:$E,5,0),"") -> 65000 | K18: 534.89 | N18: 1.7 | O18: 1.68 | P18: =IFERROR(N18*1.3,1.8) -> 2.21 | Q18: =IFERROR(K18/(P18*3),"") -> 80.677225 | R18: =IFERROR(Q18/8,"") -> 10.084653 | S18: =IFERROR(R18/8,"") -> 1.2605816 | T18: =IFERROR(S18/3,"") -> 0.42019388 | U18: =SUM(Q18:T18) -> 92.442653 | W18: =IFERROR(VLOOKUP($C18,'HC & Open Position'!$D:$J,MATCH(W$3,'HC & Open Position'!$D$3:$J$3,1),0),"") -> 65 | X18: =IFERROR(VLOOKUP($C18,'HC & Open Position'!$D:$J,MATCH(X$3,'HC & Open Position'!$D$3:$J$3,1),0),"") -> 16 | Y18: =IFERROR(VLOOKUP($C18,'HC & Open Position'!$D:$J,MATCH(Y$3,'HC & Open Position'!$D$3:$J$3,1),0),"") -> 1 | Z18: =IFERROR(VLOOKUP($C18,'HC & Open Position'!$D:$J,MATCH(Z$3,'HC & Open Position'!$D$3:$J$3,1),0),"") -> 0 | AA18: =SUM(W18:Z18) -> 82 | AB18: =U18-AA18 -> 10.442653 | AD18: 10 | AF18: 4 | AG18: 2 | AI18: =IFERROR(VLOOKUP($C18,'HC & Open Position'!$D$3:$P$55,9,0),"") -> 4 | AJ18: =IFERROR(VLOOKUP($C18,'HC & Open Position'!$D$3:$P$55,10,0),"") -> 1 | AK18: =IFERROR(VLOOKUP($C18,'HC & Open Position'!$D$3:$P$55,11,0),"") -> 1 | AL18: =IFERROR(VLOOKUP($C18,'HC & Open Position'!$D$3:$P$55,12,0),"") -> 0 | AM18: =SUM(AI18:AL18) -> 6 | AN18: 3 | AO18: 3 | AP18: =U18-SUM(AA18+AM18+AD18-AO18) -> -2.5573467
A19: CNO0000079 | B19: Wipro | C19: Wipro | D19: IT | E19: 41816 | F19: 45838 | G19: Sulabh Arora | H19: Subramanyapavan | I19: South | J19: =IFERROR(VLOOKUP(C19,CPH!$A:$E,5,0),"") -> 45000 | K19: 150 | N19: 1.6261991 | O19: 1.8872641 | P19: =IFERROR(N19*1.3,1.8) -> 2.1140588 | Q19: =IFERROR(K19/(P19*3),"") -> 23.651187 | R19: =IFERROR(Q19/8,"") -> 2.9563984 | S19: =IFERROR(R19/8,"") -> 0.36954979 | T19: =IFERROR(S19/3,"") -> 0.12318326 | U19: =SUM(Q19:T19) -> 27.100318 | W19: =IFERROR(VLOOKUP($C19,'HC & Open Position'!$D:$J,MATCH(W$3,'HC & Open Position'!$D$3:$J$3,1),0),"") -> 14 | X19: =IFERROR(VLOOKUP($C19,'HC & Open Position'!$D:$J,MATCH(X$3,'HC & Open Position'!$D$3:$J$3,1),0),"") -> 1 | Y19: =IFERROR(VLOOKUP($C19,'HC & Open Position'!$D:$J,MATCH(Y$3,'HC & Open Position'!$D$3:$J$3,1),0),"") -> 1 | Z19: =IFERROR(VLOOKUP($C19,'HC & Open Position'!$D:$J,MATCH(Z$3,'HC & Open Position'!$D$3:$J$3,1),0),"") -> 0 | AA19: =SUM(W19:Z19) -> 16 | AB19: =U19-AA19 -> 11.100318 | AD19: 3 | AI19: =IFERROR(VLOOKUP($C19,'HC & Open Position'!$D$3:$P$55,9,0),"") -> 0 | AJ19: =IFERROR(VLOOKUP($C19,'HC & Open Position'!$D$3:$P$55,10,0),"") -> 0 | AK19: =IFERROR(VLOOKUP($C19,'HC & Open Position'!$D$3:$P$55,11,0),"") -> 0 | AL19: =IFERROR(VLOOKUP($C19,'HC & Open Position'!$D$3:$P$55,12,0),"") -> 0 | AM19: =SUM(AI19:AL19) -> 0 | AP19: =U19-SUM(AA19+AM19+AD19-AO19) -> 8.1003182
A20: CNO0000032 | B20: DP World | C20: DP World | D20: Logistics | E20: 44844 | F20: 45574 | G20: Anjli Zutshi | H20: Geetu Lalwani | I20: West | J20: =IFERROR(VLOOKUP(C20,CPH!$A:$E,5,0),"") -> 70000 | K20: 24 | N20: 1.1249727 | O20: 1.1878419 | P20: =IFERROR(N20*1.3,1.8) -> 1.4624645 | Q20: =IFERROR(K20/(P20*3),"") -> 5.4702184 | R20: =IFERROR(Q20/8,"") -> 0.6837773 | S20: =IFERROR(R20/8,"") -> 0.085472162 | T20: =IFERROR(S20/3,"") -> 0.028490721 | U20: =SUM(Q20:T20) -> 6.2679586 | W20: =IFERROR(VLOOKUP($C20,'HC & Open Position'!$D:$J,MATCH(W$3,'HC & Open Position'!$D$3:$J$3,1),0),"") -> 4 | X20: =IFERROR(VLOOKUP($C20,'HC & Open Position'!$D:$J,MATCH(X$3,'HC & Open Position'!$D$3:$J$3,1),0),"") -> 1 | Y20: =IFERROR(VLOOKUP($C20,'HC & Open Position'!$D:$J,MATCH(Y$3,'HC & Open Position'!$D$3:$J$3,1),0),"") -> 0 | Z20: =IFERROR(VLOOKUP($C20,'HC & Open Position'!$D:$J,MATCH(Z$3,'HC & Open Position'!$D$3:$J$3,1),0),"") -> 0 | AA20: =SUM(W20:Z20) -> 5 | AB20: =U20-AA20 -> 1.2679586 | AI20: =IFERROR(VLOOKUP($C20,'HC & Open Position'!$D$3:$P$55,9,0),"") -> 0 | AJ20: =IFERROR(VLOOKUP($C20,'HC & Open Position'!$D$3:$P$55,10,0),"") -> 0 | AK20: =IFERROR(VLOOKUP($C20,'HC & Open Position'!$D$3:$P$55,11,0),"") -> 0 | AL20: =IFERROR(VLOOKUP($C20,'HC & Open Position'!$D$3:$P$55,12,0),"") -> 0 | AM20: =SUM(AI20:AL20) -> 0 | AP20: =U20-SUM(AA20+AM20+AD20-AO20) -> 1.2679586
A21: CNO0000008 | B21: AMNS | C21: AMNS | D21: Manufacturing | E21: 45020 | F21: 45750 | G21: Anjli Zutshi | H21: Alifiya Mohsin Hirani | I21: West | J21: =IFERROR(VLOOKUP(C21,CPH!$A:$E,5,0),"") -> 33000 | K21: 87.6 | N21: 0.9 | O21: 0.97 | P21: 1.8 | Q21: =IFERROR(K21/(P21*3),"") -> 16.222222 | R21: =IFERROR(Q21/8,"") -> 2.0277778 | S21: =IFERROR(R21/8,"") -> 0.25347222 | T21: =IFERROR(S21/3,"") -> 0.084490741 | U21: =SUM(Q21:T21) -> 18.587963 | W21: =IFERROR(VLOOKUP($C21,'HC & Open Position'!$D:$J,MATCH(W$3,'HC & Open Position'!$D$3:$J$3,1),0),"") -> 33 | X21: =IFERROR(VLOOKUP($C21,'HC & Open Position'!$D:$J,MATCH(X$3,'HC & Open Position'!$D$3:$J$3,1),0),"") -> 5 | Y21: =IFERROR(VLOOKUP($C21,'HC & Open Position'!$D:$J,MATCH(Y$3,'HC & Open Position'!$D$3:$J$3,1),0),"") -> 1 | Z21: =IFERROR(VLOOKUP($C21,'HC & Open Position'!$D:$J,MATCH(Z$3,'HC & Open Position'!$D$3:$J$3,1),0),"") -> 0 | AA21: =SUM(W21:Z21) -> 39 | AB21: =U21-AA21 -> -20.412037 | AF21: 1 | AG21: 2 | AI21: =IFERROR(VLOOKUP($C21,'HC & Open Position'!$D$3:$P$55,9,0),"") -> 3 | AJ21: =IFERROR(VLOOKUP($C21,'HC & Open Position'!$D$3:$P$55,10,0),"") -> 0 | AK21: =IFERROR(VLOOKUP($C21,'HC & Open Position'!$D$3:$P$55,11,0),"") -> 0 | AL21: =IFERROR(VLOOKUP($C21,'HC & Open Position'!$D$3:$P$55,12,0),"") -> 0 | AM21: =SUM(AI21:AL21) -> 3 | AN21: 1 | AP21: =U21-SUM(AA21+AM21+AD21-AO21) -> -23.412037
A22: CNO0000069 | B22: Tata Electronics | C22: Tata Electronics | D22: Manufacturing | E22: 45063 | F22: 45428 | G22: Sulabh Arora | H22: Krishna Kumar Pillai | I22: South | J22: =IFERROR(VLOOKUP(C22,CPH!$A:$E,5,0),"") -> 33320 | K22: 9.19 | N22: 4.0363876 | O22: 1.5781448 | P22: 2 | Q22: =IFERROR(K22/(P22*3),"") -> 1.5316667 | R22: =IFERROR(Q22/8,"") -> 0.19145833 | S22: =IFERROR(R22/8,"") -> 0.023932292 | T22: =IFERROR(S22/3,"") -> 0.0079774306 | U22: =SUM(Q22:T22) -> 1.7550347 | W22: =IFERROR(VLOOKUP($C22,'HC & Open Position'!$D:$J,MATCH(W$3,'HC & Open Position'!$D$3:$J$3,1),0),"") -> 2 | X22: =IFERROR(VLOOKUP($C22,'HC & Open Position'!$D:$J,MATCH(X$3,'HC & Open Position'!$D$3:$J$3,1),0),"") -> 1 | Y22: =IFERROR(VLOOKUP($C22,'HC & Open Position'!$D:$J,MATCH(Y$3,'HC & Open Position'!$D$3:$J$3,1),0),"") -> 1 | Z22: =IFERROR(VLOOKUP($C22,'HC & Open Position'!$D:$J,MATCH(Z$3,'HC & Open Position'!$D$3:$J$3,1),0),"") -> 0 | AA22: =SUM(W22:Z22) -> 4 | AB22: =U22-AA22 -> -2.2449653 | AI22: =IFERROR(VLOOKUP($C22,'HC & Open Position'!$D$3:$P$55,9,0),"") -> 0 | AJ22: =IFERROR(VLOOKUP($C22,'HC & Open Position'!$D$3:$P$55,10,0),"") -> 0 | AK22: =IFERROR(VLOOKUP($C22,'HC & Open Position'!$D$3:$P$55,11,0),"") -> 0 | AL22: =IFERROR(VLOOKUP($C22,'HC & Open Position'!$D$3:$P$55,12,0),"") -> 0 | AM22: =SUM(AI22:AL22) -> 0 | AP22: =U22-SUM(AA22+AM22+AD22-AO22) -> -2.2449653
A23: CNO0000104 | B23: Jindal Stainless | C23: Jindal Stainless | D23: Manufacturing | E23: 45147 | F23: 45877 | G23: Anjli Zutshi | H23: Naved Falak | I23: North | J23: =IFERROR(VLOOKUP(C23,CPH!$A:$E,5,0),"") -> 60000 | K23: 13.35 | N23: 1.7 | O23: 2.2342624 | P23: =IFERROR(N23*1.3,1.8) -> 2.21 | Q23: =IFERROR(K23/(P23*3),"") -> 2.0135747 | R23: =IFERROR(Q23/8,"") -> 0.25169683 | S23: =IFERROR(R23/8,"") -> 0.031462104 | T23: =IFERROR(S23/3,"") -> 0.010487368 | U23: =SUM(Q23:T23) -> 2.307221 | W23: =IFERROR(VLOOKUP($C23,'HC & Open Position'!$D:$J,MATCH(W$3,'HC & Open Position'!$D$3:$J$3,1),0),"") -> 4 | X23: =IFERROR(VLOOKUP($C23,'HC & Open Position'!$D:$J,MATCH(X$3,'HC & Open Position'!$D$3:$J$3,1),0),"") -> 2 | Y23: =IFERROR(VLOOKUP($C23,'HC & Open Position'!$D:$J,MATCH(Y$3,'HC & Open Position'!$D$3:$J$3,1),0),"") -> 0 | Z23: =IFERROR(VLOOKUP($C23,'HC & Open Position'!$D:$J,MATCH(Z$3,'HC & Open Position'!$D$3:$J$3,1),0),"") -> 0 | AA23: =SUM(W23:Z23) -> 6 | AB23: =U23-AA23 -> -3.692779 | AI23: =IFERROR(VLOOKUP($C23,'HC & Open Position'!$D$3:$P$55,9,0),"") -> 0 | AJ23: =IFERROR(VLOOKUP($C23,'HC & Open Position'!$D$3:$P$55,10,0),"") -> 0 | AK23: =IFERROR(VLOOKUP($C23,'HC & Open Position'!$D$3:$P$55,11,0),"") -> 0 | AL23: =IFERROR(VLOOKUP($C23,'HC & Open Position'!$D$3:$P$55,12,0),"") -> 0 | AM23: =SUM(AI23:AL23) -> 0 | AP23: =U23-SUM(AA23+AM23+AD23-AO23) -> -3.692779
A24: CNO0000107 | B24: Schaeffler | C24: Schaeffler | D24: Manufacturing | E24: 45232 | F24: 45962 | G24: Anjli Zutshi | H24: Shweta Shalini | I24: West | J24: =IFERROR(VLOOKUP(C24,CPH!$A:$E,5,0),"") -> 60000 | K24: 21.8 | N24: 1.3742101 | O24: 1.281259 | P24: =IFERROR(N24*1.3,1.8) -> 1.7864732 | Q24: =IFERROR(K24/(P24*3),"") -> 4.0676047 | R24: =IFERROR(Q24/8,"") -> 0.50845058 | S24: =IFERROR(R24/8,"") -> 0.063556323 | T24: =IFERROR(S24/3,"") -> 0.021185441 | U24: =SUM(Q24:T24) -> 4.660797 | W24: =IFERROR(VLOOKUP($C24,'HC & Open Position'!$D:$J,MATCH(W$3,'HC & Open Position'!$D$3:$J$3,1),0),"") -> 4 | X24: =IFERROR(VLOOKUP($C24,'HC & Open Position'!$D:$J,MATCH(X$3,'HC & Open Position'!$D$3:$J$3,1),0),"") -> 1 | Y24: =IFERROR(VLOOKUP($C24,'HC & Open Position'!$D:$J,MATCH(Y$3,'HC & Open Position'!$D$3:$J$3,1),0),"") -> 0 | Z24: =IFERROR(VLOOKUP($C24,'HC & Open Position'!$D:$J,MATCH(Z$3,'HC & Open Position'!$D$3:$J$3,1),0),"") -> 0 | AA24: =SUM(W24:Z24) -> 5 | AB24: =U24-AA24 -> -0.33920299 | AD24: 3 | AG24: 1 | AI24: =IFERROR(VLOOKUP($C24,'HC & Open Position'!$D$3:$P$55,9,0),"") -> 0 | AJ24: =IFERROR(VLOOKUP($C24,'HC & Open Position'!$D$3:$P$55,10,0),"") -> 1 | AK24: =IFERROR(VLOOKUP($C24,'HC & Open Position'!$D$3:$P$55,11,0),"") -> 0 | AL24: =IFERROR(VLOOKUP($C24,'HC & Open Position'!$D$3:$P$55,12,0),"") -> 0 | AM24: =SUM(AI24:AL24) -> 1 | AO24: 1 | AP24: =U24-SUM(AA24+AM24+AD24-AO24) -> -3.339203
A25: CNO0000109 | B25: Royal Enfield | C25: Royal Enfield | D25: Auto | E25: 45260 | F25: 46355 | G25: Sulabh Arora | H25: Krishna Kumar Pillai | I25: South | J25: =IFERROR(VLOOKUP(C25,CPH!$A:$E,5,0),"") -> 69700 | K25: 42 | N25: 1.5 | O25: 1.83 | P25: =IFERROR(N25*1.3,1.8) -> 1.95 | Q25: =IFERROR(K25/(P25*3),"") -> 7.1794872 | R25: =IFERROR(Q25/8,"") -> 0.8974359 | S25: =IFERROR(R25/8,"") -> 0.11217949 | T25: =IFERROR(S25/3,"") -> 0.037393162 | U25: =SUM(Q25:T25) -> 8.2264957 | W25: =IFERROR(VLOOKUP($C25,'HC & Open Position'!$D:$J,MATCH(W$3,'HC & Open Position'!$D$3:$J$3,1),0),"") -> 15 | X25: =IFERROR(VLOOKUP($C25,'HC & Open Position'!$D:$J,MATCH(X$3,'HC & Open Position'!$D$3:$J$3,1),0),"") -> 1 | Y25: =IFERROR(VLOOKUP($C25,'HC & Open Position'!$D:$J,MATCH(Y$3,'HC & Open Position'!$D$3:$J$3,1),0),"") -> 0 | Z25: =IFERROR(VLOOKUP($C25,'HC & Open Position'!$D:$J,MATCH(Z$3,'HC & Open Position'!$D$3:$J$3,1),0),"") -> 0 | AA25: =SUM(W25:Z25) -> 16 | AB25: =U25-AA25 -> -7.7735043 | AD25: 3 | AG25: 2 | AI25: =IFERROR(VLOOKUP($C25,'HC & Open Position'!$D$3:$P$55,9,0),"") -> 1 | AJ25: =IFERROR(VLOOKUP($C25,'HC & Open Position'!$D$3:$P$55,10,0),"") -> 1 | AK25: =IFERROR(VLOOKUP($C25,'HC & Open Position'!$D$3:$P$55,11,0),"") -> 0 | AL25: =IFERROR(VLOOKUP($C25,'HC & Open Position'!$D$3:$P$55,12,0),"") -> 0 | AM25: =SUM(AI25:AL25) -> 2 | AP25: =U25-SUM(AA25+AM25+AD25-AO25) -> -12.773504
A26: CNO0000122 | B26: SBI | C26: SBI Cards | D26: Financial | E26: 45338 | F26: 46433 | G26: Anjli Zutshi | H26: Naved Falak | I26: North | J26: =IFERROR(VLOOKUP(C26,CPH!$A:$E,5,0),"") -> 23000 | K26: 47.6 | N26: 1.3 | O26: 1.1 | P26: =IFERROR(N26*1.3,1.8) -> 1.69 | Q26: =IFERROR(K26/(P26*3),"") -> 9.3885602 | R26: =IFERROR(Q26/8,"") -> 1.17357 | S26: =IFERROR(R26/8,"") -> 0.14669625 | T26: =IFERROR(S26/3,"") -> 0.048898751 | U26: =SUM(Q26:T26) -> 10.757725 | W26: =IFERROR(VLOOKUP($C26,'HC & Open Position'!$D:$J,MATCH(W$3,'HC & Open Position'!$D$3:$J$3,1),0),"") -> 12 | X26: =IFERROR(VLOOKUP($C26,'HC & Open Position'!$D:$J,MATCH(X$3,'HC & Open Position'!$D$3:$J$3,1),0),"") -> 2 | Y26: =IFERROR(VLOOKUP($C26,'HC & Open Position'!$D:$J,MATCH(Y$3,'HC & Open Position'!$D$3:$J$3,1),0),"") -> 0 | Z26: =IFERROR(VLOOKUP($C26,'HC & Open Position'!$D:$J,MATCH(Z$3,'HC & Open Position'!$D$3:$J$3,1),0),"") -> 0 | AA26: =SUM(W26:Z26) -> 14 | AB26: =U26-AA26 -> -3.2422748 | AD26: 2 | AI26: =IFERROR(VLOOKUP($C26,'HC & Open Position'!$D$3:$P$55,9,0),"") -> 0 | AJ26: =IFERROR(VLOOKUP($C26,'HC & Open Position'!$D$3:$P$55,10,0),"") -> 0 | AK26: =IFERROR(VLOOKUP($C26,'HC & Open Position'!$D$3:$P$55,11,0),"") -> 0 | AL26: =IFERROR(VLOOKUP($C26,'HC & Open Position'!$D$3:$P$55,12,0),"") -> 0 | AM26: =SUM(AI26:AL26) -> 0 | AO26: 1 | AP26: =U26-SUM(AA26+AM26+AD26-AO26) -> -4.2422748
A27: CNO0000100 | B27: Hyundai | C27: Hyundai Motor | D27: Auto | E27: 45343 | F27: 46073 | G27: Anjli Zutshi | H27: Shweta Shalini | I27: West | J27: =IFERROR(VLOOKUP(C27,CPH!$A:$E,5,0),"") -> 51800 | K27: 24 | N27: 1.9 | O27: 1.42 | P27: =IFERROR(N27*1.3,1.8) -> 2.47 | Q27: =IFERROR(K27/(P27*3),"") -> 3.2388664 | R27: =IFERROR(Q27/8,"") -> 0.4048583 | S27: =IFERROR(R27/8,"") -> 0.050607287 | T27: =IFERROR(S27/3,"") -> 0.016869096 | U27: =SUM(Q27:T27) -> 3.7112011 | W27: =IFERROR(VLOOKUP($C27,'HC & Open Position'!$D:$J,MATCH(W$3,'HC & Open Position'!$D$3:$J$3,1),0),"") -> 7 | X27: =IFERROR(VLOOKUP($C27,'HC & Open Position'!$D:$J,MATCH(X$3,'HC & Open Position'!$D$3:$J$3,1),0),"") -> 0 | Y27: =IFERROR(VLOOKUP($C27,'HC & Open Position'!$D:$J,MATCH(Y$3,'HC & Open Position'!$D$3:$J$3,1),0),"") -> 1 | Z27: =IFERROR(VLOOKUP($C27,'HC & Open Position'!$D:$J,MATCH(Z$3,'HC & Open Position'!$D$3:$J$3,1),0),"") -> 0 | AA27: =SUM(W27:Z27) -> 8 | AB27: =U27-AA27 -> -4.2887989 | AD27: 2 | AG27: 2 | AI27: =IFERROR(VLOOKUP($C27,'HC & Open Position'!$D$3:$P$55,9,0),"") -> 1 | AJ27: =IFERROR(VLOOKUP($C27,'HC & Open Position'!$D$3:$P$55,10,0),"") -> 1 | AK27: =IFERROR(VLOOKUP($C27,'HC & Open Position'!$D$3:$P$55,11,0),"") -> 0 | AL27: =IFERROR(VLOOKUP($C27,'HC & Open Position'!$D$3:$P$55,12,0),"") -> 0 | AM27: =SUM(AI27:AL27) -> 2 | AO27: 1 | AP27: =U27-SUM(AA27+AM27+AD27-AO27) -> -7.2887989
A28: CNO0000099 | B28: Maruti | C28: Maruti Suzuki(MSIL) | D28: Auto | E28: 45292 | F28: 46394 | G28: Anjli Zutshi | H28: Naved Falak | I28: North | J28: =IFERROR(VLOOKUP(C28,CPH!$A:$E,5,0),"") -> 59000 | K28: 87.17 | N28: 1.3 | O28: 0.86621177 | P28: =IFERROR(N28*1.3,1.8) -> 1.69 | Q28: =IFERROR(K28/(P28*3),"") -> 17.193294 | R28: =IFERROR(Q28/8,"") -> 2.1491617 | S28: =IFERROR(R28/8,"") -> 0.26864522 | T28: =IFERROR(S28/3,"") -> 0.089548406 | U28: =SUM(Q28:T28) -> 19.700649 | W28: =IFERROR(VLOOKUP($C28,'HC & Open Position'!$D:$J,MATCH(W$3,'HC & Open Position'!$D$3:$J$3,1),0),"") -> 33 | X28: =IFERROR(VLOOKUP($C28,'HC & Open Position'!$D:$J,MATCH(X$3,'HC & Open Position'!$D$3:$J$3,1),0),"") -> 5 | Y28: =IFERROR(VLOOKUP($C28,'HC & Open Position'!$D:$J,MATCH(Y$3,'HC & Open Position'!$D$3:$J$3,1),0),"") -> 2 | Z28: =IFERROR(VLOOKUP($C28,'HC & Open Position'!$D:$J,MATCH(Z$3,'HC & Open Position'!$D$3:$J$3,1),0),"") -> 0 | AA28: =SUM(W28:Z28) -> 40 | AB28: =U28-AA28 -> -20.299351 | AD28: 1 | AI28: =IFERROR(VLOOKUP($C28,'HC & Open Position'!$D$3:$P$55,9,0),"") -> 0 | AJ28: =IFERROR(VLOOKUP($C28,'HC & Open Position'!$D$3:$P$55,10,0),"") -> 0 | AK28: =IFERROR(VLOOKUP($C28,'HC & Open Position'!$D$3:$P$55,11,0),"") -> 0 | AL28: =IFERROR(VLOOKUP($C28,'HC & Open Position'!$D$3:$P$55,12,0),"") -> 0 | AM28: =SUM(AI28:AL28) -> 0 | AO28: 2 | AP28: =U28-SUM(AA28+AM28+AD28-AO28) -> -19.299351
A29: CNO0000102 | B29: Excelacom | C29: Ametek | D29: IT | E29: 45352 | F29: 45688 | G29: Sulabh Arora | H29: Krishna Kumar Pillai | I29: South | J29: =IFERROR(VLOOKUP(C29,CPH!$A:$E,5,0),"") -> 70000 | K29: 0 | N29: 1.7 | O29: 1.5042746 | P29: =IFERROR(N29*1.3,1.8) -> 2.21 | Q29: =IFERROR(K29/(P29*3),"") -> 0 | R29: =IFERROR(Q29/8,"") -> 0 | S29: =IFERROR(R29/8,"") -> 0 | T29: =IFERROR(S29/3,"") -> 0 | U29: =SUM(Q29:T29) -> 0 | W29: =IFERROR(VLOOKUP($C29,'HC & Open Position'!$D:$J,MATCH(W$3,'HC & Open Position'!$D$3:$J$3,1),0),"") -> 0 | X29: =IFERROR(VLOOKUP($C29,'HC & Open Position'!$D:$J,MATCH(X$3,'HC & Open Position'!$D$3:$J$3,1),0),"") -> 1 | Y29: =IFERROR(VLOOKUP($C29,'HC & Open Position'!$D:$J,MATCH(Y$3,'HC & Open Position'!$D$3:$J$3,1),0),"") -> 0 | Z29: =IFERROR(VLOOKUP($C29,'HC & Open Position'!$D:$J,MATCH(Z$3,'HC & Open Position'!$D$3:$J$3,1),0),"") -> 0 | AA29: =SUM(W29:Z29) -> 1 | AB29: =U29-AA29 -> -1 | AI29: =IFERROR(VLOOKUP($C29,'HC & Open Position'!$D$3:$P$55,9,0),"") -> 0 | AJ29: =IFERROR(VLOOKUP($C29,'HC & Open Position'!$D$3:$P$55,10,0),"") -> 0 | AK29: =IFERROR(VLOOKUP($C29,'HC & Open Position'!$D$3:$P$55,11,0),"") -> 0 | AL29: =IFERROR(VLOOKUP($C29,'HC & Open Position'!$D$3:$P$55,12,0),"") -> 0 | AM29: =SUM(AI29:AL29) -> 0 | AP29: =U29-SUM(AA29+AM29+AD29-AO29) -> -1
A30: CNO0000123 | B30: Tata Consumer | C30: Tata Consumer | D30: Retail | E30: 45352 | F30: 45900 | G30: Anjli Zutshi | H30: Usha Babu Shetty | I30: West | J30: =IFERROR(VLOOKUP(C30,CPH!$A:$E,5,0),"") -> 58700 | K30: 57.34 | N30: 0.9568346 | O30: 0.80857784 | P30: =IFERROR(N30*1.3,1.8) -> 1.243885 | Q30: =IFERROR(K30/(P30*3),"") -> 15.365837 | R30: =IFERROR(Q30/8,"") -> 1.9207296 | S30: =IFERROR(R30/8,"") -> 0.2400912 | T30: =IFERROR(S30/3,"") -> 0.080030399 | U30: =SUM(Q30:T30) -> 17.606688 | W30: =IFERROR(VLOOKUP($C30,'HC & Open Position'!$D:$J,MATCH(W$3,'HC & Open Position'!$D$3:$J$3,1),0),"") -> 13 | X30: =IFERROR(VLOOKUP($C30,'HC & Open Position'!$D:$J,MATCH(X$3,'HC & Open Position'!$D$3:$J$3,1),0),"") -> 1 | Y30: =IFERROR(VLOOKUP($C30,'HC & Open Position'!$D:$J,MATCH(Y$3,'HC & Open Position'!$D$3:$J$3,1),0),"") -> 0 | Z30: =IFERROR(VLOOKUP($C30,'HC & Open Position'!$D:$J,MATCH(Z$3,'HC & Open Position'!$D$3:$J$3,1),0),"") -> 0 | AA30: =SUM(W30:Z30) -> 14 | AB30: =U30-AA30 -> 3.6066878 | AG30: 1 | AI30: =IFERROR(VLOOKUP($C30,'HC & Open Position'!$D$3:$P$55,9,0),"") -> 1 | AJ30: =IFERROR(VLOOKUP($C30,'HC & Open Position'!$D$3:$P$55,10,0),"") -> 0 | AK30: =IFERROR(VLOOKUP($C30,'HC & Open Position'!$D$3:$P$55,11,0),"") -> 0 | AL30: =IFERROR(VLOOKUP($C30,'HC & Open Position'!$D$3:$P$55,12,0),"") -> 0 | AM30: =SUM(AI30:AL30) -> 1 | AP30: =U30-SUM(AA30+AM30+AD30-AO30) -> 2.6066878
A31: CNO0000129 | B31: Tata Play | C31: Tata Play | D31: Tech | E31: 45383 | F31: 46498 | G31: Anjli Zutshi | H31: Elton Francis Isaac | I31: West | J31: =IFERROR(VLOOKUP(C31,CPH!$A:$E,5,0),"") -> 56000 | K31: 5.44 | N31: 0.47125926 | O31: 0.462665 | P31: 1 | Q31: =IFERROR(K31/(P31*3),"") -> 1.8133333 | R31: =IFERROR(Q31/8,"") -> 0.22666667 | S31: =IFERROR(R31/8,"") -> 0.028333333 | T31: =IFERROR(S31/3,"") -> 0.0094444444 | U31: =SUM(Q31:T31) -> 2.0777778 | W31: =IFERROR(VLOOKUP($C31,'HC & Open Position'!$D:$J,MATCH(W$3,'HC & Open Position'!$D$3:$J$3,1),0),"") -> 1 | X31: =IFERROR(VLOOKUP($C31,'HC & Open Position'!$D:$J,MATCH(X$3,'HC & Open Position'!$D$3:$J$3,1),0),"") -> 0 | Y31: =IFERROR(VLOOKUP($C31,'HC & Open Position'!$D:$J,MATCH(Y$3,'HC & Open Position'!$D$3:$J$3,1),0),"") -> 0 | Z31: =IFERROR(VLOOKUP($C31,'HC & Open Position'!$D:$J,MATCH(Z$3,'HC & Open Position'!$D$3:$J$3,1),0),"") -> 0 | AA31: =SUM(W31:Z31) -> 1 | AB31: =U31-AA31 -> 1.0777778 | AI31: =IFERROR(VLOOKUP($C31,'HC & Open Position'!$D$3:$P$55,9,0),"") -> 0 | AJ31: =IFERROR(VLOOKUP($C31,'HC & Open Position'!$D$3:$P$55,10,0),"") -> 0 | AK31: =IFERROR(VLOOKUP($C31,'HC & Open Position'!$D$3:$P$55,11,0),"") -> 0 | AL31: =IFERROR(VLOOKUP($C31,'HC & Open Position'!$D$3:$P$55,12,0),"") -> 0 | AM31: =SUM(AI31:AL31) -> 0 | AP31: =U31-SUM(AA31+AM31+AD31-AO31) -> 1.0777778
A32: CNO0000132 | B32: Mahindra Finance | C32: Mahindra Finance | D32: Financial | E32: 45383 | F32: 46140 | G32: Anjli Zutshi | H32: Geetu Lalwani | I32: West | J32: =IFERROR(VLOOKUP(C32,CPH!$A:$E,5,0),"") -> 62000 | K32: 11.1 | N32: 1.3036395 | O32: 1.2831215 | P32: =IFERROR(N32*1.3,1.8) -> 1.6947313 | Q32: =IFERROR(K32/(P32*3),"") -> 2.1832369 | R32: =IFERROR(Q32/8,"") -> 0.27290462 | S32: =IFERROR(R32/8,"") -> 0.034113077 | T32: =IFERROR(S32/3,"") -> 0.011371026 | U32: =SUM(Q32:T32) -> 2.5016257 | W32: =IFERROR(VLOOKUP($C32,'HC & Open Position'!$D:$J,MATCH(W$3,'HC & Open Position'!$D$3:$J$3,1),0),"") -> 0 | X32: =IFERROR(VLOOKUP($C32,'HC & Open Position'!$D:$J,MATCH(X$3,'HC & Open Position'!$D$3:$J$3,1),0),"") -> 0 | Y32: =IFERROR(VLOOKUP($C32,'HC & Open Position'!$D:$J,MATCH(Y$3,'HC & Open Position'!$D$3:$J$3,1),0),"") -> 1 | Z32: =IFERROR(VLOOKUP($C32,'HC & Open Position'!$D:$J,MATCH(Z$3,'HC & Open Position'!$D$3:$J$3,1),0),"") -> 0 | AA32: =SUM(W32:Z32) -> 1 | AB32: =U32-AA32 -> 1.5016257 | AI32: =IFERROR(VLOOKUP($C32,'HC & Open Position'!$D$3:$P$55,9,0),"") -> 0 | AJ32: =IFERROR(VLOOKUP($C32,'HC & Open Position'!$D$3:$P$55,10,0),"") -> 0 | AK32: =IFERROR(VLOOKUP($C32,'HC & Open Position'!$D$3:$P$55,11,0),"") -> 0 | AL32: =IFERROR(VLOOKUP($C32,'HC & Open Position'!$D$3:$P$55,12,0),"") -> 0 | AM32: =SUM(AI32:AL32) -> 0 | AP32: =U32-SUM(AA32+AM32+AD32-AO32) -> 1.5016257
B33: Suzuki | C33: Suzuki R&D | G33: Anjli Zutshi | H33: Naved Falak | I33: North | J33: =IFERROR(VLOOKUP(C33,CPH!$A:$E,5,0),"") -> 60000 | K33: 0 | N33: - | O33: 0.62068751 | P33: =IFERROR(N33*1.3,1.8) -> 1.8 | Q33: =IFERROR(K33/(P33*3),"") -> 0 | R33: =IFERROR(Q33/8,"") -> 0 | S33: =IFERROR(R33/8,"") -> 0 | T33: =IFERROR(S33/3,"") -> 0 | U33: =SUM(Q33:T33) -> 0 | W33: =IFERROR(VLOOKUP($C33,'HC & Open Position'!$D:$J,MATCH(W$3,'HC & Open Position'!$D$3:$J$3,1),0),"") -> 1 | X33: =IFERROR(VLOOKUP($C33,'HC & Open Position'!$D:$J,MATCH(X$3,'HC & Open Position'!$D$3:$J$3,1),0),"") -> 0 | Y33: =IFERROR(VLOOKUP($C33,'HC & Open Position'!$D:$J,MATCH(Y$3,'HC & Open Position'!$D$3:$J$3,1),0),"") -> 0 | Z33: =IFERROR(VLOOKUP($C33,'HC & Open Position'!$D:$J,MATCH(Z$3,'HC & Open Position'!$D$3:$J$3,1),0),"") -> 0 | AA33: =SUM(W33:Z33) -> 1 | AB33: =U33-AA33 -> -1 | AI33: =IFERROR(VLOOKUP($C33,'HC & Open Position'!$D$3:$P$55,9,0),"") -> 0 | AJ33: =IFERROR(VLOOKUP($C33,'HC & Open Position'!$D$3:$P$55,10,0),"") -> 0 | AK33: =IFERROR(VLOOKUP($C33,'HC & Open Position'!$D$3:$P$55,11,0),"") -> 0 | AL33: =IFERROR(VLOOKUP($C33,'HC & Open Position'!$D$3:$P$55,12,0),"") -> 0 | AM33: =SUM(AI33:AL33) -> 0 | AP33: =U33-SUM(AA33+AM33+AD33-AO33) -> -1
A34: CNO0000146 | B34: Subros | C34: Subros Ltd | D34: Manufacturing | E34: 45505 | F34: 46247 | G34: Anjli Zutshi | H34: Naved Falak | I34: North | J34: =IFERROR(VLOOKUP(C34,CPH!$A:$E,5,0),"") -> 54000 | K34: 12.8 | N34: 2.2 | O34: 0.66 | P34: =IFERROR(N34*1.3,1.8) -> 2.86 | Q34: =IFERROR(K34/(P34*3),"") -> 1.4918415 | R34: =IFERROR(Q34/8,"") -> 0.18648019 | S34: =IFERROR(R34/8,"") -> 0.023310023 | T34: =IFERROR(S34/3,"") -> 0.0077700078 | U34: =SUM(Q34:T34) -> 1.7094017 | W34: =IFERROR(VLOOKUP($C34,'HC & Open Position'!$D:$J,MATCH(W$3,'HC & Open Position'!$D$3:$J$3,1),0),"") -> 3 | X34: =IFERROR(VLOOKUP($C34,'HC & Open Position'!$D:$J,MATCH(X$3,'HC & Open Position'!$D$3:$J$3,1),0),"") -> 0 | Y34: =IFERROR(VLOOKUP($C34,'HC & Open Position'!$D:$J,MATCH(Y$3,'HC & Open Position'!$D$3:$J$3,1),0),"") -> 0 | Z34: =IFERROR(VLOOKUP($C34,'HC & Open Position'!$D:$J,MATCH(Z$3,'HC & Open Position'!$D$3:$J$3,1),0),"") -> 0 | AA34: =SUM(W34:Z34) -> 3 | AB34: =U34-AA34 -> -1.2905983 | AI34: =IFERROR(VLOOKUP($C34,'HC & Open Position'!$D$3:$P$55,9,0),"") -> 0 | AJ34: =IFERROR(VLOOKUP($C34,'HC & Open Position'!$D$3:$P$55,10,0),"") -> 0 | AK34: =IFERROR(VLOOKUP($C34,'HC & Open Position'!$D$3:$P$55,11,0),"") -> 0 | AL34: =IFERROR(VLOOKUP($C34,'HC & Open Position'!$D$3:$P$55,12,0),"") -> 0 | AM34: =SUM(AI34:AL34) -> 0 | AP34: =U34-SUM(AA34+AM34+AD34-AO34) -> -1.2905983
A35: CNO0000144 | B35: Atomberg | C35: Atomberg Technologies | D35: Manufacturing | E35: 45505 | F35: 46699 | G35: Anjli Zutshi | H35: Geetu Lalwani | I35: West | J35: =IFERROR(VLOOKUP(C35,CPH!$A:$E,5,0),"") -> 41600 | K35: 24.98 | N35: 1.9 | O35: 1.6091534 | P35: =IFERROR(N35*1.3,1.8) -> 2.47 | Q35: =IFERROR(K35/(P35*3),"") -> 3.3711201 | R35: =IFERROR(Q35/8,"") -> 0.42139001 | S35: =IFERROR(R35/8,"") -> 0.052673752 | T35: =IFERROR(S35/3,"") -> 0.017557917 | U35: =SUM(Q35:T35) -> 3.8627418 | W35: =IFERROR(VLOOKUP($C35,'HC & Open Position'!$D:$J,MATCH(W$3,'HC & Open Position'!$D$3:$J$3,1),0),"") -> 4 | X35: =IFERROR(VLOOKUP($C35,'HC & Open Position'!$D:$J,MATCH(X$3,'HC & Open Position'!$D$3:$J$3,1),0),"") -> 1 | Y35: =IFERROR(VLOOKUP($C35,'HC & Open Position'!$D:$J,MATCH(Y$3,'HC & Open Position'!$D$3:$J$3,1),0),"") -> 0 | Z35: =IFERROR(VLOOKUP($C35,'HC & Open Position'!$D:$J,MATCH(Z$3,'HC & Open Position'!$D$3:$J$3,1),0),"") -> 0 | AA35: =SUM(W35:Z35) -> 5 | AB35: =U35-AA35 -> -1.1372582 | AI35: =IFERROR(VLOOKUP($C35,'HC & Open Position'!$D$3:$P$55,9,0),"") -> 0 | AJ35: =IFERROR(VLOOKUP($C35,'HC & Open Position'!$D$3:$P$55,10,0),"") -> 0 | AK35: =IFERROR(VLOOKUP($C35,'HC & Open Position'!$D$3:$P$55,11,0),"") -> 0 | AL35: =IFERROR(VLOOKUP($C35,'HC & Open Position'!$D$3:$P$55,12,0),"") -> 0 | AM35: =SUM(AI35:AL35) -> 0 | AP35: =U35-SUM(AA35+AM35+AD35-AO35) -> -1.1372582
A36: CNO0000162 | B36: Bridgestone | C36: Bridgestone | D36: Manufacturing | E36: 45600 | F36: 46330 | G36: Anjli Zutshi | H36: Shweta Shalini | I36: West | J36: =IFERROR(VLOOKUP(C36,CPH!$A:$E,5,0),"") | K36: 10.86 | N36: 0.96666667 | O36: 2.1749833 | P36: 2.4 | Q36: =IFERROR(K36/(P36*3),"") -> 1.5083333 | R36: =IFERROR(Q36/8,"") -> 0.18854167 | S36: =IFERROR(R36/8,"") -> 0.023567708 | T36: =IFERROR(S36/3,"") -> 0.0078559028 | U36: =SUM(Q36:T36) -> 1.7282986 | W36: =IFERROR(VLOOKUP($C36,'HC & Open Position'!$D:$J,MATCH(W$3,'HC & Open Position'!$D$3:$J$3,1),0),"") -> 2 | X36: =IFERROR(VLOOKUP($C36,'HC & Open Position'!$D:$J,MATCH(X$3,'HC & Open Position'!$D$3:$J$3,1),0),"") -> 1 | Y36: =IFERROR(VLOOKUP($C36,'HC & Open Position'!$D:$J,MATCH(Y$3,'HC & Open Position'!$D$3:$J$3,1),0),"") -> 0 | Z36: =IFERROR(VLOOKUP($C36,'HC & Open Position'!$D:$J,MATCH(Z$3,'HC & Open Position'!$D$3:$J$3,1),0),"") -> 0 | AA36: =SUM(W36:Z36) -> 3 | AB36: =U36-AA36 -> -1.2717014 | AI36: =IFERROR(VLOOKUP($C36,'HC & Open Position'!$D$3:$P$55,9,0),"") -> 0 | AJ36: =IFERROR(VLOOKUP($C36,'HC & Open Position'!$D$3:$P$55,10,0),"") -> 0 | AK36: =IFERROR(VLOOKUP($C36,'HC & Open Position'!$D$3:$P$55,11,0),"") -> 0 | AL36: =IFERROR(VLOOKUP($C36,'HC & Open Position'!$D$3:$P$55,12,0),"") -> 0 | AM36: =SUM(AI36:AL36) -> 0 | AP36: =U36-SUM(AA36+AM36+AD36-AO36) -> -1.2717014
A37: CNO0000147 | B37: Ambuja | C37: Ambuja Cement | D37: Manufacturing | E37: 45536 | F37: 46656 | G37: Anjli Zutshi | H37: Elton Francis Isaac | I37: West | J37: =IFERROR(VLOOKUP(C37,CPH!$A:$E,5,0),"") -> 32000 | K37: 122.59 | N37: 0.9 | O37: 1.6376302 | P37: 2 | Q37: =IFERROR(K37/(P37*3),"") -> 20.431667 | R37: =IFERROR(Q37/8,"") -> 2.5539583 | S37: =IFERROR(R37/8,"") -> 0.31924479 | T37: =IFERROR(S37/3,"") -> 0.10641493 | U37: =SUM(Q37:T37) -> 23.411285 | W37: =IFERROR(VLOOKUP($C37,'HC & Open Position'!$D:$J,MATCH(W$3,'HC & Open Position'!$D$3:$J$3,1),0),"") -> 22 | X37: =IFERROR(VLOOKUP($C37,'HC & Open Position'!$D:$J,MATCH(X$3,'HC & Open Position'!$D$3:$J$3,1),0),"") -> 1 | Y37: =IFERROR(VLOOKUP($C37,'HC & Open Position'!$D:$J,MATCH(Y$3,'HC & Open Position'!$D$3:$J$3,1),0),"") -> 0 | Z37: =IFERROR(VLOOKUP($C37,'HC & Open Position'!$D:$J,MATCH(Z$3,'HC & Open Position'!$D$3:$J$3,1),0),"") -> 0 | AA37: =SUM(W37:Z37) -> 23 | AB37: =U37-AA37 -> 0.41128472 | AD37: 6 | AG37: 1 | AI37: =IFERROR(VLOOKUP($C37,'HC & Open Position'!$D$3:$P$55,9,0),"") -> 1 | AJ37: =IFERROR(VLOOKUP($C37,'HC & Open Position'!$D$3:$P$55,10,0),"") -> 0 | AK37: =IFERROR(VLOOKUP($C37,'HC & Open Position'!$D$3:$P$55,11,0),"") -> 0 | AL37: =IFERROR(VLOOKUP($C37,'HC & Open Position'!$D$3:$P$55,12,0),"") -> 0 | AM37: =SUM(AI37:AL37) -> 1 | AO37: 1 | AP37: =U37-SUM(AA37+AM37+AD37-AO37) -> -5.5887153
A38: CNO0000148 | B38: Ashok Leyland | C38: ASHOK LEYLAND LIMITED | D38: Manufacturing | E38: 45587 | F38: 45952 | G38: Sulabh Arora | H38: Krishna Kumar Pillai | I38: South | J38: =IFERROR(VLOOKUP(C38,CPH!$A:$E,5,0),"") -> 97346 | K38: 42 | N38: 1.5 | O38: 1.7 | P38: =IFERROR(N38*1.3,1.8) -> 1.95 | Q38: =IFERROR(K38/(P38*3),"") -> 7.1794872 | R38: =IFERROR(Q38/8,"") -> 0.8974359 | S38: =IFERROR(R38/8,"") -> 0.11217949 | T38: =IFERROR(S38/3,"") -> 0.037393162 | U38: =SUM(Q38:T38) -> 8.2264957 | W38: =IFERROR(VLOOKUP($C38,'HC & Open Position'!$D:$J,MATCH(W$3,'HC & Open Position'!$D$3:$J$3,1),0),"") -> 10 | X38: =IFERROR(VLOOKUP($C38,'HC & Open Position'!$D:$J,MATCH(X$3,'HC & Open Position'!$D$3:$J$3,1),0),"") -> 4 | Y38: =IFERROR(VLOOKUP($C38,'HC & Open Position'!$D:$J,MATCH(Y$3,'HC & Open Position'!$D$3:$J$3,1),0),"") -> 0 | Z38: =IFERROR(VLOOKUP($C38,'HC & Open Position'!$D:$J,MATCH(Z$3,'HC & Open Position'!$D$3:$J$3,1),0),"") -> 0 | AA38: =SUM(W38:Z38) -> 14 | AB38: =U38-AA38 -> -5.7735043 | AD38: 2 | AI38: =IFERROR(VLOOKUP($C38,'HC & Open Position'!$D$3:$P$55,9,0),"") -> 0 | AJ38: =IFERROR(VLOOKUP($C38,'HC & Open Position'!$D$3:$P$55,10,0),"") -> 0 | AK38: =IFERROR(VLOOKUP($C38,'HC & Open Position'!$D$3:$P$55,11,0),"") -> 0 | AL38: =IFERROR(VLOOKUP($C38,'HC & Open Position'!$D$3:$P$55,12,0),"") -> 0 | AM38: =SUM(AI38:AL38) -> 0 | AP38: =U38-SUM(AA38+AM38+AD38-AO38) -> -7.7735043
A39: CNO0000163 | B39: Sterling Tool | C39: Sterling Tools | E39: 45616 | F39: 46710 | G39: Anjli Zutshi | H39: Naved Falak | I39: North | J39: =IFERROR(VLOOKUP(C39,CPH!$A:$E,5,0),"") -> 83000 | K39: 18.9 | N39: - | O39: 0.79399785 | P39: =IFERROR(N39*1.3,1.8) -> 1.8 | Q39: =IFERROR(K39/(P39*3),"") -> 3.5 | R39: =IFERROR(Q39/8,"") -> 0.4375 | S39: =IFERROR(R39/8,"") -> 0.0546875 | T39: =IFERROR(S39/3,"") -> 0.018229167 | U39: =SUM(Q39:T39) -> 4.0104167 | W39: =IFERROR(VLOOKUP($C39,'HC & Open Position'!$D:$J,MATCH(W$3,'HC & Open Position'!$D$3:$J$3,1),0),"") -> 3 | X39: =IFERROR(VLOOKUP($C39,'HC & Open Position'!$D:$J,MATCH(X$3,'HC & Open Position'!$D$3:$J$3,1),0),"") -> 1 | Y39: =IFERROR(VLOOKUP($C39,'HC & Open Position'!$D:$J,MATCH(Y$3,'HC & Open Position'!$D$3:$J$3,1),0),"") -> 0 | Z39: =IFERROR(VLOOKUP($C39,'HC & Open Position'!$D:$J,MATCH(Z$3,'HC & Open Position'!$D$3:$J$3,1),0),"") -> 0 | AA39: =SUM(W39:Z39) -> 4 | AB39: =U39-AA39 -> 0.010416667 | AI39: =IFERROR(VLOOKUP($C39,'HC & Open Position'!$D$3:$P$55,9,0),"") -> 0 | AJ39: =IFERROR(VLOOKUP($C39,'HC & Open Position'!$D$3:$P$55,10,0),"") -> 0 | AK39: =IFERROR(VLOOKUP($C39,'HC & Open Position'!$D$3:$P$55,11,0),"") -> 0 | AL39: =IFERROR(VLOOKUP($C39,'HC & Open Position'!$D$3:$P$55,12,0),"") -> 0 | AM39: =SUM(AI39:AL39) -> 0 | AP39: =U39-SUM(AA39+AM39+AD39-AO39) -> 0.010416667
A40: CNO0000170 | B40: M2P | C40: M2P Fintech | E40: 45639 | F40: 46368 | G40: Sulabh Arora | H40: Krishna Kumar Pillai | I40: South | J40: =IFERROR(VLOOKUP(C40,CPH!$A:$E,5,0),"") -> 60000 | K40: 0 | N40: 0.9 | O40: 1.5349463 | P40: 1.8 | Q40: =IFERROR(K40/(P40*3),"") -> 0 | R40: =IFERROR(Q40/8,"") -> 0 | S40: =IFERROR(R40/8,"") -> 0 | T40: =IFERROR(S40/3,"") -> 0 | U40: =SUM(Q40:T40) -> 0 | W40: =IFERROR(VLOOKUP($C40,'HC & Open Position'!$D:$J,MATCH(W$3,'HC & Open Position'!$D$3:$J$3,1),0),"") -> 1 | X40: =IFERROR(VLOOKUP($C40,'HC & Open Position'!$D:$J,MATCH(X$3,'HC & Open Position'!$D$3:$J$3,1),0),"") -> 0 | Y40: =IFERROR(VLOOKUP($C40,'HC & Open Position'!$D:$J,MATCH(Y$3,'HC & Open Position'!$D$3:$J$3,1),0),"") -> 0 | Z40: =IFERROR(VLOOKUP($C40,'HC & Open Position'!$D:$J,MATCH(Z$3,'HC & Open Position'!$D$3:$J$3,1),0),"") -> 0 | AA40: =SUM(W40:Z40) -> 1 | AB40: =U40-AA40 -> -1 | AI40: =IFERROR(VLOOKUP($C40,'HC & Open Position'!$D$3:$P$55,9,0),"") -> 0 | AJ40: =IFERROR(VLOOKUP($C40,'HC & Open Position'!$D$3:$P$55,10,0),"") -> 0 | AK40: =IFERROR(VLOOKUP($C40,'HC & Open Position'!$D$3:$P$55,11,0),"") -> 0 | AL40: =IFERROR(VLOOKUP($C40,'HC & Open Position'!$D$3:$P$55,12,0),"") -> 0 | AM40: =SUM(AI40:AL40) -> 0 | AP40: =U40-SUM(AA40+AM40+AD40-AO40) -> -1
...

Sheet HR Guru | Lyftr
A1: Customer Name | B1: HR Guru
A2: Ambuja | B2: 6
A3: AMNS | B3: 0
A4: ASHOK LEYLAND LIMITED | B4: 2
A5: Birla Paints | B5: 1
A6: Digitization | B6: 0
A7: DP World | B7: 0
A8: Honeywell | B8: 0
A9: HPE | B9: 0
A10: Hyundai Motor | B10: 2
A11: Ingram Micro | B11: 0
A12: Internal (HR) | B12: 0
A13: Isuzu | B13: 0
... A35: Wipro | B35: 0
A36: Grand Total | B36: =SUM(B2:B35) -> 31.98
A39: Customer Name | B39: Lyftr
A40: Wipro | B40: 3

Sheet Open Positin List
A1: Index | B1: Requisition ID | C1: Requisition Status | D1: Requisition Create Date | E1: Requisition Approved Date | F1: Req Type | G1: Replacement Name | H1: Replacement Code | I1: Hiring Manager | J1: TA SPOC | K1: Work Level | L1: Grade | M1: Location | N1: Client | O1: Vertical (client) | P1: Designation | Q1: Status | R1: Candidate Name | S1: Date of offer | T1: Date of joining | U1: Whether the replacement person is existing in the system?
A2: 1 | B2: NA | C2: Not Created | D2: NA | E2: NA | F2: New | G2: NA | H2: NA | I2: Anshuman Srivastava | J2: Bhawna Keshri | K2: WL3 | L2: G9 | M2: Gurgaon | N2: AVP - Exec Search | O2: Leadership | P2: AVP - Executive Search | Q2: Open
A3: 2 | B3: tgd/pm/1382538 | C3: Approved | D3: 45819 | E3: 45820 | F3: Replacement | G3: Kaviyasuru | H3: 11175 | I3: Dhriti | J3: Bhawna Keshri | K3: WL2 | L3: G6 | M3: Chennai | N3: M&M | P3: Manager - RPO | Q3: Open | U3: Exited
A4: 3 | B4: tgd/m/1541058 | C4: Not Approved | D4: 45959 | E4: NA | F4: New | G4: NA | H4: NA | I4: Usha Babu Shetty | J4: Riya Singh | K4: WL2 | L4: G6 | M4: Mumbai | N4: Pfizer | P4: Manager RPO | Q4: Open
A5: 4 | B5: tgd/arm/1540331 | C5: Approved | D5: 45959 | E5: NA | F5: New | G5: NA | H5: NA | I5: Anjli Zutshi | J5: Riya Singh | K5: WL3 | L5: G9 | M5: Mumbai | N5: Regional Head (RPO) | P5: AVP - RPO | Q5: YTJ | R5: Sudha Pandey | S5: 46044 | T5: 46104
A6: 5 | B6: tgd/-/1557180 | C6: Approved | D6: 45976 | E6: 45979 | F6: New | G6: NA | H6: NA | I6: Ankit Dave | J6: Bhawna Keshri | K6: WL2 | L6: G6 | M6: Mumbai | N6: NeoSoft | P6: Manager RPO | Q6: Open
A7: 6 | B7: TGD/SM/1618240 | C7: Approved | D7: 46031 | E7: 46031 | F7: New | G7: NA | H7: NA | I7: Anjli Zutshi | J7: Bhawna Keshri | K7: WL3 | L7: G8 | M7: Mumbai | N7: Saint Gobain | P7: SDL | Q7: YTJ | R7: Sunita K Velayudhan | S7: 46037 | T7: 46079
A8: 7 | B8: tgd/pm/1621978 | C8: Approved | D8: 46036 | E8: 46036 | F8: New | G8: NA | H8: NA | I8: ARCHANA TRIKHA | J8: Riya Singh | K8: WL2 | L8: G6 | M8: Mumbai | N8: CG Power | P8: Manager | Q8: Open
A9: 8 | B9: tgd/pm/1621987 | C9: Approved | D9: 46036 | E9: 46036 | F9: New | G9: NA | H9: NA | I9: ARCHANA TRIKHA | J9: Riya Singh | K9: WL2 | L9: G6 | M9: Gurgaon | N9: CG Power | P9: Manager | Q9: Open
