Workbook

Sheet Position Tracker
A1: S.No | B1: Requisition Date | C1: Aging | D1: Bucket | E1: Role | F1: No of Openings | G1: Diversity | H1: Hiring Manager | I1: HR Spoc | J1: Status | K1: Grade | L1: Experience | M1: Min Budget | N1: Max Budget | O1: Variable % | P1: Education | Q1: Location | R1: Mandatory CTQ | S1: Requisition Date | T1: Roll Id | U1: Total Shotlisted | V1: Reject count | W1: MINUS | X1: FTR% | Y1: Level | Z1: Date | AA1: Status | AB1: Intake Date | AC1: Hold Date | AD1: Offer Date | AE1: Join Date | AF1: TTO | AG1: TTF | AH1: Remarks | AI1: Replacement/New | AJ1: Replacement of (Name)
A2: 1 | B2: 45401 | C2: =IF(B2="","",NETWORKDAYS.INTL(B2,TODAY(),1,'HELPER(Dont Delete)'!A:A)) -> 419 | D2: =IF(J2="Open", IF(AND(C2>=0, C2<=30), "0-30", IF(AND(C2>=31, C2<=45), "31-45", IF(AND(C2>=46, C2<=60), "46-60", IF(AND(C2>=61, C2<=75), "61-75", IF(AND(C2>=76, C2<=90), "76-90", IF(AND(C2>=91, C2<=105), "91-105", IF(AND(C2>=106, C2<=120), "106-120", IF(C2>120, "120+", "")))))))),"") | E2: Fabrication | F2: 1 | G2: No | H2: SK Goel | I2: Ujjwal | J2: Hold | K2: DGM/GM | L2: 8-12 years | M2: 35 LPA/40 LPA | N2: 40 LPA/45 LPA | O2: 10%/30% | P2: B.tech | Q2: Mumbai | S2: =B2 -> 45401 | U2: =COUNTIFS('Candidate Tracker'!D:D,'Position Tracker'!E2,'Candidate Tracker'!V:V, "<>Screening Pending") -> 6 | V2: =COUNTIFS('Candidate Tracker'!D:D,'Position Tracker'!E2,'Candidate Tracker'!V:V, "Screen Reject") -> 0 | W2: =U2-V2 -> 6 | X2: =IFERROR(IF(U2=0,0,IF(V2=0,"100%",W2/U2)),"") -> 100% | Y2: RL3 | AF2: =IF(OR(AD2="",B2=""),"",NETWORKDAYS.INTL(B2,AD2,1,'HELPER(Dont Delete)'!A:A)) | AG2: =IF(OR(AD2="",B2=""),"",NETWORKDAYS.INTL(B2,AE2,1,'HELPER(Dont Delete)'!A:A))
A3: 2 | B3: 45356 | C3: =IF(B3="","",NETWORKDAYS.INTL(B3,TODAY(),1,'HELPER(Dont Delete)'!A:A)) -> 444 | D3: =IF(J3="Open", IF(AND(C3>=0, C3<=30), "0-30", IF(AND(C3>=31, C3<=45), "31-45", IF(AND(C3>=46, C3<=60), "46-60", IF(AND(C3>=61, C3<=75), "61-75", IF(AND(C3>=76, C3<=90), "76-90", IF(AND(C3>=91, C3<=105), "91-105", IF(AND(C3>=106, C3<=120), "106-120", IF(C3>120, "120+", "")))))))),"") | E3: KAM (Mumbai) | F3: 1 | G3: No | H3: Aman | I3: Ujjwal | J3: Scap | K3: Executive | L3: 2-4 years | N3: 7.5 LPA | O3: 0.1 | P3: B.tech/ B.tech + MBA/ MBA | Q3: Mumbai | S3: =B3 -> 45356 | U3: =COUNTIFS('Candidate Tracker'!D:D,'Position Tracker'!E3,'Candidate Tracker'!V:V, "<>Screening Pending") -> 5 | V3: =COUNTIFS('Candidate Tracker'!D:D,'Position Tracker'!E3,'Candidate Tracker'!V:V, "Screen Reject") -> 1 | W3: =U3-V3 -> 4 | X3: =IFERROR(IF(U3=0,0,IF(V3=0,"100%",W3/U3)),"") -> 0.8 | Y3: RL1 | AF3: =IF(OR(AD3="",B3=""),"",NETWORKDAYS.INTL(B3,AD3,1,'HELPER(Dont Delete)'!A:A)) | AG3: =IF(OR(AD3="",B3=""),"",NETWORKDAYS.INTL(B3,AE3,1,'HELPER(Dont Delete)'!A:A))
A4: 3 | B4: 45299 | C4: =IF(B4="","",NETWORKDAYS.INTL(B4,TODAY(),1,'HELPER(Dont Delete)'!A:A)) -> 479 | D4: =IF(J4="Open", IF(AND(C4>=0, C4<=30), "0-30", IF(AND(C4>=31, C4<=45), "31-45", IF(AND(C4>=46, C4<=60), "46-60", IF(AND(C4>=61, C4<=75), "61-75", IF(AND(C4>=76, C4<=90), "76-90", IF(AND(C4>=91, C4<=105), "91-105", IF(AND(C4>=106, C4<=120), "106-120", IF(C4>120, "120+", "")))))))),"") | E4: Logistics - Manager/Sr Manager | F4: 1 | G4: No | H4: DB Singh | I4: Ujjwal | J4: Joined | K4: Manager/Senior Manager | L4: 7-10 years | N4: 20 LPA | O4: 0.1 | P4: B.tech | Q4: Gurugram | R4: Logistics, Transportation, Trucks, Railways. Domestic transportation | S4: =B4 -> 45299 | U4: =COUNTIFS('Candidate Tracker'!D:D,'Position Tracker'!E4,'Candidate Tracker'!V:V, "<>Screening Pending") -> 11 | V4: =COUNTIFS('Candidate Tracker'!D:D,'Position Tracker'!E4,'Candidate Tracker'!V:V, "Screen Reject") -> 2 | W4: =U4-V4 -> 9 | X4: =IFERROR(IF(U4=0,0,IF(V4=0,"100%",W4/U4)),"") -> 0.81818182 | Y4: RL2 | AD4: 45425 | AE4: 45481 | AF4: =IF(OR(AD4="",B4=""),"",NETWORKDAYS.INTL(B4,AD4,1,'HELPER(Dont Delete)'!A:A)) -> 76 | AG4: =IF(OR(AD4="",B4=""),"",NETWORKDAYS.INTL(B4,AE4,1,'HELPER(Dont Delete)'!A:A)) -> 114
A5: 4 | B5: 45327 | C5: =IF(B5="","",NETWORKDAYS.INTL(B5,TODAY(),1,'HELPER(Dont Delete)'!A:A)) -> 463 | D5: =IF(J5="Open", IF(AND(C5>=0, C5<=30), "0-30", IF(AND(C5>=31, C5<=45), "31-45", IF(AND(C5>=46, C5<=60), "46-60", IF(AND(C5>=61, C5<=75), "61-75", IF(AND(C5>=76, C5<=90), "76-90", IF(AND(C5>=91, C5<=105), "91-105", IF(AND(C5>=106, C5<=120), "106-120", IF(C5>120, "120+", "")))))))),"") | E5: KAM (Kolkata) | F5: 1 | G5: No | H5: Aman | I5: Ujjwal | J5: Joined | K5: Manager | L5: 3-8 years | N5: 7.5 LPA | O5: 0.1 | P5: B.tech/ B.tech + MBA/ MBA | Q5: Kolkata | S5: =B5 -> 45327 | U5: =COUNTIFS('Candidate Tracker'!D:D,'Position Tracker'!E5,'Candidate Tracker'!V:V, "<>Screening Pending") -> 25 | V5: =COUNTIFS('Candidate Tracker'!D:D,'Position Tracker'!E5,'Candidate Tracker'!V:V, "Screen Reject") -> 7 | W5: =U5-V5 -> 18 | X5: =IFERROR(IF(U5=0,0,IF(V5=0,"100%",W5/U5)),"") -> 0.72 | Y5: RL2 | AD5: 45369 | AE5: 45390 | AF5: =IF(OR(AD5="",B5=""),"",NETWORKDAYS.INTL(B5,AD5,1,'HELPER(Dont Delete)'!A:A)) -> 27 | AG5: =IF(OR(AD5="",B5=""),"",NETWORKDAYS.INTL(B5,AE5,1,'HELPER(Dont Delete)'!A:A)) -> 39
A6: 5 | B6: 45356 | C6: =IF(B6="","",NETWORKDAYS.INTL(B6,TODAY(),1,'HELPER(Dont Delete)'!A:A)) -> 444 | D6: =IF(J6="Open", IF(AND(C6>=0, C6<=30), "0-30", IF(AND(C6>=31, C6<=45), "31-45", IF(AND(C6>=46, C6<=60), "46-60", IF(AND(C6>=61, C6<=75), "61-75", IF(AND(C6>=76, C6<=90), "76-90", IF(AND(C6>=91, C6<=105), "91-105", IF(AND(C6>=106, C6<=120), "106-120", IF(C6>120, "120+", "")))))))),"") | E6: KAM (Ahmedabad) | F6: 1 | G6: No | H6: Aman | I6: Ujjwal | J6: Joined | K6: Executive | L6: 2-4 years | N6: 7.5 LPA | O6: 0.1 | P6: B.tech/ B.tech + MBA/ MBA | Q6: Ahmedabad | S6: =B6 -> 45356 | U6: =COUNTIFS('Candidate Tracker'!D:D,'Position Tracker'!E6,'Candidate Tracker'!V:V, "<>Screening Pending") -> 0 | V6: =COUNTIFS('Candidate Tracker'!D:D,'Position Tracker'!E6,'Candidate Tracker'!V:V, "Screen Reject") -> 0 | W6: =U6-V6 -> 0 | X6: =IFERROR(IF(U6=0,0,IF(V6=0,"100%",W6/U6)),"") -> 0 | Y6: RL1 | AD6: 45397 | AE6: 45432 | AF6: =IF(OR(AD6="",B6=""),"",NETWORKDAYS.INTL(B6,AD6,1,'HELPER(Dont Delete)'!A:A)) -> 23 | AG6: =IF(OR(AD6="",B6=""),"",NETWORKDAYS.INTL(B6,AE6,1,'HELPER(Dont Delete)'!A:A)) -> 46
A7: 6 | B7: 45356 | C7: =IF(B7="","",NETWORKDAYS.INTL(B7,TODAY(),1,'HELPER(Dont Delete)'!A:A)) -> 444 | D7: =IF(J7="Open", IF(AND(C7>=0, C7<=30), "0-30", IF(AND(C7>=31, C7<=45), "31-45", IF(AND(C7>=46, C7<=60), "46-60", IF(AND(C7>=61, C7<=75), "61-75", IF(AND(C7>=76, C7<=90), "76-90", IF(AND(C7>=91, C7<=105), "91-105", IF(AND(C7>=106, C7<=120), "106-120", IF(C7>120, "120+", "")))))))),"") | E7: KAM (Gurgaon) | F7: 1 | G7: No | H7: Aman | I7: Ujjwal | J7: Hold | K7: Executive | L7: 2-4 years | N7: 7.5 LPA | O7: 0.1 | P7: B.tech/ B.tech + MBA/ MBA | Q7: Gurgaon | S7: =B7 -> 45356 | U7: =COUNTIFS('Candidate Tracker'!D:D,'Position Tracker'!E7,'Candidate Tracker'!V:V, "<>Screening Pending") -> 24 | V7: =COUNTIFS('Candidate Tracker'!D:D,'Position Tracker'!E7,'Candidate Tracker'!V:V, "Screen Reject") -> 4 | W7: =U7-V7 -> 20 | X7: =IFERROR(IF(U7=0,0,IF(V7=0,"100%",W7/U7)),"") -> 0.83333333 | Y7: RL1 | AF7: =IF(OR(AD7="",B7=""),"",NETWORKDAYS.INTL(B7,AD7,1,'HELPER(Dont Delete)'!A:A)) | AG7: =IF(OR(AD7="",B7=""),"",NETWORKDAYS.INTL(B7,AE7,1,'HELPER(Dont Delete)'!A:A))
A8: 7 | B8: 45476 | C8: =IF(B8="","",NETWORKDAYS.INTL(B8,TODAY(),1,'HELPER(Dont Delete)'!A:A))-9 -> 360 | D8: =IF(J8="Open", IF(AND(C8>=0, C8<=30), "0-30", IF(AND(C8>=31, C8<=45), "31-45", IF(AND(C8>=46, C8<=60), "46-60", IF(AND(C8>=61, C8<=75), "61-75", IF(AND(C8>=76, C8<=90), "76-90", IF(AND(C8>=91, C8<=105), "91-105", IF(AND(C8>=106, C8<=120), "106-120", IF(C8>120, "120+", "")))))))),"") | E8: KAM_ Steel (Mumbai) | F8: 1 | G8: No | H8: Aman | I8: Ujjwal | J8: Joined | K8: Executive | L8: 2-4 years | N8: 8 LPA | O8: 0.1 | P8: B.tech | Q8: Mumbai | R8: Position on hold at 16 Sep, position reopen at 24 Sep | S8: =B8 -> 45476 | U8: =COUNTIFS('Candidate Tracker'!D:D,'Position Tracker'!E8,'Candidate Tracker'!V:V, "<>Screening Pending") -> 20 | V8: =COUNTIFS('Candidate Tracker'!D:D,'Position Tracker'!E8,'Candidate Tracker'!V:V, "Screen Reject") -> 3 | W8: =U8-V8 -> 17 | X8: =IFERROR(IF(U8=0,0,IF(V8=0,"100%",W8/U8)),"") -> 0.85 | Y8: RL1 | AF8: =IF(OR(AD8="",B8=""),"",NETWORKDAYS.INTL(B8,AD8,1,'HELPER(Dont Delete)'!A:A)) | AG8: =IF(OR(AD8="",B8=""),"",NETWORKDAYS.INTL(B8,AE8,1,'HELPER(Dont Delete)'!A:A))
A9: 8 | B9: 45476 | C9: =IF(B9="","",NETWORKDAYS.INTL(B9,TODAY(),1,'HELPER(Dont Delete)'!A:A)) -> 369 | D9: =IF(J9="Open", IF(AND(C9>=0, C9<=30), "0-30", IF(AND(C9>=31, C9<=45), "31-45", IF(AND(C9>=46, C9<=60), "46-60", IF(AND(C9>=61, C9<=75), "61-75", IF(AND(C9>=76, C9<=90), "76-90", IF(AND(C9>=91, C9<=105), "91-105", IF(AND(C9>=106, C9<=120), "106-120", IF(C9>120, "120+", "")))))))),"") | E9: KAM - AM | F9: 1 | G9: No | H9: Aman | I9: Ujjwal | J9: Hold | K9: AM | L9: 3-8 Years | N9: 11 LPA | O9: 0.1 | P9: B.tech | Q9: Vadodara | S9: =B9 -> 45476 | U9: =COUNTIFS('Candidate Tracker'!D:D,'Position Tracker'!E9,'Candidate Tracker'!V:V, "<>Screening Pending") -> 8 | V9: =COUNTIFS('Candidate Tracker'!D:D,'Position Tracker'!E9,'Candidate Tracker'!V:V, "Screen Reject") -> 1 | W9: =U9-V9 -> 7 | X9: =IFERROR(IF(U9=0,0,IF(V9=0,"100%",W9/U9)),"") -> 0.875 | Y9: RL1 | AF9: =IF(OR(AD9="",B9=""),"",NETWORKDAYS.INTL(B9,AD9,1,'HELPER(Dont Delete)'!A:A)) | AG9: =IF(OR(AD9="",B9=""),"",NETWORKDAYS.INTL(B9,AE9,1,'HELPER(Dont Delete)'!A:A))
A10: 9 | B10: 45548 | C10: =IF(B10="","",NETWORKDAYS.INTL(B10,TODAY(),1,'HELPER(Dont Delete)'!A:A)) -> 321 | D10: =IF(J10="Open", IF(AND(C10>=0, C10<=30), "0-30", IF(AND(C10>=31, C10<=45), "31-45", IF(AND(C10>=46, C10<=60), "46-60", IF(AND(C10>=61, C10<=75), "61-75", IF(AND(C10>=76, C10<=90), "76-90", IF(AND(C10>=91, C10<=105), "91-105", IF(AND(C10>=106, C10<=120), "106-120", IF(C10>120, "120+", "")))))))),"") | E10: KAM_ Steel (Hyderabad) | F10: 1 | G10: No | H10: Aman | I10: Ujjwal | J10: Joined | K10: Executive | L10: 2-4 years | N10: 9 LPA | O10: 0.1 | P10: B.tech | Q10: Hyderabad | S10: =B10 -> 45548 | U10: =COUNTIFS('Candidate Tracker'!D:D,'Position Tracker'!E10,'Candidate Tracker'!V:V, "<>Screening Pending") -> 4 | V10: =COUNTIFS('Candidate Tracker'!D:D,'Position Tracker'!E10,'Candidate Tracker'!V:V, "Screen Reject") -> 0 | W10: =U10-V10 -> 4 | X10: =IFERROR(IF(U10=0,0,IF(V10=0,"100%",W10/U10)),"") -> 100% | Y10: RL1 | AF10: =IF(OR(AD10="",B10=""),"",NETWORKDAYS.INTL(B10,AD10,1,'HELPER(Dont Delete)'!A:A)) | AG10: =IF(OR(AD10="",B10=""),"",NETWORKDAYS.INTL(B10,AE10,1,'HELPER(Dont Delete)'!A:A))
A11: 10 | B11: 45551 | C11: =IF(B11="","",NETWORKDAYS.INTL(B11,TODAY(),1,'HELPER(Dont Delete)'!A:A)) -> 320 | D11: =IF(J11="Open", IF(AND(C11>=0, C11<=30), "0-30", IF(AND(C11>=31, C11<=45), "31-45", IF(AND(C11>=46, C11<=60), "46-60", IF(AND(C11>=61, C11<=75), "61-75", IF(AND(C11>=76, C11<=90), "76-90", IF(AND(C11>=91, C11<=105), "91-105", IF(AND(C11>=106, C11<=120), "106-120", IF(C11>120, "120+", "")))))))),"") | E11: Supply Chain Manager | F11: 1 | G11: No | H11: Aman | I11: Ujjwal | J11: Joined | K11: Manager | L11: 5-10 years | N11: 19 LPA | O11: 0.1 | P11: B.tech / MBA | Q11: Gurgaon | S11: =B11 -> 45551 | U11: =COUNTIFS('Candidate Tracker'!D:D,'Position Tracker'!E11,'Candidate Tracker'!V:V, "<>Screening Pending") -> 14 | V11: =COUNTIFS('Candidate Tracker'!D:D,'Position Tracker'!E11,'Candidate Tracker'!V:V, "Screen Reject") -> 3 | W11: =U11-V11 -> 11 | X11: =IFERROR(IF(U11=0,0,IF(V11=0,"100%",W11/U11)),"") -> 0.78571429 | Y11: RL2 | AF11: =IF(OR(AD11="",B11=""),"",NETWORKDAYS.INTL(B11,AD11,1,'HELPER(Dont Delete)'!A:A)) | AG11: =IF(OR(AD11="",B11=""),"",NETWORKDAYS.INTL(B11,AE11,1,'HELPER(Dont Delete)'!A:A))
A12: 11 | B12: 45593 | C12: =IF(B12="","",NETWORKDAYS.INTL(B12,TODAY(),1,'HELPER(Dont Delete)'!A:A)) -> 295 | D12: =IF(J12="Open", IF(AND(C12>=0, C12<=30), "0-30", IF(AND(C12>=31, C12<=45), "31-45", IF(AND(C12>=46, C12<=60), "46-60", IF(AND(C12>=61, C12<=75), "61-75", IF(AND(C12>=76, C12<=90), "76-90", IF(AND(C12>=91, C12<=105), "91-105", IF(AND(C12>=106, C12<=120), "106-120", IF(C12>120, "120+", "")))))))),"") | E12: Plant Head | F12: 1 | G12: No | H12: Aman | I12: Ujjwal | J12: Hold | K12: AGM/DGM | L12: 20-25 Years | N12: 60 LPA | O12: 0.2 | P12: B.tech | Q12: Mumbai | R12: Fabrication, steel, Remarks (2 Jan put on hold ) | S12: =B12 -> 45593 | U12: =COUNTIFS('Candidate Tracker'!D:D,'Position Tracker'!E12,'Candidate Tracker'!V:V, "<>Screening Pending") -> 8 | V12: =COUNTIFS('Candidate Tracker'!D:D,'Position Tracker'!E12,'Candidate Tracker'!V:V, "Screen Reject") -> 1 | W12: =U12-V12 -> 7 | X12: =IFERROR(IF(U12=0,0,IF(V12=0,"100%",W12/U12)),"") -> 0.875 | Y12: RL3
A13: 12 | B13: 45629 | C13: =IF(B13="","",NETWORKDAYS.INTL(B13,TODAY(),1,'HELPER(Dont Delete)'!A:A)) -> 272 | D13: =IF(J13="Open", IF(AND(C13>=0, C13<=30), "0-30", IF(AND(C13>=31, C13<=45), "31-45", IF(AND(C13>=46, C13<=60), "46-60", IF(AND(C13>=61, C13<=75), "61-75", IF(AND(C13>=76, C13<=90), "76-90", IF(AND(C13>=91, C13<=105), "91-105", IF(AND(C13>=106, C13<=120), "106-120", IF(C13>120, "120+", "")))))))),"") | E13: Electrical Manager Maintenance | F13: 1 | G13: No | H13: Aman | I13: Ujjwal | J13: Joined | K13: Manager | L13: 10-12 Years | N13: 19 LPA | O13: 0.1 | P13: B.tech | Q13: Mumbai | R13: Internally Closed on 1 NOV, reopen at 3 Dec | S13: =B13 -> 45629 | T13: 2032 | U13: =COUNTIFS('Candidate Tracker'!D:D,'Position Tracker'!E13,'Candidate Tracker'!V:V, "<>Screening Pending") -> 8 | V13: =COUNTIFS('Candidate Tracker'!D:D,'Position Tracker'!E13,'Candidate Tracker'!V:V, "Screen Reject") -> 1 | W13: =U13-V13 -> 7 | X13: =IFERROR(IF(U13=0,0,IF(V13=0,"100%",W13/U13)),"") -> 0.875 | Y13: RL2
A14: 13 | B14: 45628 | C14: =IF(B14="","",NETWORKDAYS.INTL(B14,TODAY(),1,'HELPER(Dont Delete)'!A:A)) -> 273 | D14: =IF(J14="Open", IF(AND(C14>=0, C14<=30), "0-30", IF(AND(C14>=31, C14<=45), "31-45", IF(AND(C14>=46, C14<=60), "46-60", IF(AND(C14>=61, C14<=75), "61-75", IF(AND(C14>=76, C14<=90), "76-90", IF(AND(C14>=91, C14<=105), "91-105", IF(AND(C14>=106, C14<=120), "106-120", IF(C14>120, "120+", "")))))))),"") | E14: KAM_ Steel (Chennai) | F14: 1 | G14: No | H14: Aman | I14: Ujjwal | J14: Joined | K14: AM | L14: 3-9 Years | M14: 5 LPA | N14: 11 LPA | O14: 0.1 | P14: B.tech | Q14: Chennai | S14: =B14 -> 45628 | T14: 2031 | U14: =COUNTIFS('Candidate Tracker'!D:D,'Position Tracker'!E14,'Candidate Tracker'!V:V, "<>Screening Pending") -> 4 | V14: =COUNTIFS('Candidate Tracker'!D:D,'Position Tracker'!E14,'Candidate Tracker'!V:V, "Screen Reject") -> 1 | W14: =U14-V14 -> 3 | X14: =IFERROR(IF(U14=0,0,IF(V14=0,"100%",W14/U14)),"") -> 0.75 | Y14: RL1
A15: 14 | B15: 45750 | C15: =IF(B15="","",NETWORKDAYS.INTL(B15,TODAY(),1,'HELPER(Dont Delete)'!A:A)) -> 187 | D15: =IF(J15="Open", IF(AND(C15>=0, C15<=30), "0-30", IF(AND(C15>=31, C15<=45), "31-45", IF(AND(C15>=46, C15<=60), "46-60", IF(AND(C15>=61, C15<=75), "61-75", IF(AND(C15>=76, C15<=90), "76-90", IF(AND(C15>=91, C15<=105), "91-105", IF(AND(C15>=106, C15<=120), "106-120", IF(C15>120, "120+", "")))))))),"") | E15: Design Executive | F15: 3 | G15: No | H15: Neeraj | I15: Ujjwal | J15: Hold | K15: Executive | L15: 3-5 Years | M15: 5 LPA | N15: 7 LPA | O15: 0.1 | P15: B.tech | Q15: Gurgaon | R15: Position closed on 29 jan | S15: =B15 -> 45750 | T15: 2321 | U15: =COUNTIFS('Candidate Tracker'!D:D,'Position Tracker'!E15,'Candidate Tracker'!V:V, "<>Screening Pending") -> 25 | V15: =COUNTIFS('Candidate Tracker'!D:D,'Position Tracker'!E15,'Candidate Tracker'!V:V, "Screen Reject") -> 13 | W15: =U15-V15 -> 12 | X15: =IFERROR(IF(U15=0,0,IF(V15=0,"100%",W15/U15)),"") -> 0.48 | Y15: RL1 | AC15: 45771 | AH15: 2Jan2025 - New req created|2076
A16: 15 | B16: 45659 | C16: =IF(B16="","",NETWORKDAYS.INTL(B16,TODAY(),1,'HELPER(Dont Delete)'!A:A)) -> 252 | D16: =IF(J16="Open", IF(AND(C16>=0, C16<=30), "0-30", IF(AND(C16>=31, C16<=45), "31-45", IF(AND(C16>=46, C16<=60), "46-60", IF(AND(C16>=61, C16<=75), "61-75", IF(AND(C16>=76, C16<=90), "76-90", IF(AND(C16>=91, C16<=105), "91-105", IF(AND(C16>=106, C16<=120), "106-120", IF(C16>120, "120+", "")))))))),"") | E16: Mechanical Maintenance | F16: 1 | G16: No | H16: Nilesh | I16: Ujjwal | J16: Joined | K16: AM | L16: 6-10 Years | M16: 10 LPA | N16: 12 LPA | O16: 0.1 | P16: B.tech | Q16: Mumbai | S16: =B16 -> 45659 | T16: 2074 | U16: =COUNTIFS('Candidate Tracker'!D:D,'Position Tracker'!E16,'Candidate Tracker'!V:V, "<>Screening Pending") -> 7 | V16: =COUNTIFS('Candidate Tracker'!D:D,'Position Tracker'!E16,'Candidate Tracker'!V:V, "Screen Reject") -> 1 | W16: =U16-V16 -> 6 | X16: =IFERROR(IF(U16=0,0,IF(V16=0,"100%",W16/U16)),"") -> 0.85714286 | Y16: RL1
A17: 16 | B17: 45685 | C17: =IF(B17="","",NETWORKDAYS.INTL(B17,TODAY(),1,'HELPER(Dont Delete)'!A:A)) -> 234 | D17: =IF(J17="Open", IF(AND(C17>=0, C17<=30), "0-30", IF(AND(C17>=31, C17<=45), "31-45", IF(AND(C17>=46, C17<=60), "46-60", IF(AND(C17>=61, C17<=75), "61-75", IF(AND(C17>=76, C17<=90), "76-90", IF(AND(C17>=91, C17<=105), "91-105", IF(AND(C17>=106, C17<=120), "106-120", IF(C17>120, "120+", "")))))))),"") | E17: Electrical Maintenance AM | F17: 1 | G17: No | H17: Hem Patel, Nilesh Faldu | I17: Ujjwal | J17: Joined | K17: AM | L17: 6-10 Years | M17: 10 LPA | N17: 11 LPA | O17: 0.1 | P17: B.tech | Q17: Mumbai | S17: =B17 -> 45685 | T17: 2131 | U17: =COUNTIFS('Candidate Tracker'!D:D,'Position Tracker'!E17,'Candidate Tracker'!V:V, "<>Screening Pending") -> 20 | V17: =COUNTIFS('Candidate Tracker'!D:D,'Position Tracker'!E17,'Candidate Tracker'!V:V, "Screen Reject") -> 5 | W17: =U17-V17 -> 15 | X17: =IFERROR(IF(U17=0,0,IF(V17=0,"100%",W17/U17)),"") -> 0.75 | Y17: RL1 | AH17: 1/28/2025- Req date (Electrical Maintenance AM) Req 2131 | AK17: 45792 | AL17: =AK17-B17 -> 107
A18: 17 | B18: 45742 | C18: =IF(B18="","",NETWORKDAYS.INTL(B18,TODAY(),1,'HELPER(Dont Delete)'!A:A)) -> 193 | D18: =IF(J18="Open", IF(AND(C18>=0, C18<=30), "0-30", IF(AND(C18>=31, C18<=45), "31-45", IF(AND(C18>=46, C18<=60), "46-60", IF(AND(C18>=61, C18<=75), "61-75", IF(AND(C18>=76, C18<=90), "76-90", IF(AND(C18>=91, C18<=105), "91-105", IF(AND(C18>=106, C18<=120), "106-120", IF(C18>120, "120+", "")))))))),"") | E18: Manager Design | F18: 1 | G18: No | H18: Suresh P | I18: Ujjwal | J18: Joined | K18: Manager | L18: 6-15 Years | N18: 20 LPA | O18: 0.1 | P18: B.tech | Q18: Mumbai | S18: =B18 -> 45742 | T18: 2289 | U18: =COUNTIFS('Candidate Tracker'!D:D,'Position Tracker'!E18,'Candidate Tracker'!V:V, "<>Screening Pending") -> 21 | V18: =COUNTIFS('Candidate Tracker'!D:D,'Position Tracker'!E18,'Candidate Tracker'!V:V, "Screen Reject") -> 2 | W18: =U18-V18 -> 19 | X18: =IFERROR(IF(U18=0,0,IF(V18=0,"100%",W18/U18)),"") -> 0.9047619 | Y18: RL1
A19: 18 | B19: 45743 | C19: =IF(B19="","",NETWORKDAYS.INTL(B19,TODAY(),1,'HELPER(Dont Delete)'!A:A)) -> 192 | D19: =IF(J19="Open", IF(AND(C19>=0, C19<=30), "0-30", IF(AND(C19>=31, C19<=45), "31-45", IF(AND(C19>=46, C19<=60), "46-60", IF(AND(C19>=61, C19<=75), "61-75", IF(AND(C19>=76, C19<=90), "76-90", IF(AND(C19>=91, C19<=105), "91-105", IF(AND(C19>=106, C19<=120), "106-120", IF(C19>120, "120+", "")))))))),"") | E19: Manager QA | F19: 1 | G19: No | H19: Nilesh, P Suresh | I19: Ujjwal | J19: Joined | K19: Manager | L19: 10-15 Years | N19: 15 - 16LPA | O19: 0.1 | P19: B.tech | Q19: Mumbai | S19: =B19 -> 45743 | T19: 2297 | U19: =COUNTIFS('Candidate Tracker'!D:D,'Position Tracker'!E19,'Candidate Tracker'!V:V, "<>Screening Pending") -> 7 | V19: =COUNTIFS('Candidate Tracker'!D:D,'Position Tracker'!E19,'Candidate Tracker'!V:V, "Screen Reject") -> 2 | W19: =U19-V19 -> 5 | X19: =IFERROR(IF(U19=0,0,IF(V19=0,"100%",W19/U19)),"") -> 0.71428571 | Y19: RL1
A20: 19 | B20: 45743 | C20: =IF(B20="","",NETWORKDAYS.INTL(B20,TODAY(),1,'HELPER(Dont Delete)'!A:A)) -> 192 | D20: =IF(J20="Open", IF(AND(C20>=0, C20<=30), "0-30", IF(AND(C20>=31, C20<=45), "31-45", IF(AND(C20>=46, C20<=60), "46-60", IF(AND(C20>=61, C20<=75), "61-75", IF(AND(C20>=76, C20<=90), "76-90", IF(AND(C20>=91, C20<=105), "91-105", IF(AND(C20>=106, C20<=120), "106-120", IF(C20>120, "120+", "")))))))),"") | E20: AM Purchase | F20: 1 | G20: No | H20: Shiv | I20: Ujjwal | J20: Joined | K20: AM | L20: 6-10 Years | M20: 10LPA | N20: 11LPA | O20: 0.1 | P20: B.tech | Q20: Mumbai | S20: =B20 -> 45743 | T20: 2295 | U20: =COUNTIFS('Candidate Tracker'!D:D,'Position Tracker'!E20,'Candidate Tracker'!V:V, "<>Screening Pending") -> 9 | V20: =COUNTIFS('Candidate Tracker'!D:D,'Position Tracker'!E20,'Candidate Tracker'!V:V, "Screen Reject") -> 1 | W20: =U20-V20 -> 8 | X20: =IFERROR(IF(U20=0,0,IF(V20=0,"100%",W20/U20)),"") -> 0.88888889 | Y20: RL1
A21: 20 | B21: 45743 | C21: =IF(B21="","",NETWORKDAYS.INTL(B21,TODAY(),1,'HELPER(Dont Delete)'!A:A)) -> 192 | D21: =IF(J21="Open", IF(AND(C21>=0, C21<=30), "0-30", IF(AND(C21>=31, C21<=45), "31-45", IF(AND(C21>=46, C21<=60), "46-60", IF(AND(C21>=61, C21<=75), "61-75", IF(AND(C21>=76, C21<=90), "76-90", IF(AND(C21>=91, C21<=105), "91-105", IF(AND(C21>=106, C21<=120), "106-120", IF(C21>120, "120+", "")))))))),"") | E21: Manager mechanical Maintenance | F21: 1 | G21: No | H21: Nilesh | I21: Ujjwal | J21: Hold | K21: Manager | L21: 10-15 Years | N21: 15-16 LPA | O21: 0.1 | P21: B.tech | Q21: Mumbai | S21: =B21 -> 45743 | T21: 2296 | U21: =COUNTIFS('Candidate Tracker'!D:D,'Position Tracker'!E21,'Candidate Tracker'!V:V, "<>Screening Pending") -> 7 | V21: =COUNTIFS('Candidate Tracker'!D:D,'Position Tracker'!E21,'Candidate Tracker'!V:V, "Screen Reject") -> 6 | W21: =U21-V21 -> 1 | X21: =IFERROR(IF(U21=0,0,IF(V21=0,"100%",W21/U21)),"") -> 0.14285714 | Y21: RL1 | AC21: 45771
A22: 21 | B22: 45743 | C22: =IF(B22="","",NETWORKDAYS.INTL(B22,TODAY(),1,'HELPER(Dont Delete)'!A:A)) -> 192 | D22: =IF(J22="Open", IF(AND(C22>=0, C22<=30), "0-30", IF(AND(C22>=31, C22<=45), "31-45", IF(AND(C22>=46, C22<=60), "46-60", IF(AND(C22>=61, C22<=75), "61-75", IF(AND(C22>=76, C22<=90), "76-90", IF(AND(C22>=91, C22<=105), "91-105", IF(AND(C22>=106, C22<=120), "106-120", IF(C22>120, "120+", "")))))))),"") | E22: AGM Finance | F22: 1 | G22: No | H22: DB Singh | I22: Ujjwal | J22: Internally Closed | K22: AGM | N22: 35-40 | O22: 0.1 | P22: B.tech | Q22: Gurugram | S22: =B22 -> 45743 | T22: 2470 | U22: =COUNTIFS('Candidate Tracker'!D:D,'Position Tracker'!E22,'Candidate Tracker'!V:V, "<>Screening Pending") -> 3 | V22: =COUNTIFS('Candidate Tracker'!D:D,'Position Tracker'!E22,'Candidate Tracker'!V:V, "Screen Reject") -> 1 | W22: =U22-V22 -> 2 | X22: =IFERROR(IF(U22=0,0,IF(V22=0,"100%",W22/U22)),"") -> 0.66666667 | Y22: RL3 | AC22: 45833
A23: 22 | B23: 45743 | C23: =IF(B23="","",NETWORKDAYS.INTL(B23,TODAY(),1,'HELPER(Dont Delete)'!A:A)) -> 192 | D23: =IF(J23="Open", IF(AND(C23>=0, C23<=30), "0-30", IF(AND(C23>=31, C23<=45), "31-45", IF(AND(C23>=46, C23<=60), "46-60", IF(AND(C23>=61, C23<=75), "61-75", IF(AND(C23>=76, C23<=90), "76-90", IF(AND(C23>=91, C23<=105), "91-105", IF(AND(C23>=106, C23<=120), "106-120", IF(C23>120, "120+", "")))))))),"") | E23: DGM Sales | F23: 1 | G23: No | H23: Madhur Gupta | I23: Ujjwal | J23: Hold | K23: DGM | N23: 40-45 | O23: 0.1 | P23: B.tech | Q23: Gurugram | S23: =B23 -> 45743 | U23: =COUNTIFS('Candidate Tracker'!D:D,'Position Tracker'!E23,'Candidate Tracker'!V:V, "<>Screening Pending") -> 6 | V23: =COUNTIFS('Candidate Tracker'!D:D,'Position Tracker'!E23,'Candidate Tracker'!V:V, "Screen Reject") -> 4 | W23: =U23-V23 -> 2 | X23: =IFERROR(IF(U23=0,0,IF(V23=0,"100%",W23/U23)),"") -> 0.33333333 | Y23: RL3 | AC23: 45828
A24: 23 | B24: 45747 | C24: =IF(B24="","",NETWORKDAYS.INTL(B24,TODAY(),1,'HELPER(Dont Delete)'!A:A)) -> 190 | D24: =IF(J24="Open", IF(AND(C24>=0, C24<=30), "0-30", IF(AND(C24>=31, C24<=45), "31-45", IF(AND(C24>=46, C24<=60), "46-60", IF(AND(C24>=61, C24<=75), "61-75", IF(AND(C24>=76, C24<=90), "76-90", IF(AND(C24>=91, C24<=105), "91-105", IF(AND(C24>=106, C24<=120), "106-120", IF(C24>120, "120+", "")))))))),"") | E24: Project head (reopened as lead) | F24: 1 | G24: No | H24: Venka Shivakrishna, Suresh p | I24: Ujjwal | J24: Hold | K24: Sr Mgr | L24: 12-18 Years | M24: 20LPA | N24: 25 LPA | O24: 0.1 | P24: B.tech | Q24: Mumbai | S24: =B24 -> 45747 | T24: 2317 | U24: =COUNTIFS('Candidate Tracker'!D:D,'Position Tracker'!E24,'Candidate Tracker'!V:V, "<>Screening Pending") -> 0 | V24: =COUNTIFS('Candidate Tracker'!D:D,'Position Tracker'!E24,'Candidate Tracker'!V:V, "Screen Reject") -> 0 | W24: =U24-V24 -> 0 | X24: =IFERROR(IF(U24=0,0,IF(V24=0,"100%",W24/U24)),"") -> 0 | Y24: RL3 | AC24: 45825 | AH24: 3/31/2025 - Requirement is changed
A25: 24 | B25: 45747 | C25: =IF(B25="","",NETWORKDAYS.INTL(B25,TODAY(),1,'HELPER(Dont Delete)'!A:A)) -> 190 | D25: =IF(J25="Open", IF(AND(C25>=0, C25<=30), "0-30", IF(AND(C25>=31, C25<=45), "31-45", IF(AND(C25>=46, C25<=60), "46-60", IF(AND(C25>=61, C25<=75), "61-75", IF(AND(C25>=76, C25<=90), "76-90", IF(AND(C25>=91, C25<=105), "91-105", IF(AND(C25>=106, C25<=120), "106-120", IF(C25>120, "120+", "")))))))),"") | E25: Project Manager (reopned as cordinator) | F25: 1 | G25: No | H25: Venka Shivakrishna, Suresh p | I25: Ujjwal | J25: Hold | K25: AM | L25: 6-10 Years | N25: 11 LPA | O25: 0.1 | P25: B.tech | Q25: Mumbai | S25: =B25 -> 45747 | T25: 2318 | U25: =COUNTIFS('Candidate Tracker'!D:D,'Position Tracker'!E25,'Candidate Tracker'!V:V, "<>Screening Pending") -> 0 | V25: =COUNTIFS('Candidate Tracker'!D:D,'Position Tracker'!E25,'Candidate Tracker'!V:V, "Screen Reject") -> 0 | W25: =U25-V25 -> 0 | X25: =IFERROR(IF(U25=0,0,IF(V25=0,"100%",W25/U25)),"") -> 0 | Y25: RL1 | AC25: 45860 | AH25: 3/31/2025 - Requirement is changed
A26: 25 | B26: 45747 | C26: =IF(B26="","",NETWORKDAYS.INTL(B26,TODAY(),1,'HELPER(Dont Delete)'!A:A)) -> 190 | D26: =IF(J26="Open", IF(AND(C26>=0, C26<=30), "0-30", IF(AND(C26>=31, C26<=45), "31-45", IF(AND(C26>=46, C26<=60), "46-60", IF(AND(C26>=61, C26<=75), "61-75", IF(AND(C26>=76, C26<=90), "76-90", IF(AND(C26>=91, C26<=105), "91-105", IF(AND(C26>=106, C26<=120), "106-120", IF(C26>120, "120+", "")))))))),"") | E26: Manager Purchase | F26: 1 | G26: No | H26: SK Sharma | I26: Ujjwal | J26: Offer Stage | K26: Manager / SM | L26: 10-15 Years | M26: 15 LPA | N26: 21LPA | O26: 0.1 | P26: B.tech | Q26: Gurugram | S26: =B26 -> 45747 | T26: 2303 | U26: =COUNTIFS('Candidate Tracker'!D:D,'Position Tracker'!E26,'Candidate Tracker'!V:V, "<>Screening Pending") -> 23 | V26: =COUNTIFS('Candidate Tracker'!D:D,'Position Tracker'!E26,'Candidate Tracker'!V:V, "Screen Reject") -> 3 | W26: =U26-V26 -> 20 | X26: =IFERROR(IF(U26=0,0,IF(V26=0,"100%",W26/U26)),"") -> 0.86956522 | Y26: RL1
A27: 26 | B27: 45747 | C27: =IF(B27="","",NETWORKDAYS.INTL(B27,TODAY(),1,'HELPER(Dont Delete)'!A:A)) -> 190 | D27: =IF(J27="Open", IF(AND(C27>=0, C27<=30), "0-30", IF(AND(C27>=31, C27<=45), "31-45", IF(AND(C27>=46, C27<=60), "46-60", IF(AND(C27>=61, C27<=75), "61-75", IF(AND(C27>=76, C27<=90), "76-90", IF(AND(C27>=91, C27<=105), "91-105", IF(AND(C27>=106, C27<=120), "106-120", IF(C27>120, "120+", "")))))))),"") | E27: Manager PPC | F27: 1 | G27: No | H27: Nilesh, P Suresh | I27: Ujjwal | J27: Joined | K27: Manager | L27: 10-15 Years | M27: 15 - 16 | N27: 17 - 22 | O27: 0.1 | P27: B.tech | Q27: Mumbai | S27: =B27 -> 45747 | T27: 2643 | U27: =COUNTIFS('Candidate Tracker'!D:D,'Position Tracker'!E27,'Candidate Tracker'!V:V, "<>Screening Pending") -> 8 | V27: =COUNTIFS('Candidate Tracker'!D:D,'Position Tracker'!E27,'Candidate Tracker'!V:V, "Screen Reject") -> 2 | W27: =U27-V27 -> 6 | X27: =IFERROR(IF(U27=0,0,IF(V27=0,"100%",W27/U27)),"") -> 0.75 | Y27: RL1 | AH27: 2316
A28: 31 | B28: 45848 | C28: =IF(B28="","",NETWORKDAYS.INTL(B28,TODAY(),1,'HELPER(Dont Delete)'!A:A)) -> 117 | D28: =IF(J28="Open", IF(AND(C28>=0, C28<=30), "0-30", IF(AND(C28>=31, C28<=45), "31-45", IF(AND(C28>=46, C28<=60), "46-60", IF(AND(C28>=61, C28<=75), "61-75", IF(AND(C28>=76, C28<=90), "76-90", IF(AND(C28>=91, C28<=105), "91-105", IF(AND(C28>=106, C28<=120), "106-120", IF(C28>120, "120+", "")))))))),"") | E28: Quality Assurance (QA) Coordinator | F28: 1 | G28: No | H28: Manoj Bhutani & P Suresh | I28: Ujjwal | J28: Hold | K28: Engineer/ Assistant Engineer | L28: 1-3 Years | M28: 5.5 LPA | N28: 7.6 LPA | O28: 0.1 | P28: Diploma / B.Tech in Mechanical / Industrial / Production / Metallurgy Engineering | Q28: Mumbai | S28: =B28 -> 45848 | T28: 2663 | U28: =COUNTIFS('Candidate Tracker'!D:D,'Position Tracker'!E32,'Candidate Tracker'!V:V, "<>Screening Pending") -> 27 | V28: =COUNTIFS('Candidate Tracker'!D:D,'Position Tracker'!E32,'Candidate Tracker'!V:V, "Screen Reject") -> 7 | W28: =U28-V28 -> 20 | X28: =IFERROR(IF(U28=0,0,IF(V28=0,"100%",W28/U28)),"") -> 0.74074074 | Y28: RL1 | AC28: 45898
A29: 28 | B29: 45750 | C29: =IF(B29="","",NETWORKDAYS.INTL(B29,TODAY(),1,'HELPER(Dont Delete)'!A:A)) -> 187 | D29: =IF(J29="Open", IF(AND(C29>=0, C29<=30), "0-30", IF(AND(C29>=31, C29<=45), "31-45", IF(AND(C29>=46, C29<=60), "46-60", IF(AND(C29>=61, C29<=75), "61-75", IF(AND(C29>=76, C29<=90), "76-90", IF(AND(C29>=91, C29<=105), "91-105", IF(AND(C29>=106, C29<=120), "106-120", IF(C29>120, "120+", "")))))))),"") | E29: Executive- Design | F29: 1 | G29: No | H29: Neeraj | I29: Ujjwal | J29: Joined | K29: Executive | L29: 3-5 Years | N29: 8.5 | O29: 0.1 | P29: B.tech | Q29: Mumbai | S29: =B29 -> 45750 | T29: 2321 | U29: =COUNTIFS('Candidate Tracker'!D:D,'Position Tracker'!E29,'Candidate Tracker'!V:V, "<>Screening Pending") -> 12 | V29: =COUNTIFS('Candidate Tracker'!D:D,'Position Tracker'!E29,'Candidate Tracker'!V:V, "Screen Reject") -> 1 | W29: =U29-V29 -> 11 | X29: =IFERROR(IF(U29=0,0,IF(V29=0,"100%",W29/U29)),"") -> 0.91666667 | Y29: RL1
A30: 29 | B30: 45762 | C30: =IF(B30="","",NETWORKDAYS.INTL(B30,TODAY(),1,'HELPER(Dont Delete)'!A:A)) -> 179 | D30: =IF(J30="Open", IF(AND(C30>=0, C30<=30), "0-30", IF(AND(C30>=31, C30<=45), "31-45", IF(AND(C30>=46, C30<=60), "46-60", IF(AND(C30>=61, C30<=75), "61-75", IF(AND(C30>=76, C30<=90), "76-90", IF(AND(C30>=91, C30<=105), "91-105", IF(AND(C30>=106, C30<=120), "106-120", IF(C30>120, "120+", "")))))))),"") | E30: Quality Engineer | F30: 2 | G30: No | H30: Suresh P | I30: Ujjwal | J30: Joined | K30: Executive | L30: 3-5 Years | N30: 8LPA | O30: 0.1 | P30: B.tech | Q30: Mumbai | S30: =B30 -> 45762 | T30: 2208, 2348 | U30: =COUNTIFS('Candidate Tracker'!D:D,'Position Tracker'!E30,'Candidate Tracker'!V:V, "<>Screening Pending") -> 0 | V30: =COUNTIFS('Candidate Tracker'!D:D,'Position Tracker'!E30,'Candidate Tracker'!V:V, "Screen Reject") -> 0 | W30: =U30-V30 -> 0 | X30: =IFERROR(IF(U30=0,0,IF(V30=0,"100%",W30/U30)),"") -> 0 | Y30: RL1
A31: 30 | B31: 45848 | C31: =IF(B31="","",NETWORKDAYS.INTL(B31,TODAY(),1,'HELPER(Dont Delete)'!A:A)) -> 117 | D31: =IF(J31="Open", IF(AND(C31>=0, C31<=30), "0-30", IF(AND(C31>=31, C31<=45), "31-45", IF(AND(C31>=46, C31<=60), "46-60", IF(AND(C31>=61, C31<=75), "61-75", IF(AND(C31>=76, C31<=90), "76-90", IF(AND(C31>=91, C31<=105), "91-105", IF(AND(C31>=106, C31<=120), "106-120", IF(C31>120, "120+", "")))))))),"") | E31: Quality Assurance (QA) Lead | F31: 1 | G31: No | H31: Manoj Bhutani & P Suresh | I31: Ujjwal | J31: Offer Stage | K31: Manager/ Associate Manager | L31: 8+ Years | M31: 12 LPA | N31: 18.4 LPA | O31: 0.1 | P31: B.Tech / Diploma in Mechanical / Production / Metallurgy / Materials Engineering | Q31: Mumbai | S31: =B31 -> 45848 | T31: 2664 | U31: =COUNTIFS('Candidate Tracker'!D:D,'Position Tracker'!E31,'Candidate Tracker'!V:V, "<>Screening Pending") -> 7 | V31: =COUNTIFS('Candidate Tracker'!D:D,'Position Tracker'!E31,'Candidate Tracker'!V:V, "Screen Reject") -> 3 | W31: =U31-V31 -> 4 | X31: =IFERROR(IF(U31=0,0,IF(V31=0,"100%",W31/U31)),"") -> 0.57142857 | Y31: RL1
A32: 32 | B32: 45848 | C32: =IF(B32="","",NETWORKDAYS.INTL(B32,TODAY(),1,'HELPER(Dont Delete)'!A:A)) -> 117 | D32: =IF(J32="Open", IF(AND(C32>=0, C32<=30), "0-30", IF(AND(C32>=31, C32<=45), "31-45", IF(AND(C32>=46, C32<=60), "46-60", IF(AND(C32>=61, C32<=75), "61-75", IF(AND(C32>=76, C32<=90), "76-90", IF(AND(C32>=91, C32<=105), "91-105", IF(AND(C32>=106, C32<=120), "106-120", IF(C32>120, "120+", "")))))))),"") | E32: Quality Control (QC) Coordinator | F32: 6 | G32: No | H32: Manoj Bhutani & P Suresh | I32: Ujjwal | J32: Offer Stage | K32: Engineer/ Assistant Engineer | L32: 1-4 Years | M32: 5.5 LPA | N32: 7.6 LPA | O32: 0.1 | P32: Diploma or B.Tech in Mechanical / Welding / Fabrication Engineering | Q32: Mumbai | S32: =B32 -> 45848 | T32: 2689 | U32: =COUNTIFS('Candidate Tracker'!D:D,'Position Tracker'!E33,'Candidate Tracker'!V:V, "<>Screening Pending") -> 18 | V32: =COUNTIFS('Candidate Tracker'!D:D,'Position Tracker'!E33,'Candidate Tracker'!V:V, "Screen Reject") -> 5 | W32: =U32-V32 -> 13 | X32: =IFERROR(IF(U32=0,0,IF(V32=0,"100%",W32/U32)),"") -> 0.72222222 | Y32: RL1
A33: 33 | B33: 45910 | C33: =IF(B33="","",NETWORKDAYS.INTL(B33,TODAY(),1,'HELPER(Dont Delete)'!A:A)) -> 73 | D33: =IF(J33="Open", IF(AND(C33>=0, C33<=30), "0-30", IF(AND(C33>=31, C33<=45), "31-45", IF(AND(C33>=46, C33<=60), "46-60", IF(AND(C33>=61, C33<=75), "61-75", IF(AND(C33>=76, C33<=90), "76-90", IF(AND(C33>=91, C33<=105), "91-105", IF(AND(C33>=106, C33<=120), "106-120", IF(C33>120, "120+", "")))))))),"") | E33: Machining & Beam Welding | F33: 3 | G33: No | H33: P Suresh & Navin Lalwani | I33: Ujjwal | J33: 1Hold/2joined | K33: Associate Manager/ Executive/ Engineer | L33: 5+ Years | M33: 7.6 LPA | N33: 12 LPA | O33: 0.1 | P33: Diploma or B.Tech in Mechanical, Production, or Fabrication Engineering | Q33: Mumbai | S33: =B33 -> 45910 | T33: 2661 | U33: =COUNTIFS('Candidate Tracker'!D:D,'Position Tracker'!E34,'Candidate Tracker'!V:V, "<>Screening Pending") -> 18 | V33: =COUNTIFS('Candidate Tracker'!D:D,'Position Tracker'!E34,'Candidate Tracker'!V:V, "Screen Reject") -> 5 | W33: =U33-V33 -> 13 | X33: =IFERROR(IF(U33=0,0,IF(V33=0,"100%",W33/U33)),"") -> 0.72222222 | Y33: RL1 | AC33: 45923 | AH33: 10July2025 - Req date chenged coz of bridge fabrication exp
A34: 35 | B34: 45848 | C34: =IF(B34="","",NETWORKDAYS.INTL(B34,TODAY(),1,'HELPER(Dont Delete)'!A:A)) -> 117 | D34: =IF(J34="Open", IF(AND(C34>=0, C34<=30), "0-30", IF(AND(C34>=31, C34<=45), "31-45", IF(AND(C34>=46, C34<=60), "46-60", IF(AND(C34>=61, C34<=75), "61-75", IF(AND(C34>=76, C34<=90), "76-90", IF(AND(C34>=91, C34<=105), "91-105", IF(AND(C34>=106, C34<=120), "106-120", IF(C34>120, "120+", "")))))))),"") | E34: Shot Blasting & Painting | F34: 3 | G34: No | H34: P Suresh & Navin Lalwani | I34: Ujjwal | J34: Offer stage | K34: Associate Manager/ Executive/ Engineer | L34: 5+ Years | M34: 7.6 LPA | N34: 12 LPA | O34: 0.1 | P34: ITI Painter or Diploma in Mechanical, Fabrication, or Paint Technology | Q34: Mumbai | S34: =B34 -> 45848 | T34: 2478/2791 | U34: =COUNTIFS('Candidate Tracker'!D:D,'Position Tracker'!E36,'Candidate Tracker'!V:V, "<>Screening Pending") -> 1 | V34: =COUNTIFS('Candidate Tracker'!D:D,'Position Tracker'!E36,'Candidate Tracker'!V:V, "Screen Reject") -> 0 | W34: =U34-V34 -> 1 | X34: =IFERROR(IF(U34=0,0,IF(V34=0,"100%",W34/U34)),"") -> 100% | Y34: RL1
A35: 34 | B35: 45848 | C35: =IF(B35="","",NETWORKDAYS.INTL(B35,TODAY(),1,'HELPER(Dont Delete)'!A:A)) -> 117 | D35: =IF(J35="Open", IF(AND(C35>=0, C35<=30), "0-30", IF(AND(C35>=31, C35<=45), "31-45", IF(AND(C35>=46, C35<=60), "46-60", IF(AND(C35>=61, C35<=75), "61-75", IF(AND(C35>=76, C35<=90), "76-90", IF(AND(C35>=91, C35<=105), "91-105", IF(AND(C35>=106, C35<=120), "106-120", IF(C35>120, "120+", "")))))))),"") | E35: Manual Welding | F35: 3 | G35: No | H35: P Suresh & Navin Lalwani | I35: Ujjwal | J35: 1Hold/2joined | K35: Associate Manager/ Executive/ Engineer | L35: 6+ Years | M35: 7.6 LPA | N35: 12 LPA | O35: 0.1 | P35: Diploma in Welding, Mechanical, or Fabrication Engineering (B.Tech. preferred) | Q35: Mumbai | S35: =B35 -> 45848 | T35: 2662 | U35: =COUNTIFS('Candidate Tracker'!D:D,'Position Tracker'!E35,'Candidate Tracker'!V:V, "<>Screening Pending") -> 8 | V35: =COUNTIFS('Candidate Tracker'!D:D,'Position Tracker'!E35,'Candidate Tracker'!V:V, "Screen Reject") -> 2 | W35: =U35-V35 -> 6 | X35: =IFERROR(IF(U35=0,0,IF(V35=0,"100%",W35/U35)),"") -> 0.75 | Y35: RL1 | AC35: 45923
A36: 36 | B36: 45848 | C36: =IF(B36="","",NETWORKDAYS.INTL(B36,TODAY(),1,'HELPER(Dont Delete)'!A:A)) -> 117 | D36: =IF(J36="Open", IF(AND(C36>=0, C36<=30), "0-30", IF(AND(C36>=31, C36<=45), "31-45", IF(AND(C36>=46, C36<=60), "46-60", IF(AND(C36>=61, C36<=75), "61-75", IF(AND(C36>=76, C36<=90), "76-90", IF(AND(C36>=91, C36<=105), "91-105", IF(AND(C36>=106, C36<=120), "106-120", IF(C36>120, "120+", "")))))))),"") | E36: Detailer | F36: 1 | G36: No | H36: Navin Lalwani & Niraj Yadav | I36: Ujjwal | J36: Internally Closed | K36: Engineer/ Assistant Engineer | L36: 3-7 Years | M36: 5.5 LPA | N36: 7.6 LPA | O36: 0.1 | P36: Diploma or B.Tech. in Mechanical/ Civil/ Structural/ Production Engineering | Q36: Mumbai | S36: =B36 -> 45848 | T36: 2686 | U36: =COUNTIFS('Candidate Tracker'!D:D,'Position Tracker'!E37,'Candidate Tracker'!V:V, "<>Screening Pending") -> 5 | V36: =COUNTIFS('Candidate Tracker'!D:D,'Position Tracker'!E37,'Candidate Tracker'!V:V, "Screen Reject") -> 1 | W36: =U36-V36 -> 4 | X36: =IFERROR(IF(U36=0,0,IF(V36=0,"100%",W36/U36)),"") -> 0.8 | Y36: RL1 | AC36: 45881
A37: 37 | B37: 45848 | C37: =IF(B37="","",NETWORKDAYS.INTL(B37,TODAY(),1,'HELPER(Dont Delete)'!A:A)) -> 117 | D37: =IF(J37="Open", IF(AND(C37>=0, C37<=30), "0-30", IF(AND(C37>=31, C37<=45), "31-45", IF(AND(C37>=46, C37<=60), "46-60", IF(AND(C37>=61, C37<=75), "61-75", IF(AND(C37>=76, C37<=90), "76-90", IF(AND(C37>=91, C37<=105), "91-105", IF(AND(C37>=106, C37<=120), "106-120", IF(C37>120, "120+", "")))))))),"") | E37: Welding Expert | F37: 1 | G37: No | H37: P Suresh & Navin Lalwani | I37: Ujjwal | J37: Hold | K37: Senior Manager/ Manager | L37: 12+ Years | M37: 18.4 LPA | N37: 24 LPA | O37: 0.1 | P37: B.Tech / M.Tech in Metallurgy or Mechanical Engineering | Q37: Mumbai | S37: =B37 -> 45848 | T37: 2666 | U37: =COUNTIFS('Candidate Tracker'!D:D,'Position Tracker'!E38,'Candidate Tracker'!V:V, "<>Screening Pending") -> 0 | V37: =COUNTIFS('Candidate Tracker'!D:D,'Position Tracker'!E38,'Candidate Tracker'!V:V, "Screen Reject") -> 0 | W37: =U37-V37 -> 0 | X37: =IFERROR(IF(U37=0,0,IF(V37=0,"100%",W37/U37)),"") -> 0 | Y37: RL2 | AC37: 45880
A38: 38 | B38: 45859 | C38: =IF(B38="","",NETWORKDAYS.INTL(B38,TODAY(),1,'HELPER(Dont Delete)'!A:A)) -> 110 | D38: =IF(J38="Open", IF(AND(C38>=0, C38<=30), "0-30", IF(AND(C38>=31, C38<=45), "31-45", IF(AND(C38>=46, C38<=60), "46-60", IF(AND(C38>=61, C38<=75), "61-75", IF(AND(C38>=76, C38<=90), "76-90", IF(AND(C38>=91, C38<=105), "91-105", IF(AND(C38>=106, C38<=120), "106-120", IF(C38>120, "120+", "")))))))),"") | E38: Plant Project Lead | F38: 1 | G38: No | H38: P Suresh & Navin Lalwani | I38: Ujjwal | J38: Cancelled | K38: Manager / SM | L38: 15-25 Years | M38: 24LPA | N38: 33LPA | O38: 0.1 | P38: B.tech | Q38: Mumbai | S38: =B38 -> 45859 | U38: =COUNTIFS('Candidate Tracker'!D:D,'Position Tracker'!E39,'Candidate Tracker'!V:V, "<>Screening Pending") -> 9 | V38: =COUNTIFS('Candidate Tracker'!D:D,'Position Tracker'!E39,'Candidate Tracker'!V:V, "Screen Reject") -> 4 | W38: =U38-V38 -> 5 | X38: =IFERROR(IF(U38=0,0,IF(V38=0,"100%",W38/U38)),"") -> 0.55555556 | Y38: RL2 | AC38: 45908
A39: 39 | B39: 45758 | C39: =IF(B39="","",NETWORKDAYS.INTL(B39,TODAY(),1,'HELPER(Dont Delete)'!A:A)) -> 181 | D39: =IF(J39="Open", IF(AND(C39>=0, C39<=30), "0-30", IF(AND(C39>=31, C39<=45), "31-45", IF(AND(C39>=46, C39<=60), "46-60", IF(AND(C39>=61, C39<=75), "61-75", IF(AND(C39>=76, C39<=90), "76-90", IF(AND(C39>=91, C39<=105), "91-105", IF(AND(C39>=106, C39<=120), "106-120", IF(C39>120, "120+", "")))))))),"") | E39: Plant Head (New) | F39: 1 | G39: No | H39: SK Goyal | I39: Ujjwal | J39: Internally Closed | K39: DGM | O39: 0.1 | P39: B.tech | Q39: Mumbai | S39: =B39 -> 45758 | U39: =COUNTIFS('Candidate Tracker'!D:D,'Position Tracker'!E28,'Candidate Tracker'!V:V, "<>Screening Pending") -> 15 | V39: =COUNTIFS('Candidate Tracker'!D:D,'Position Tracker'!E28,'Candidate Tracker'!V:V, "Screen Reject") -> 5 | W39: =U39-V39 -> 10 | X39: =IFERROR(IF(U39=0,0,IF(V39=0,"100%",W39/U39)),"") -> 0.66666667 | Y39: RL3 | AC39: 45871
A40: 40 | B40: 45860 | C40: =IF(B40="","",NETWORKDAYS.INTL(B40,TODAY(),1,'HELPER(Dont Delete)'!A:A)) -> 109 | D40: =IF(J40="Open", IF(AND(C40>=0, C40<=30), "0-30", IF(AND(C40>=31, C40<=45), "31-45", IF(AND(C40>=46, C40<=60), "46-60", IF(AND(C40>=61, C40<=75), "61-75", IF(AND(C40>=76, C40<=90), "76-90", IF(AND(C40>=91, C40<=105), "91-105", IF(AND(C40>=106, C40<=120), "106-120", IF(C40>120, "120+", "")))))))),"") | E40: Sales (new) | F40: 1 | G40: No | H40: Aman Vashishtha | I40: Ujjwal | J40: Hold | K40: DGM | L40: 15-20 Years | N40: 45 LPA | O40: 0.1 | P40: B.Tech & MBA | Q40: Gurugram | S40: =B40 -> 45860 | U40: =COUNTIFS('Candidate Tracker'!D:D,'Position Tracker'!E40,'Candidate Tracker'!V:V, "<>Screening Pending") -> 0 | V40: =COUNTIFS('Candidate Tracker'!D:D,'Position Tracker'!E40,'Candidate Tracker'!V:V, "Screen Reject") -> 0 | W40: =U40-V40 -> 0 | X40: =IFERROR(IF(U40=0,0,IF(V40=0,"100%",W40/U40)),"") -> 0 | Y40: RL3
...

Sheet Candidate Tracker
A1: 1 | B1: 45219 | C1: 45219 | D1: KAM | E1: Steelway | F1: Ujjwal Singh | G1: Parsi Sainaresh Gupta | H1: 7004306497 | I1: parsisainaresh700@gmail.com | J1: Key Account Manager | K1: 5 | L1: 3 | M1: Mjunction Services limited | N1: LWD: 7/12/2023 | O1: 8.5 | P1: As per market | Q1: B.Tech | R1: Pune | T1: Steel Industries Exp | U1: Preeti Koli | V1: L1 Reject | X1: 45295 | Y1: 45296 | Z1: Reject | AP1: =IF(OR(X1="",C1=""),"",NETWORKDAYS.INTL(C1,X1,1,'HELPER(Dont Delete)'!A:A)) -> 51 | AQ1: =IF(OR(X1="",Y1=""),"",NETWORKDAYS.INTL(X1,Y1,1,'HELPER(Dont Delete)'!A:A)) -> 2 | AR1: =IF(OR(Y1="",AA1=""),"",NETWORKDAYS.INTL(Y1,AA1,1,'HELPER(Dont Delete)'!A:A))
A2: 2 | B2: 45219 | C2: 45229 | D2: KAM | E2: Steelway | F2: Ujjwal Singh | G2: Kumaran S | H2: 9600624431 | I2: skumaran106@gmail.com | K2: 8 | L2: 8 | M2: Saint-Gobain India Private Limited | N2: Immediate | O2: 10.85 | P2: 12.5 | Q2: B.E Mechanical | R2: Chennai | U2: Prakash Mishra | V2: Candidate Backout | X2: 45295 | AP2: =IF(OR(X2="",C2=""),"",NETWORKDAYS.INTL(C2,X2,1,'HELPER(Dont Delete)'!A:A)) -> 46 | AQ2: =IF(OR(X2="",Y2=""),"",NETWORKDAYS.INTL(X2,Y2,1,'HELPER(Dont Delete)'!A:A)) | AR2: =IF(OR(Y2="",AA2=""),"",NETWORKDAYS.INTL(Y2,AA2,1,'HELPER(Dont Delete)'!A:A))
A3: 3 | B3: 45219 | C3: 45229 | D3: KAM | E3: Steelway | F3: Ujjwal Singh | G3: Abhijot Mittal | H3: 9501614374 | I3: abhijotmittal@gmail.com | K3: 5 | L3: 5 | M3: Steel Strips Wheels Limited | N3: 60 | O3: 15 | P3: 25% Hike | Q3: B.Tech | R3: Pune | U3: Prakash Mishra | V3: Candidate Backout | X3: 45295 | AP3: =IF(OR(X3="",C3=""),"",NETWORKDAYS.INTL(C3,X3,1,'HELPER(Dont Delete)'!A:A)) -> 46 | AQ3: =IF(OR(X3="",Y3=""),"",NETWORKDAYS.INTL(X3,Y3,1,'HELPER(Dont Delete)'!A:A)) | AR3: =IF(OR(Y3="",AA3=""),"",NETWORKDAYS.INTL(Y3,AA3,1,'HELPER(Dont Delete)'!A:A))
A4: 4 | B4: 45219 | C4: 45236 | D4: KAM | E4: Steelway | F4: Ujjwal Singh | G4: Kabilan Ramdoss | H4: 9600097730 | I4: kapilan15@gmail.com | J4: KAM | K4: 6 | L4: 5 | M4: Baliga Lighting Equipments | N4: 60 | O4: 6.5 | P4: 8 | Q4: B.E.(Mechanical) | R4: Chennai | T4: Product sales, Key account management, handling Export and domestic sales | U4: Trupti Harichandan | V4: L1 Reject | X4: 45295 | Y4: 45296 | Z4: Reject | AP4: =IF(OR(X4="",C4=""),"",NETWORKDAYS.INTL(C4,X4,1,'HELPER(Dont Delete)'!A:A)) -> 41 | AQ4: =IF(OR(X4="",Y4=""),"",NETWORKDAYS.INTL(X4,Y4,1,'HELPER(Dont Delete)'!A:A)) -> 2 | AR4: =IF(OR(Y4="",AA4=""),"",NETWORKDAYS.INTL(Y4,AA4,1,'HELPER(Dont Delete)'!A:A))
A5: 5 | B5: 45275 | C5: 45276 | D5: Logistics - Manager/Sr Manager | E5: Steelway | F5: Ujjwal Singh | G5: ARYAN BHARDWAJ | H5: 9711477470 | I5: aryan.sharma230@gmail.com | J5: 9 yrs exp in logistic | K5: 9 | L5: 9 | M5: TATA Steel | N5: 90 | O5: 14 | P5: 20 | Q5: B.Tech +Mba | R5: New delhi | U5: Preeti Koli | V5: L1 Reject | X5: 45294 | Y5: 45307 | Z5: Reject | AP5: =IF(OR(X5="",C5=""),"",NETWORKDAYS.INTL(C5,X5,1,'HELPER(Dont Delete)'!A:A)) -> 11 | AQ5: =IF(OR(X5="",Y5=""),"",NETWORKDAYS.INTL(X5,Y5,1,'HELPER(Dont Delete)'!A:A)) -> 9 | AR5: =IF(OR(Y5="",AA5=""),"",NETWORKDAYS.INTL(Y5,AA5,1,'HELPER(Dont Delete)'!A:A))
A6: 6 | B6: 45275 | C6: 45276 | D6: Logistics - Manager/Sr Manager | E6: Steelway | F6: Ujjwal Singh | G6: PURUSOTTAM BEHERA | H6: 8126580486 | I6: purushottam.behera1986@gmail.com | J6: 15 yrs exp in logistic | K6: 15 | L6: 15 | M6: Tata Steel Downstream Products Ltd | N6: LWD: 14-Feb-23 | O6: 9.5 | P6: 25% Hike | Q6: B.Tech | R6: A.P-Tada | U6: Preeti Koli | V6: L1 Reject | X6: 45294 | Y6: 45295 | Z6: Reject | AP6: =IF(OR(X6="",C6=""),"",NETWORKDAYS.INTL(C6,X6,1,'HELPER(Dont Delete)'!A:A)) -> 11 | AQ6: =IF(OR(X6="",Y6=""),"",NETWORKDAYS.INTL(X6,Y6,1,'HELPER(Dont Delete)'!A:A)) -> 2 | AR6: =IF(OR(Y6="",AA6=""),"",NETWORKDAYS.INTL(Y6,AA6,1,'HELPER(Dont Delete)'!A:A))
A7: 7 | B7: 45275 | C7: 45276 | D7: Logistics - Manager/Sr Manager | E7: Steelway | F7: Ujjwal Singh | G7: Amit Chaudhari | H7: 9891020260 | I7: amitaustown@gmail.com | J7: 11 yrs in Lugistic, Supply chain | K7: 11 | L7: 11 | M7: Nippon Express India Pvt. Ltd. | N7: 60 | O7: 11 | P7: 25% Hike | Q7: B.Com + MBA | R7: Gurgaon | U7: Preeti Koli | V7: L1 Reject | X7: 45294 | Y7: 45307 | Z7: Reject | AP7: =IF(OR(X7="",C7=""),"",NETWORKDAYS.INTL(C7,X7,1,'HELPER(Dont Delete)'!A:A)) -> 11 | AQ7: =IF(OR(X7="",Y7=""),"",NETWORKDAYS.INTL(X7,Y7,1,'HELPER(Dont Delete)'!A:A)) -> 9 | AR7: =IF(OR(Y7="",AA7=""),"",NETWORKDAYS.INTL(Y7,AA7,1,'HELPER(Dont Delete)'!A:A))
A8: 8 | B8: 45189 | C8: 45276 | D8: Fabrication | E8: Steelway | F8: Ujjwal Singh | G8: Niteen kumar Belkoniker | H8: 9036897409 | I8: niteen.b17@gmail.com | K8: 18 | L8: 18 | M8: Tata Projects | N8: 60 | O8: 17.5 | P8: 30% Hike | Q8: B.tech | R8: Mumbai | U8: Ajay Singh | V8: L1 Reject | X8: 45405 | Y8: 45406 | Z8: Reject | AP8: =IF(OR(X8="",C8=""),"",NETWORKDAYS.INTL(C8,X8,1,'HELPER(Dont Delete)'!A:A)) -> 76 | AQ8: =IF(OR(X8="",Y8=""),"",NETWORKDAYS.INTL(X8,Y8,1,'HELPER(Dont Delete)'!A:A)) -> 2 | AR8: =IF(OR(Y8="",AA8=""),"",NETWORKDAYS.INTL(Y8,AA8,1,'HELPER(Dont Delete)'!A:A))
A9: 9 | B9: 45219 | C9: 45301 | D9: KAM | E9: Steelway | F9: Ujjwal Singh | G9: Karthikeyan Dhanpal | H9: 7306467140 | I9: dhanpalkarthikeyan@gmail.com | J9: 8 yrs exp in sales, industry- metal | K9: 10 | L9: 8 | M9: Samrat Irons | N9: 30 | O9: 7 | P9: 30% Hike | Q9: B.Sc | R9: Telengana | U9: Preeti Koli | V9: Position on Hold | AP9: =IF(OR(X9="",C9=""),"",NETWORKDAYS.INTL(C9,X9,1,'HELPER(Dont Delete)'!A:A)) | AQ9: =IF(OR(X9="",Y9=""),"",NETWORKDAYS.INTL(X9,Y9,1,'HELPER(Dont Delete)'!A:A)) | AR9: =IF(OR(Y9="",AA9=""),"",NETWORKDAYS.INTL(Y9,AA9,1,'HELPER(Dont Delete)'!A:A))
A10: 10 | B10: 45219 | C10: 45301 | D10: KAM | E10: Steelway | F10: Ujjwal Singh | G10: Praveen Arokiaraj | H10: 9600696769 | I10: praveenarokiaraj1610@gmail.com | J10: 8 yrs exp in sales, 6 yrs in steel industry | K10: 8 | L10: 8 | M10: Tata BlueScope Steel Private Ltd | N10: 45 | O10: 8.5 | P10: 30% Hike | Negotiable | Q10: B.Tech | R10: Chennai | U10: Preeti Koli | V10: Position on Hold | AP10: =IF(OR(X10="",C10=""),"",NETWORKDAYS.INTL(C10,X10,1,'HELPER(Dont Delete)'!A:A)) | AQ10: =IF(OR(X10="",Y10=""),"",NETWORKDAYS.INTL(X10,Y10,1,'HELPER(Dont Delete)'!A:A)) | AR10: =IF(OR(Y10="",AA10=""),"",NETWORKDAYS.INTL(Y10,AA10,1,'HELPER(Dont Delete)'!A:A))
A11: 11 | B11: 45275 | C11: 45310 | D11: Logistics - Manager/Sr Manager | E11: Steelway | F11: Ujjwal Singh | G11: Chandra Shekhar Vishwakarma | H11: 9968231511 | I11: chandrashekharvishwakarma@yahoo.co.in | J11: 14 yrs exp in Logistic, inventory management, transportation, | K11: 14 | L11: 14 | M11: Derwiser India | N11: 30 | O11: 11.7 | P11: 25% Hike | Q11: B.Sc + MBA | R11: Noida | U11: Preeti Koli | V11: Screen Reject | X11: 45316 | AP11: =IF(OR(X11="",C11=""),"",NETWORKDAYS.INTL(C11,X11,1,'HELPER(Dont Delete)'!A:A)) -> 4 | AQ11: =IF(OR(X11="",Y11=""),"",NETWORKDAYS.INTL(X11,Y11,1,'HELPER(Dont Delete)'!A:A)) | AR11: =IF(OR(Y11="",AA11=""),"",NETWORKDAYS.INTL(Y11,AA11,1,'HELPER(Dont Delete)'!A:A))
A12: 12 | B12: 45275 | C12: 45310 | D12: Logistics - Manager/Sr Manager | E12: Steelway | F12: Ujjwal Singh | G12: Gaurav Gupta | H12: 8427060151 | I12: gaurav.guptascm@gmail.com | J12: 15 Yrs exp in logistic, inventory management,transportion, shipments | K12: 15 | L12: 15 | M12: Stylam Industries | N12: 60 | O12: 15 | P12: 18 | Q12: B.Sc + MBA | R12: Chandigarh | U12: Preeti Koli | V12: L1 Reject | X12: 45316 | AP12: =IF(OR(X12="",C12=""),"",NETWORKDAYS.INTL(C12,X12,1,'HELPER(Dont Delete)'!A:A)) -> 4 | AQ12: =IF(OR(X12="",Y12=""),"",NETWORKDAYS.INTL(X12,Y12,1,'HELPER(Dont Delete)'!A:A)) | AR12: =IF(OR(Y12="",AA12=""),"",NETWORKDAYS.INTL(Y12,AA12,1,'HELPER(Dont Delete)'!A:A))
A13: 13 | B13: 45324 | C13: 45327 | D13: KAM (Gurgaon) | E13: Steelway | F13: Ujjwal Singh | G13: Keshav Kaushik | H13: 9999254190 | K13: 8 | L13: 5 | M13: Nippon Steel Pipe India | N13: 60 | Q13: B.Tech | R13: Faridabad | U13: Preeti Koli | V13: Candidate Backout | X13: 45330 | Z13: 45342 | AP13: =IF(OR(X13="",C13=""),"",NETWORKDAYS.INTL(C13,X13,1,'HELPER(Dont Delete)'!A:A)) -> 4 | AQ13: =IF(OR(X13="",Y13=""),"",NETWORKDAYS.INTL(X13,Y13,1,'HELPER(Dont Delete)'!A:A)) | AR13: =IF(OR(Y13="",AA13=""),"",NETWORKDAYS.INTL(Y13,AA13,1,'HELPER(Dont Delete)'!A:A))
A14: 14 | B14: 45324 | C14: 45327 | D14: KAM (Gurgaon) | E14: Steelway | F14: Ujjwal Singh | G14: Prashant Sharma | H14: 8741855547 | I14: prashantjims@gmail.co | K14: 12 | L14: 8.5 | M14: Nippon Steel Pipes | N14: 30 | Q14: M.Sc+ PGDM | R14: Gurgaon | U14: Preeti Koli | V14: Candidate Backout | X14: 45330 | Z14: 45342 | AP14: =IF(OR(X14="",C14=""),"",NETWORKDAYS.INTL(C14,X14,1,'HELPER(Dont Delete)'!A:A)) -> 4 | AQ14: =IF(OR(X14="",Y14=""),"",NETWORKDAYS.INTL(X14,Y14,1,'HELPER(Dont Delete)'!A:A)) | AR14: =IF(OR(Y14="",AA14=""),"",NETWORKDAYS.INTL(Y14,AA14,1,'HELPER(Dont Delete)'!A:A))
A15: 15 | B15: 45324 | C15: 45327 | D15: KAM (Gurgaon) | E15: Steelway | F15: Ujjwal Singh | G15: Bhawana | H15: 8742967460 | I15: sbhawna376@gmail.com | K15: 7 | L15: 5 | M15: Maharashtra Seamless Limited | N15: 60 | Q15: B.tech + MBA | R15: Gurgaon | U15: Preeti Koli | V15: Candidate Backout | X15: 45330 | AP15: =IF(OR(X15="",C15=""),"",NETWORKDAYS.INTL(C15,X15,1,'HELPER(Dont Delete)'!A:A)) -> 4 | AQ15: =IF(OR(X15="",Y15=""),"",NETWORKDAYS.INTL(X15,Y15,1,'HELPER(Dont Delete)'!A:A)) | AR15: =IF(OR(Y15="",AA15=""),"",NETWORKDAYS.INTL(Y15,AA15,1,'HELPER(Dont Delete)'!A:A))
A16: 16 | B16: 45324 | C16: 45337 | D16: KAM (Gurgaon) | E16: Steelway | F16: Ujjwal Singh | G16: Pravesh Kumar Sahu | H16: 7060796556 | I16: praveshsahu269@gmail.com | K16: 4.5 | L16: 4.5 | M16: Ambica Steels | N16: 30 Days | O16: 4.3 LPA | P16: 6 .5 LPA | Q16: B.Tech Mechanical | R16: New Delhi | U16: Prakash Mishra | V16: Candidate Backout | X16: 45343 | Z16: 45344 | AP16: =IF(OR(X16="",C16=""),"",NETWORKDAYS.INTL(C16,X16,1,'HELPER(Dont Delete)'!A:A)) -> 4 | AQ16: =IF(OR(X16="",Y16=""),"",NETWORKDAYS.INTL(X16,Y16,1,'HELPER(Dont Delete)'!A:A)) | AR16: =IF(OR(Y16="",AA16=""),"",NETWORKDAYS.INTL(Y16,AA16,1,'HELPER(Dont Delete)'!A:A))
A17: 17 | B17: 45324 | C17: 45337 | D17: KAM (Gurgaon) | E17: Steelway | F17: Ujjwal Singh | G17: Rahul Khurana | H17: 9871631046 | I17: rahulrkkhurana001@gmail.com | K17: 8.5 | L17: 8.5 | M17: Ambica Steels | N17: 60 Days | O17: 16 LPA | P17: 22 LPA | Q17: B.Tech (Mechanical & Automation) | R17: New Delhi | U17: Prakash Mishra | V17: L1 Reject | X17: 45343 | Z17: 45344 | AP17: =IF(OR(X17="",C17=""),"",NETWORKDAYS.INTL(C17,X17,1,'HELPER(Dont Delete)'!A:A)) -> 4 | AQ17: =IF(OR(X17="",Y17=""),"",NETWORKDAYS.INTL(X17,Y17,1,'HELPER(Dont Delete)'!A:A)) | AR17: =IF(OR(Y17="",AA17=""),"",NETWORKDAYS.INTL(Y17,AA17,1,'HELPER(Dont Delete)'!A:A))
A18: 18 | B18: 45324 | C18: 45351 | D18: KAM (Gurgaon) | E18: Steelway | F18: Ujjwal Singh | G18: Mohit Tyagi | H18: 8800334384 | I18: mohitmtl.tyagi@gmail.com | J18: KAM- BD- Pipes | K18: 12 | L18: 12.00 Years | M18: Apl Apollo Pipes | N18: 30 | O18: 7 | P18: 25% hike on fixed | Q18: MBA | R18: Ghaziabad | U18: Nikitha Agarwal | V18: Duplicate | X18: 45352 | AP18: =IF(OR(X18="",C18=""),"",NETWORKDAYS.INTL(C18,X18,1,'HELPER(Dont Delete)'!A:A)) -> 2 | AQ18: =IF(OR(X18="",Y18=""),"",NETWORKDAYS.INTL(X18,Y18,1,'HELPER(Dont Delete)'!A:A)) | AR18: =IF(OR(Y18="",AA18=""),"",NETWORKDAYS.INTL(Y18,AA18,1,'HELPER(Dont Delete)'!A:A))
A19: 19 | B19: 45324 | C19: 45351 | D19: KAM (Kolkata) | E19: Steelway | F19: Ujjwal Singh | G19: Kushgra Wardhan | H19: 8210445564 | I19: kushagra.wardhan94@gmail.com | J19: KAM- BD- Pipes | K19: 30 | L19: 2.10 Years | M19: Shyam Steel manufacture | N19: 60 | O19: 7 | P19: 30% hike on 6.47 LPA | Q19: PGDM- full time | R19: Kolkata | U19: Nikitha Agarwal | V19: Final Select | W19: Joined | X19: 45352 | Y19: 45355 | Z19: Select | AG19: 45369 | AP19: =IF(OR(X19="",C19=""),"",NETWORKDAYS.INTL(C19,X19,1,'HELPER(Dont Delete)'!A:A)) -> 2 | AQ19: =IF(OR(X19="",Y19=""),"",NETWORKDAYS.INTL(X19,Y19,1,'HELPER(Dont Delete)'!A:A)) -> 2 | AR19: =IF(OR(Y19="",AA19=""),"",NETWORKDAYS.INTL(Y19,AA19,1,'HELPER(Dont Delete)'!A:A))
A20: 20 | B20: 45324 | C20: 45351 | D20: KAM (Gurgaon) | E20: Steelway | F20: Ujjwal Singh | G20: Siddarth Birla | H20: 8373994823 | I20: siddharth.birla1@gmail.com | J20: KAM- BD- Pipes | K20: 5.00 Years | L20: 2.00 Years | M20: DBS Building Products | N20: 30 | O20: 10.2 | P20: 25% on hike fixed | Q20: Btech, PDGM - full time | R20: Ghaziabad | U20: Nikitha Agarwal | V20: Candidate Backout | X20: 45352 | AP20: =IF(OR(X20="",C20=""),"",NETWORKDAYS.INTL(C20,X20,1,'HELPER(Dont Delete)'!A:A)) -> 2 | AQ20: =IF(OR(X20="",Y20=""),"",NETWORKDAYS.INTL(X20,Y20,1,'HELPER(Dont Delete)'!A:A)) | AR20: =IF(OR(Y20="",AA20=""),"",NETWORKDAYS.INTL(Y20,AA20,1,'HELPER(Dont Delete)'!A:A))
A21: 21 | B21: 45275 | C21: 45352 | D21: Logistics - Manager/Sr Manager | E21: Steelway | F21: Ujjwal Singh | G21: Tinu Anand | H21: 8908416288 | I21: tinuanand29@gmail.com | J21: logistics, transportation management, | K21: 11 | L21: 9 | M21: Adani Logistics Ltd,Multi-modal logistics parks | N21: 60 | O21: 14.5 | P21: 30% hike | Q21: MBA | R21: Gurgaon | U21: Shilpa H | V21: L1 Reject | X21: 45357 | Y21: 45357 | Z21: Reject | AP21: =IF(OR(X21="",C21=""),"",NETWORKDAYS.INTL(C21,X21,1,'HELPER(Dont Delete)'!A:A)) -> 3 | AQ21: =IF(OR(X21="",Y21=""),"",NETWORKDAYS.INTL(X21,Y21,1,'HELPER(Dont Delete)'!A:A)) -> 0 | AR21: =IF(OR(Y21="",AA21=""),"",NETWORKDAYS.INTL(Y21,AA21,1,'HELPER(Dont Delete)'!A:A))
A22: 22 | B22: 45275 | C22: 45352 | D22: Logistics - Manager/Sr Manager | E22: Steelway | F22: Ujjwal Singh | G22: Sudhanshu Tripathi | H22: 7218435695, 9834595866 | I22: tripathi5690@gmail.com | K22: 10 | L22: 8.5 | M22: Reliance retail Limited | N22: 60 | O22: 12 | P22: 25% hike | Q22: B.Com + MBA | R22: Jajjar | U22: Preeti Koli | V22: Screen Reject | X22: 45357 | AP22: =IF(OR(X22="",C22=""),"",NETWORKDAYS.INTL(C22,X22,1,'HELPER(Dont Delete)'!A:A)) -> 3 | AQ22: =IF(OR(X22="",Y22=""),"",NETWORKDAYS.INTL(X22,Y22,1,'HELPER(Dont Delete)'!A:A)) | AR22: =IF(OR(Y22="",AA22=""),"",NETWORKDAYS.INTL(Y22,AA22,1,'HELPER(Dont Delete)'!A:A))
A23: 23 | B23: 45327 | C23: 45355 | D23: KAM (Gurgaon) | E23: Steelway | F23: Ujjwal Singh | G23: Amit Gupta | H23: 7042904888 | I23: amit85ei@gmail.com | J23: Sales, BD, KAM, Customer Acquisition, Customer Retention, B2B, Market Mapping | K23: 14+ | L23: 14+ | M23: Surya Roshni | N23: 30 | O23: 15 LPA | P23: 25-30% hike | Q23: BE + MBA | R23: Delhi | T23: 14 + yrs of exp in sales and marketing | U23: Vinay Kumar | V23: L1 Reject | X23: 45359 | Y23: 45362 | Z23: Reject | AP23: =IF(OR(X23="",C23=""),"",NETWORKDAYS.INTL(C23,X23,1,'HELPER(Dont Delete)'!A:A)) -> 3 | AQ23: =IF(OR(X23="",Y23=""),"",NETWORKDAYS.INTL(X23,Y23,1,'HELPER(Dont Delete)'!A:A)) -> 1 | AR23: =IF(OR(Y23="",AA23=""),"",NETWORKDAYS.INTL(Y23,AA23,1,'HELPER(Dont Delete)'!A:A))
A24: 24 | B24: 45327 | C24: 45355 | D24: KAM (Gurgaon) | E24: Steelway | F24: Ujjwal Singh | G24: Gaurav Singh | H24: 9713478007 | I24: grvsingh2009@gmail.com | J24: Sales, BD, KAM, Customer Acquisition, Customer Retention, B2B, Market Mapping | K24: 8.9 | L24: 8.9 | M24: APL Apollo Tubes | N24: 30 | O24: 5 LPA | P24: 7 to 8 LPA | Q24: BE + MBA | R24: Indore | T24: 8.9 yrs of exp in sales and marketing | U24: Vinay Kumar | V24: L1 Reject | X24: 45359 | Y24: 45366 | Z24: Reject | AP24: =IF(OR(X24="",C24=""),"",NETWORKDAYS.INTL(C24,X24,1,'HELPER(Dont Delete)'!A:A)) -> 3 | AQ24: =IF(OR(X24="",Y24=""),"",NETWORKDAYS.INTL(X24,Y24,1,'HELPER(Dont Delete)'!A:A)) -> 5 | AR24: =IF(OR(Y24="",AA24=""),"",NETWORKDAYS.INTL(Y24,AA24,1,'HELPER(Dont Delete)'!A:A))
A25: 25 | B25: 45327 | C25: 45355 | D25: KAM (Gurgaon) | E25: Steelway | F25: Ujjwal Singh | G25: Ajay Kumar Singh | H25: 9056272236 | I25: ajay20580@gmail.com | J25: Sales, BD, KAM, Customer Acquisition, Customer Retention, B2B, Market Mapping | K25: 14 | L25: 14 | M25: APL Apollo Tubes | N25: 30 | O25: 8.9 LPA | P25: 12 LPA | Q25: MBA | R25: Bhubaneshwar | T25: 14 yrs of exp in sales and marketing | U25: Vinay Kumar | V25: L1 Reject | X25: 45359 | Y25: 45366 | Z25: Reject | AP25: =IF(OR(X25="",C25=""),"",NETWORKDAYS.INTL(C25,X25,1,'HELPER(Dont Delete)'!A:A)) -> 3 | AQ25: =IF(OR(X25="",Y25=""),"",NETWORKDAYS.INTL(X25,Y25,1,'HELPER(Dont Delete)'!A:A)) -> 5 | AR25: =IF(OR(Y25="",AA25=""),"",NETWORKDAYS.INTL(Y25,AA25,1,'HELPER(Dont Delete)'!A:A))
A26: 26 | B26: 45327 | C26: 45355 | D26: KAM (Gurgaon) | E26: Steelway | F26: Ujjwal Singh | G26: Deepanshu Katiyar | H26: 7982783407 | I26: dkatiyarmae@gmail.com | J26: Sales, BD, KAM, Customer Acquisition, Customer Retention, B2B, Market Mapping | K26: 11 | L26: 11 | M26: Uttam Strips | N26: 30 | O26: 9.7 LPA | P26: 25-30% hike | Q26: B Tech+ MBA | R26: Faridabad | T26: 11 yrs of exp in sales and marketing | U26: Vinay Kumar | V26: L1 Reject | X26: 45359 | Y26: 45366 | Z26: Reject | AP26: =IF(OR(X26="",C26=""),"",NETWORKDAYS.INTL(C26,X26,1,'HELPER(Dont Delete)'!A:A)) -> 3 | AQ26: =IF(OR(X26="",Y26=""),"",NETWORKDAYS.INTL(X26,Y26,1,'HELPER(Dont Delete)'!A:A)) -> 5 | AR26: =IF(OR(Y26="",AA26=""),"",NETWORKDAYS.INTL(Y26,AA26,1,'HELPER(Dont Delete)'!A:A))
A27: 27 | B27: 45327 | C27: 45355 | D27: KAM (Kolkata) | E27: Steelway | F27: Ujjwal Singh | G27: Kuldeep Jain | H27: 9981145050 | I27: kuldeep_jain01@yahoo.co.in | J27: Sales, BD, KAM, Customer Acquisition, Customer Retention, B2B, Market Mapping | K27: 14 | L27: 14 | M27: APL Apollo Tubes | N27: 45 | O27: 8.5 LPA | P27: 25-30% hike | Q27: MBA | R27: Jabalpur | T27: 14 yrs of exp in sales and marketing | U27: Vinay Kumar | V27: Final Select | W27: Joined | X27: 45359 | Y27: 45362 | Z27: Select | AP27: =IF(OR(X27="",C27=""),"",NETWORKDAYS.INTL(C27,X27,1,'HELPER(Dont Delete)'!A:A)) -> 3 | AQ27: =IF(OR(X27="",Y27=""),"",NETWORKDAYS.INTL(X27,Y27,1,'HELPER(Dont Delete)'!A:A)) -> 1 | AR27: =IF(OR(Y27="",AA27=""),"",NETWORKDAYS.INTL(Y27,AA27,1,'HELPER(Dont Delete)'!A:A))
A28: 28 | B28: 45327 | C28: 45355 | D28: KAM (Kolkata) | E28: Steelway | F28: Ujjwal Singh | G28: Shakti Kundu | H28: 9811169004 | I28: shaktikundu466@gmail.com | J28: - | K28: 10 | L28: 8 | M28: Mukand Sumi Special Steel Ltd | N28: 90 | O28: 10 LPA | P28: 16 LPA | Q28: B.Tech/B.E.,Mechanical | R28: Gurgaon | T28: - | U28: Rutali | V28: Candidate Backout | X28: 45359 | AP28: =IF(OR(X28="",C28=""),"",NETWORKDAYS.INTL(C28,X28,1,'HELPER(Dont Delete)'!A:A)) -> 3 | AQ28: =IF(OR(X28="",Y28=""),"",NETWORKDAYS.INTL(X28,Y28,1,'HELPER(Dont Delete)'!A:A)) | AR28: =IF(OR(Y28="",AA28=""),"",NETWORKDAYS.INTL(Y28,AA28,1,'HELPER(Dont Delete)'!A:A))
