Workbook
Name Pivot: OFFSET('Positions Tracker'!$A$1,0,0,COUNTA('Positions Tracker'!A:A),COUNTA('Positions Tracker'!1048575:1048575))
Name Pivots: OFFSET('Positions Tracker'!$A$1,0,0,COUNTA('Positions Tracker'!$A:$A),COUNTA('Positions Tracker'!$1:$1))

Sheet Positions Tracker
A1: S.No | B1: ORC ID | C1: Final Status | D1: Current Stage | E1: Position Title | F1: Skills | G1: BU | H1: Department | I1: HM | J1: Source of Hire | K1: ORC Open Date | L1: Req Received Date- RPO | M1: Intake Meeting Date | N1: Track Level | O1: Hold Date 1 | P1: Hold Date 2 | Q1: Hold Date 3 | R1: Re - Open Date 1 | S1: Re - Open Date 2 | T1: Re - Open Date 3 | U1: Years of Experience | V1: Min Salary | W1: Max Salary | X1: Job Location | Y1: Recruiter | Z1: Sourcer | AA1: Remarks | AB1: Total CV | AC1: Active CV | AD1: Diversity CV | AE1: Candidate Name | AF1: Contact Number | AG1: Email Address | AH1: Gender | AI1: Date of Selection | AJ1: Fitment Approval Date | AK1: Offered location | AL1: CTC offered | AM1: Fitment released Date | AN1: Fitment Acceptance Date | AO1: Offer Reject Date | AP1: AL relesaed date | AQ1: AL Acceptance Date | AR1: OB Trigger Date | AS1: DOJ | AT1: RSLA | AU1: Ageing | AV1: Bucket | AW1: TTO | AX1: TTH | AY1: Offer Drop | AZ1: FTR% | BA1: Diversity of Supply Female | BB1: Diversity of Supply Male | BC1: Hit Ratio | BD1: Intake Month | BE1: Selection Month | BF1: Offer Month | BG1: Joining Month
A2: 1 | B2: 20245762 | C2: Cancelled | D2: Position Cancelled | E2: FEA - Associate | F2: FEM | G2: Integrated Business Services | H2: Core Engineering | I2: AmitKumar | J2: External | K2: 45532 | L2: 45161 | M2: 45161 | N2: T8 | X2: Pune | Y2: Motwani, Hani | Z2: Bharwade, Amruta | AA2: Updated as on 21 Feb 25- 1 F2f interview scheduled, 1 L1 interview scheduled Update as on 8th Feb- 3 L1 interview are scheduled 11th, 12th and 14 feb | AB2: 30 | AC2: 19 | AT2: =IFERROR(SUM(IF(AND(ISBLANK(T2),ISBLANK(Q2)),0,IF(T2="",TODAY()-Q2,T2-Q2))+IF(AND(ISBLANK(S2),ISBLANK(P2)),0,IF(S2="",TODAY()-P2,S2-P2))+IF(AND(ISBLANK(O2),ISBLANK(R2)),0,IF(R2="",TODAY()-O2,R2-O2))),"") -> 0 | AU2: =IFERROR(IF(($M2=""),"",IF(OR(,$C2="Offer in Progress",$C2="WIP",$C2="WIP/Drop",$C2="WIP/New",$C2="WIP/Hold"),(TODAY()-$M2)-$AT2,"")),"") | AV2: {=IFERROR(_xlfn.IFS($AU2="","",$AU2<=15,"0-15",AND($AU2>=16,$AU2<=30),"16-30",AND($AU2>=31,$AU2<=45),"31-45",AND($AU2>=46,$AU2<=60),"46-60",AND($AU2>=61,$AU2<=90),"61-90",AND($AU2>=91),"> 90",AND($AU2>=2000),""),"")} | AW2: {=IFERROR(_xlfn.IFS(OR($M2="",$AM2=""),"",OR($C2="Offered",$C2="Joined"),($AM2-$M2)-$AT2),"")} | AX2: {=IFERROR(_xlfn.IFS(OR($M2="",$AS2=""),"",$C2="Joined",($AS2-$M2)-$AT2),"")} | AY2: =IFERROR(IF(COUNTIFS('Candidate Tracker'!$E:$E,'Positions Tracker'!$B2,'Candidate Tracker'!$C:$C,"Offer Drop")=0,"",COUNTIFS('Candidate Tracker'!$E:$E,'Positions Tracker'!$B2,'Candidate Tracker'!$C:$C,"Offer Drop")),"") | AZ2: =IFERROR(IF((COUNTIFS('Candidate Tracker'!$D:$D,"<>",'Candidate Tracker'!$D:$D,"<>Screening",'Candidate Tracker'!$D:$D,"<>Screening Pending",'Candidate Tracker'!$D:$D,"<>Candidate Hold",'Candidate Tracker'!$D:$D,"<>Position Cancelled",'Candidate Tracker'!$D:$D,"<>Internal closed")/COUNTIF('Candidate Tracker'!$D:$D,"<>"))=0,"",(COUNTIFS('Candidate Tracker'!$D:$D,"<>",'Candidate Tracker'!$D:$D,"<>Screening",'Candidate Tracker'!$D:$D,"<>Candidate Hold",'Candidate Tracker'!$D:$D,"<>Position Cancelled",'Candidate Tracker'!$D:$D,"<>Internal closed")/COUNTIF('Candidate Tracker'!$D:$D,"<>"))),"") -> 0.88111888 | BA2: =IFERROR(IF(COUNTIFS('Candidate Tracker'!$E:$E,'Positions Tracker'!$B2,'Candidate Tracker'!$I:$I,"Female")=0,"",COUNTIFS('Candidate Tracker'!$E:$E,'Positions Tracker'!$B2,'Candidate Tracker'!$I:$I,"Female")),"") | BB2: =IFERROR(IF(COUNTIFS('Candidate Tracker'!$E:$E,'Positions Tracker'!$B2,'Candidate Tracker'!$I:$I,"male")=0,"",COUNTIFS('Candidate Tracker'!$E:$E,'Positions Tracker'!$B2,'Candidate Tracker'!$I:$I,"male")),"") -> 7 | BC2: =IFERROR(IF(COUNTIFS('Candidate Tracker'!$E:$E,'Positions Tracker'!$B2,'Candidate Tracker'!$C:$C,"<>WIP",'Candidate Tracker'!$C:$C,"<>Hold",'Candidate Tracker'!$C:$C,"<>Cancelled",'Candidate Tracker'!$C:$C,"<>Closed")/COUNTIFS('Candidate Tracker'!$E:$E,'Positions Tracker'!$B2)=0,"",COUNTIFS('Candidate Tracker'!$E:$E,'Positions Tracker'!$B2,'Candidate Tracker'!$C:$C,"<>WIP",'Candidate Tracker'!$C:$C,"<>Hold",'Candidate Tracker'!$C:$C,"<>Cancelled",'Candidate Tracker'!$C:$C,"<>Closed")/COUNTIFS('Candidate Tracker'!$E:$E,'Positions Tracker'!$B2)),"") | BD2: =IFERROR(IF($M2="","",TEXT($M2,"MMM-YY")),"") -> Aug-23 | BE2: =IFERROR(IF($AI2="","",TEXT($AI2,"MMM-YY")),"") | BF2: =IFERROR(IF($AM2="","",TEXT($AM2,"MMM-YY")),"") | BG2: =IFERROR(IF($AS2="","",TEXT($AS2,"MMM-YY")),"")
A3: =A2+1 -> 2 | B3: 20250721 | C3: Cancelled | D3: Position Cancelled | E3: Junior Writer, Portfolio Content Creation | F3: CAM | G3: Integrated Business Services | H3: Core Engineering | I3: Hemantkumar shinde | J3: External | K3: 45625 | L3: 45625 | M3: 45625 | N3: T8 | X3: Pune | Y3: Bharwade, Amruta | Z3: Bharwade, Amruta | AA3: Update on 13th feb- Offer declined pooja sawant, Update as on 21st Feb 3 profiles shared for shortlisting | AB3: 15 | AC3: 12 | AD3: 5 | AT3: =IFERROR(SUM(IF(AND(ISBLANK(T3),ISBLANK(Q3)),0,IF(T3="",TODAY()-Q3,T3-Q3))+IF(AND(ISBLANK(S3),ISBLANK(P3)),0,IF(S3="",TODAY()-P3,S3-P3))+IF(AND(ISBLANK(O3),ISBLANK(R3)),0,IF(R3="",TODAY()-O3,R3-O3))),"") -> 0 | AU3: =IFERROR(IF(($M3=""),"",IF(OR(,$C3="Offer in Progress",$C3="WIP",$C3="WIP/Drop",$C3="WIP/New",$C3="WIP/Hold"),(TODAY()-$M3)-$AT3,"")),"") | AV3: {=IFERROR(_xlfn.IFS($AU3="","",$AU3<=15,"0-15",AND($AU3>=16,$AU3<=30),"16-30",AND($AU3>=31,$AU3<=45),"31-45",AND($AU3>=46,$AU3<=60),"46-60",AND($AU3>=61,$AU3<=90),"61-90",AND($AU3>=91),"> 90",AND($AU3>=2000),""),"")} | AW3: {=IFERROR(_xlfn.IFS(OR($M3="",$AM3=""),"",OR($C3="Offered",$C3="Joined"),($AM3-$M3)-$AT3),"")} | AX3: {=IFERROR(_xlfn.IFS(OR($M3="",$AS3=""),"",$C3="Joined",($AS3-$M3)-$AT3),"")} | AY3: =IFERROR(IF(COUNTIFS('Candidate Tracker'!$E:$E,'Positions Tracker'!$B3,'Candidate Tracker'!$C:$C,"Offer Drop")=0,"",COUNTIFS('Candidate Tracker'!$E:$E,'Positions Tracker'!$B3,'Candidate Tracker'!$C:$C,"Offer Drop")),"") | AZ3: =IFERROR(IF((COUNTIFS('Candidate Tracker'!$D:$D,"<>",'Candidate Tracker'!$D:$D,"<>Screening",'Candidate Tracker'!$D:$D,"<>Screening Pending",'Candidate Tracker'!$D:$D,"<>Candidate Hold",'Candidate Tracker'!$D:$D,"<>Position Cancelled",'Candidate Tracker'!$D:$D,"<>Internal closed")/COUNTIF('Candidate Tracker'!$D:$D,"<>"))=0,"",(COUNTIFS('Candidate Tracker'!$D:$D,"<>",'Candidate Tracker'!$D:$D,"<>Screening",'Candidate Tracker'!$D:$D,"<>Candidate Hold",'Candidate Tracker'!$D:$D,"<>Position Cancelled",'Candidate Tracker'!$D:$D,"<>Internal closed")/COUNTIF('Candidate Tracker'!$D:$D,"<>"))),"") -> 0.88111888 | BA3: =IFERROR(IF(COUNTIFS('Candidate Tracker'!$E:$E,'Positions Tracker'!$B3,'Candidate Tracker'!$I:$I,"Female")=0,"",COUNTIFS('Candidate Tracker'!$E:$E,'Positions Tracker'!$B3,'Candidate Tracker'!$I:$I,"Female")),"") | BB3: =IFERROR(IF(COUNTIFS('Candidate Tracker'!$E:$E,'Positions Tracker'!$B3,'Candidate Tracker'!$I:$I,"male")=0,"",COUNTIFS('Candidate Tracker'!$E:$E,'Positions Tracker'!$B3,'Candidate Tracker'!$I:$I,"male")),"") -> 9 | BC3: =IFERROR(IF(COUNTIFS('Candidate Tracker'!$E:$E,'Positions Tracker'!$B3,'Candidate Tracker'!$C:$C,"<>WIP",'Candidate Tracker'!$C:$C,"<>Hold",'Candidate Tracker'!$C:$C,"<>Cancelled",'Candidate Tracker'!$C:$C,"<>Closed")/COUNTIFS('Candidate Tracker'!$E:$E,'Positions Tracker'!$B3)=0,"",COUNTIFS('Candidate Tracker'!$E:$E,'Positions Tracker'!$B3,'Candidate Tracker'!$C:$C,"<>WIP",'Candidate Tracker'!$C:$C,"<>Hold",'Candidate Tracker'!$C:$C,"<>Cancelled",'Candidate Tracker'!$C:$C,"<>Closed")/COUNTIFS('Candidate Tracker'!$E:$E,'Positions Tracker'!$B3)),"") | BD3: =IFERROR(IF($M3="","",TEXT($M3,"MMM-YY")),"") -> Nov-24 | BE3: =IFERROR(IF($AI3="","",TEXT($AI3,"MMM-YY")),"") | BF3: =IFERROR(IF($AM3="","",TEXT($AM3,"MMM-YY")),"") | BG3: =IFERROR(IF($AS3="","",TEXT($AS3,"MMM-YY")),"")
A4: =A3+1 -> 3 | B4: 20245969 | C4: Offer Drop | D4: Offer Decline | E4: Senior Writer, Portfolio Content Creation | F4: CAM | G4: Integrated Business Services | H4: Core Engineering | I4: Hemantkumar shinde | J4: External | K4: 45625 | L4: 45625 | M4: 45625 | N4: T10 | X4: Pune | Y4: Bharwade, Amruta | Z4: Bharwade, Amruta | AA4: Komal has backout - CTC Compensation . Update as on 8th Feb: Komal Dhumal comp breakup to be sent to HM on 8thFeb | AB4: 11 | AC4: 8 | AE4: Komal Dhumal | AF4: 7709030818 | AG4: dhumalkomal2904@gmail.com | AH4: Female | AI4: 45695 | AJ4: 45693 | AK4: Pune | AL4: 1000000 | AM4: 45693 | AN4: 45693 | AP4: 45698 | AQ4: 45698 | AR4: 45757 | AS4: 45761 | AT4: =IFERROR(SUM(IF(AND(ISBLANK(T4),ISBLANK(Q4)),0,IF(T4="",TODAY()-Q4,T4-Q4))+IF(AND(ISBLANK(S4),ISBLANK(P4)),0,IF(S4="",TODAY()-P4,S4-P4))+IF(AND(ISBLANK(O4),ISBLANK(R4)),0,IF(R4="",TODAY()-O4,R4-O4))),"") -> 0 | AU4: =IFERROR(IF(($M4=""),"",IF(OR(,$C4="Offer in Progress",$C4="WIP",$C4="WIP/Drop",$C4="WIP/New",$C4="WIP/Hold"),(TODAY()-$M4)-$AT4,"")),"") | AV4: {=IFERROR(_xlfn.IFS($AU4="","",$AU4<=15,"0-15",AND($AU4>=16,$AU4<=30),"16-30",AND($AU4>=31,$AU4<=45),"31-45",AND($AU4>=46,$AU4<=60),"46-60",AND($AU4>=61,$AU4<=90),"61-90",AND($AU4>=91),"> 90",AND($AU4>=2000),""),"")} | AW4: {=IFERROR(_xlfn.IFS(OR($M4="",$AM4=""),"",OR($C4="Offered",$C4="Joined"),($AM4-$M4)-$AT4),"")} | AX4: {=IFERROR(_xlfn.IFS(OR($M4="",$AS4=""),"",$C4="Joined",($AS4-$M4)-$AT4),"")} | AY4: =IFERROR(IF(COUNTIFS('Candidate Tracker'!$E:$E,'Positions Tracker'!$B4,'Candidate Tracker'!$C:$C,"Offer Drop")=0,"",COUNTIFS('Candidate Tracker'!$E:$E,'Positions Tracker'!$B4,'Candidate Tracker'!$C:$C,"Offer Drop")),"") | AZ4: =IFERROR(IF((COUNTIFS('Candidate Tracker'!$D:$D,"<>",'Candidate Tracker'!$D:$D,"<>Screening",'Candidate Tracker'!$D:$D,"<>Screening Pending",'Candidate Tracker'!$D:$D,"<>Candidate Hold",'Candidate Tracker'!$D:$D,"<>Position Cancelled",'Candidate Tracker'!$D:$D,"<>Internal closed")/COUNTIF('Candidate Tracker'!$D:$D,"<>"))=0,"",(COUNTIFS('Candidate Tracker'!$D:$D,"<>",'Candidate Tracker'!$D:$D,"<>Screening",'Candidate Tracker'!$D:$D,"<>Candidate Hold",'Candidate Tracker'!$D:$D,"<>Position Cancelled",'Candidate Tracker'!$D:$D,"<>Internal closed")/COUNTIF('Candidate Tracker'!$D:$D,"<>"))),"") -> 0.88111888 | BA4: =IFERROR(IF(COUNTIFS('Candidate Tracker'!$E:$E,'Positions Tracker'!$B4,'Candidate Tracker'!$I:$I,"Female")=0,"",COUNTIFS('Candidate Tracker'!$E:$E,'Positions Tracker'!$B4,'Candidate Tracker'!$I:$I,"Female")),"") -> 4 | BB4: =IFERROR(IF(COUNTIFS('Candidate Tracker'!$E:$E,'Positions Tracker'!$B4,'Candidate Tracker'!$I:$I,"male")=0,"",COUNTIFS('Candidate Tracker'!$E:$E,'Positions Tracker'!$B4,'Candidate Tracker'!$I:$I,"male")),"") -> 15 | BC4: =IFERROR(IF(COUNTIFS('Candidate Tracker'!$E:$E,'Positions Tracker'!$B4,'Candidate Tracker'!$C:$C,"<>WIP",'Candidate Tracker'!$C:$C,"<>Hold",'Candidate Tracker'!$C:$C,"<>Cancelled",'Candidate Tracker'!$C:$C,"<>Closed")/COUNTIFS('Candidate Tracker'!$E:$E,'Positions Tracker'!$B4)=0,"",COUNTIFS('Candidate Tracker'!$E:$E,'Positions Tracker'!$B4,'Candidate Tracker'!$C:$C,"<>WIP",'Candidate Tracker'!$C:$C,"<>Hold",'Candidate Tracker'!$C:$C,"<>Cancelled",'Candidate Tracker'!$C:$C,"<>Closed")/COUNTIFS('Candidate Tracker'!$E:$E,'Positions Tracker'!$B4)),"") | BD4: =IFERROR(IF($M4="","",TEXT($M4,"MMM-YY")),"") -> Nov-24 | BE4: =IFERROR(IF($AI4="","",TEXT($AI4,"MMM-YY")),"") -> Feb-25 | BF4: =IFERROR(IF($AM4="","",TEXT($AM4,"MMM-YY")),"") -> Feb-25 | BG4: =IFERROR(IF($AS4="","",TEXT($AS4,"MMM-YY")),"") -> Apr-25
A5: =A4+1 -> 4 | B5: 20253846 | C5: Hold | D5: Hold | E5: Engineer II Technical Publications X: Sr Technical Writer | F5: CAM | G5: Integrated Business Services | H5: Core Engineering | I5: Sami Kar | J5: External | K5: 45744 | L5: 45744 | M5: 45744 | N5: T10 | O5: 45757 | R5: 45776 | U5: 6 | X5: Pune | Y5: Bharwade, Amruta | Z5: Bharwade, Amruta | AA5: 23-June-25: Position on hold 18-June-25: 1 candidates Final interview done - F/b pending , 3 cvs shared with HM feedback pending - 11 june. 17-June-25 : 1 candidates Final interview done - F/b pending , 3 cvs shared with HM feedback pending - 11 june. 9-Jun-25: 3 L1 Interviews scheduled, 4 profiles shared for shortlisting awaiting on 27th May 25 for feedback 2-May-25: 2 candidates Test to be schedule , 1 candidates L2 to be schedule (Vinayak) 12th April 25: 2 L1 interview feedback is pending since 8th April 25, 1 L1 interview scheduled on 14th April 25 7th April 25: 2 L1 interviews scheduled Update on 8th feb- 1 candidate on hold, Update as on 21st Feb 3 profiles shared for shortlisting | AB5: 10 | AC5: 7 | AD5: 4 | AT5: =IFERROR(SUM(IF(AND(ISBLANK(T5),ISBLANK(Q5)),0,IF(T5="",TODAY()-Q5,T5-Q5))+IF(AND(ISBLANK(S5),ISBLANK(P5)),0,IF(S5="",TODAY()-P5,S5-P5))+IF(AND(ISBLANK(O5),ISBLANK(R5)),0,IF(R5="",TODAY()-O5,R5-O5))),"") -> 19 | AU5: =IFERROR(IF(($M5=""),"",IF(OR(,$C5="Offer in Progress",$C5="WIP",$C5="WIP/Drop",$C5="WIP/New",$C5="WIP/Hold"),(TODAY()-$M5)-$AT5,"")),"") | AV5: {=IFERROR(_xlfn.IFS($AU5="","",$AU5<=15,"0-15",AND($AU5>=16,$AU5<=30),"16-30",AND($AU5>=31,$AU5<=45),"31-45",AND($AU5>=46,$AU5<=60),"46-60",AND($AU5>=61,$AU5<=90),"61-90",AND($AU5>=91),"> 90",AND($AU5>=2000),""),"")} | AW5: {=IFERROR(_xlfn.IFS(OR($M5="",$AM5=""),"",OR($C5="Offered",$C5="Joined"),($AM5-$M5)-$AT5),"")} | AX5: {=IFERROR(_xlfn.IFS(OR($M5="",$AS5=""),"",$C5="Joined",($AS5-$M5)-$AT5),"")} | AY5: =IFERROR(IF(COUNTIFS('Candidate Tracker'!$E:$E,'Positions Tracker'!$B5,'Candidate Tracker'!$C:$C,"Offer Drop")=0,"",COUNTIFS('Candidate Tracker'!$E:$E,'Positions Tracker'!$B5,'Candidate Tracker'!$C:$C,"Offer Drop")),"") | AZ5: =IFERROR(IF((COUNTIFS('Candidate Tracker'!$D:$D,"<>",'Candidate Tracker'!$D:$D,"<>Screening",'Candidate Tracker'!$D:$D,"<>Screening Pending",'Candidate Tracker'!$D:$D,"<>Candidate Hold",'Candidate Tracker'!$D:$D,"<>Position Cancelled",'Candidate Tracker'!$D:$D,"<>Internal closed")/COUNTIF('Candidate Tracker'!$D:$D,"<>"))=0,"",(COUNTIFS('Candidate Tracker'!$D:$D,"<>",'Candidate Tracker'!$D:$D,"<>Screening",'Candidate Tracker'!$D:$D,"<>Candidate Hold",'Candidate Tracker'!$D:$D,"<>Position Cancelled",'Candidate Tracker'!$D:$D,"<>Internal closed")/COUNTIF('Candidate Tracker'!$D:$D,"<>"))),"") -> 0.88111888 | BA5: =IFERROR(IF(COUNTIFS('Candidate Tracker'!$E:$E,'Positions Tracker'!$B5,'Candidate Tracker'!$I:$I,"Female")=0,"",COUNTIFS('Candidate Tracker'!$E:$E,'Positions Tracker'!$B5,'Candidate Tracker'!$I:$I,"Female")),"") -> 1 | BB5: =IFERROR(IF(COUNTIFS('Candidate Tracker'!$E:$E,'Positions Tracker'!$B5,'Candidate Tracker'!$I:$I,"male")=0,"",COUNTIFS('Candidate Tracker'!$E:$E,'Positions Tracker'!$B5,'Candidate Tracker'!$I:$I,"male")),"") -> 2 | BC5: =IFERROR(IF(COUNTIFS('Candidate Tracker'!$E:$E,'Positions Tracker'!$B5,'Candidate Tracker'!$C:$C,"<>WIP",'Candidate Tracker'!$C:$C,"<>Hold",'Candidate Tracker'!$C:$C,"<>Cancelled",'Candidate Tracker'!$C:$C,"<>Closed")/COUNTIFS('Candidate Tracker'!$E:$E,'Positions Tracker'!$B5)=0,"",COUNTIFS('Candidate Tracker'!$E:$E,'Positions Tracker'!$B5,'Candidate Tracker'!$C:$C,"<>WIP",'Candidate Tracker'!$C:$C,"<>Hold",'Candidate Tracker'!$C:$C,"<>Cancelled",'Candidate Tracker'!$C:$C,"<>Closed")/COUNTIFS('Candidate Tracker'!$E:$E,'Positions Tracker'!$B5)),"") | BD5: =IFERROR(IF($M5="","",TEXT($M5,"MMM-YY")),"") -> Mar-25 | BE5: =IFERROR(IF($AI5="","",TEXT($AI5,"MMM-YY")),"") | BF5: =IFERROR(IF($AM5="","",TEXT($AM5,"MMM-YY")),"") | BG5: =IFERROR(IF($AS5="","",TEXT($AS5,"MMM-YY")),"")
A6: =A5+1 -> 5 | C6: Cancelled | D6: Position Cancelled | E6: Senior Writer, Software and IT Systems | F6: CAM | G6: Integrated Business Services | H6: Core Engineering | I6: Hemantkumar shinde | J6: External | K6: 45625 | L6: 45625 | M6: 45625 | N6: T10 | X6: Pune | Y6: Bharwade, Amruta | Z6: Bharwade, Amruta | AA6: Update on 8th feb- 2 L1 interviews scheduled on 12 Feb 14th feb 21st Feb 25 Rutvik P final satge | AB6: 12 | AC6: 9 | AT6: =IFERROR(SUM(IF(AND(ISBLANK(T6),ISBLANK(Q6)),0,IF(T6="",TODAY()-Q6,T6-Q6))+IF(AND(ISBLANK(S6),ISBLANK(P6)),0,IF(S6="",TODAY()-P6,S6-P6))+IF(AND(ISBLANK(O6),ISBLANK(R6)),0,IF(R6="",TODAY()-O6,R6-O6))),"") -> 0 | AU6: =IFERROR(IF(($M6=""),"",IF(OR(,$C6="Offer in Progress",$C6="WIP",$C6="WIP/Drop",$C6="WIP/New",$C6="WIP/Hold"),(TODAY()-$M6)-$AT6,"")),"") | AV6: {=IFERROR(_xlfn.IFS($AU6="","",$AU6<=15,"0-15",AND($AU6>=16,$AU6<=30),"16-30",AND($AU6>=31,$AU6<=45),"31-45",AND($AU6>=46,$AU6<=60),"46-60",AND($AU6>=61,$AU6<=90),"61-90",AND($AU6>=91),"> 90",AND($AU6>=2000),""),"")} | AW6: {=IFERROR(_xlfn.IFS(OR($M6="",$AM6=""),"",OR($C6="Offered",$C6="Joined"),($AM6-$M6)-$AT6),"")} | AX6: {=IFERROR(_xlfn.IFS(OR($M6="",$AS6=""),"",$C6="Joined",($AS6-$M6)-$AT6),"")} | AY6: =IFERROR(IF(COUNTIFS('Candidate Tracker'!$E:$E,'Positions Tracker'!$B6,'Candidate Tracker'!$C:$C,"Offer Drop")=0,"",COUNTIFS('Candidate Tracker'!$E:$E,'Positions Tracker'!$B6,'Candidate Tracker'!$C:$C,"Offer Drop")),"") | AZ6: =IFERROR(IF((COUNTIFS('Candidate Tracker'!$D:$D,"<>",'Candidate Tracker'!$D:$D,"<>Screening",'Candidate Tracker'!$D:$D,"<>Screening Pending",'Candidate Tracker'!$D:$D,"<>Candidate Hold",'Candidate Tracker'!$D:$D,"<>Position Cancelled",'Candidate Tracker'!$D:$D,"<>Internal closed")/COUNTIF('Candidate Tracker'!$D:$D,"<>"))=0,"",(COUNTIFS('Candidate Tracker'!$D:$D,"<>",'Candidate Tracker'!$D:$D,"<>Screening",'Candidate Tracker'!$D:$D,"<>Candidate Hold",'Candidate Tracker'!$D:$D,"<>Position Cancelled",'Candidate Tracker'!$D:$D,"<>Internal closed")/COUNTIF('Candidate Tracker'!$D:$D,"<>"))),"") -> 0.88111888 | BA6: =IFERROR(IF(COUNTIFS('Candidate Tracker'!$E:$E,'Positions Tracker'!$B6,'Candidate Tracker'!$I:$I,"Female")=0,"",COUNTIFS('Candidate Tracker'!$E:$E,'Positions Tracker'!$B6,'Candidate Tracker'!$I:$I,"Female")),"") | BB6: =IFERROR(IF(COUNTIFS('Candidate Tracker'!$E:$E,'Positions Tracker'!$B6,'Candidate Tracker'!$I:$I,"male")=0,"",COUNTIFS('Candidate Tracker'!$E:$E,'Positions Tracker'!$B6,'Candidate Tracker'!$I:$I,"male")),"") | BC6: =IFERROR(IF(COUNTIFS('Candidate Tracker'!$E:$E,'Positions Tracker'!$B6,'Candidate Tracker'!$C:$C,"<>WIP",'Candidate Tracker'!$C:$C,"<>Hold",'Candidate Tracker'!$C:$C,"<>Cancelled",'Candidate Tracker'!$C:$C,"<>Closed")/COUNTIFS('Candidate Tracker'!$E:$E,'Positions Tracker'!$B6)=0,"",COUNTIFS('Candidate Tracker'!$E:$E,'Positions Tracker'!$B6,'Candidate Tracker'!$C:$C,"<>WIP",'Candidate Tracker'!$C:$C,"<>Hold",'Candidate Tracker'!$C:$C,"<>Cancelled",'Candidate Tracker'!$C:$C,"<>Closed")/COUNTIFS('Candidate Tracker'!$E:$E,'Positions Tracker'!$B6)),"") | BD6: =IFERROR(IF($M6="","",TEXT($M6,"MMM-YY")),"") -> Nov-24 | BE6: =IFERROR(IF($AI6="","",TEXT($AI6,"MMM-YY")),"") | BF6: =IFERROR(IF($AM6="","",TEXT($AM6,"MMM-YY")),"") | BG6: =IFERROR(IF($AS6="","",TEXT($AS6,"MMM-YY")),"")
A7: =A6+1 -> 6 | B7: 20253845 | C7: Hold | D7: Hold | E7: Sr. Engineer Technical Publications XI: Lead Writer | F7: CAM | G7: Integrated Business Services | H7: Core Engineering | I7: Sami Kar | J7: Referral | K7: 45744 | L7: 45744 | M7: 45744 | N7: T11 | U7: 8 | X7: Pune | Y7: Bharwade, Amruta | Z7: Bharwade, Amruta | AA7: 23-June-25: Position on hold 18-June- 25: Test interview feedback pending , 3 cvs shared with HM on 11th June - Feedback is pending . Position is on HOLD in ORC. 17-June-25 : Test interview feedback pending , 3 cvs shared with HM on 11th June - Feedback is pending . Position is on HOLD in ORC. 7th April 25: 1 LOB interview scheduled Update on 8th feb- 1 Final interview feedback is awaiting, 2 L3 interview scheduled Update as on 21 Feb 25 Nigar shaikh rehired case | AB7: 47 | AC7: 30 | AE7: Nigar Shaikh | AF7: 7775960656 | AG7: nigarshaikh89@gmail.com | AH7: Female | AI7: 45758 | AJ7: 45764 | AK7: Pune | AL7: 1800000 | AM7: 45764 | AN7: 45765 | AO7: 45810 | AP7: 45768 | AQ7: 45768 | AT7: =IFERROR(SUM(IF(AND(ISBLANK(T7),ISBLANK(Q7)),0,IF(T7="",TODAY()-Q7,T7-Q7))+IF(AND(ISBLANK(S7),ISBLANK(P7)),0,IF(S7="",TODAY()-P7,S7-P7))+IF(AND(ISBLANK(O7),ISBLANK(R7)),0,IF(R7="",TODAY()-O7,R7-O7))),"") -> 0 | AU7: =IFERROR(IF(($M7=""),"",IF(OR(,$C7="Offer in Progress",$C7="WIP",$C7="WIP/Drop",$C7="WIP/New",$C7="WIP/Hold"),(TODAY()-$M7)-$AT7,"")),"") | AV7: {=IFERROR(_xlfn.IFS($AU7="","",$AU7<=15,"0-15",AND($AU7>=16,$AU7<=30),"16-30",AND($AU7>=31,$AU7<=45),"31-45",AND($AU7>=46,$AU7<=60),"46-60",AND($AU7>=61,$AU7<=90),"61-90",AND($AU7>=91),"> 90",AND($AU7>=2000),""),"")} | AW7: {=IFERROR(_xlfn.IFS(OR($M7="",$AM7=""),"",OR($C7="Offered",$C7="Joined"),($AM7-$M7)-$AT7),"")} | AX7: {=IFERROR(_xlfn.IFS(OR($M7="",$AS7=""),"",$C7="Joined",($AS7-$M7)-$AT7),"")} | AY7: =IFERROR(IF(COUNTIFS('Candidate Tracker'!$E:$E,'Positions Tracker'!$B7,'Candidate Tracker'!$C:$C,"Offer Drop")=0,"",COUNTIFS('Candidate Tracker'!$E:$E,'Positions Tracker'!$B7,'Candidate Tracker'!$C:$C,"Offer Drop")),"") | AZ7: =IFERROR(IF((COUNTIFS('Candidate Tracker'!$D:$D,"<>",'Candidate Tracker'!$D:$D,"<>Screening",'Candidate Tracker'!$D:$D,"<>Screening Pending",'Candidate Tracker'!$D:$D,"<>Candidate Hold",'Candidate Tracker'!$D:$D,"<>Position Cancelled",'Candidate Tracker'!$D:$D,"<>Internal closed")/COUNTIF('Candidate Tracker'!$D:$D,"<>"))=0,"",(COUNTIFS('Candidate Tracker'!$D:$D,"<>",'Candidate Tracker'!$D:$D,"<>Screening",'Candidate Tracker'!$D:$D,"<>Candidate Hold",'Candidate Tracker'!$D:$D,"<>Position Cancelled",'Candidate Tracker'!$D:$D,"<>Internal closed")/COUNTIF('Candidate Tracker'!$D:$D,"<>"))),"") -> 0.88111888 | BA7: =IFERROR(IF(COUNTIFS('Candidate Tracker'!$E:$E,'Positions Tracker'!$B7,'Candidate Tracker'!$I:$I,"Female")=0,"",COUNTIFS('Candidate Tracker'!$E:$E,'Positions Tracker'!$B7,'Candidate Tracker'!$I:$I,"Female")),"") | BB7: =IFERROR(IF(COUNTIFS('Candidate Tracker'!$E:$E,'Positions Tracker'!$B7,'Candidate Tracker'!$I:$I,"male")=0,"",COUNTIFS('Candidate Tracker'!$E:$E,'Positions Tracker'!$B7,'Candidate Tracker'!$I:$I,"male")),"") | BC7: =IFERROR(IF(COUNTIFS('Candidate Tracker'!$E:$E,'Positions Tracker'!$B7,'Candidate Tracker'!$C:$C,"<>WIP",'Candidate Tracker'!$C:$C,"<>Hold",'Candidate Tracker'!$C:$C,"<>Cancelled",'Candidate Tracker'!$C:$C,"<>Closed")/COUNTIFS('Candidate Tracker'!$E:$E,'Positions Tracker'!$B7)=0,"",COUNTIFS('Candidate Tracker'!$E:$E,'Positions Tracker'!$B7,'Candidate Tracker'!$C:$C,"<>WIP",'Candidate Tracker'!$C:$C,"<>Hold",'Candidate Tracker'!$C:$C,"<>Cancelled",'Candidate Tracker'!$C:$C,"<>Closed")/COUNTIFS('Candidate Tracker'!$E:$E,'Positions Tracker'!$B7)),"") | BD7: =IFERROR(IF($M7="","",TEXT($M7,"MMM-YY")),"") -> Mar-25 | BE7: =IFERROR(IF($AI7="","",TEXT($AI7,"MMM-YY")),"") -> Apr-25 | BF7: =IFERROR(IF($AM7="","",TEXT($AM7,"MMM-YY")),"") -> Apr-25 | BG7: =IFERROR(IF($AS7="","",TEXT($AS7,"MMM-YY")),"")
A8: =A7+1 -> 7 | B8: 20250697 | C8: Cancelled | D8: Position Cancelled | E8: Multimedia Designer | F8: Adobe after Effect | G8: Integrated Business Services | H8: Core Engineering | I8: Rashmin Patel | J8: External | K8: 45625 | L8: 45625 | M8: 45625 | N8: T10 | X8: Pune | Y8: Bharwade, Amruta | Z8: Bharwade, Amruta | AA8: Update as on 8th feb: 2 L1 interviews scheduled on 11 feb and 13 Feb , 1 candidate on hold Update as on 21st Feb 25 | AB8: 12 | AC8: 9 | AT8: =IFERROR(SUM(IF(AND(ISBLANK(T8),ISBLANK(Q8)),0,IF(T8="",TODAY()-Q8,T8-Q8))+IF(AND(ISBLANK(S8),ISBLANK(P8)),0,IF(S8="",TODAY()-P8,S8-P8))+IF(AND(ISBLANK(O8),ISBLANK(R8)),0,IF(R8="",TODAY()-O8,R8-O8))),"") -> 0 | AU8: =IFERROR(IF(($M8=""),"",IF(OR(,$C8="Offer in Progress",$C8="WIP",$C8="WIP/Drop",$C8="WIP/New",$C8="WIP/Hold"),(TODAY()-$M8)-$AT8,"")),"") | AV8: {=IFERROR(_xlfn.IFS($AU8="","",$AU8<=15,"0-15",AND($AU8>=16,$AU8<=30),"16-30",AND($AU8>=31,$AU8<=45),"31-45",AND($AU8>=46,$AU8<=60),"46-60",AND($AU8>=61,$AU8<=90),"61-90",AND($AU8>=91),"> 90",AND($AU8>=2000),""),"")} | AW8: {=IFERROR(_xlfn.IFS(OR($M8="",$AM8=""),"",OR($C8="Offered",$C8="Joined"),($AM8-$M8)-$AT8),"")} | AX8: {=IFERROR(_xlfn.IFS(OR($M8="",$AS8=""),"",$C8="Joined",($AS8-$M8)-$AT8),"")} | AY8: =IFERROR(IF(COUNTIFS('Candidate Tracker'!$E:$E,'Positions Tracker'!$B8,'Candidate Tracker'!$C:$C,"Offer Drop")=0,"",COUNTIFS('Candidate Tracker'!$E:$E,'Positions Tracker'!$B8,'Candidate Tracker'!$C:$C,"Offer Drop")),"") | AZ8: =IFERROR(IF((COUNTIFS('Candidate Tracker'!$D:$D,"<>",'Candidate Tracker'!$D:$D,"<>Screening",'Candidate Tracker'!$D:$D,"<>Screening Pending",'Candidate Tracker'!$D:$D,"<>Candidate Hold",'Candidate Tracker'!$D:$D,"<>Position Cancelled",'Candidate Tracker'!$D:$D,"<>Internal closed")/COUNTIF('Candidate Tracker'!$D:$D,"<>"))=0,"",(COUNTIFS('Candidate Tracker'!$D:$D,"<>",'Candidate Tracker'!$D:$D,"<>Screening",'Candidate Tracker'!$D:$D,"<>Candidate Hold",'Candidate Tracker'!$D:$D,"<>Position Cancelled",'Candidate Tracker'!$D:$D,"<>Internal closed")/COUNTIF('Candidate Tracker'!$D:$D,"<>"))),"") -> 0.88111888 | BA8: =IFERROR(IF(COUNTIFS('Candidate Tracker'!$E:$E,'Positions Tracker'!$B8,'Candidate Tracker'!$I:$I,"Female")=0,"",COUNTIFS('Candidate Tracker'!$E:$E,'Positions Tracker'!$B8,'Candidate Tracker'!$I:$I,"Female")),"") -> 1 | BB8: =IFERROR(IF(COUNTIFS('Candidate Tracker'!$E:$E,'Positions Tracker'!$B8,'Candidate Tracker'!$I:$I,"male")=0,"",COUNTIFS('Candidate Tracker'!$E:$E,'Positions Tracker'!$B8,'Candidate Tracker'!$I:$I,"male")),"") -> 7 | BC8: =IFERROR(IF(COUNTIFS('Candidate Tracker'!$E:$E,'Positions Tracker'!$B8,'Candidate Tracker'!$C:$C,"<>WIP",'Candidate Tracker'!$C:$C,"<>Hold",'Candidate Tracker'!$C:$C,"<>Cancelled",'Candidate Tracker'!$C:$C,"<>Closed")/COUNTIFS('Candidate Tracker'!$E:$E,'Positions Tracker'!$B8)=0,"",COUNTIFS('Candidate Tracker'!$E:$E,'Positions Tracker'!$B8,'Candidate Tracker'!$C:$C,"<>WIP",'Candidate Tracker'!$C:$C,"<>Hold",'Candidate Tracker'!$C:$C,"<>Cancelled",'Candidate Tracker'!$C:$C,"<>Closed")/COUNTIFS('Candidate Tracker'!$E:$E,'Positions Tracker'!$B8)),"") | BD8: =IFERROR(IF($M8="","",TEXT($M8,"MMM-YY")),"") -> Nov-24 | BE8: =IFERROR(IF($AI8="","",TEXT($AI8,"MMM-YY")),"") | BF8: =IFERROR(IF($AM8="","",TEXT($AM8,"MMM-YY")),"") | BG8: =IFERROR(IF($AS8="","",TEXT($AS8,"MMM-YY")),"")
A9: =A8+1 -> 8 | B9: 20250696 | C9: Cancelled | D9: Position Cancelled | E9: Senior Multimedia Designer | F9: Adobe after Effect | G9: Integrated Business Services | H9: Core Engineering | I9: Rashmin Patel | J9: External | K9: 45625 | L9: 45625 | M9: 45625 | N9: T8 | X9: Pune | Y9: Bharwade, Amruta | Z9: Bharwade, Amruta | AA9: Update as on 8th Feb:I shaan Deshpande Offer revovked Update as on 21st Feb 5 L1 interviews scheduled | AB9: 28 | AC9: 20 | AT9: =IFERROR(SUM(IF(AND(ISBLANK(T9),ISBLANK(Q9)),0,IF(T9="",TODAY()-Q9,T9-Q9))+IF(AND(ISBLANK(S9),ISBLANK(P9)),0,IF(S9="",TODAY()-P9,S9-P9))+IF(AND(ISBLANK(O9),ISBLANK(R9)),0,IF(R9="",TODAY()-O9,R9-O9))),"") -> 0 | AU9: =IFERROR(IF(($M9=""),"",IF(OR(,$C9="Offer in Progress",$C9="WIP",$C9="WIP/Drop",$C9="WIP/New",$C9="WIP/Hold"),(TODAY()-$M9)-$AT9,"")),"") | AV9: {=IFERROR(_xlfn.IFS($AU9="","",$AU9<=15,"0-15",AND($AU9>=16,$AU9<=30),"16-30",AND($AU9>=31,$AU9<=45),"31-45",AND($AU9>=46,$AU9<=60),"46-60",AND($AU9>=61,$AU9<=90),"61-90",AND($AU9>=91),"> 90",AND($AU9>=2000),""),"")} | AW9: {=IFERROR(_xlfn.IFS(OR($M9="",$AM9=""),"",OR($C9="Offered",$C9="Joined"),($AM9-$M9)-$AT9),"")} | AX9: {=IFERROR(_xlfn.IFS(OR($M9="",$AS9=""),"",$C9="Joined",($AS9-$M9)-$AT9),"")} | AY9: =IFERROR(IF(COUNTIFS('Candidate Tracker'!$E:$E,'Positions Tracker'!$B9,'Candidate Tracker'!$C:$C,"Offer Drop")=0,"",COUNTIFS('Candidate Tracker'!$E:$E,'Positions Tracker'!$B9,'Candidate Tracker'!$C:$C,"Offer Drop")),"") | AZ9: =IFERROR(IF((COUNTIFS('Candidate Tracker'!$D:$D,"<>",'Candidate Tracker'!$D:$D,"<>Screening",'Candidate Tracker'!$D:$D,"<>Screening Pending",'Candidate Tracker'!$D:$D,"<>Candidate Hold",'Candidate Tracker'!$D:$D,"<>Position Cancelled",'Candidate Tracker'!$D:$D,"<>Internal closed")/COUNTIF('Candidate Tracker'!$D:$D,"<>"))=0,"",(COUNTIFS('Candidate Tracker'!$D:$D,"<>",'Candidate Tracker'!$D:$D,"<>Screening",'Candidate Tracker'!$D:$D,"<>Candidate Hold",'Candidate Tracker'!$D:$D,"<>Position Cancelled",'Candidate Tracker'!$D:$D,"<>Internal closed")/COUNTIF('Candidate Tracker'!$D:$D,"<>"))),"") -> 0.88111888 | BA9: =IFERROR(IF(COUNTIFS('Candidate Tracker'!$E:$E,'Positions Tracker'!$B9,'Candidate Tracker'!$I:$I,"Female")=0,"",COUNTIFS('Candidate Tracker'!$E:$E,'Positions Tracker'!$B9,'Candidate Tracker'!$I:$I,"Female")),"") -> 2 | BB9: =IFERROR(IF(COUNTIFS('Candidate Tracker'!$E:$E,'Positions Tracker'!$B9,'Candidate Tracker'!$I:$I,"male")=0,"",COUNTIFS('Candidate Tracker'!$E:$E,'Positions Tracker'!$B9,'Candidate Tracker'!$I:$I,"male")),"") -> 10 | BC9: =IFERROR(IF(COUNTIFS('Candidate Tracker'!$E:$E,'Positions Tracker'!$B9,'Candidate Tracker'!$C:$C,"<>WIP",'Candidate Tracker'!$C:$C,"<>Hold",'Candidate Tracker'!$C:$C,"<>Cancelled",'Candidate Tracker'!$C:$C,"<>Closed")/COUNTIFS('Candidate Tracker'!$E:$E,'Positions Tracker'!$B9)=0,"",COUNTIFS('Candidate Tracker'!$E:$E,'Positions Tracker'!$B9,'Candidate Tracker'!$C:$C,"<>WIP",'Candidate Tracker'!$C:$C,"<>Hold",'Candidate Tracker'!$C:$C,"<>Cancelled",'Candidate Tracker'!$C:$C,"<>Closed")/COUNTIFS('Candidate Tracker'!$E:$E,'Positions Tracker'!$B9)),"") | BD9: =IFERROR(IF($M9="","",TEXT($M9,"MMM-YY")),"") -> Nov-24 | BE9: =IFERROR(IF($AI9="","",TEXT($AI9,"MMM-YY")),"") | BF9: =IFERROR(IF($AM9="","",TEXT($AM9,"MMM-YY")),"") | BG9: =IFERROR(IF($AS9="","",TEXT($AS9,"MMM-YY")),"")
A10: =A9+1 -> 9 | B10: 20251179 | C10: Cancelled | D10: Position Cancelled | E10: Sr Test Engineer | F10: HIL | G10: Integrated Business Services | H10: Core Engineering | I10: Ankur Singh | J10: External | K10: 45643 | L10: 45643 | M10: 45643 | N10: T11 | X10: Pune | Y10: Bharwade, Amruta | Z10: Bharwade, Amruta | AA10: Update as on 21st Feb 25- Position cancelled in the sys | AT10: =IFERROR(SUM(IF(AND(ISBLANK(T10),ISBLANK(Q10)),0,IF(T10="",TODAY()-Q10,T10-Q10))+IF(AND(ISBLANK(S10),ISBLANK(P10)),0,IF(S10="",TODAY()-P10,S10-P10))+IF(AND(ISBLANK(O10),ISBLANK(R10)),0,IF(R10="",TODAY()-O10,R10-O10))),"") -> 0 | AU10: =IFERROR(IF(($M10=""),"",IF(OR(,$C10="Offer in Progress",$C10="WIP",$C10="WIP/Drop",$C10="WIP/New",$C10="WIP/Hold"),(TODAY()-$M10)-$AT10,"")),"") | AV10: {=IFERROR(_xlfn.IFS($AU10="","",$AU10<=15,"0-15",AND($AU10>=16,$AU10<=30),"16-30",AND($AU10>=31,$AU10<=45),"31-45",AND($AU10>=46,$AU10<=60),"46-60",AND($AU10>=61,$AU10<=90),"61-90",AND($AU10>=91),"> 90",AND($AU10>=2000),""),"")} | AW10: {=IFERROR(_xlfn.IFS(OR($M10="",$AM10=""),"",OR($C10="Offered",$C10="Joined"),($AM10-$M10)-$AT10),"")} | AX10: {=IFERROR(_xlfn.IFS(OR($M10="",$AS10=""),"",$C10="Joined",($AS10-$M10)-$AT10),"")} | AY10: =IFERROR(IF(COUNTIFS('Candidate Tracker'!$E:$E,'Positions Tracker'!$B10,'Candidate Tracker'!$C:$C,"Offer Drop")=0,"",COUNTIFS('Candidate Tracker'!$E:$E,'Positions Tracker'!$B10,'Candidate Tracker'!$C:$C,"Offer Drop")),"") | AZ10: =IFERROR(IF((COUNTIFS('Candidate Tracker'!$D:$D,"<>",'Candidate Tracker'!$D:$D,"<>Screening",'Candidate Tracker'!$D:$D,"<>Screening Pending",'Candidate Tracker'!$D:$D,"<>Candidate Hold",'Candidate Tracker'!$D:$D,"<>Position Cancelled",'Candidate Tracker'!$D:$D,"<>Internal closed")/COUNTIF('Candidate Tracker'!$D:$D,"<>"))=0,"",(COUNTIFS('Candidate Tracker'!$D:$D,"<>",'Candidate Tracker'!$D:$D,"<>Screening",'Candidate Tracker'!$D:$D,"<>Candidate Hold",'Candidate Tracker'!$D:$D,"<>Position Cancelled",'Candidate Tracker'!$D:$D,"<>Internal closed")/COUNTIF('Candidate Tracker'!$D:$D,"<>"))),"") -> 0.88111888 | BA10: =IFERROR(IF(COUNTIFS('Candidate Tracker'!$E:$E,'Positions Tracker'!$B10,'Candidate Tracker'!$I:$I,"Female")=0,"",COUNTIFS('Candidate Tracker'!$E:$E,'Positions Tracker'!$B10,'Candidate Tracker'!$I:$I,"Female")),"") | BB10: =IFERROR(IF(COUNTIFS('Candidate Tracker'!$E:$E,'Positions Tracker'!$B10,'Candidate Tracker'!$I:$I,"male")=0,"",COUNTIFS('Candidate Tracker'!$E:$E,'Positions Tracker'!$B10,'Candidate Tracker'!$I:$I,"male")),"") | BC10: =IFERROR(IF(COUNTIFS('Candidate Tracker'!$E:$E,'Positions Tracker'!$B10,'Candidate Tracker'!$C:$C,"<>WIP",'Candidate Tracker'!$C:$C,"<>Hold",'Candidate Tracker'!$C:$C,"<>Cancelled",'Candidate Tracker'!$C:$C,"<>Closed")/COUNTIFS('Candidate Tracker'!$E:$E,'Positions Tracker'!$B10)=0,"",COUNTIFS('Candidate Tracker'!$E:$E,'Positions Tracker'!$B10,'Candidate Tracker'!$C:$C,"<>WIP",'Candidate Tracker'!$C:$C,"<>Hold",'Candidate Tracker'!$C:$C,"<>Cancelled",'Candidate Tracker'!$C:$C,"<>Closed")/COUNTIFS('Candidate Tracker'!$E:$E,'Positions Tracker'!$B10)),"") | BD10: =IFERROR(IF($M10="","",TEXT($M10,"MMM-YY")),"") -> Dec-24 | BE10: =IFERROR(IF($AI10="","",TEXT($AI10,"MMM-YY")),"") | BF10: =IFERROR(IF($AM10="","",TEXT($AM10,"MMM-YY")),"") | BG10: =IFERROR(IF($AS10="","",TEXT($AS10,"MMM-YY")),"")
A11: =A10+1 -> 10 | B11: 20242803 | C11: Hold | D11: Hold | E11: Mid Mendix Developer | F11: Mendix | G11: Integrated Business Services | H11: GSP | I11: Lucian | K11: 45580 | L11: 45580 | M11: 45710 | N11: T11 | O11: 45719 | R11: 45737 | X11: Pune | Y11: Bharwade, Amruta | Z11: Bharwade, Amruta | AA11: 21st April 25: 3 L1 interviews scheduled 12th April: 3 Profiles shared for shortlisting feedback awaited from 9th April 7th April 25: 5 profiles shared for shortlisting 28th Feb 25: 1 candidate scheduled 28th Feb 252 candidates L1 scheduled 3rd and 4th March 21st Feb 25- 3 L1 interviews scheidledUpdate as on 8th Feb 25Abhishek J Offer Declined, Satyjeet Pardeshi TBO Update as on 21st Feb 3 L1 scheduled, 2 L1 to be scheduled | AB11: 38 | AC11: 30 | AD11: 12 | AT11: =IFERROR(SUM(IF(AND(ISBLANK(T11),ISBLANK(Q11)),0,IF(T11="",TODAY()-Q11,T11-Q11))+IF(AND(ISBLANK(S11),ISBLANK(P11)),0,IF(S11="",TODAY()-P11,S11-P11))+IF(AND(ISBLANK(O11),ISBLANK(R11)),0,IF(R11="",TODAY()-O11,R11-O11))),"") -> 18 | AU11: =IFERROR(IF(($M11=""),"",IF(OR(,$C11="Offer in Progress",$C11="WIP",$C11="WIP/Drop",$C11="WIP/New",$C11="WIP/Hold"),(TODAY()-$M11)-$AT11,"")),"") | AV11: {=IFERROR(_xlfn.IFS($AU11="","",$AU11<=15,"0-15",AND($AU11>=16,$AU11<=30),"16-30",AND($AU11>=31,$AU11<=45),"31-45",AND($AU11>=46,$AU11<=60),"46-60",AND($AU11>=61,$AU11<=90),"61-90",AND($AU11>=91),"> 90",AND($AU11>=2000),""),"")} | AW11: {=IFERROR(_xlfn.IFS(OR($M11="",$AM11=""),"",OR($C11="Offered",$C11="Joined"),($AM11-$M11)-$AT11),"")} | AX11: {=IFERROR(_xlfn.IFS(OR($M11="",$AS11=""),"",$C11="Joined",($AS11-$M11)-$AT11),"")} | AY11: =IFERROR(IF(COUNTIFS('Candidate Tracker'!$E:$E,'Positions Tracker'!$B11,'Candidate Tracker'!$C:$C,"Offer Drop")=0,"",COUNTIFS('Candidate Tracker'!$E:$E,'Positions Tracker'!$B11,'Candidate Tracker'!$C:$C,"Offer Drop")),"") | AZ11: =IFERROR(IF((COUNTIFS('Candidate Tracker'!$D:$D,"<>",'Candidate Tracker'!$D:$D,"<>Screening",'Candidate Tracker'!$D:$D,"<>Screening Pending",'Candidate Tracker'!$D:$D,"<>Candidate Hold",'Candidate Tracker'!$D:$D,"<>Position Cancelled",'Candidate Tracker'!$D:$D,"<>Internal closed")/COUNTIF('Candidate Tracker'!$D:$D,"<>"))=0,"",(COUNTIFS('Candidate Tracker'!$D:$D,"<>",'Candidate Tracker'!$D:$D,"<>Screening",'Candidate Tracker'!$D:$D,"<>Candidate Hold",'Candidate Tracker'!$D:$D,"<>Position Cancelled",'Candidate Tracker'!$D:$D,"<>Internal closed")/COUNTIF('Candidate Tracker'!$D:$D,"<>"))),"") -> 0.88111888 | BA11: =IFERROR(IF(COUNTIFS('Candidate Tracker'!$E:$E,'Positions Tracker'!$B11,'Candidate Tracker'!$I:$I,"Female")=0,"",COUNTIFS('Candidate Tracker'!$E:$E,'Positions Tracker'!$B11,'Candidate Tracker'!$I:$I,"Female")),"") -> 14 | BB11: =IFERROR(IF(COUNTIFS('Candidate Tracker'!$E:$E,'Positions Tracker'!$B11,'Candidate Tracker'!$I:$I,"male")=0,"",COUNTIFS('Candidate Tracker'!$E:$E,'Positions Tracker'!$B11,'Candidate Tracker'!$I:$I,"male")),"") -> 31 | BC11: =IFERROR(IF(COUNTIFS('Candidate Tracker'!$E:$E,'Positions Tracker'!$B11,'Candidate Tracker'!$C:$C,"<>WIP",'Candidate Tracker'!$C:$C,"<>Hold",'Candidate Tracker'!$C:$C,"<>Cancelled",'Candidate Tracker'!$C:$C,"<>Closed")/COUNTIFS('Candidate Tracker'!$E:$E,'Positions Tracker'!$B11)=0,"",COUNTIFS('Candidate Tracker'!$E:$E,'Positions Tracker'!$B11,'Candidate Tracker'!$C:$C,"<>WIP",'Candidate Tracker'!$C:$C,"<>Hold",'Candidate Tracker'!$C:$C,"<>Cancelled",'Candidate Tracker'!$C:$C,"<>Closed")/COUNTIFS('Candidate Tracker'!$E:$E,'Positions Tracker'!$B11)),"") | BD11: =IFERROR(IF($M11="","",TEXT($M11,"MMM-YY")),"") -> Feb-25 | BE11: =IFERROR(IF($AI11="","",TEXT($AI11,"MMM-YY")),"") | BF11: =IFERROR(IF($AM11="","",TEXT($AM11,"MMM-YY")),"") | BG11: =IFERROR(IF($AS11="","",TEXT($AS11,"MMM-YY")),"")
A12: =A11+1 -> 11 | B12: 20245321 | C12: Hold | D12: Hold | E12: Sr Mendix Developer | F12: Mendix | G12: Integrated Business Services | H12: GSP | I12: Lucian | K12: 45580 | L12: 45580 | M12: 45580 | N12: T11 | O12: 45649 | R12: 45664 | X12: Pune | Y12: Bharwade, Amruta | Z12: Bharwade, Amruta | AA12: 21st April 25: 2 L1 interviews scheduled 12th April 25: 2 L1 feedback is pending 2 L1 interviews scheduled 7th April 25: 2 L1 interviews scheduled, 2 L1 interview feedback pending 28-Feb-25: L1 interview to be schedule 4 and 5 March . 8th Feb- 2 L1 interview to be scheduled, Update as on 21st Feb 25 3 L1 interviews scheduled | AB12: 38 | AC12: 29 | AD12: 10 | AT12: =IFERROR(SUM(IF(AND(ISBLANK(T12),ISBLANK(Q12)),0,IF(T12="",TODAY()-Q12,T12-Q12))+IF(AND(ISBLANK(S12),ISBLANK(P12)),0,IF(S12="",TODAY()-P12,S12-P12))+IF(AND(ISBLANK(O12),ISBLANK(R12)),0,IF(R12="",TODAY()-O12,R12-O12))),"") -> 15 | AU12: =IFERROR(IF(($M12=""),"",IF(OR(,$C12="Offer in Progress",$C12="WIP",$C12="WIP/Drop",$C12="WIP/New",$C12="WIP/Hold"),(TODAY()-$M12)-$AT12,"")),"") | AV12: {=IFERROR(_xlfn.IFS($AU12="","",$AU12<=15,"0-15",AND($AU12>=16,$AU12<=30),"16-30",AND($AU12>=31,$AU12<=45),"31-45",AND($AU12>=46,$AU12<=60),"46-60",AND($AU12>=61,$AU12<=90),"61-90",AND($AU12>=91),"> 90",AND($AU12>=2000),""),"")} | AW12: {=IFERROR(_xlfn.IFS(OR($M12="",$AM12=""),"",OR($C12="Offered",$C12="Joined"),($AM12-$M12)-$AT12),"")} | AX12: {=IFERROR(_xlfn.IFS(OR($M12="",$AS12=""),"",$C12="Joined",($AS12-$M12)-$AT12),"")} | AY12: =IFERROR(IF(COUNTIFS('Candidate Tracker'!$E:$E,'Positions Tracker'!$B12,'Candidate Tracker'!$C:$C,"Offer Drop")=0,"",COUNTIFS('Candidate Tracker'!$E:$E,'Positions Tracker'!$B12,'Candidate Tracker'!$C:$C,"Offer Drop")),"") | AZ12: =IFERROR(IF((COUNTIFS('Candidate Tracker'!$D:$D,"<>",'Candidate Tracker'!$D:$D,"<>Screening",'Candidate Tracker'!$D:$D,"<>Screening Pending",'Candidate Tracker'!$D:$D,"<>Candidate Hold",'Candidate Tracker'!$D:$D,"<>Position Cancelled",'Candidate Tracker'!$D:$D,"<>Internal closed")/COUNTIF('Candidate Tracker'!$D:$D,"<>"))=0,"",(COUNTIFS('Candidate Tracker'!$D:$D,"<>",'Candidate Tracker'!$D:$D,"<>Screening",'Candidate Tracker'!$D:$D,"<>Candidate Hold",'Candidate Tracker'!$D:$D,"<>Position Cancelled",'Candidate Tracker'!$D:$D,"<>Internal closed")/COUNTIF('Candidate Tracker'!$D:$D,"<>"))),"") -> 0.88111888 | BA12: =IFERROR(IF(COUNTIFS('Candidate Tracker'!$E:$E,'Positions Tracker'!$B12,'Candidate Tracker'!$I:$I,"Female")=0,"",COUNTIFS('Candidate Tracker'!$E:$E,'Positions Tracker'!$B12,'Candidate Tracker'!$I:$I,"Female")),"") -> 9 | BB12: =IFERROR(IF(COUNTIFS('Candidate Tracker'!$E:$E,'Positions Tracker'!$B12,'Candidate Tracker'!$I:$I,"male")=0,"",COUNTIFS('Candidate Tracker'!$E:$E,'Positions Tracker'!$B12,'Candidate Tracker'!$I:$I,"male")),"") -> 18 | BC12: =IFERROR(IF(COUNTIFS('Candidate Tracker'!$E:$E,'Positions Tracker'!$B12,'Candidate Tracker'!$C:$C,"<>WIP",'Candidate Tracker'!$C:$C,"<>Hold",'Candidate Tracker'!$C:$C,"<>Cancelled",'Candidate Tracker'!$C:$C,"<>Closed")/COUNTIFS('Candidate Tracker'!$E:$E,'Positions Tracker'!$B12)=0,"",COUNTIFS('Candidate Tracker'!$E:$E,'Positions Tracker'!$B12,'Candidate Tracker'!$C:$C,"<>WIP",'Candidate Tracker'!$C:$C,"<>Hold",'Candidate Tracker'!$C:$C,"<>Cancelled",'Candidate Tracker'!$C:$C,"<>Closed")/COUNTIFS('Candidate Tracker'!$E:$E,'Positions Tracker'!$B12)),"") | BD12: =IFERROR(IF($M12="","",TEXT($M12,"MMM-YY")),"") -> Oct-24 | BE12: =IFERROR(IF($AI12="","",TEXT($AI12,"MMM-YY")),"") | BF12: =IFERROR(IF($AM12="","",TEXT($AM12,"MMM-YY")),"") | BG12: =IFERROR(IF($AS12="","",TEXT($AS12,"MMM-YY")),"")
A13: =A12+1 -> 12 | B13: 20243902 | C13: Joined | D13: Joined | E13: Electrical Design Engineer | F13: Revit, Load Calculations | G13: Integrated Business Services | H13: Core Engineering | I13: Vinayak Bhat | J13: External | K13: 45476 | L13: 45476 | M13: 45660 | N13: T8 | O13: 45681 | P13: 45727 | R13: 45748 | X13: Pune | Y13: Bharwade, Amruta | Z13: Bharwade, Amruta | AA13: 7th April 25: 1 LOB interview TBS, 1 L1 interview scheduled Update as on 8th Feb- 3 L1 to be scheduled Update as on 21st Feb 25-1 F2f scheduled | AB13: 25 | AC13: 17 | AE13: Utkarsh Patil | AF13: 9637764488 | AG13: patilutkarsh025@gmail.com | AH13: Male | AI13: 45756 | AK13: Pune | AL13: 971942 | AM13: 45819 | AN13: 45819 | AP13: 45821 | AQ13: 45821 | AR13: 45855 | AS13: 45859 | AT13: =IFERROR(SUM(IF(AND(ISBLANK(T13),ISBLANK(Q13)),0,IF(T13="",TODAY()-Q13,T13-Q13))+IF(AND(ISBLANK(S13),ISBLANK(P13)),0,IF(S13="",TODAY()-P13,S13-P13))+IF(AND(ISBLANK(O13),ISBLANK(R13)),0,IF(R13="",TODAY()-O13,R13-O13))),"") -> 341 | AU13: =IFERROR(IF(($M13=""),"",IF(OR(,$C13="Offer in Progress",$C13="WIP",$C13="WIP/Drop",$C13="WIP/New",$C13="WIP/Hold"),(TODAY()-$M13)-$AT13,"")),"") | AV13: {=IFERROR(_xlfn.IFS($AU13="","",$AU13<=15,"0-15",AND($AU13>=16,$AU13<=30),"16-30",AND($AU13>=31,$AU13<=45),"31-45",AND($AU13>=46,$AU13<=60),"46-60",AND($AU13>=61,$AU13<=90),"61-90",AND($AU13>=91),"> 90",AND($AU13>=2000),""),"")} | AW13: {=IFERROR(_xlfn.IFS(OR($M13="",$AM13=""),"",OR($C13="Offered",$C13="Joined"),($AM13-$M13)-$AT13),"")} -> -182 | AX13: {=IFERROR(_xlfn.IFS(OR($M13="",$AS13=""),"",$C13="Joined",($AS13-$M13)-$AT13),"")} -> -142 | AY13: =IFERROR(IF(COUNTIFS('Candidate Tracker'!$E:$E,'Positions Tracker'!$B13,'Candidate Tracker'!$C:$C,"Offer Drop")=0,"",COUNTIFS('Candidate Tracker'!$E:$E,'Positions Tracker'!$B13,'Candidate Tracker'!$C:$C,"Offer Drop")),"") | AZ13: =IFERROR(IF((COUNTIFS('Candidate Tracker'!$D:$D,"<>",'Candidate Tracker'!$D:$D,"<>Screening",'Candidate Tracker'!$D:$D,"<>Screening Pending",'Candidate Tracker'!$D:$D,"<>Candidate Hold",'Candidate Tracker'!$D:$D,"<>Position Cancelled",'Candidate Tracker'!$D:$D,"<>Internal closed")/COUNTIF('Candidate Tracker'!$D:$D,"<>"))=0,"",(COUNTIFS('Candidate Tracker'!$D:$D,"<>",'Candidate Tracker'!$D:$D,"<>Screening",'Candidate Tracker'!$D:$D,"<>Candidate Hold",'Candidate Tracker'!$D:$D,"<>Position Cancelled",'Candidate Tracker'!$D:$D,"<>Internal closed")/COUNTIF('Candidate Tracker'!$D:$D,"<>"))),"") -> 0.88111888 | BA13: =IFERROR(IF(COUNTIFS('Candidate Tracker'!$E:$E,'Positions Tracker'!$B13,'Candidate Tracker'!$I:$I,"Female")=0,"",COUNTIFS('Candidate Tracker'!$E:$E,'Positions Tracker'!$B13,'Candidate Tracker'!$I:$I,"Female")),"") -> 2 | BB13: =IFERROR(IF(COUNTIFS('Candidate Tracker'!$E:$E,'Positions Tracker'!$B13,'Candidate Tracker'!$I:$I,"male")=0,"",COUNTIFS('Candidate Tracker'!$E:$E,'Positions Tracker'!$B13,'Candidate Tracker'!$I:$I,"male")),"") -> 13 | BC13: =IFERROR(IF(COUNTIFS('Candidate Tracker'!$E:$E,'Positions Tracker'!$B13,'Candidate Tracker'!$C:$C,"<>WIP",'Candidate Tracker'!$C:$C,"<>Hold",'Candidate Tracker'!$C:$C,"<>Cancelled",'Candidate Tracker'!$C:$C,"<>Closed")/COUNTIFS('Candidate Tracker'!$E:$E,'Positions Tracker'!$B13)=0,"",COUNTIFS('Candidate Tracker'!$E:$E,'Positions Tracker'!$B13,'Candidate Tracker'!$C:$C,"<>WIP",'Candidate Tracker'!$C:$C,"<>Hold",'Candidate Tracker'!$C:$C,"<>Cancelled",'Candidate Tracker'!$C:$C,"<>Closed")/COUNTIFS('Candidate Tracker'!$E:$E,'Positions Tracker'!$B13)),"") | BD13: =IFERROR(IF($M13="","",TEXT($M13,"MMM-YY")),"") -> Jan-25 | BE13: =IFERROR(IF($AI13="","",TEXT($AI13,"MMM-YY")),"") -> Apr-25 | BF13: =IFERROR(IF($AM13="","",TEXT($AM13,"MMM-YY")),"") -> Jun-25 | BG13: =IFERROR(IF($AS13="","",TEXT($AS13,"MMM-YY")),"") -> Jul-25
A14: =A13+1 -> 13 | B14: 20252045 | C14: Joined | D14: Joined | E14: Associate Technical Publication | F14: CAM, DAM | G14: Integrated Business Services | H14: Core Engineering | I14: Hemantkumar shinde | J14: Referral | K14: 45691 | L14: 45691 | M14: 45691 | N14: T8 | X14: Pune | Y14: Bharwade, Amruta | Z14: Bharwade, Amruta | AA14: Update as on 8th Feb: Siddheshwar Patil comp <80% Uodate as on 21st Feb Siddheshwar Patil Offer accepted | AB14: 5 | AC14: 5 | AE14: Siddheshwar Patil | AF14: 8766529114 | AG14: sid.patil1553@gmail.com | AH14: Male | AI14: 45693 | AJ14: 45700 | AK14: Pune | AL14: 700000 | AM14: 45699 | AN14: 45702 | AP14: 45706 | AQ14: 45706 | AR14: 45751 | AS14: 45740 | AT14: =IFERROR(SUM(IF(AND(ISBLANK(T14),ISBLANK(Q14)),0,IF(T14="",TODAY()-Q14,T14-Q14))+IF(AND(ISBLANK(S14),ISBLANK(P14)),0,IF(S14="",TODAY()-P14,S14-P14))+IF(AND(ISBLANK(O14),ISBLANK(R14)),0,IF(R14="",TODAY()-O14,R14-O14))),"") -> 0 | AU14: =IFERROR(IF(($M14=""),"",IF(OR(,$C14="Offer in Progress",$C14="WIP",$C14="WIP/Drop",$C14="WIP/New",$C14="WIP/Hold"),(TODAY()-$M14)-$AT14,"")),"") | AV14: {=IFERROR(_xlfn.IFS($AU14="","",$AU14<=15,"0-15",AND($AU14>=16,$AU14<=30),"16-30",AND($AU14>=31,$AU14<=45),"31-45",AND($AU14>=46,$AU14<=60),"46-60",AND($AU14>=61,$AU14<=90),"61-90",AND($AU14>=91),"> 90",AND($AU14>=2000),""),"")} | AW14: {=IFERROR(_xlfn.IFS(OR($M14="",$AM14=""),"",OR($C14="Offered",$C14="Joined"),($AM14-$M14)-$AT14),"")} -> 8 | AX14: {=IFERROR(_xlfn.IFS(OR($M14="",$AS14=""),"",$C14="Joined",($AS14-$M14)-$AT14),"")} -> 49 | AY14: =IFERROR(IF(COUNTIFS('Candidate Tracker'!$E:$E,'Positions Tracker'!$B14,'Candidate Tracker'!$C:$C,"Offer Drop")=0,"",COUNTIFS('Candidate Tracker'!$E:$E,'Positions Tracker'!$B14,'Candidate Tracker'!$C:$C,"Offer Drop")),"") | AZ14: =IFERROR(IF((COUNTIFS('Candidate Tracker'!$D:$D,"<>",'Candidate Tracker'!$D:$D,"<>Screening",'Candidate Tracker'!$D:$D,"<>Screening Pending",'Candidate Tracker'!$D:$D,"<>Candidate Hold",'Candidate Tracker'!$D:$D,"<>Position Cancelled",'Candidate Tracker'!$D:$D,"<>Internal closed")/COUNTIF('Candidate Tracker'!$D:$D,"<>"))=0,"",(COUNTIFS('Candidate Tracker'!$D:$D,"<>",'Candidate Tracker'!$D:$D,"<>Screening",'Candidate Tracker'!$D:$D,"<>Candidate Hold",'Candidate Tracker'!$D:$D,"<>Position Cancelled",'Candidate Tracker'!$D:$D,"<>Internal closed")/COUNTIF('Candidate Tracker'!$D:$D,"<>"))),"") -> 0.88111888 | BA14: =IFERROR(IF(COUNTIFS('Candidate Tracker'!$E:$E,'Positions Tracker'!$B14,'Candidate Tracker'!$I:$I,"Female")=0,"",COUNTIFS('Candidate Tracker'!$E:$E,'Positions Tracker'!$B14,'Candidate Tracker'!$I:$I,"Female")),"") | BB14: =IFERROR(IF(COUNTIFS('Candidate Tracker'!$E:$E,'Positions Tracker'!$B14,'Candidate Tracker'!$I:$I,"male")=0,"",COUNTIFS('Candidate Tracker'!$E:$E,'Positions Tracker'!$B14,'Candidate Tracker'!$I:$I,"male")),"") -> 1 | BC14: =IFERROR(IF(COUNTIFS('Candidate Tracker'!$E:$E,'Positions Tracker'!$B14,'Candidate Tracker'!$C:$C,"<>WIP",'Candidate Tracker'!$C:$C,"<>Hold",'Candidate Tracker'!$C:$C,"<>Cancelled",'Candidate Tracker'!$C:$C,"<>Closed")/COUNTIFS('Candidate Tracker'!$E:$E,'Positions Tracker'!$B14)=0,"",COUNTIFS('Candidate Tracker'!$E:$E,'Positions Tracker'!$B14,'Candidate Tracker'!$C:$C,"<>WIP",'Candidate Tracker'!$C:$C,"<>Hold",'Candidate Tracker'!$C:$C,"<>Cancelled",'Candidate Tracker'!$C:$C,"<>Closed")/COUNTIFS('Candidate Tracker'!$E:$E,'Positions Tracker'!$B14)),"") -> 1 | BD14: =IFERROR(IF($M14="","",TEXT($M14,"MMM-YY")),"") -> Feb-25 | BE14: =IFERROR(IF($AI14="","",TEXT($AI14,"MMM-YY")),"") -> Feb-25 | BF14: =IFERROR(IF($AM14="","",TEXT($AM14,"MMM-YY")),"") -> Feb-25 | BG14: =IFERROR(IF($AS14="","",TEXT($AS14,"MMM-YY")),"") -> Mar-25
A15: =A14+1 -> 14 | B15: 20252046 | C15: Joined | D15: Joined | E15: Engineer I Technical Publications IX | F15: CAM, DAM | G15: Integrated Business Services | H15: Core Engineering | I15: Hemantkumar shinde | J15: Referral | K15: 45691 | L15: 45691 | M15: 45691 | N15: T10 | X15: Pune | Y15: Bharwade, Amruta | Z15: Bharwade, Amruta | AA15: Update as on 8th Feb: comp approval shared with HM on 7th Feb, approval awaited Update as on 21st Feb: Raja Kumar yadav offered | AB15: 10 | AC15: 6 | AE15: Raja Kumar Yadhav | AF15: 9973287316 | AG15: raja.rex92@gmail.com | AH15: Male | AI15: 45695 | AJ15: 45706 | AK15: Pune | AL15: 1050000 | AM15: 45709 | AN15: 45712 | AP15: 45713 | AQ15: 45713 | AR15: 45807 | AS15: 45810 | AT15: =IFERROR(SUM(IF(AND(ISBLANK(T15),ISBLANK(Q15)),0,IF(T15="",TODAY()-Q15,T15-Q15))+IF(AND(ISBLANK(S15),ISBLANK(P15)),0,IF(S15="",TODAY()-P15,S15-P15))+IF(AND(ISBLANK(O15),ISBLANK(R15)),0,IF(R15="",TODAY()-O15,R15-O15))),"") -> 0 | AU15: =IFERROR(IF(($M15=""),"",IF(OR(,$C15="Offer in Progress",$C15="WIP",$C15="WIP/Drop",$C15="WIP/New",$C15="WIP/Hold"),(TODAY()-$M15)-$AT15,"")),"") | AV15: {=IFERROR(_xlfn.IFS($AU15="","",$AU15<=15,"0-15",AND($AU15>=16,$AU15<=30),"16-30",AND($AU15>=31,$AU15<=45),"31-45",AND($AU15>=46,$AU15<=60),"46-60",AND($AU15>=61,$AU15<=90),"61-90",AND($AU15>=91),"> 90",AND($AU15>=2000),""),"")} | AW15: {=IFERROR(_xlfn.IFS(OR($M15="",$AM15=""),"",OR($C15="Offered",$C15="Joined"),($AM15-$M15)-$AT15),"")} -> 18 | AX15: {=IFERROR(_xlfn.IFS(OR($M15="",$AS15=""),"",$C15="Joined",($AS15-$M15)-$AT15),"")} -> 119 | AY15: =IFERROR(IF(COUNTIFS('Candidate Tracker'!$E:$E,'Positions Tracker'!$B15,'Candidate Tracker'!$C:$C,"Offer Drop")=0,"",COUNTIFS('Candidate Tracker'!$E:$E,'Positions Tracker'!$B15,'Candidate Tracker'!$C:$C,"Offer Drop")),"") | AZ15: =IFERROR(IF((COUNTIFS('Candidate Tracker'!$D:$D,"<>",'Candidate Tracker'!$D:$D,"<>Screening",'Candidate Tracker'!$D:$D,"<>Screening Pending",'Candidate Tracker'!$D:$D,"<>Candidate Hold",'Candidate Tracker'!$D:$D,"<>Position Cancelled",'Candidate Tracker'!$D:$D,"<>Internal closed")/COUNTIF('Candidate Tracker'!$D:$D,"<>"))=0,"",(COUNTIFS('Candidate Tracker'!$D:$D,"<>",'Candidate Tracker'!$D:$D,"<>Screening",'Candidate Tracker'!$D:$D,"<>Candidate Hold",'Candidate Tracker'!$D:$D,"<>Position Cancelled",'Candidate Tracker'!$D:$D,"<>Internal closed")/COUNTIF('Candidate Tracker'!$D:$D,"<>"))),"") -> 0.88111888 | BA15: =IFERROR(IF(COUNTIFS('Candidate Tracker'!$E:$E,'Positions Tracker'!$B15,'Candidate Tracker'!$I:$I,"Female")=0,"",COUNTIFS('Candidate Tracker'!$E:$E,'Positions Tracker'!$B15,'Candidate Tracker'!$I:$I,"Female")),"") | BB15: =IFERROR(IF(COUNTIFS('Candidate Tracker'!$E:$E,'Positions Tracker'!$B15,'Candidate Tracker'!$I:$I,"male")=0,"",COUNTIFS('Candidate Tracker'!$E:$E,'Positions Tracker'!$B15,'Candidate Tracker'!$I:$I,"male")),"") -> 1 | BC15: =IFERROR(IF(COUNTIFS('Candidate Tracker'!$E:$E,'Positions Tracker'!$B15,'Candidate Tracker'!$C:$C,"<>WIP",'Candidate Tracker'!$C:$C,"<>Hold",'Candidate Tracker'!$C:$C,"<>Cancelled",'Candidate Tracker'!$C:$C,"<>Closed")/COUNTIFS('Candidate Tracker'!$E:$E,'Positions Tracker'!$B15)=0,"",COUNTIFS('Candidate Tracker'!$E:$E,'Positions Tracker'!$B15,'Candidate Tracker'!$C:$C,"<>WIP",'Candidate Tracker'!$C:$C,"<>Hold",'Candidate Tracker'!$C:$C,"<>Cancelled",'Candidate Tracker'!$C:$C,"<>Closed")/COUNTIFS('Candidate Tracker'!$E:$E,'Positions Tracker'!$B15)),"") -> 1 | BD15: =IFERROR(IF($M15="","",TEXT($M15,"MMM-YY")),"") -> Feb-25 | BE15: =IFERROR(IF($AI15="","",TEXT($AI15,"MMM-YY")),"") -> Feb-25 | BF15: =IFERROR(IF($AM15="","",TEXT($AM15,"MMM-YY")),"") -> Feb-25 | BG15: =IFERROR(IF($AS15="","",TEXT($AS15,"MMM-YY")),"") -> Jun-25
A16: =A15+1 -> 15 | B16: 20254425 | C16: Joined | D16: Joined | E16: Manager Materials and Manufacturing Planning | F16: PPC | G16: India Business | H16: Core Engineering | I16: Ankush Mehta | J16: External | K16: 45580 | L16: 45580 | M16: 45580 | N16: M2 | O16: 45615 | P16: 45649 | Q16: 45706 | U16: 13 | X16: Pune | Y16: Bharwade, Amruta | Z16: Bharwade, Amruta | AA16: Update on 8th feb-2 Interviews scheduled, 3 profiles shared for shortlisting Update as on 21st Feb 1 final interview is scheduled | AB16: 27 | AC16: 24 | AE16: Amar Lahoti | AF16: 8983128692 | AG16: amar.lahoti123@gmail.com | AH16: Male | AI16: 45742 | AJ16: 45764 | AK16: Pune | AL16: 2341410 | AM16: 45764 | AN16: 45764 | AP16: 45765 | AQ16: 45765 | AR16: 45827 | AS16: 45831 | AT16: =IFERROR(SUM(IF(AND(ISBLANK(T16),ISBLANK(Q16)),0,IF(T16="",TODAY()-Q16,T16-Q16))+IF(AND(ISBLANK(S16),ISBLANK(P16)),0,IF(S16="",TODAY()-P16,S16-P16))+IF(AND(ISBLANK(O16),ISBLANK(R16)),0,IF(R16="",TODAY()-O16,R16-O16))),"") -> 1033 | AU16: =IFERROR(IF(($M16=""),"",IF(OR(,$C16="Offer in Progress",$C16="WIP",$C16="WIP/Drop",$C16="WIP/New",$C16="WIP/Hold"),(TODAY()-$M16)-$AT16,"")),"") | AV16: {=IFERROR(_xlfn.IFS($AU16="","",$AU16<=15,"0-15",AND($AU16>=16,$AU16<=30),"16-30",AND($AU16>=31,$AU16<=45),"31-45",AND($AU16>=46,$AU16<=60),"46-60",AND($AU16>=61,$AU16<=90),"61-90",AND($AU16>=91),"> 90",AND($AU16>=2000),""),"")} | AW16: {=IFERROR(_xlfn.IFS(OR($M16="",$AM16=""),"",OR($C16="Offered",$C16="Joined"),($AM16-$M16)-$AT16),"")} -> -849 | AX16: {=IFERROR(_xlfn.IFS(OR($M16="",$AS16=""),"",$C16="Joined",($AS16-$M16)-$AT16),"")} -> -782 | AY16: =IFERROR(IF(COUNTIFS('Candidate Tracker'!$E:$E,'Positions Tracker'!$B16,'Candidate Tracker'!$C:$C,"Offer Drop")=0,"",COUNTIFS('Candidate Tracker'!$E:$E,'Positions Tracker'!$B16,'Candidate Tracker'!$C:$C,"Offer Drop")),"") | AZ16: =IFERROR(IF((COUNTIFS('Candidate Tracker'!$D:$D,"<>",'Candidate Tracker'!$D:$D,"<>Screening",'Candidate Tracker'!$D:$D,"<>Screening Pending",'Candidate Tracker'!$D:$D,"<>Candidate Hold",'Candidate Tracker'!$D:$D,"<>Position Cancelled",'Candidate Tracker'!$D:$D,"<>Internal closed")/COUNTIF('Candidate Tracker'!$D:$D,"<>"))=0,"",(COUNTIFS('Candidate Tracker'!$D:$D,"<>",'Candidate Tracker'!$D:$D,"<>Screening",'Candidate Tracker'!$D:$D,"<>Candidate Hold",'Candidate Tracker'!$D:$D,"<>Position Cancelled",'Candidate Tracker'!$D:$D,"<>Internal closed")/COUNTIF('Candidate Tracker'!$D:$D,"<>"))),"") -> 0.88111888 | BA16: =IFERROR(IF(COUNTIFS('Candidate Tracker'!$E:$E,'Positions Tracker'!$B16,'Candidate Tracker'!$I:$I,"Female")=0,"",COUNTIFS('Candidate Tracker'!$E:$E,'Positions Tracker'!$B16,'Candidate Tracker'!$I:$I,"Female")),"") | BB16: =IFERROR(IF(COUNTIFS('Candidate Tracker'!$E:$E,'Positions Tracker'!$B16,'Candidate Tracker'!$I:$I,"male")=0,"",COUNTIFS('Candidate Tracker'!$E:$E,'Positions Tracker'!$B16,'Candidate Tracker'!$I:$I,"male")),"") | BC16: =IFERROR(IF(COUNTIFS('Candidate Tracker'!$E:$E,'Positions Tracker'!$B16,'Candidate Tracker'!$C:$C,"<>WIP",'Candidate Tracker'!$C:$C,"<>Hold",'Candidate Tracker'!$C:$C,"<>Cancelled",'Candidate Tracker'!$C:$C,"<>Closed")/COUNTIFS('Candidate Tracker'!$E:$E,'Positions Tracker'!$B16)=0,"",COUNTIFS('Candidate Tracker'!$E:$E,'Positions Tracker'!$B16,'Candidate Tracker'!$C:$C,"<>WIP",'Candidate Tracker'!$C:$C,"<>Hold",'Candidate Tracker'!$C:$C,"<>Cancelled",'Candidate Tracker'!$C:$C,"<>Closed")/COUNTIFS('Candidate Tracker'!$E:$E,'Positions Tracker'!$B16)),"") | BD16: =IFERROR(IF($M16="","",TEXT($M16,"MMM-YY")),"") -> Oct-24 | BE16: =IFERROR(IF($AI16="","",TEXT($AI16,"MMM-YY")),"") -> Mar-25 | BF16: =IFERROR(IF($AM16="","",TEXT($AM16,"MMM-YY")),"") -> Apr-25 | BG16: =IFERROR(IF($AS16="","",TEXT($AS16,"MMM-YY")),"") -> Jun-25
A17: =A16+1 -> 16 | B17: TG6 | C17: Joined | D17: Joined | E17: Engineer - Firmware | F17: HMI | G17: Integrated Business Services | H17: HMI | I17: Yogesh S | J17: External | K17: 44999 | L17: 44999 | M17: 45274 | N17: T10 | X17: Pune | Y17: Raisoni, Rushabh | Z17: Priyanka Gupta | AA17: Joined | AE17: Sharikh Shaikh | AF17: 8793916009 | AG17: sharikhshaikh@gmail.com | AH17: Male | AI17: 45296 | AJ17: 45299 | AK17: Pune | AL17: 750000 | AM17: 45299 | AN17: 45299 | AP17: 45302 | AQ17: 45302 | AR17: 45360 | AS17: 45362 | AT17: =IFERROR(SUM(IF(AND(ISBLANK(T17),ISBLANK(Q17)),0,IF(T17="",TODAY()-Q17,T17-Q17))+IF(AND(ISBLANK(S17),ISBLANK(P17)),0,IF(S17="",TODAY()-P17,S17-P17))+IF(AND(ISBLANK(O17),ISBLANK(R17)),0,IF(R17="",TODAY()-O17,R17-O17))),"") -> 0 | AU17: =IFERROR(IF(($M17=""),"",IF(OR(,$C17="Offer in Progress",$C17="WIP",$C17="WIP/Drop",$C17="WIP/New",$C17="WIP/Hold"),(TODAY()-$M17)-$AT17,"")),"") | AV17: {=IFERROR(_xlfn.IFS($AU17="","",$AU17<=15,"0-15",AND($AU17>=16,$AU17<=30),"16-30",AND($AU17>=31,$AU17<=45),"31-45",AND($AU17>=46,$AU17<=60),"46-60",AND($AU17>=61,$AU17<=90),"61-90",AND($AU17>=91),"> 90",AND($AU17>=2000),""),"")} | AW17: {=IFERROR(_xlfn.IFS(OR($M17="",$AM17=""),"",OR($C17="Offered",$C17="Joined"),($AM17-$M17)-$AT17),"")} -> 25 | AX17: {=IFERROR(_xlfn.IFS(OR($M17="",$AS17=""),"",$C17="Joined",($AS17-$M17)-$AT17),"")} -> 88 | AY17: =IFERROR(IF(COUNTIFS('Candidate Tracker'!$E:$E,'Positions Tracker'!$B17,'Candidate Tracker'!$C:$C,"Offer Drop")=0,"",COUNTIFS('Candidate Tracker'!$E:$E,'Positions Tracker'!$B17,'Candidate Tracker'!$C:$C,"Offer Drop")),"") | AZ17: =IFERROR(IF((COUNTIFS('Candidate Tracker'!$D:$D,"<>",'Candidate Tracker'!$D:$D,"<>Screening",'Candidate Tracker'!$D:$D,"<>Screening Pending",'Candidate Tracker'!$D:$D,"<>Candidate Hold",'Candidate Tracker'!$D:$D,"<>Position Cancelled",'Candidate Tracker'!$D:$D,"<>Internal closed")/COUNTIF('Candidate Tracker'!$D:$D,"<>"))=0,"",(COUNTIFS('Candidate Tracker'!$D:$D,"<>",'Candidate Tracker'!$D:$D,"<>Screening",'Candidate Tracker'!$D:$D,"<>Candidate Hold",'Candidate Tracker'!$D:$D,"<>Position Cancelled",'Candidate Tracker'!$D:$D,"<>Internal closed")/COUNTIF('Candidate Tracker'!$D:$D,"<>"))),"") -> 0.88111888 | BA17: =IFERROR(IF(COUNTIFS('Candidate Tracker'!$E:$E,'Positions Tracker'!$B17,'Candidate Tracker'!$I:$I,"Female")=0,"",COUNTIFS('Candidate Tracker'!$E:$E,'Positions Tracker'!$B17,'Candidate Tracker'!$I:$I,"Female")),"") | BB17: =IFERROR(IF(COUNTIFS('Candidate Tracker'!$E:$E,'Positions Tracker'!$B17,'Candidate Tracker'!$I:$I,"male")=0,"",COUNTIFS('Candidate Tracker'!$E:$E,'Positions Tracker'!$B17,'Candidate Tracker'!$I:$I,"male")),"") -> 1 | BC17: =IFERROR(IF(COUNTIFS('Candidate Tracker'!$E:$E,'Positions Tracker'!$B17,'Candidate Tracker'!$C:$C,"<>WIP",'Candidate Tracker'!$C:$C,"<>Hold",'Candidate Tracker'!$C:$C,"<>Cancelled",'Candidate Tracker'!$C:$C,"<>Closed")/COUNTIFS('Candidate Tracker'!$E:$E,'Positions Tracker'!$B17)=0,"",COUNTIFS('Candidate Tracker'!$E:$E,'Positions Tracker'!$B17,'Candidate Tracker'!$C:$C,"<>WIP",'Candidate Tracker'!$C:$C,"<>Hold",'Candidate Tracker'!$C:$C,"<>Cancelled",'Candidate Tracker'!$C:$C,"<>Closed")/COUNTIFS('Candidate Tracker'!$E:$E,'Positions Tracker'!$B17)),"") -> 1 | BD17: =IFERROR(IF($M17="","",TEXT($M17,"MMM-YY")),"") -> Dec-23 | BE17: =IFERROR(IF($AI17="","",TEXT($AI17,"MMM-YY")),"") -> Jan-24 | BF17: =IFERROR(IF($AM17="","",TEXT($AM17,"MMM-YY")),"") -> Jan-24 | BG17: =IFERROR(IF($AS17="","",TEXT($AS17,"MMM-YY")),"") -> Mar-24
